2021-10-05 09:30:09,921 - INFO - root - Hello! This is Joey-NMT (version 1.3).
2021-10-05 09:30:09,993 - INFO - joeynmt.data - Loading training data...
2021-10-05 09:30:13,177 - INFO - joeynmt.data - Building vocabulary...
2021-10-05 09:30:13,681 - INFO - joeynmt.data - Loading dev data...
2021-10-05 09:30:13,746 - INFO - joeynmt.data - Loading test data...
2021-10-05 09:30:13,822 - INFO - joeynmt.data - Data loaded.
2021-10-05 09:30:13,822 - INFO - joeynmt.model - Building an encoder-decoder model...
2021-10-05 09:30:14,395 - INFO - joeynmt.model - Enc-dec model built.
2021-10-05 09:30:14,401 - INFO - joeynmt.training - Total params: 25158656
2021-10-05 09:30:18,910 - INFO - joeynmt.helpers - cfg.name                           : LSTM_th_b
2021-10-05 09:30:18,911 - INFO - joeynmt.helpers - cfg.data.src                       : th_b
2021-10-05 09:30:18,911 - INFO - joeynmt.helpers - cfg.data.trg                       : en_b_th
2021-10-05 09:30:18,911 - INFO - joeynmt.helpers - cfg.data.train                     : ../2DL4NLP/all_data/th_b.en_b_th/train.bpe
2021-10-05 09:30:18,911 - INFO - joeynmt.helpers - cfg.data.dev                       : ../2DL4NLP/all_data/th_b.en_b_th/val.bpe
2021-10-05 09:30:18,911 - INFO - joeynmt.helpers - cfg.data.test                      : ../2DL4NLP/all_data/th_b.en_b_th/test.bpe
2021-10-05 09:30:18,911 - INFO - joeynmt.helpers - cfg.data.level                     : bpe
2021-10-05 09:30:18,911 - INFO - joeynmt.helpers - cfg.data.lowercase                 : False
2021-10-05 09:30:18,911 - INFO - joeynmt.helpers - cfg.data.max_sent_length           : 50
2021-10-05 09:30:18,911 - INFO - joeynmt.helpers - cfg.data.src_voc_min_freq          : 0
2021-10-05 09:30:18,911 - INFO - joeynmt.helpers - cfg.data.src_voc_limit             : 100000
2021-10-05 09:30:18,912 - INFO - joeynmt.helpers - cfg.data.trg_voc_min_freq          : 0
2021-10-05 09:30:18,912 - INFO - joeynmt.helpers - cfg.data.trg_voc_limit             : 100000
2021-10-05 09:30:18,912 - INFO - joeynmt.helpers - cfg.data.src_vocab                 : ../2DL4NLP/all_data/th_b.en_b_th/th_b.en_b_th.vocab.txt
2021-10-05 09:30:18,912 - INFO - joeynmt.helpers - cfg.data.trg_vocab                 : ../2DL4NLP/all_data/th_b.en_b_th/th_b.en_b_th.vocab.txt
2021-10-05 09:30:18,912 - INFO - joeynmt.helpers - cfg.testing.beam_size              : 5
2021-10-05 09:30:18,912 - INFO - joeynmt.helpers - cfg.testing.alpha                  : 1.0
2021-10-05 09:30:18,912 - INFO - joeynmt.helpers - cfg.training.random_seed           : 42
2021-10-05 09:30:18,912 - INFO - joeynmt.helpers - cfg.training.optimizer             : adam
2021-10-05 09:30:18,912 - INFO - joeynmt.helpers - cfg.training.learning_rate         : 0.0003
2021-10-05 09:30:18,912 - INFO - joeynmt.helpers - cfg.training.learning_rate_min     : 5e-07
2021-10-05 09:30:18,912 - INFO - joeynmt.helpers - cfg.training.weight_decay          : 0.0
2021-10-05 09:30:18,913 - INFO - joeynmt.helpers - cfg.training.clip_grad_norm        : 1.0
2021-10-05 09:30:18,913 - INFO - joeynmt.helpers - cfg.training.batch_size            : 80
2021-10-05 09:30:18,913 - INFO - joeynmt.helpers - cfg.training.scheduling            : plateau
2021-10-05 09:30:18,913 - INFO - joeynmt.helpers - cfg.training.patience              : 10
2021-10-05 09:30:18,913 - INFO - joeynmt.helpers - cfg.training.decrease_factor       : 0.5
2021-10-05 09:30:18,913 - INFO - joeynmt.helpers - cfg.training.early_stopping_metric : eval_metric
2021-10-05 09:30:18,913 - INFO - joeynmt.helpers - cfg.training.epochs                : 20
2021-10-05 09:30:18,913 - INFO - joeynmt.helpers - cfg.training.validation_freq       : 100
2021-10-05 09:30:18,913 - INFO - joeynmt.helpers - cfg.training.logging_freq          : 1000
2021-10-05 09:30:18,913 - INFO - joeynmt.helpers - cfg.training.eval_metric           : bleu
2021-10-05 09:30:18,913 - INFO - joeynmt.helpers - cfg.training.model_dir             : models/LSTM_th_b
2021-10-05 09:30:18,913 - INFO - joeynmt.helpers - cfg.training.overwrite             : True
2021-10-05 09:30:18,914 - INFO - joeynmt.helpers - cfg.training.shuffle               : True
2021-10-05 09:30:18,914 - INFO - joeynmt.helpers - cfg.training.use_cuda              : True
2021-10-05 09:30:18,914 - INFO - joeynmt.helpers - cfg.training.max_output_length     : 100
2021-10-05 09:30:18,914 - INFO - joeynmt.helpers - cfg.training.print_valid_sents     : [0, 1, 2]
2021-10-05 09:30:18,914 - INFO - joeynmt.helpers - cfg.training.keep_best_ckpts       : 1
2021-10-05 09:30:18,914 - INFO - joeynmt.helpers - cfg.training.save_latest_ckpt      : True
2021-10-05 09:30:18,914 - INFO - joeynmt.helpers - cfg.model.encoder.rnn_type         : lstm
2021-10-05 09:30:18,914 - INFO - joeynmt.helpers - cfg.model.encoder.embeddings.embedding_dim : 512
2021-10-05 09:30:18,914 - INFO - joeynmt.helpers - cfg.model.encoder.embeddings.scale : False
2021-10-05 09:30:18,914 - INFO - joeynmt.helpers - cfg.model.encoder.hidden_size      : 512
2021-10-05 09:30:18,914 - INFO - joeynmt.helpers - cfg.model.encoder.bidirectional    : False
2021-10-05 09:30:18,915 - INFO - joeynmt.helpers - cfg.model.encoder.dropout          : 0.2
2021-10-05 09:30:18,915 - INFO - joeynmt.helpers - cfg.model.encoder.num_layers       : 1
2021-10-05 09:30:18,915 - INFO - joeynmt.helpers - cfg.model.decoder.rnn_type         : lstm
2021-10-05 09:30:18,915 - INFO - joeynmt.helpers - cfg.model.decoder.embeddings.embedding_dim : 512
2021-10-05 09:30:18,915 - INFO - joeynmt.helpers - cfg.model.decoder.embeddings.scale : False
2021-10-05 09:30:18,915 - INFO - joeynmt.helpers - cfg.model.decoder.emb_scale        : False
2021-10-05 09:30:18,915 - INFO - joeynmt.helpers - cfg.model.decoder.hidden_size      : 1024
2021-10-05 09:30:18,915 - INFO - joeynmt.helpers - cfg.model.decoder.dropout          : 0.2
2021-10-05 09:30:18,915 - INFO - joeynmt.helpers - cfg.model.decoder.hidden_dropout   : 0.2
2021-10-05 09:30:18,915 - INFO - joeynmt.helpers - cfg.model.decoder.num_layers       : 1
2021-10-05 09:30:18,915 - INFO - joeynmt.helpers - cfg.model.decoder.input_feeding    : True
2021-10-05 09:30:18,916 - INFO - joeynmt.helpers - cfg.model.decoder.init_hidden      : bridge
2021-10-05 09:30:18,916 - INFO - joeynmt.helpers - cfg.model.decoder.attention        : bahdanau
2021-10-05 09:30:18,916 - INFO - joeynmt.helpers - Data set sizes: 
	train 73893,
	valid 2990,
	test 3714
2021-10-05 09:30:18,916 - INFO - joeynmt.helpers - First training example:
	[SRC] th
	[TRG] en
--- Logging error ---
Traceback (most recent call last):
  File "/sw/arch/Debian10/EB_production/2019/software/Anaconda3/2018.12/lib/python3.7/logging/__init__.py", line 1036, in emit
    stream.write(msg)
UnicodeEncodeError: 'latin-1' codec can't encode character '\u0e48' in position 114: ordinal not in range(256)
Call stack:
  File "/sw/arch/Debian10/EB_production/2019/software/Anaconda3/2018.12/lib/python3.7/runpy.py", line 193, in _run_module_as_main
    "__main__", mod_spec)
  File "/sw/arch/Debian10/EB_production/2019/software/Anaconda3/2018.12/lib/python3.7/runpy.py", line 85, in _run_code
    exec(code, run_globals)
  File "/home/lcur0007/joeynmt/joeynmt/__main__.py", line 48, in <module>
    main()
  File "/home/lcur0007/joeynmt/joeynmt/__main__.py", line 35, in main
    train(cfg_file=args.config_path, skip_test=args.skip_test)
  File "/home/lcur0007/joeynmt/joeynmt/training.py", line 835, in train
    trg_vocab=trg_vocab)
  File "/home/lcur0007/joeynmt/joeynmt/helpers.py", line 164, in log_data_info
    " ".join('(%d) %s' % (i, t) for i, t in enumerate(src_vocab.itos[:10])))
Message: 'First 10 words (src): %s'
Arguments: ('(0) <unk> (1) <pad> (2) <s> (3) </s> (4) \u0e48 (5) \u0e49 (6) , (7) \u0e47 (8) the (9) ."',)
2021-10-05 09:30:18,916 - INFO - joeynmt.helpers - First 10 words (src): (0) <unk> (1) <pad> (2) <s> (3) </s> (4) \u0e48 (5) \u0e49 (6) , (7) \u0e47 (8) the (9) ."
--- Logging error ---
Traceback (most recent call last):
  File "/sw/arch/Debian10/EB_production/2019/software/Anaconda3/2018.12/lib/python3.7/logging/__init__.py", line 1036, in emit
    stream.write(msg)
UnicodeEncodeError: 'latin-1' codec can't encode character '\u0e48' in position 114: ordinal not in range(256)
Call stack:
  File "/sw/arch/Debian10/EB_production/2019/software/Anaconda3/2018.12/lib/python3.7/runpy.py", line 193, in _run_module_as_main
    "__main__", mod_spec)
  File "/sw/arch/Debian10/EB_production/2019/software/Anaconda3/2018.12/lib/python3.7/runpy.py", line 85, in _run_code
    exec(code, run_globals)
  File "/home/lcur0007/joeynmt/joeynmt/__main__.py", line 48, in <module>
    main()
  File "/home/lcur0007/joeynmt/joeynmt/__main__.py", line 35, in main
    train(cfg_file=args.config_path, skip_test=args.skip_test)
  File "/home/lcur0007/joeynmt/joeynmt/training.py", line 835, in train
    trg_vocab=trg_vocab)
  File "/home/lcur0007/joeynmt/joeynmt/helpers.py", line 167, in log_data_info
    " ".join('(%d) %s' % (i, t) for i, t in enumerate(trg_vocab.itos[:10])))
Message: 'First 10 words (trg): %s'
Arguments: ('(0) <unk> (1) <pad> (2) <s> (3) </s> (4) \u0e48 (5) \u0e49 (6) , (7) \u0e47 (8) the (9) ."',)
2021-10-05 09:30:18,918 - INFO - joeynmt.helpers - First 10 words (trg): (0) <unk> (1) <pad> (2) <s> (3) </s> (4) \u0e48 (5) \u0e49 (6) , (7) \u0e47 (8) the (9) ."
2021-10-05 09:30:18,918 - INFO - joeynmt.helpers - Number of Src words (types): 4341
2021-10-05 09:30:18,918 - INFO - joeynmt.helpers - Number of Trg words (types): 4341
2021-10-05 09:30:18,919 - INFO - joeynmt.training - Model(
	encoder=RecurrentEncoder(LSTM(512, 512, batch_first=True)),
	decoder=RecurrentDecoder(rnn=LSTM(1536, 1024, batch_first=True), attention=BahdanauAttention),
	src_embed=Embeddings(embedding_dim=512, vocab_size=4341),
	trg_embed=Embeddings(embedding_dim=512, vocab_size=4341))
2021-10-05 09:30:18,928 - INFO - joeynmt.training - Train stats:
	device: cuda
	n_gpu: 1
	16-bits training: False
	gradient accumulation: 1
	batch size per device: 80
	total batch size (w. parallel & accumulation): 80
2021-10-05 09:30:18,928 - INFO - joeynmt.training - EPOCH 1
2021-10-05 09:31:00,627 - WARNING - sacrebleu - That's 100 lines that end in a tokenized period ('.')
2021-10-05 09:31:00,628 - WARNING - sacrebleu - It looks like you forgot to detokenize your test data, which may hurt your score.
2021-10-05 09:31:00,628 - WARNING - sacrebleu - If you insist your data is detokenized, or don't care, you can suppress this message with the `force` parameter.
2021-10-05 09:31:00,651 - INFO - joeynmt.training - Hooray! New best validation result [eval_metric]!
2021-10-05 09:31:01,590 - INFO - joeynmt.training - Example #0
2021-10-05 09:31:01,590 - INFO - joeynmt.training - 	Source:     th
2021-10-05 09:31:01,590 - INFO - joeynmt.training - 	Reference:  en
2021-10-05 09:31:01,591 - INFO - joeynmt.training - 	Hypothesis: I .
2021-10-05 09:31:01,591 - INFO - joeynmt.training - Example #1
--- Logging error ---
Traceback (most recent call last):
  File "/sw/arch/Debian10/EB_production/2019/software/Anaconda3/2018.12/lib/python3.7/logging/__init__.py", line 1036, in emit
    stream.write(msg)
UnicodeEncodeError: 'latin-1' codec can't encode characters in position 72-74: ordinal not in range(256)
Call stack:
  File "/sw/arch/Debian10/EB_production/2019/software/Anaconda3/2018.12/lib/python3.7/runpy.py", line 193, in _run_module_as_main
    "__main__", mod_spec)
  File "/sw/arch/Debian10/EB_production/2019/software/Anaconda3/2018.12/lib/python3.7/runpy.py", line 85, in _run_code
    exec(code, run_globals)
  File "/home/lcur0007/joeynmt/joeynmt/__main__.py", line 48, in <module>
    main()
  File "/home/lcur0007/joeynmt/joeynmt/__main__.py", line 35, in main
    train(cfg_file=args.config_path, skip_test=args.skip_test)
  File "/home/lcur0007/joeynmt/joeynmt/training.py", line 846, in train
    trainer.train_and_validate(train_data=train_data, valid_data=dev_data)
  File "/home/lcur0007/joeynmt/joeynmt/training.py", line 497, in train_and_validate
    valid_duration = self._validate(valid_data, epoch_no)
  File "/home/lcur0007/joeynmt/joeynmt/training.py", line 642, in _validate
    references=valid_references)
  File "/home/lcur0007/joeynmt/joeynmt/training.py", line 731, in _log_examples
    logger.debug("\tRaw source:     %s", sources_raw[p])
Message: '\tRaw source:     %s'
Arguments: (['\u0e15\u0e2d\u0e19@@', '\u0e09\u0e31\u0e19@@', '\u0e2d\u0e32\u0e22\u0e38', '11', '\u0e09\u0e31\u0e19@@', '\u0e08\u0e33@@', '\u0e44\u0e14', '\u0e49', '\u0e27', '\u0e48', '\u0e32@@', '\u0e15\u0e37', '\u0e48', '\u0e19\u0e02\u0e36', '\u0e49', '\u0e19\u0e21\u0e32@@', '\u0e40\u0e0a', '\u0e49', '\u0e32\u0e27@@', '\u0e31\u0e19@@', '\u0e2b\u0e19\u0e36', '\u0e48', '\u0e07', '\u0e41\u0e25\u0e30@@', '\u0e44\u0e14', '\u0e49', '\u0e22\u0e34\u0e19@@', '\u0e40\u0e2a\u0e35\u0e22\u0e07@@', '\u0e23', '\u0e49', '\u0e2d\u0e07@@', '\u0e14', '\u0e49', '\u0e27\u0e22\u0e04\u0e27\u0e32\u0e21@@', '\u0e22\u0e34\u0e19@@', '\u0e14\u0e35@@', '\u0e43\u0e19@@', '\u0e1a', '\u0e49', '\u0e32\u0e19'],)
--- Logging error ---
Traceback (most recent call last):
  File "/sw/arch/Debian10/EB_production/2019/software/Anaconda3/2018.12/lib/python3.7/logging/__init__.py", line 1036, in emit
    stream.write(msg)
UnicodeEncodeError: 'latin-1' codec can't encode characters in position 65-74: ordinal not in range(256)
Call stack:
  File "/sw/arch/Debian10/EB_production/2019/software/Anaconda3/2018.12/lib/python3.7/runpy.py", line 193, in _run_module_as_main
    "__main__", mod_spec)
  File "/sw/arch/Debian10/EB_production/2019/software/Anaconda3/2018.12/lib/python3.7/runpy.py", line 85, in _run_code
    exec(code, run_globals)
  File "/home/lcur0007/joeynmt/joeynmt/__main__.py", line 48, in <module>
    main()
  File "/home/lcur0007/joeynmt/joeynmt/__main__.py", line 35, in main
    train(cfg_file=args.config_path, skip_test=args.skip_test)
  File "/home/lcur0007/joeynmt/joeynmt/training.py", line 846, in train
    trainer.train_and_validate(train_data=train_data, valid_data=dev_data)
  File "/home/lcur0007/joeynmt/joeynmt/training.py", line 497, in train_and_validate
    valid_duration = self._validate(valid_data, epoch_no)
  File "/home/lcur0007/joeynmt/joeynmt/training.py", line 642, in _validate
    references=valid_references)
  File "/home/lcur0007/joeynmt/joeynmt/training.py", line 737, in _log_examples
    logger.info("\tSource:     %s", sources[p])
Message: '\tSource:     %s'
Arguments: ('\u0e15\u0e2d\u0e19\u0e09\u0e31\u0e19\u0e2d\u0e32\u0e22\u0e38 11 \u0e09\u0e31\u0e19\u0e08\u0e33\u0e44\u0e14 \u0e49 \u0e27 \u0e48 \u0e32\u0e15\u0e37 \u0e48 \u0e19\u0e02\u0e36 \u0e49 \u0e19\u0e21\u0e32\u0e40\u0e0a \u0e49 \u0e32\u0e27\u0e31\u0e19\u0e2b\u0e19\u0e36 \u0e48 \u0e07 \u0e41\u0e25\u0e30\u0e44\u0e14 \u0e49 \u0e22\u0e34\u0e19\u0e40\u0e2a\u0e35\u0e22\u0e07\u0e23 \u0e49 \u0e2d\u0e07\u0e14 \u0e49 \u0e27\u0e22\u0e04\u0e27\u0e32\u0e21\u0e22\u0e34\u0e19\u0e14\u0e35\u0e43\u0e19\u0e1a \u0e49 \u0e32\u0e19',)
2021-10-05 09:31:01,593 - INFO - joeynmt.training - 	Source:     \u0e15\u0e2d\u0e19\u0e09\u0e31\u0e19\u0e2d\u0e32\u0e22\u0e38 11 \u0e09\u0e31\u0e19\u0e08\u0e33\u0e44\u0e14 \u0e49 \u0e27 \u0e48 \u0e32\u0e15\u0e37 \u0e48 \u0e19\u0e02\u0e36 \u0e49 \u0e19\u0e21\u0e32\u0e40\u0e0a \u0e49 \u0e32\u0e27\u0e31\u0e19\u0e2b\u0e19\u0e36 \u0e48 \u0e07 \u0e41\u0e25\u0e30\u0e44\u0e14 \u0e49 \u0e22\u0e34\u0e19\u0e40\u0e2a\u0e35\u0e22\u0e07\u0e23 \u0e49 \u0e2d\u0e07\u0e14 \u0e49 \u0e27\u0e22\u0e04\u0e27\u0e32\u0e21\u0e22\u0e34\u0e19\u0e14\u0e35\u0e43\u0e19\u0e1a \u0e49 \u0e32\u0e19
2021-10-05 09:31:01,593 - INFO - joeynmt.training - 	Reference:  "When I was 11 , I remember waking up one morning to the sound of joy in my house ."
2021-10-05 09:31:01,594 - INFO - joeynmt.training - 	Hypothesis: "And I , , , , , , , , , , , , , , , , , , , , , , , , , , , , , , , ."
2021-10-05 09:31:01,594 - INFO - joeynmt.training - Example #2
--- Logging error ---
Traceback (most recent call last):
  File "/sw/arch/Debian10/EB_production/2019/software/Anaconda3/2018.12/lib/python3.7/logging/__init__.py", line 1036, in emit
    stream.write(msg)
UnicodeEncodeError: 'latin-1' codec can't encode character '\u0e1e' in position 72: ordinal not in range(256)
Call stack:
  File "/sw/arch/Debian10/EB_production/2019/software/Anaconda3/2018.12/lib/python3.7/runpy.py", line 193, in _run_module_as_main
    "__main__", mod_spec)
  File "/sw/arch/Debian10/EB_production/2019/software/Anaconda3/2018.12/lib/python3.7/runpy.py", line 85, in _run_code
    exec(code, run_globals)
  File "/home/lcur0007/joeynmt/joeynmt/__main__.py", line 48, in <module>
    main()
  File "/home/lcur0007/joeynmt/joeynmt/__main__.py", line 35, in main
    train(cfg_file=args.config_path, skip_test=args.skip_test)
  File "/home/lcur0007/joeynmt/joeynmt/training.py", line 846, in train
    trainer.train_and_validate(train_data=train_data, valid_data=dev_data)
  File "/home/lcur0007/joeynmt/joeynmt/training.py", line 497, in train_and_validate
    valid_duration = self._validate(valid_data, epoch_no)
  File "/home/lcur0007/joeynmt/joeynmt/training.py", line 642, in _validate
    references=valid_references)
  File "/home/lcur0007/joeynmt/joeynmt/training.py", line 731, in _log_examples
    logger.debug("\tRaw source:     %s", sources_raw[p])
Message: '\tRaw source:     %s'
Arguments: (['\u0e1e', '\u0e48', '\u0e2d@@', '\u0e02\u0e2d\u0e07\u0e09\u0e31\u0e19@@', '\u0e01\u0e33\u0e25\u0e31\u0e07@@', '\u0e1f\u0e31\u0e07@@', '\u0e02', '\u0e48', '\u0e32\u0e27@@', '\u0e1a\u0e35@@', '\u0e1a\u0e35@@', '\u0e0b\u0e35', '\u0e08\u0e32\u0e01@@', '\u0e27\u0e34\u0e17@@', '\u0e22\u0e38@@', '\u0e2a\u0e35@@', '\u0e40\u0e17@@', '\u0e32@@', '\u0e2d\u0e31\u0e19@@', '\u0e40\u0e25', '\u0e47', '\u0e01'],)
--- Logging error ---
Traceback (most recent call last):
  File "/sw/arch/Debian10/EB_production/2019/software/Anaconda3/2018.12/lib/python3.7/logging/__init__.py", line 1036, in emit
    stream.write(msg)
UnicodeEncodeError: 'latin-1' codec can't encode character '\u0e1e' in position 65: ordinal not in range(256)
Call stack:
  File "/sw/arch/Debian10/EB_production/2019/software/Anaconda3/2018.12/lib/python3.7/runpy.py", line 193, in _run_module_as_main
    "__main__", mod_spec)
  File "/sw/arch/Debian10/EB_production/2019/software/Anaconda3/2018.12/lib/python3.7/runpy.py", line 85, in _run_code
    exec(code, run_globals)
  File "/home/lcur0007/joeynmt/joeynmt/__main__.py", line 48, in <module>
    main()
  File "/home/lcur0007/joeynmt/joeynmt/__main__.py", line 35, in main
    train(cfg_file=args.config_path, skip_test=args.skip_test)
  File "/home/lcur0007/joeynmt/joeynmt/training.py", line 846, in train
    trainer.train_and_validate(train_data=train_data, valid_data=dev_data)
  File "/home/lcur0007/joeynmt/joeynmt/training.py", line 497, in train_and_validate
    valid_duration = self._validate(valid_data, epoch_no)
  File "/home/lcur0007/joeynmt/joeynmt/training.py", line 642, in _validate
    references=valid_references)
  File "/home/lcur0007/joeynmt/joeynmt/training.py", line 737, in _log_examples
    logger.info("\tSource:     %s", sources[p])
Message: '\tSource:     %s'
Arguments: ('\u0e1e \u0e48 \u0e2d\u0e02\u0e2d\u0e07\u0e09\u0e31\u0e19\u0e01\u0e33\u0e25\u0e31\u0e07\u0e1f\u0e31\u0e07\u0e02 \u0e48 \u0e32\u0e27\u0e1a\u0e35\u0e1a\u0e35\u0e0b\u0e35 \u0e08\u0e32\u0e01\u0e27\u0e34\u0e17\u0e22\u0e38\u0e2a\u0e35\u0e40\u0e17\u0e32\u0e2d\u0e31\u0e19\u0e40\u0e25 \u0e47 \u0e01',)
2021-10-05 09:31:01,595 - INFO - joeynmt.training - 	Source:     \u0e1e \u0e48 \u0e2d\u0e02\u0e2d\u0e07\u0e09\u0e31\u0e19\u0e01\u0e33\u0e25\u0e31\u0e07\u0e1f\u0e31\u0e07\u0e02 \u0e48 \u0e32\u0e27\u0e1a\u0e35\u0e1a\u0e35\u0e0b\u0e35 \u0e08\u0e32\u0e01\u0e27\u0e34\u0e17\u0e22\u0e38\u0e2a\u0e35\u0e40\u0e17\u0e32\u0e2d\u0e31\u0e19\u0e40\u0e25 \u0e47 \u0e01
2021-10-05 09:31:01,595 - INFO - joeynmt.training - 	Reference:  "My father was listening to BBC News on his small , gray radio ."
2021-10-05 09:31:01,595 - INFO - joeynmt.training - 	Hypothesis: "And &apos;s a , , , , , , , , , .
2021-10-05 09:31:01,595 - INFO - joeynmt.training - Validation result (greedy) at epoch   1, step      100: bleu:   1.66, loss: 550310.4375, ppl: 491.4691, duration: 22.4832s
2021-10-05 09:31:47,030 - WARNING - sacrebleu - That's 100 lines that end in a tokenized period ('.')
2021-10-05 09:31:47,031 - WARNING - sacrebleu - It looks like you forgot to detokenize your test data, which may hurt your score.
2021-10-05 09:31:47,031 - WARNING - sacrebleu - If you insist your data is detokenized, or don't care, you can suppress this message with the `force` parameter.
2021-10-05 09:31:47,056 - INFO - joeynmt.training - Example #0
2021-10-05 09:31:47,057 - INFO - joeynmt.training - 	Source:     th
2021-10-05 09:31:47,057 - INFO - joeynmt.training - 	Reference:  en
2021-10-05 09:31:47,057 - INFO - joeynmt.training - 	Hypothesis: ( Applause .
2021-10-05 09:31:47,057 - INFO - joeynmt.training - Example #1
--- Logging error ---
Traceback (most recent call last):
  File "/sw/arch/Debian10/EB_production/2019/software/Anaconda3/2018.12/lib/python3.7/logging/__init__.py", line 1036, in emit
    stream.write(msg)
UnicodeEncodeError: 'latin-1' codec can't encode characters in position 72-74: ordinal not in range(256)
Call stack:
  File "/sw/arch/Debian10/EB_production/2019/software/Anaconda3/2018.12/lib/python3.7/runpy.py", line 193, in _run_module_as_main
    "__main__", mod_spec)
  File "/sw/arch/Debian10/EB_production/2019/software/Anaconda3/2018.12/lib/python3.7/runpy.py", line 85, in _run_code
    exec(code, run_globals)
  File "/home/lcur0007/joeynmt/joeynmt/__main__.py", line 48, in <module>
    main()
  File "/home/lcur0007/joeynmt/joeynmt/__main__.py", line 35, in main
    train(cfg_file=args.config_path, skip_test=args.skip_test)
  File "/home/lcur0007/joeynmt/joeynmt/training.py", line 846, in train
    trainer.train_and_validate(train_data=train_data, valid_data=dev_data)
  File "/home/lcur0007/joeynmt/joeynmt/training.py", line 497, in train_and_validate
    valid_duration = self._validate(valid_data, epoch_no)
  File "/home/lcur0007/joeynmt/joeynmt/training.py", line 642, in _validate
    references=valid_references)
  File "/home/lcur0007/joeynmt/joeynmt/training.py", line 731, in _log_examples
    logger.debug("\tRaw source:     %s", sources_raw[p])
Message: '\tRaw source:     %s'
Arguments: (['\u0e15\u0e2d\u0e19@@', '\u0e09\u0e31\u0e19@@', '\u0e2d\u0e32\u0e22\u0e38', '11', '\u0e09\u0e31\u0e19@@', '\u0e08\u0e33@@', '\u0e44\u0e14', '\u0e49', '\u0e27', '\u0e48', '\u0e32@@', '\u0e15\u0e37', '\u0e48', '\u0e19\u0e02\u0e36', '\u0e49', '\u0e19\u0e21\u0e32@@', '\u0e40\u0e0a', '\u0e49', '\u0e32\u0e27@@', '\u0e31\u0e19@@', '\u0e2b\u0e19\u0e36', '\u0e48', '\u0e07', '\u0e41\u0e25\u0e30@@', '\u0e44\u0e14', '\u0e49', '\u0e22\u0e34\u0e19@@', '\u0e40\u0e2a\u0e35\u0e22\u0e07@@', '\u0e23', '\u0e49', '\u0e2d\u0e07@@', '\u0e14', '\u0e49', '\u0e27\u0e22\u0e04\u0e27\u0e32\u0e21@@', '\u0e22\u0e34\u0e19@@', '\u0e14\u0e35@@', '\u0e43\u0e19@@', '\u0e1a', '\u0e49', '\u0e32\u0e19'],)
--- Logging error ---
Traceback (most recent call last):
  File "/sw/arch/Debian10/EB_production/2019/software/Anaconda3/2018.12/lib/python3.7/logging/__init__.py", line 1036, in emit
    stream.write(msg)
UnicodeEncodeError: 'latin-1' codec can't encode characters in position 65-74: ordinal not in range(256)
Call stack:
  File "/sw/arch/Debian10/EB_production/2019/software/Anaconda3/2018.12/lib/python3.7/runpy.py", line 193, in _run_module_as_main
    "__main__", mod_spec)
  File "/sw/arch/Debian10/EB_production/2019/software/Anaconda3/2018.12/lib/python3.7/runpy.py", line 85, in _run_code
    exec(code, run_globals)
  File "/home/lcur0007/joeynmt/joeynmt/__main__.py", line 48, in <module>
    main()
  File "/home/lcur0007/joeynmt/joeynmt/__main__.py", line 35, in main
    train(cfg_file=args.config_path, skip_test=args.skip_test)
  File "/home/lcur0007/joeynmt/joeynmt/training.py", line 846, in train
    trainer.train_and_validate(train_data=train_data, valid_data=dev_data)
  File "/home/lcur0007/joeynmt/joeynmt/training.py", line 497, in train_and_validate
    valid_duration = self._validate(valid_data, epoch_no)
  File "/home/lcur0007/joeynmt/joeynmt/training.py", line 642, in _validate
    references=valid_references)
  File "/home/lcur0007/joeynmt/joeynmt/training.py", line 737, in _log_examples
    logger.info("\tSource:     %s", sources[p])
Message: '\tSource:     %s'
Arguments: ('\u0e15\u0e2d\u0e19\u0e09\u0e31\u0e19\u0e2d\u0e32\u0e22\u0e38 11 \u0e09\u0e31\u0e19\u0e08\u0e33\u0e44\u0e14 \u0e49 \u0e27 \u0e48 \u0e32\u0e15\u0e37 \u0e48 \u0e19\u0e02\u0e36 \u0e49 \u0e19\u0e21\u0e32\u0e40\u0e0a \u0e49 \u0e32\u0e27\u0e31\u0e19\u0e2b\u0e19\u0e36 \u0e48 \u0e07 \u0e41\u0e25\u0e30\u0e44\u0e14 \u0e49 \u0e22\u0e34\u0e19\u0e40\u0e2a\u0e35\u0e22\u0e07\u0e23 \u0e49 \u0e2d\u0e07\u0e14 \u0e49 \u0e27\u0e22\u0e04\u0e27\u0e32\u0e21\u0e22\u0e34\u0e19\u0e14\u0e35\u0e43\u0e19\u0e1a \u0e49 \u0e32\u0e19',)
2021-10-05 09:31:47,058 - INFO - joeynmt.training - 	Source:     \u0e15\u0e2d\u0e19\u0e09\u0e31\u0e19\u0e2d\u0e32\u0e22\u0e38 11 \u0e09\u0e31\u0e19\u0e08\u0e33\u0e44\u0e14 \u0e49 \u0e27 \u0e48 \u0e32\u0e15\u0e37 \u0e48 \u0e19\u0e02\u0e36 \u0e49 \u0e19\u0e21\u0e32\u0e40\u0e0a \u0e49 \u0e32\u0e27\u0e31\u0e19\u0e2b\u0e19\u0e36 \u0e48 \u0e07 \u0e41\u0e25\u0e30\u0e44\u0e14 \u0e49 \u0e22\u0e34\u0e19\u0e40\u0e2a\u0e35\u0e22\u0e07\u0e23 \u0e49 \u0e2d\u0e07\u0e14 \u0e49 \u0e27\u0e22\u0e04\u0e27\u0e32\u0e21\u0e22\u0e34\u0e19\u0e14\u0e35\u0e43\u0e19\u0e1a \u0e49 \u0e32\u0e19
2021-10-05 09:31:47,059 - INFO - joeynmt.training - 	Reference:  "When I was 11 , I remember waking up one morning to the sound of joy in my house ."
2021-10-05 09:31:47,059 - INFO - joeynmt.training - 	Hypothesis: "And I the the the the the the the the the the the the the the the the the the the the the the the the the the the the the the the the the the the the the the the the the the the the the the the the the the the the the the the the the the the the the the the the the the the the the the the the the the the the the the the the the the the the the the the the the the the the the the the the the the
2021-10-05 09:31:47,059 - INFO - joeynmt.training - Example #2
--- Logging error ---
Traceback (most recent call last):
  File "/sw/arch/Debian10/EB_production/2019/software/Anaconda3/2018.12/lib/python3.7/logging/__init__.py", line 1036, in emit
    stream.write(msg)
UnicodeEncodeError: 'latin-1' codec can't encode character '\u0e1e' in position 72: ordinal not in range(256)
Call stack:
  File "/sw/arch/Debian10/EB_production/2019/software/Anaconda3/2018.12/lib/python3.7/runpy.py", line 193, in _run_module_as_main
    "__main__", mod_spec)
  File "/sw/arch/Debian10/EB_production/2019/software/Anaconda3/2018.12/lib/python3.7/runpy.py", line 85, in _run_code
    exec(code, run_globals)
  File "/home/lcur0007/joeynmt/joeynmt/__main__.py", line 48, in <module>
    main()
  File "/home/lcur0007/joeynmt/joeynmt/__main__.py", line 35, in main
    train(cfg_file=args.config_path, skip_test=args.skip_test)
  File "/home/lcur0007/joeynmt/joeynmt/training.py", line 846, in train
    trainer.train_and_validate(train_data=train_data, valid_data=dev_data)
  File "/home/lcur0007/joeynmt/joeynmt/training.py", line 497, in train_and_validate
    valid_duration = self._validate(valid_data, epoch_no)
  File "/home/lcur0007/joeynmt/joeynmt/training.py", line 642, in _validate
    references=valid_references)
  File "/home/lcur0007/joeynmt/joeynmt/training.py", line 731, in _log_examples
    logger.debug("\tRaw source:     %s", sources_raw[p])
Message: '\tRaw source:     %s'
Arguments: (['\u0e1e', '\u0e48', '\u0e2d@@', '\u0e02\u0e2d\u0e07\u0e09\u0e31\u0e19@@', '\u0e01\u0e33\u0e25\u0e31\u0e07@@', '\u0e1f\u0e31\u0e07@@', '\u0e02', '\u0e48', '\u0e32\u0e27@@', '\u0e1a\u0e35@@', '\u0e1a\u0e35@@', '\u0e0b\u0e35', '\u0e08\u0e32\u0e01@@', '\u0e27\u0e34\u0e17@@', '\u0e22\u0e38@@', '\u0e2a\u0e35@@', '\u0e40\u0e17@@', '\u0e32@@', '\u0e2d\u0e31\u0e19@@', '\u0e40\u0e25', '\u0e47', '\u0e01'],)
--- Logging error ---
Traceback (most recent call last):
  File "/sw/arch/Debian10/EB_production/2019/software/Anaconda3/2018.12/lib/python3.7/logging/__init__.py", line 1036, in emit
    stream.write(msg)
UnicodeEncodeError: 'latin-1' codec can't encode character '\u0e1e' in position 65: ordinal not in range(256)
Call stack:
  File "/sw/arch/Debian10/EB_production/2019/software/Anaconda3/2018.12/lib/python3.7/runpy.py", line 193, in _run_module_as_main
    "__main__", mod_spec)
  File "/sw/arch/Debian10/EB_production/2019/software/Anaconda3/2018.12/lib/python3.7/runpy.py", line 85, in _run_code
    exec(code, run_globals)
  File "/home/lcur0007/joeynmt/joeynmt/__main__.py", line 48, in <module>
    main()
  File "/home/lcur0007/joeynmt/joeynmt/__main__.py", line 35, in main
    train(cfg_file=args.config_path, skip_test=args.skip_test)
  File "/home/lcur0007/joeynmt/joeynmt/training.py", line 846, in train
    trainer.train_and_validate(train_data=train_data, valid_data=dev_data)
  File "/home/lcur0007/joeynmt/joeynmt/training.py", line 497, in train_and_validate
    valid_duration = self._validate(valid_data, epoch_no)
  File "/home/lcur0007/joeynmt/joeynmt/training.py", line 642, in _validate
    references=valid_references)
  File "/home/lcur0007/joeynmt/joeynmt/training.py", line 737, in _log_examples
    logger.info("\tSource:     %s", sources[p])
Message: '\tSource:     %s'
Arguments: ('\u0e1e \u0e48 \u0e2d\u0e02\u0e2d\u0e07\u0e09\u0e31\u0e19\u0e01\u0e33\u0e25\u0e31\u0e07\u0e1f\u0e31\u0e07\u0e02 \u0e48 \u0e32\u0e27\u0e1a\u0e35\u0e1a\u0e35\u0e0b\u0e35 \u0e08\u0e32\u0e01\u0e27\u0e34\u0e17\u0e22\u0e38\u0e2a\u0e35\u0e40\u0e17\u0e32\u0e2d\u0e31\u0e19\u0e40\u0e25 \u0e47 \u0e01',)
2021-10-05 09:31:47,059 - INFO - joeynmt.training - 	Source:     \u0e1e \u0e48 \u0e2d\u0e02\u0e2d\u0e07\u0e09\u0e31\u0e19\u0e01\u0e33\u0e25\u0e31\u0e07\u0e1f\u0e31\u0e07\u0e02 \u0e48 \u0e32\u0e27\u0e1a\u0e35\u0e1a\u0e35\u0e0b\u0e35 \u0e08\u0e32\u0e01\u0e27\u0e34\u0e17\u0e22\u0e38\u0e2a\u0e35\u0e40\u0e17\u0e32\u0e2d\u0e31\u0e19\u0e40\u0e25 \u0e47 \u0e01
2021-10-05 09:31:47,060 - INFO - joeynmt.training - 	Reference:  "My father was listening to BBC News on his small , gray radio ."
2021-10-05 09:31:47,060 - INFO - joeynmt.training - 	Hypothesis: "And I the the the the the the the the the the the the the the the the the the the the the the the the the the the the the the the the the the the the the the ."
2021-10-05 09:31:47,060 - INFO - joeynmt.training - Validation result (greedy) at epoch   1, step      200: bleu:   0.42, loss: 529103.6875, ppl: 387.0587, duration: 23.3633s
2021-10-05 09:32:28,295 - WARNING - sacrebleu - That's 100 lines that end in a tokenized period ('.')
2021-10-05 09:32:28,296 - WARNING - sacrebleu - It looks like you forgot to detokenize your test data, which may hurt your score.
2021-10-05 09:32:28,296 - WARNING - sacrebleu - If you insist your data is detokenized, or don't care, you can suppress this message with the `force` parameter.
2021-10-05 09:32:28,324 - INFO - joeynmt.training - Example #0
2021-10-05 09:32:28,324 - INFO - joeynmt.training - 	Source:     th
2021-10-05 09:32:28,324 - INFO - joeynmt.training - 	Reference:  en
2021-10-05 09:32:28,324 - INFO - joeynmt.training - 	Hypothesis: (
2021-10-05 09:32:28,325 - INFO - joeynmt.training - Example #1
--- Logging error ---
Traceback (most recent call last):
  File "/sw/arch/Debian10/EB_production/2019/software/Anaconda3/2018.12/lib/python3.7/logging/__init__.py", line 1036, in emit
    stream.write(msg)
UnicodeEncodeError: 'latin-1' codec can't encode characters in position 72-74: ordinal not in range(256)
Call stack:
  File "/sw/arch/Debian10/EB_production/2019/software/Anaconda3/2018.12/lib/python3.7/runpy.py", line 193, in _run_module_as_main
    "__main__", mod_spec)
  File "/sw/arch/Debian10/EB_production/2019/software/Anaconda3/2018.12/lib/python3.7/runpy.py", line 85, in _run_code
    exec(code, run_globals)
  File "/home/lcur0007/joeynmt/joeynmt/__main__.py", line 48, in <module>
    main()
  File "/home/lcur0007/joeynmt/joeynmt/__main__.py", line 35, in main
    train(cfg_file=args.config_path, skip_test=args.skip_test)
  File "/home/lcur0007/joeynmt/joeynmt/training.py", line 846, in train
    trainer.train_and_validate(train_data=train_data, valid_data=dev_data)
  File "/home/lcur0007/joeynmt/joeynmt/training.py", line 497, in train_and_validate
    valid_duration = self._validate(valid_data, epoch_no)
  File "/home/lcur0007/joeynmt/joeynmt/training.py", line 642, in _validate
    references=valid_references)
  File "/home/lcur0007/joeynmt/joeynmt/training.py", line 731, in _log_examples
    logger.debug("\tRaw source:     %s", sources_raw[p])
Message: '\tRaw source:     %s'
Arguments: (['\u0e15\u0e2d\u0e19@@', '\u0e09\u0e31\u0e19@@', '\u0e2d\u0e32\u0e22\u0e38', '11', '\u0e09\u0e31\u0e19@@', '\u0e08\u0e33@@', '\u0e44\u0e14', '\u0e49', '\u0e27', '\u0e48', '\u0e32@@', '\u0e15\u0e37', '\u0e48', '\u0e19\u0e02\u0e36', '\u0e49', '\u0e19\u0e21\u0e32@@', '\u0e40\u0e0a', '\u0e49', '\u0e32\u0e27@@', '\u0e31\u0e19@@', '\u0e2b\u0e19\u0e36', '\u0e48', '\u0e07', '\u0e41\u0e25\u0e30@@', '\u0e44\u0e14', '\u0e49', '\u0e22\u0e34\u0e19@@', '\u0e40\u0e2a\u0e35\u0e22\u0e07@@', '\u0e23', '\u0e49', '\u0e2d\u0e07@@', '\u0e14', '\u0e49', '\u0e27\u0e22\u0e04\u0e27\u0e32\u0e21@@', '\u0e22\u0e34\u0e19@@', '\u0e14\u0e35@@', '\u0e43\u0e19@@', '\u0e1a', '\u0e49', '\u0e32\u0e19'],)
--- Logging error ---
Traceback (most recent call last):
  File "/sw/arch/Debian10/EB_production/2019/software/Anaconda3/2018.12/lib/python3.7/logging/__init__.py", line 1036, in emit
    stream.write(msg)
UnicodeEncodeError: 'latin-1' codec can't encode characters in position 65-74: ordinal not in range(256)
Call stack:
  File "/sw/arch/Debian10/EB_production/2019/software/Anaconda3/2018.12/lib/python3.7/runpy.py", line 193, in _run_module_as_main
    "__main__", mod_spec)
  File "/sw/arch/Debian10/EB_production/2019/software/Anaconda3/2018.12/lib/python3.7/runpy.py", line 85, in _run_code
    exec(code, run_globals)
  File "/home/lcur0007/joeynmt/joeynmt/__main__.py", line 48, in <module>
    main()
  File "/home/lcur0007/joeynmt/joeynmt/__main__.py", line 35, in main
    train(cfg_file=args.config_path, skip_test=args.skip_test)
  File "/home/lcur0007/joeynmt/joeynmt/training.py", line 846, in train
    trainer.train_and_validate(train_data=train_data, valid_data=dev_data)
  File "/home/lcur0007/joeynmt/joeynmt/training.py", line 497, in train_and_validate
    valid_duration = self._validate(valid_data, epoch_no)
  File "/home/lcur0007/joeynmt/joeynmt/training.py", line 642, in _validate
    references=valid_references)
  File "/home/lcur0007/joeynmt/joeynmt/training.py", line 737, in _log_examples
    logger.info("\tSource:     %s", sources[p])
Message: '\tSource:     %s'
Arguments: ('\u0e15\u0e2d\u0e19\u0e09\u0e31\u0e19\u0e2d\u0e32\u0e22\u0e38 11 \u0e09\u0e31\u0e19\u0e08\u0e33\u0e44\u0e14 \u0e49 \u0e27 \u0e48 \u0e32\u0e15\u0e37 \u0e48 \u0e19\u0e02\u0e36 \u0e49 \u0e19\u0e21\u0e32\u0e40\u0e0a \u0e49 \u0e32\u0e27\u0e31\u0e19\u0e2b\u0e19\u0e36 \u0e48 \u0e07 \u0e41\u0e25\u0e30\u0e44\u0e14 \u0e49 \u0e22\u0e34\u0e19\u0e40\u0e2a\u0e35\u0e22\u0e07\u0e23 \u0e49 \u0e2d\u0e07\u0e14 \u0e49 \u0e27\u0e22\u0e04\u0e27\u0e32\u0e21\u0e22\u0e34\u0e19\u0e14\u0e35\u0e43\u0e19\u0e1a \u0e49 \u0e32\u0e19',)
2021-10-05 09:32:28,327 - INFO - joeynmt.training - 	Source:     \u0e15\u0e2d\u0e19\u0e09\u0e31\u0e19\u0e2d\u0e32\u0e22\u0e38 11 \u0e09\u0e31\u0e19\u0e08\u0e33\u0e44\u0e14 \u0e49 \u0e27 \u0e48 \u0e32\u0e15\u0e37 \u0e48 \u0e19\u0e02\u0e36 \u0e49 \u0e19\u0e21\u0e32\u0e40\u0e0a \u0e49 \u0e32\u0e27\u0e31\u0e19\u0e2b\u0e19\u0e36 \u0e48 \u0e07 \u0e41\u0e25\u0e30\u0e44\u0e14 \u0e49 \u0e22\u0e34\u0e19\u0e40\u0e2a\u0e35\u0e22\u0e07\u0e23 \u0e49 \u0e2d\u0e07\u0e14 \u0e49 \u0e27\u0e22\u0e04\u0e27\u0e32\u0e21\u0e22\u0e34\u0e19\u0e14\u0e35\u0e43\u0e19\u0e1a \u0e49 \u0e32\u0e19
2021-10-05 09:32:28,328 - INFO - joeynmt.training - 	Reference:  "When I was 11 , I remember waking up one morning to the sound of joy in my house ."
2021-10-05 09:32:28,328 - INFO - joeynmt.training - 	Hypothesis: "And the the a a a a a a a a the the the the the the the the the the the the the the the the the the the the ."
2021-10-05 09:32:28,328 - INFO - joeynmt.training - Example #2
--- Logging error ---
Traceback (most recent call last):
  File "/sw/arch/Debian10/EB_production/2019/software/Anaconda3/2018.12/lib/python3.7/logging/__init__.py", line 1036, in emit
    stream.write(msg)
UnicodeEncodeError: 'latin-1' codec can't encode character '\u0e1e' in position 72: ordinal not in range(256)
Call stack:
  File "/sw/arch/Debian10/EB_production/2019/software/Anaconda3/2018.12/lib/python3.7/runpy.py", line 193, in _run_module_as_main
    "__main__", mod_spec)
  File "/sw/arch/Debian10/EB_production/2019/software/Anaconda3/2018.12/lib/python3.7/runpy.py", line 85, in _run_code
    exec(code, run_globals)
  File "/home/lcur0007/joeynmt/joeynmt/__main__.py", line 48, in <module>
    main()
  File "/home/lcur0007/joeynmt/joeynmt/__main__.py", line 35, in main
    train(cfg_file=args.config_path, skip_test=args.skip_test)
  File "/home/lcur0007/joeynmt/joeynmt/training.py", line 846, in train
    trainer.train_and_validate(train_data=train_data, valid_data=dev_data)
  File "/home/lcur0007/joeynmt/joeynmt/training.py", line 497, in train_and_validate
    valid_duration = self._validate(valid_data, epoch_no)
  File "/home/lcur0007/joeynmt/joeynmt/training.py", line 642, in _validate
    references=valid_references)
  File "/home/lcur0007/joeynmt/joeynmt/training.py", line 731, in _log_examples
    logger.debug("\tRaw source:     %s", sources_raw[p])
Message: '\tRaw source:     %s'
Arguments: (['\u0e1e', '\u0e48', '\u0e2d@@', '\u0e02\u0e2d\u0e07\u0e09\u0e31\u0e19@@', '\u0e01\u0e33\u0e25\u0e31\u0e07@@', '\u0e1f\u0e31\u0e07@@', '\u0e02', '\u0e48', '\u0e32\u0e27@@', '\u0e1a\u0e35@@', '\u0e1a\u0e35@@', '\u0e0b\u0e35', '\u0e08\u0e32\u0e01@@', '\u0e27\u0e34\u0e17@@', '\u0e22\u0e38@@', '\u0e2a\u0e35@@', '\u0e40\u0e17@@', '\u0e32@@', '\u0e2d\u0e31\u0e19@@', '\u0e40\u0e25', '\u0e47', '\u0e01'],)
--- Logging error ---
Traceback (most recent call last):
  File "/sw/arch/Debian10/EB_production/2019/software/Anaconda3/2018.12/lib/python3.7/logging/__init__.py", line 1036, in emit
    stream.write(msg)
UnicodeEncodeError: 'latin-1' codec can't encode character '\u0e1e' in position 65: ordinal not in range(256)
Call stack:
  File "/sw/arch/Debian10/EB_production/2019/software/Anaconda3/2018.12/lib/python3.7/runpy.py", line 193, in _run_module_as_main
    "__main__", mod_spec)
  File "/sw/arch/Debian10/EB_production/2019/software/Anaconda3/2018.12/lib/python3.7/runpy.py", line 85, in _run_code
    exec(code, run_globals)
  File "/home/lcur0007/joeynmt/joeynmt/__main__.py", line 48, in <module>
    main()
  File "/home/lcur0007/joeynmt/joeynmt/__main__.py", line 35, in main
    train(cfg_file=args.config_path, skip_test=args.skip_test)
  File "/home/lcur0007/joeynmt/joeynmt/training.py", line 846, in train
    trainer.train_and_validate(train_data=train_data, valid_data=dev_data)
  File "/home/lcur0007/joeynmt/joeynmt/training.py", line 497, in train_and_validate
    valid_duration = self._validate(valid_data, epoch_no)
  File "/home/lcur0007/joeynmt/joeynmt/training.py", line 642, in _validate
    references=valid_references)
  File "/home/lcur0007/joeynmt/joeynmt/training.py", line 737, in _log_examples
    logger.info("\tSource:     %s", sources[p])
Message: '\tSource:     %s'
Arguments: ('\u0e1e \u0e48 \u0e2d\u0e02\u0e2d\u0e07\u0e09\u0e31\u0e19\u0e01\u0e33\u0e25\u0e31\u0e07\u0e1f\u0e31\u0e07\u0e02 \u0e48 \u0e32\u0e27\u0e1a\u0e35\u0e1a\u0e35\u0e0b\u0e35 \u0e08\u0e32\u0e01\u0e27\u0e34\u0e17\u0e22\u0e38\u0e2a\u0e35\u0e40\u0e17\u0e32\u0e2d\u0e31\u0e19\u0e40\u0e25 \u0e47 \u0e01',)
2021-10-05 09:32:28,328 - INFO - joeynmt.training - 	Source:     \u0e1e \u0e48 \u0e2d\u0e02\u0e2d\u0e07\u0e09\u0e31\u0e19\u0e01\u0e33\u0e25\u0e31\u0e07\u0e1f\u0e31\u0e07\u0e02 \u0e48 \u0e32\u0e27\u0e1a\u0e35\u0e1a\u0e35\u0e0b\u0e35 \u0e08\u0e32\u0e01\u0e27\u0e34\u0e17\u0e22\u0e38\u0e2a\u0e35\u0e40\u0e17\u0e32\u0e2d\u0e31\u0e19\u0e40\u0e25 \u0e47 \u0e01
2021-10-05 09:32:28,329 - INFO - joeynmt.training - 	Reference:  "My father was listening to BBC News on his small , gray radio ."
2021-10-05 09:32:28,329 - INFO - joeynmt.training - 	Hypothesis: And I &apos;re a a a a a a a a a a a .
2021-10-05 09:32:28,329 - INFO - joeynmt.training - Validation result (greedy) at epoch   1, step      300: bleu:   1.63, loss: 509289.9062, ppl: 309.6493, duration: 17.8501s
2021-10-05 09:33:13,992 - WARNING - sacrebleu - That's 100 lines that end in a tokenized period ('.')
2021-10-05 09:33:13,992 - WARNING - sacrebleu - It looks like you forgot to detokenize your test data, which may hurt your score.
2021-10-05 09:33:13,992 - WARNING - sacrebleu - If you insist your data is detokenized, or don't care, you can suppress this message with the `force` parameter.
2021-10-05 09:33:14,026 - INFO - joeynmt.training - Example #0
2021-10-05 09:33:14,027 - INFO - joeynmt.training - 	Source:     th
2021-10-05 09:33:14,027 - INFO - joeynmt.training - 	Reference:  en
2021-10-05 09:33:14,027 - INFO - joeynmt.training - 	Hypothesis: Thank you .
2021-10-05 09:33:14,027 - INFO - joeynmt.training - Example #1
--- Logging error ---
Traceback (most recent call last):
  File "/sw/arch/Debian10/EB_production/2019/software/Anaconda3/2018.12/lib/python3.7/logging/__init__.py", line 1036, in emit
    stream.write(msg)
UnicodeEncodeError: 'latin-1' codec can't encode characters in position 72-74: ordinal not in range(256)
Call stack:
  File "/sw/arch/Debian10/EB_production/2019/software/Anaconda3/2018.12/lib/python3.7/runpy.py", line 193, in _run_module_as_main
    "__main__", mod_spec)
  File "/sw/arch/Debian10/EB_production/2019/software/Anaconda3/2018.12/lib/python3.7/runpy.py", line 85, in _run_code
    exec(code, run_globals)
  File "/home/lcur0007/joeynmt/joeynmt/__main__.py", line 48, in <module>
    main()
  File "/home/lcur0007/joeynmt/joeynmt/__main__.py", line 35, in main
    train(cfg_file=args.config_path, skip_test=args.skip_test)
  File "/home/lcur0007/joeynmt/joeynmt/training.py", line 846, in train
    trainer.train_and_validate(train_data=train_data, valid_data=dev_data)
  File "/home/lcur0007/joeynmt/joeynmt/training.py", line 497, in train_and_validate
    valid_duration = self._validate(valid_data, epoch_no)
  File "/home/lcur0007/joeynmt/joeynmt/training.py", line 642, in _validate
    references=valid_references)
  File "/home/lcur0007/joeynmt/joeynmt/training.py", line 731, in _log_examples
    logger.debug("\tRaw source:     %s", sources_raw[p])
Message: '\tRaw source:     %s'
Arguments: (['\u0e15\u0e2d\u0e19@@', '\u0e09\u0e31\u0e19@@', '\u0e2d\u0e32\u0e22\u0e38', '11', '\u0e09\u0e31\u0e19@@', '\u0e08\u0e33@@', '\u0e44\u0e14', '\u0e49', '\u0e27', '\u0e48', '\u0e32@@', '\u0e15\u0e37', '\u0e48', '\u0e19\u0e02\u0e36', '\u0e49', '\u0e19\u0e21\u0e32@@', '\u0e40\u0e0a', '\u0e49', '\u0e32\u0e27@@', '\u0e31\u0e19@@', '\u0e2b\u0e19\u0e36', '\u0e48', '\u0e07', '\u0e41\u0e25\u0e30@@', '\u0e44\u0e14', '\u0e49', '\u0e22\u0e34\u0e19@@', '\u0e40\u0e2a\u0e35\u0e22\u0e07@@', '\u0e23', '\u0e49', '\u0e2d\u0e07@@', '\u0e14', '\u0e49', '\u0e27\u0e22\u0e04\u0e27\u0e32\u0e21@@', '\u0e22\u0e34\u0e19@@', '\u0e14\u0e35@@', '\u0e43\u0e19@@', '\u0e1a', '\u0e49', '\u0e32\u0e19'],)
--- Logging error ---
Traceback (most recent call last):
  File "/sw/arch/Debian10/EB_production/2019/software/Anaconda3/2018.12/lib/python3.7/logging/__init__.py", line 1036, in emit
    stream.write(msg)
UnicodeEncodeError: 'latin-1' codec can't encode characters in position 65-74: ordinal not in range(256)
Call stack:
  File "/sw/arch/Debian10/EB_production/2019/software/Anaconda3/2018.12/lib/python3.7/runpy.py", line 193, in _run_module_as_main
    "__main__", mod_spec)
  File "/sw/arch/Debian10/EB_production/2019/software/Anaconda3/2018.12/lib/python3.7/runpy.py", line 85, in _run_code
    exec(code, run_globals)
  File "/home/lcur0007/joeynmt/joeynmt/__main__.py", line 48, in <module>
    main()
  File "/home/lcur0007/joeynmt/joeynmt/__main__.py", line 35, in main
    train(cfg_file=args.config_path, skip_test=args.skip_test)
  File "/home/lcur0007/joeynmt/joeynmt/training.py", line 846, in train
    trainer.train_and_validate(train_data=train_data, valid_data=dev_data)
  File "/home/lcur0007/joeynmt/joeynmt/training.py", line 497, in train_and_validate
    valid_duration = self._validate(valid_data, epoch_no)
  File "/home/lcur0007/joeynmt/joeynmt/training.py", line 642, in _validate
    references=valid_references)
  File "/home/lcur0007/joeynmt/joeynmt/training.py", line 737, in _log_examples
    logger.info("\tSource:     %s", sources[p])
Message: '\tSource:     %s'
Arguments: ('\u0e15\u0e2d\u0e19\u0e09\u0e31\u0e19\u0e2d\u0e32\u0e22\u0e38 11 \u0e09\u0e31\u0e19\u0e08\u0e33\u0e44\u0e14 \u0e49 \u0e27 \u0e48 \u0e32\u0e15\u0e37 \u0e48 \u0e19\u0e02\u0e36 \u0e49 \u0e19\u0e21\u0e32\u0e40\u0e0a \u0e49 \u0e32\u0e27\u0e31\u0e19\u0e2b\u0e19\u0e36 \u0e48 \u0e07 \u0e41\u0e25\u0e30\u0e44\u0e14 \u0e49 \u0e22\u0e34\u0e19\u0e40\u0e2a\u0e35\u0e22\u0e07\u0e23 \u0e49 \u0e2d\u0e07\u0e14 \u0e49 \u0e27\u0e22\u0e04\u0e27\u0e32\u0e21\u0e22\u0e34\u0e19\u0e14\u0e35\u0e43\u0e19\u0e1a \u0e49 \u0e32\u0e19',)
2021-10-05 09:33:14,028 - INFO - joeynmt.training - 	Source:     \u0e15\u0e2d\u0e19\u0e09\u0e31\u0e19\u0e2d\u0e32\u0e22\u0e38 11 \u0e09\u0e31\u0e19\u0e08\u0e33\u0e44\u0e14 \u0e49 \u0e27 \u0e48 \u0e32\u0e15\u0e37 \u0e48 \u0e19\u0e02\u0e36 \u0e49 \u0e19\u0e21\u0e32\u0e40\u0e0a \u0e49 \u0e32\u0e27\u0e31\u0e19\u0e2b\u0e19\u0e36 \u0e48 \u0e07 \u0e41\u0e25\u0e30\u0e44\u0e14 \u0e49 \u0e22\u0e34\u0e19\u0e40\u0e2a\u0e35\u0e22\u0e07\u0e23 \u0e49 \u0e2d\u0e07\u0e14 \u0e49 \u0e27\u0e22\u0e04\u0e27\u0e32\u0e21\u0e22\u0e34\u0e19\u0e14\u0e35\u0e43\u0e19\u0e1a \u0e49 \u0e32\u0e19
2021-10-05 09:33:14,029 - INFO - joeynmt.training - 	Reference:  "When I was 11 , I remember waking up one morning to the sound of joy in my house ."
2021-10-05 09:33:14,029 - INFO - joeynmt.training - 	Hypothesis: "And I &apos;re a a a a a a a a a a a a a a a the a the a the a the a the a the a the a the a the a the a the a the a the a ."
2021-10-05 09:33:14,029 - INFO - joeynmt.training - Example #2
--- Logging error ---
Traceback (most recent call last):
  File "/sw/arch/Debian10/EB_production/2019/software/Anaconda3/2018.12/lib/python3.7/logging/__init__.py", line 1036, in emit
    stream.write(msg)
UnicodeEncodeError: 'latin-1' codec can't encode character '\u0e1e' in position 72: ordinal not in range(256)
Call stack:
  File "/sw/arch/Debian10/EB_production/2019/software/Anaconda3/2018.12/lib/python3.7/runpy.py", line 193, in _run_module_as_main
    "__main__", mod_spec)
  File "/sw/arch/Debian10/EB_production/2019/software/Anaconda3/2018.12/lib/python3.7/runpy.py", line 85, in _run_code
    exec(code, run_globals)
  File "/home/lcur0007/joeynmt/joeynmt/__main__.py", line 48, in <module>
    main()
  File "/home/lcur0007/joeynmt/joeynmt/__main__.py", line 35, in main
    train(cfg_file=args.config_path, skip_test=args.skip_test)
  File "/home/lcur0007/joeynmt/joeynmt/training.py", line 846, in train
    trainer.train_and_validate(train_data=train_data, valid_data=dev_data)
  File "/home/lcur0007/joeynmt/joeynmt/training.py", line 497, in train_and_validate
    valid_duration = self._validate(valid_data, epoch_no)
  File "/home/lcur0007/joeynmt/joeynmt/training.py", line 642, in _validate
    references=valid_references)
  File "/home/lcur0007/joeynmt/joeynmt/training.py", line 731, in _log_examples
    logger.debug("\tRaw source:     %s", sources_raw[p])
Message: '\tRaw source:     %s'
Arguments: (['\u0e1e', '\u0e48', '\u0e2d@@', '\u0e02\u0e2d\u0e07\u0e09\u0e31\u0e19@@', '\u0e01\u0e33\u0e25\u0e31\u0e07@@', '\u0e1f\u0e31\u0e07@@', '\u0e02', '\u0e48', '\u0e32\u0e27@@', '\u0e1a\u0e35@@', '\u0e1a\u0e35@@', '\u0e0b\u0e35', '\u0e08\u0e32\u0e01@@', '\u0e27\u0e34\u0e17@@', '\u0e22\u0e38@@', '\u0e2a\u0e35@@', '\u0e40\u0e17@@', '\u0e32@@', '\u0e2d\u0e31\u0e19@@', '\u0e40\u0e25', '\u0e47', '\u0e01'],)
--- Logging error ---
Traceback (most recent call last):
  File "/sw/arch/Debian10/EB_production/2019/software/Anaconda3/2018.12/lib/python3.7/logging/__init__.py", line 1036, in emit
    stream.write(msg)
UnicodeEncodeError: 'latin-1' codec can't encode character '\u0e1e' in position 65: ordinal not in range(256)
Call stack:
  File "/sw/arch/Debian10/EB_production/2019/software/Anaconda3/2018.12/lib/python3.7/runpy.py", line 193, in _run_module_as_main
    "__main__", mod_spec)
  File "/sw/arch/Debian10/EB_production/2019/software/Anaconda3/2018.12/lib/python3.7/runpy.py", line 85, in _run_code
    exec(code, run_globals)
  File "/home/lcur0007/joeynmt/joeynmt/__main__.py", line 48, in <module>
    main()
  File "/home/lcur0007/joeynmt/joeynmt/__main__.py", line 35, in main
    train(cfg_file=args.config_path, skip_test=args.skip_test)
  File "/home/lcur0007/joeynmt/joeynmt/training.py", line 846, in train
    trainer.train_and_validate(train_data=train_data, valid_data=dev_data)
  File "/home/lcur0007/joeynmt/joeynmt/training.py", line 497, in train_and_validate
    valid_duration = self._validate(valid_data, epoch_no)
  File "/home/lcur0007/joeynmt/joeynmt/training.py", line 642, in _validate
    references=valid_references)
  File "/home/lcur0007/joeynmt/joeynmt/training.py", line 737, in _log_examples
    logger.info("\tSource:     %s", sources[p])
Message: '\tSource:     %s'
Arguments: ('\u0e1e \u0e48 \u0e2d\u0e02\u0e2d\u0e07\u0e09\u0e31\u0e19\u0e01\u0e33\u0e25\u0e31\u0e07\u0e1f\u0e31\u0e07\u0e02 \u0e48 \u0e32\u0e27\u0e1a\u0e35\u0e1a\u0e35\u0e0b\u0e35 \u0e08\u0e32\u0e01\u0e27\u0e34\u0e17\u0e22\u0e38\u0e2a\u0e35\u0e40\u0e17\u0e32\u0e2d\u0e31\u0e19\u0e40\u0e25 \u0e47 \u0e01',)
2021-10-05 09:33:14,030 - INFO - joeynmt.training - 	Source:     \u0e1e \u0e48 \u0e2d\u0e02\u0e2d\u0e07\u0e09\u0e31\u0e19\u0e01\u0e33\u0e25\u0e31\u0e07\u0e1f\u0e31\u0e07\u0e02 \u0e48 \u0e32\u0e27\u0e1a\u0e35\u0e1a\u0e35\u0e0b\u0e35 \u0e08\u0e32\u0e01\u0e27\u0e34\u0e17\u0e22\u0e38\u0e2a\u0e35\u0e40\u0e17\u0e32\u0e2d\u0e31\u0e19\u0e40\u0e25 \u0e47 \u0e01
2021-10-05 09:33:14,031 - INFO - joeynmt.training - 	Reference:  "My father was listening to BBC News on his small , gray radio ."
2021-10-05 09:33:14,031 - INFO - joeynmt.training - 	Hypothesis: "And the first a a a a a a a a the a the a the a the a the world .
2021-10-05 09:33:14,031 - INFO - joeynmt.training - Validation result (greedy) at epoch   1, step      400: bleu:   0.51, loss: 482725.1875, ppl: 229.5860, duration: 24.0483s
srun: Job step aborted: Waiting up to 32 seconds for job step to finish.
slurmstepd: error: *** JOB 8223834 ON r30n2 CANCELLED AT 2021-10-05T09:33:23 ***
slurmstepd: error: *** STEP 8223834.0 ON r30n2 CANCELLED AT 2021-10-05T09:33:23 ***
