2021-10-03 14:01:53,896 - INFO - root - Hello! This is Joey-NMT (version 1.3).
2021-10-03 14:01:53,957 - INFO - joeynmt.data - Loading training data...
2021-10-03 14:01:54,085 - INFO - joeynmt.data - Building vocabulary...
2021-10-03 14:01:54,555 - INFO - joeynmt.data - Loading dev data...
2021-10-03 14:01:54,569 - INFO - joeynmt.data - Loading test data...
2021-10-03 14:01:54,581 - INFO - joeynmt.data - Data loaded.
2021-10-03 14:01:54,581 - INFO - joeynmt.model - Building an encoder-decoder model...
2021-10-03 14:01:55,125 - INFO - joeynmt.model - Enc-dec model built.
2021-10-03 14:01:55,130 - INFO - joeynmt.training - Total params: 24886272
2021-10-03 14:01:59,352 - INFO - joeynmt.helpers - cfg.name                           : LSTM_th
2021-10-03 14:01:59,353 - INFO - joeynmt.helpers - cfg.data.src                       : th
2021-10-03 14:01:59,353 - INFO - joeynmt.helpers - cfg.data.trg                       : en_s
2021-10-03 14:01:59,353 - INFO - joeynmt.helpers - cfg.data.train                     : ../2DL4NLP/all_data/th.en_s/train.bpe
2021-10-03 14:01:59,353 - INFO - joeynmt.helpers - cfg.data.dev                       : ../2DL4NLP/all_data/th.en_s/val.bpe
2021-10-03 14:01:59,353 - INFO - joeynmt.helpers - cfg.data.test                      : ../2DL4NLP/all_data/th.en_s/test.bpe
2021-10-03 14:01:59,353 - INFO - joeynmt.helpers - cfg.data.level                     : bpe
2021-10-03 14:01:59,353 - INFO - joeynmt.helpers - cfg.data.lowercase                 : False
2021-10-03 14:01:59,353 - INFO - joeynmt.helpers - cfg.data.max_sent_length           : 50
2021-10-03 14:01:59,353 - INFO - joeynmt.helpers - cfg.data.src_voc_min_freq          : 0
2021-10-03 14:01:59,353 - INFO - joeynmt.helpers - cfg.data.src_voc_limit             : 100000
2021-10-03 14:01:59,353 - INFO - joeynmt.helpers - cfg.data.trg_voc_min_freq          : 0
2021-10-03 14:01:59,353 - INFO - joeynmt.helpers - cfg.data.trg_voc_limit             : 100000
2021-10-03 14:01:59,353 - INFO - joeynmt.helpers - cfg.data.src_vocab                 : ../2DL4NLP/all_data/th.en_s/th.en_s.vocab.txt
2021-10-03 14:01:59,354 - INFO - joeynmt.helpers - cfg.data.trg_vocab                 : ../2DL4NLP/all_data/th.en_s/th.en_s.vocab.txt
2021-10-03 14:01:59,354 - INFO - joeynmt.helpers - cfg.testing.beam_size              : 5
2021-10-03 14:01:59,354 - INFO - joeynmt.helpers - cfg.testing.alpha                  : 1.0
2021-10-03 14:01:59,354 - INFO - joeynmt.helpers - cfg.training.random_seed           : 42
2021-10-03 14:01:59,354 - INFO - joeynmt.helpers - cfg.training.optimizer             : adam
2021-10-03 14:01:59,354 - INFO - joeynmt.helpers - cfg.training.learning_rate         : 0.0003
2021-10-03 14:01:59,354 - INFO - joeynmt.helpers - cfg.training.learning_rate_min     : 5e-07
2021-10-03 14:01:59,354 - INFO - joeynmt.helpers - cfg.training.weight_decay          : 0.0
2021-10-03 14:01:59,354 - INFO - joeynmt.helpers - cfg.training.clip_grad_norm        : 1.0
2021-10-03 14:01:59,354 - INFO - joeynmt.helpers - cfg.training.batch_size            : 80
2021-10-03 14:01:59,354 - INFO - joeynmt.helpers - cfg.training.scheduling            : plateau
2021-10-03 14:01:59,354 - INFO - joeynmt.helpers - cfg.training.patience              : 10
2021-10-03 14:01:59,354 - INFO - joeynmt.helpers - cfg.training.decrease_factor       : 0.5
2021-10-03 14:01:59,354 - INFO - joeynmt.helpers - cfg.training.early_stopping_metric : eval_metric
2021-10-03 14:01:59,354 - INFO - joeynmt.helpers - cfg.training.epochs                : 20
2021-10-03 14:01:59,354 - INFO - joeynmt.helpers - cfg.training.validation_freq       : 100
2021-10-03 14:01:59,355 - INFO - joeynmt.helpers - cfg.training.logging_freq          : 1000
2021-10-03 14:01:59,355 - INFO - joeynmt.helpers - cfg.training.eval_metric           : bleu
2021-10-03 14:01:59,355 - INFO - joeynmt.helpers - cfg.training.model_dir             : models/LSTM_th
2021-10-03 14:01:59,355 - INFO - joeynmt.helpers - cfg.training.overwrite             : True
2021-10-03 14:01:59,355 - INFO - joeynmt.helpers - cfg.training.shuffle               : True
2021-10-03 14:01:59,355 - INFO - joeynmt.helpers - cfg.training.use_cuda              : True
2021-10-03 14:01:59,355 - INFO - joeynmt.helpers - cfg.training.max_output_length     : 100
2021-10-03 14:01:59,355 - INFO - joeynmt.helpers - cfg.training.print_valid_sents     : [0, 1, 2]
2021-10-03 14:01:59,355 - INFO - joeynmt.helpers - cfg.training.keep_best_ckpts       : 1
2021-10-03 14:01:59,355 - INFO - joeynmt.helpers - cfg.training.save_latest_ckpt      : True
2021-10-03 14:01:59,355 - INFO - joeynmt.helpers - cfg.model.encoder.rnn_type         : lstm
2021-10-03 14:01:59,355 - INFO - joeynmt.helpers - cfg.model.encoder.embeddings.embedding_dim : 512
2021-10-03 14:01:59,355 - INFO - joeynmt.helpers - cfg.model.encoder.embeddings.scale : False
2021-10-03 14:01:59,355 - INFO - joeynmt.helpers - cfg.model.encoder.hidden_size      : 512
2021-10-03 14:01:59,355 - INFO - joeynmt.helpers - cfg.model.encoder.bidirectional    : False
2021-10-03 14:01:59,356 - INFO - joeynmt.helpers - cfg.model.encoder.dropout          : 0.2
2021-10-03 14:01:59,356 - INFO - joeynmt.helpers - cfg.model.encoder.num_layers       : 1
2021-10-03 14:01:59,356 - INFO - joeynmt.helpers - cfg.model.decoder.rnn_type         : lstm
2021-10-03 14:01:59,356 - INFO - joeynmt.helpers - cfg.model.decoder.embeddings.embedding_dim : 512
2021-10-03 14:01:59,356 - INFO - joeynmt.helpers - cfg.model.decoder.embeddings.scale : False
2021-10-03 14:01:59,356 - INFO - joeynmt.helpers - cfg.model.decoder.emb_scale        : False
2021-10-03 14:01:59,356 - INFO - joeynmt.helpers - cfg.model.decoder.hidden_size      : 1024
2021-10-03 14:01:59,356 - INFO - joeynmt.helpers - cfg.model.decoder.dropout          : 0.2
2021-10-03 14:01:59,356 - INFO - joeynmt.helpers - cfg.model.decoder.hidden_dropout   : 0.2
2021-10-03 14:01:59,356 - INFO - joeynmt.helpers - cfg.model.decoder.num_layers       : 1
2021-10-03 14:01:59,356 - INFO - joeynmt.helpers - cfg.model.decoder.input_feeding    : True
2021-10-03 14:01:59,356 - INFO - joeynmt.helpers - cfg.model.decoder.init_hidden      : bridge
2021-10-03 14:01:59,356 - INFO - joeynmt.helpers - cfg.model.decoder.attention        : bahdanau
2021-10-03 14:01:59,356 - INFO - joeynmt.helpers - Data set sizes: 
	train 4698,
	valid 551,
	test 602
2021-10-03 14:01:59,356 - INFO - joeynmt.helpers - First training example:
	[SRC] th
	[TRG] en
--- Logging error ---
Traceback (most recent call last):
  File "/sw/arch/Debian10/EB_production/2019/software/Anaconda3/2018.12/lib/python3.7/logging/__init__.py", line 1036, in emit
    stream.write(msg)
UnicodeEncodeError: 'latin-1' codec can't encode character '\u0e48' in position 114: ordinal not in range(256)
Call stack:
  File "/sw/arch/Debian10/EB_production/2019/software/Anaconda3/2018.12/lib/python3.7/runpy.py", line 193, in _run_module_as_main
    "__main__", mod_spec)
  File "/sw/arch/Debian10/EB_production/2019/software/Anaconda3/2018.12/lib/python3.7/runpy.py", line 85, in _run_code
    exec(code, run_globals)
  File "/home/lcur0006/joeynmt/joeynmt/__main__.py", line 48, in <module>
    main()
  File "/home/lcur0006/joeynmt/joeynmt/__main__.py", line 35, in main
    train(cfg_file=args.config_path, skip_test=args.skip_test)
  File "/home/lcur0006/joeynmt/joeynmt/training.py", line 835, in train
    trg_vocab=trg_vocab)
  File "/home/lcur0006/joeynmt/joeynmt/helpers.py", line 164, in log_data_info
    " ".join('(%d) %s' % (i, t) for i, t in enumerate(src_vocab.itos[:10])))
Message: 'First 10 words (src): %s'
Arguments: ('(0) <unk> (1) <pad> (2) <s> (3) </s> (4) \u0e48 (5) \u0e49 (6) , (7) \u0e47 (8) the (9) .',)
2021-10-03 14:01:59,357 - INFO - joeynmt.helpers - First 10 words (src): (0) <unk> (1) <pad> (2) <s> (3) </s> (4) \u0e48 (5) \u0e49 (6) , (7) \u0e47 (8) the (9) .
--- Logging error ---
Traceback (most recent call last):
  File "/sw/arch/Debian10/EB_production/2019/software/Anaconda3/2018.12/lib/python3.7/logging/__init__.py", line 1036, in emit
    stream.write(msg)
UnicodeEncodeError: 'latin-1' codec can't encode character '\u0e48' in position 114: ordinal not in range(256)
Call stack:
  File "/sw/arch/Debian10/EB_production/2019/software/Anaconda3/2018.12/lib/python3.7/runpy.py", line 193, in _run_module_as_main
    "__main__", mod_spec)
  File "/sw/arch/Debian10/EB_production/2019/software/Anaconda3/2018.12/lib/python3.7/runpy.py", line 85, in _run_code
    exec(code, run_globals)
  File "/home/lcur0006/joeynmt/joeynmt/__main__.py", line 48, in <module>
    main()
  File "/home/lcur0006/joeynmt/joeynmt/__main__.py", line 35, in main
    train(cfg_file=args.config_path, skip_test=args.skip_test)
  File "/home/lcur0006/joeynmt/joeynmt/training.py", line 835, in train
    trg_vocab=trg_vocab)
  File "/home/lcur0006/joeynmt/joeynmt/helpers.py", line 167, in log_data_info
    " ".join('(%d) %s' % (i, t) for i, t in enumerate(trg_vocab.itos[:10])))
Message: 'First 10 words (trg): %s'
Arguments: ('(0) <unk> (1) <pad> (2) <s> (3) </s> (4) \u0e48 (5) \u0e49 (6) , (7) \u0e47 (8) the (9) .',)
2021-10-03 14:01:59,359 - INFO - joeynmt.helpers - First 10 words (trg): (0) <unk> (1) <pad> (2) <s> (3) </s> (4) \u0e48 (5) \u0e49 (6) , (7) \u0e47 (8) the (9) .
2021-10-03 14:01:59,360 - INFO - joeynmt.helpers - Number of Src words (types): 4208
2021-10-03 14:01:59,360 - INFO - joeynmt.helpers - Number of Trg words (types): 4208
2021-10-03 14:01:59,360 - INFO - joeynmt.training - Model(
	encoder=RecurrentEncoder(LSTM(512, 512, batch_first=True)),
	decoder=RecurrentDecoder(rnn=LSTM(1536, 1024, batch_first=True), attention=BahdanauAttention),
	src_embed=Embeddings(embedding_dim=512, vocab_size=4208),
	trg_embed=Embeddings(embedding_dim=512, vocab_size=4208))
2021-10-03 14:01:59,371 - INFO - joeynmt.training - Train stats:
	device: cuda
	n_gpu: 1
	16-bits training: False
	gradient accumulation: 1
	batch size per device: 80
	total batch size (w. parallel & accumulation): 80
2021-10-03 14:01:59,371 - INFO - joeynmt.training - EPOCH 1
2021-10-03 14:02:10,915 - INFO - joeynmt.training - Epoch   1: total training loss 7553.15
2021-10-03 14:02:10,915 - INFO - joeynmt.training - EPOCH 2
2021-10-03 14:02:22,728 - WARNING - sacrebleu - That's 100 lines that end in a tokenized period ('.')
2021-10-03 14:02:22,728 - WARNING - sacrebleu - It looks like you forgot to detokenize your test data, which may hurt your score.
2021-10-03 14:02:22,728 - WARNING - sacrebleu - If you insist your data is detokenized, or don't care, you can suppress this message with the `force` parameter.
2021-10-03 14:02:22,734 - INFO - joeynmt.training - Hooray! New best validation result [eval_metric]!
2021-10-03 14:02:23,664 - INFO - joeynmt.training - Example #0
2021-10-03 14:02:23,665 - INFO - joeynmt.training - 	Source:     th
2021-10-03 14:02:23,665 - INFO - joeynmt.training - 	Reference:  en
2021-10-03 14:02:23,665 - INFO - joeynmt.training - 	Hypothesis: I , .
2021-10-03 14:02:23,665 - INFO - joeynmt.training - Example #1
--- Logging error ---
Traceback (most recent call last):
  File "/sw/arch/Debian10/EB_production/2019/software/Anaconda3/2018.12/lib/python3.7/logging/__init__.py", line 1036, in emit
    stream.write(msg)
UnicodeEncodeError: 'latin-1' codec can't encode characters in position 72-74: ordinal not in range(256)
Call stack:
  File "/sw/arch/Debian10/EB_production/2019/software/Anaconda3/2018.12/lib/python3.7/runpy.py", line 193, in _run_module_as_main
    "__main__", mod_spec)
  File "/sw/arch/Debian10/EB_production/2019/software/Anaconda3/2018.12/lib/python3.7/runpy.py", line 85, in _run_code
    exec(code, run_globals)
  File "/home/lcur0006/joeynmt/joeynmt/__main__.py", line 48, in <module>
    main()
  File "/home/lcur0006/joeynmt/joeynmt/__main__.py", line 35, in main
    train(cfg_file=args.config_path, skip_test=args.skip_test)
  File "/home/lcur0006/joeynmt/joeynmt/training.py", line 846, in train
    trainer.train_and_validate(train_data=train_data, valid_data=dev_data)
  File "/home/lcur0006/joeynmt/joeynmt/training.py", line 497, in train_and_validate
    valid_duration = self._validate(valid_data, epoch_no)
  File "/home/lcur0006/joeynmt/joeynmt/training.py", line 642, in _validate
    references=valid_references)
  File "/home/lcur0006/joeynmt/joeynmt/training.py", line 731, in _log_examples
    logger.debug("\tRaw source:     %s", sources_raw[p])
Message: '\tRaw source:     %s'
Arguments: (['\u0e15\u0e2d\u0e19@@', '\u0e09\u0e31\u0e19@@', '\u0e2d\u0e32\u0e22\u0e38', '1@@', '1', '\u0e09\u0e31\u0e19@@', '\u0e08\u0e33@@', '\u0e44\u0e14', '\u0e49', '\u0e27', '\u0e48', '\u0e32\u0e15@@', '\u0e37', '\u0e48', '\u0e19@@', '\u0e02\u0e36', '\u0e49', '\u0e19\u0e21\u0e32@@', '\u0e40\u0e0a', '\u0e49', '\u0e32\u0e27@@', '\u0e31\u0e19@@', '\u0e2b\u0e19\u0e36', '\u0e48', '\u0e07', '\u0e41\u0e25\u0e30@@', '\u0e44\u0e14', '\u0e49', '\u0e22\u0e34\u0e19@@', '\u0e40\u0e2a\u0e35\u0e22\u0e07@@', '\u0e23', '\u0e49', '\u0e2d\u0e07@@', '\u0e14', '\u0e49', '\u0e27\u0e22\u0e04\u0e27\u0e32\u0e21@@', '\u0e22\u0e34\u0e19@@', '\u0e14\u0e35@@', '\u0e43\u0e19@@', '\u0e1a', '\u0e49', '\u0e32\u0e19'],)
--- Logging error ---
Traceback (most recent call last):
  File "/sw/arch/Debian10/EB_production/2019/software/Anaconda3/2018.12/lib/python3.7/logging/__init__.py", line 1036, in emit
    stream.write(msg)
UnicodeEncodeError: 'latin-1' codec can't encode characters in position 65-74: ordinal not in range(256)
Call stack:
  File "/sw/arch/Debian10/EB_production/2019/software/Anaconda3/2018.12/lib/python3.7/runpy.py", line 193, in _run_module_as_main
    "__main__", mod_spec)
  File "/sw/arch/Debian10/EB_production/2019/software/Anaconda3/2018.12/lib/python3.7/runpy.py", line 85, in _run_code
    exec(code, run_globals)
  File "/home/lcur0006/joeynmt/joeynmt/__main__.py", line 48, in <module>
    main()
  File "/home/lcur0006/joeynmt/joeynmt/__main__.py", line 35, in main
    train(cfg_file=args.config_path, skip_test=args.skip_test)
  File "/home/lcur0006/joeynmt/joeynmt/training.py", line 846, in train
    trainer.train_and_validate(train_data=train_data, valid_data=dev_data)
  File "/home/lcur0006/joeynmt/joeynmt/training.py", line 497, in train_and_validate
    valid_duration = self._validate(valid_data, epoch_no)
  File "/home/lcur0006/joeynmt/joeynmt/training.py", line 642, in _validate
    references=valid_references)
  File "/home/lcur0006/joeynmt/joeynmt/training.py", line 737, in _log_examples
    logger.info("\tSource:     %s", sources[p])
Message: '\tSource:     %s'
Arguments: ('\u0e15\u0e2d\u0e19\u0e09\u0e31\u0e19\u0e2d\u0e32\u0e22\u0e38 11 \u0e09\u0e31\u0e19\u0e08\u0e33\u0e44\u0e14 \u0e49 \u0e27 \u0e48 \u0e32\u0e15\u0e37 \u0e48 \u0e19\u0e02\u0e36 \u0e49 \u0e19\u0e21\u0e32\u0e40\u0e0a \u0e49 \u0e32\u0e27\u0e31\u0e19\u0e2b\u0e19\u0e36 \u0e48 \u0e07 \u0e41\u0e25\u0e30\u0e44\u0e14 \u0e49 \u0e22\u0e34\u0e19\u0e40\u0e2a\u0e35\u0e22\u0e07\u0e23 \u0e49 \u0e2d\u0e07\u0e14 \u0e49 \u0e27\u0e22\u0e04\u0e27\u0e32\u0e21\u0e22\u0e34\u0e19\u0e14\u0e35\u0e43\u0e19\u0e1a \u0e49 \u0e32\u0e19',)
2021-10-03 14:02:23,668 - INFO - joeynmt.training - 	Source:     \u0e15\u0e2d\u0e19\u0e09\u0e31\u0e19\u0e2d\u0e32\u0e22\u0e38 11 \u0e09\u0e31\u0e19\u0e08\u0e33\u0e44\u0e14 \u0e49 \u0e27 \u0e48 \u0e32\u0e15\u0e37 \u0e48 \u0e19\u0e02\u0e36 \u0e49 \u0e19\u0e21\u0e32\u0e40\u0e0a \u0e49 \u0e32\u0e27\u0e31\u0e19\u0e2b\u0e19\u0e36 \u0e48 \u0e07 \u0e41\u0e25\u0e30\u0e44\u0e14 \u0e49 \u0e22\u0e34\u0e19\u0e40\u0e2a\u0e35\u0e22\u0e07\u0e23 \u0e49 \u0e2d\u0e07\u0e14 \u0e49 \u0e27\u0e22\u0e04\u0e27\u0e32\u0e21\u0e22\u0e34\u0e19\u0e14\u0e35\u0e43\u0e19\u0e1a \u0e49 \u0e32\u0e19
2021-10-03 14:02:23,669 - INFO - joeynmt.training - 	Reference:  "When I was 11 , I remember waking up one morning to the sound of joy in my house ."
2021-10-03 14:02:23,669 - INFO - joeynmt.training - 	Hypothesis: "And I , , , , , , , , , , , , , , , , , , , , , , , , , , , , , , , , , ."
2021-10-03 14:02:23,669 - INFO - joeynmt.training - Example #2
--- Logging error ---
Traceback (most recent call last):
  File "/sw/arch/Debian10/EB_production/2019/software/Anaconda3/2018.12/lib/python3.7/logging/__init__.py", line 1036, in emit
    stream.write(msg)
UnicodeEncodeError: 'latin-1' codec can't encode character '\u0e1e' in position 72: ordinal not in range(256)
Call stack:
  File "/sw/arch/Debian10/EB_production/2019/software/Anaconda3/2018.12/lib/python3.7/runpy.py", line 193, in _run_module_as_main
    "__main__", mod_spec)
  File "/sw/arch/Debian10/EB_production/2019/software/Anaconda3/2018.12/lib/python3.7/runpy.py", line 85, in _run_code
    exec(code, run_globals)
  File "/home/lcur0006/joeynmt/joeynmt/__main__.py", line 48, in <module>
    main()
  File "/home/lcur0006/joeynmt/joeynmt/__main__.py", line 35, in main
    train(cfg_file=args.config_path, skip_test=args.skip_test)
  File "/home/lcur0006/joeynmt/joeynmt/training.py", line 846, in train
    trainer.train_and_validate(train_data=train_data, valid_data=dev_data)
  File "/home/lcur0006/joeynmt/joeynmt/training.py", line 497, in train_and_validate
    valid_duration = self._validate(valid_data, epoch_no)
  File "/home/lcur0006/joeynmt/joeynmt/training.py", line 642, in _validate
    references=valid_references)
  File "/home/lcur0006/joeynmt/joeynmt/training.py", line 731, in _log_examples
    logger.debug("\tRaw source:     %s", sources_raw[p])
Message: '\tRaw source:     %s'
Arguments: (['\u0e1e', '\u0e48', '\u0e2d\u0e02\u0e2d\u0e07@@', '\u0e09\u0e31\u0e19@@', '\u0e01\u0e33\u0e25\u0e31\u0e07@@', '\u0e1f\u0e31\u0e07@@', '\u0e02', '\u0e48', '\u0e32\u0e27@@', '\u0e1a\u0e35@@', '\u0e1a\u0e35@@', '\u0e0b\u0e35', '\u0e08\u0e32\u0e01@@', '\u0e27\u0e34\u0e17@@', '\u0e22\u0e38@@', '\u0e2a\u0e35@@', '\u0e40\u0e17@@', '\u0e32@@', '\u0e2d\u0e31\u0e19@@', '\u0e40\u0e25', '\u0e47', '\u0e01'],)
--- Logging error ---
Traceback (most recent call last):
  File "/sw/arch/Debian10/EB_production/2019/software/Anaconda3/2018.12/lib/python3.7/logging/__init__.py", line 1036, in emit
    stream.write(msg)
UnicodeEncodeError: 'latin-1' codec can't encode character '\u0e1e' in position 65: ordinal not in range(256)
Call stack:
  File "/sw/arch/Debian10/EB_production/2019/software/Anaconda3/2018.12/lib/python3.7/runpy.py", line 193, in _run_module_as_main
    "__main__", mod_spec)
  File "/sw/arch/Debian10/EB_production/2019/software/Anaconda3/2018.12/lib/python3.7/runpy.py", line 85, in _run_code
    exec(code, run_globals)
  File "/home/lcur0006/joeynmt/joeynmt/__main__.py", line 48, in <module>
    main()
  File "/home/lcur0006/joeynmt/joeynmt/__main__.py", line 35, in main
    train(cfg_file=args.config_path, skip_test=args.skip_test)
  File "/home/lcur0006/joeynmt/joeynmt/training.py", line 846, in train
    trainer.train_and_validate(train_data=train_data, valid_data=dev_data)
  File "/home/lcur0006/joeynmt/joeynmt/training.py", line 497, in train_and_validate
    valid_duration = self._validate(valid_data, epoch_no)
  File "/home/lcur0006/joeynmt/joeynmt/training.py", line 642, in _validate
    references=valid_references)
  File "/home/lcur0006/joeynmt/joeynmt/training.py", line 737, in _log_examples
    logger.info("\tSource:     %s", sources[p])
Message: '\tSource:     %s'
Arguments: ('\u0e1e \u0e48 \u0e2d\u0e02\u0e2d\u0e07\u0e09\u0e31\u0e19\u0e01\u0e33\u0e25\u0e31\u0e07\u0e1f\u0e31\u0e07\u0e02 \u0e48 \u0e32\u0e27\u0e1a\u0e35\u0e1a\u0e35\u0e0b\u0e35 \u0e08\u0e32\u0e01\u0e27\u0e34\u0e17\u0e22\u0e38\u0e2a\u0e35\u0e40\u0e17\u0e32\u0e2d\u0e31\u0e19\u0e40\u0e25 \u0e47 \u0e01',)
2021-10-03 14:02:23,670 - INFO - joeynmt.training - 	Source:     \u0e1e \u0e48 \u0e2d\u0e02\u0e2d\u0e07\u0e09\u0e31\u0e19\u0e01\u0e33\u0e25\u0e31\u0e07\u0e1f\u0e31\u0e07\u0e02 \u0e48 \u0e32\u0e27\u0e1a\u0e35\u0e1a\u0e35\u0e0b\u0e35 \u0e08\u0e32\u0e01\u0e27\u0e34\u0e17\u0e22\u0e38\u0e2a\u0e35\u0e40\u0e17\u0e32\u0e2d\u0e31\u0e19\u0e40\u0e25 \u0e47 \u0e01
2021-10-03 14:02:23,670 - INFO - joeynmt.training - 	Reference:  "My father was listening to BBC News on his small , gray radio ."
2021-10-03 14:02:23,670 - INFO - joeynmt.training - 	Hypothesis: "And I , , , , , , , , , , , , , , .
2021-10-03 14:02:23,671 - INFO - joeynmt.training - Validation result (greedy) at epoch   2, step      100: bleu:   0.98, loss: 94347.8828, ppl: 457.0967, duration: 4.7837s
2021-10-03 14:02:28,754 - INFO - joeynmt.training - Epoch   2: total training loss 7047.26
2021-10-03 14:02:28,754 - INFO - joeynmt.training - EPOCH 3
2021-10-03 14:02:40,190 - INFO - joeynmt.training - Epoch   3: total training loss 6837.74
2021-10-03 14:02:40,190 - INFO - joeynmt.training - EPOCH 4
2021-10-03 14:02:48,673 - WARNING - sacrebleu - That's 100 lines that end in a tokenized period ('.')
2021-10-03 14:02:48,674 - WARNING - sacrebleu - It looks like you forgot to detokenize your test data, which may hurt your score.
2021-10-03 14:02:48,674 - WARNING - sacrebleu - If you insist your data is detokenized, or don't care, you can suppress this message with the `force` parameter.
2021-10-03 14:02:48,678 - INFO - joeynmt.training - Hooray! New best validation result [eval_metric]!
2021-10-03 14:02:49,574 - INFO - joeynmt.helpers - delete models/LSTM_th/100.ckpt
2021-10-03 14:02:49,652 - INFO - joeynmt.helpers - delete /home/lcur0006/joeynmt/models/LSTM_th/100.ckpt
2021-10-03 14:02:49,653 - WARNING - joeynmt.helpers - Wanted to delete old checkpoint /home/lcur0006/joeynmt/models/LSTM_th/100.ckpt but file does not exist. ([Errno 2] No such file or directory: '/home/lcur0006/joeynmt/models/LSTM_th/100.ckpt')
2021-10-03 14:02:49,655 - INFO - joeynmt.training - Example #0
2021-10-03 14:02:49,655 - INFO - joeynmt.training - 	Source:     th
2021-10-03 14:02:49,655 - INFO - joeynmt.training - 	Reference:  en
2021-10-03 14:02:49,655 - INFO - joeynmt.training - 	Hypothesis: ( &apos;s .
2021-10-03 14:02:49,655 - INFO - joeynmt.training - Example #1
--- Logging error ---
Traceback (most recent call last):
  File "/sw/arch/Debian10/EB_production/2019/software/Anaconda3/2018.12/lib/python3.7/logging/__init__.py", line 1036, in emit
    stream.write(msg)
UnicodeEncodeError: 'latin-1' codec can't encode characters in position 72-74: ordinal not in range(256)
Call stack:
  File "/sw/arch/Debian10/EB_production/2019/software/Anaconda3/2018.12/lib/python3.7/runpy.py", line 193, in _run_module_as_main
    "__main__", mod_spec)
  File "/sw/arch/Debian10/EB_production/2019/software/Anaconda3/2018.12/lib/python3.7/runpy.py", line 85, in _run_code
    exec(code, run_globals)
  File "/home/lcur0006/joeynmt/joeynmt/__main__.py", line 48, in <module>
    main()
  File "/home/lcur0006/joeynmt/joeynmt/__main__.py", line 35, in main
    train(cfg_file=args.config_path, skip_test=args.skip_test)
  File "/home/lcur0006/joeynmt/joeynmt/training.py", line 846, in train
    trainer.train_and_validate(train_data=train_data, valid_data=dev_data)
  File "/home/lcur0006/joeynmt/joeynmt/training.py", line 497, in train_and_validate
    valid_duration = self._validate(valid_data, epoch_no)
  File "/home/lcur0006/joeynmt/joeynmt/training.py", line 642, in _validate
    references=valid_references)
  File "/home/lcur0006/joeynmt/joeynmt/training.py", line 731, in _log_examples
    logger.debug("\tRaw source:     %s", sources_raw[p])
Message: '\tRaw source:     %s'
Arguments: (['\u0e15\u0e2d\u0e19@@', '\u0e09\u0e31\u0e19@@', '\u0e2d\u0e32\u0e22\u0e38', '1@@', '1', '\u0e09\u0e31\u0e19@@', '\u0e08\u0e33@@', '\u0e44\u0e14', '\u0e49', '\u0e27', '\u0e48', '\u0e32\u0e15@@', '\u0e37', '\u0e48', '\u0e19@@', '\u0e02\u0e36', '\u0e49', '\u0e19\u0e21\u0e32@@', '\u0e40\u0e0a', '\u0e49', '\u0e32\u0e27@@', '\u0e31\u0e19@@', '\u0e2b\u0e19\u0e36', '\u0e48', '\u0e07', '\u0e41\u0e25\u0e30@@', '\u0e44\u0e14', '\u0e49', '\u0e22\u0e34\u0e19@@', '\u0e40\u0e2a\u0e35\u0e22\u0e07@@', '\u0e23', '\u0e49', '\u0e2d\u0e07@@', '\u0e14', '\u0e49', '\u0e27\u0e22\u0e04\u0e27\u0e32\u0e21@@', '\u0e22\u0e34\u0e19@@', '\u0e14\u0e35@@', '\u0e43\u0e19@@', '\u0e1a', '\u0e49', '\u0e32\u0e19'],)
--- Logging error ---
Traceback (most recent call last):
  File "/sw/arch/Debian10/EB_production/2019/software/Anaconda3/2018.12/lib/python3.7/logging/__init__.py", line 1036, in emit
    stream.write(msg)
UnicodeEncodeError: 'latin-1' codec can't encode characters in position 65-74: ordinal not in range(256)
Call stack:
  File "/sw/arch/Debian10/EB_production/2019/software/Anaconda3/2018.12/lib/python3.7/runpy.py", line 193, in _run_module_as_main
    "__main__", mod_spec)
  File "/sw/arch/Debian10/EB_production/2019/software/Anaconda3/2018.12/lib/python3.7/runpy.py", line 85, in _run_code
    exec(code, run_globals)
  File "/home/lcur0006/joeynmt/joeynmt/__main__.py", line 48, in <module>
    main()
  File "/home/lcur0006/joeynmt/joeynmt/__main__.py", line 35, in main
    train(cfg_file=args.config_path, skip_test=args.skip_test)
  File "/home/lcur0006/joeynmt/joeynmt/training.py", line 846, in train
    trainer.train_and_validate(train_data=train_data, valid_data=dev_data)
  File "/home/lcur0006/joeynmt/joeynmt/training.py", line 497, in train_and_validate
    valid_duration = self._validate(valid_data, epoch_no)
  File "/home/lcur0006/joeynmt/joeynmt/training.py", line 642, in _validate
    references=valid_references)
  File "/home/lcur0006/joeynmt/joeynmt/training.py", line 737, in _log_examples
    logger.info("\tSource:     %s", sources[p])
Message: '\tSource:     %s'
Arguments: ('\u0e15\u0e2d\u0e19\u0e09\u0e31\u0e19\u0e2d\u0e32\u0e22\u0e38 11 \u0e09\u0e31\u0e19\u0e08\u0e33\u0e44\u0e14 \u0e49 \u0e27 \u0e48 \u0e32\u0e15\u0e37 \u0e48 \u0e19\u0e02\u0e36 \u0e49 \u0e19\u0e21\u0e32\u0e40\u0e0a \u0e49 \u0e32\u0e27\u0e31\u0e19\u0e2b\u0e19\u0e36 \u0e48 \u0e07 \u0e41\u0e25\u0e30\u0e44\u0e14 \u0e49 \u0e22\u0e34\u0e19\u0e40\u0e2a\u0e35\u0e22\u0e07\u0e23 \u0e49 \u0e2d\u0e07\u0e14 \u0e49 \u0e27\u0e22\u0e04\u0e27\u0e32\u0e21\u0e22\u0e34\u0e19\u0e14\u0e35\u0e43\u0e19\u0e1a \u0e49 \u0e32\u0e19',)
2021-10-03 14:02:49,656 - INFO - joeynmt.training - 	Source:     \u0e15\u0e2d\u0e19\u0e09\u0e31\u0e19\u0e2d\u0e32\u0e22\u0e38 11 \u0e09\u0e31\u0e19\u0e08\u0e33\u0e44\u0e14 \u0e49 \u0e27 \u0e48 \u0e32\u0e15\u0e37 \u0e48 \u0e19\u0e02\u0e36 \u0e49 \u0e19\u0e21\u0e32\u0e40\u0e0a \u0e49 \u0e32\u0e27\u0e31\u0e19\u0e2b\u0e19\u0e36 \u0e48 \u0e07 \u0e41\u0e25\u0e30\u0e44\u0e14 \u0e49 \u0e22\u0e34\u0e19\u0e40\u0e2a\u0e35\u0e22\u0e07\u0e23 \u0e49 \u0e2d\u0e07\u0e14 \u0e49 \u0e27\u0e22\u0e04\u0e27\u0e32\u0e21\u0e22\u0e34\u0e19\u0e14\u0e35\u0e43\u0e19\u0e1a \u0e49 \u0e32\u0e19
2021-10-03 14:02:49,656 - INFO - joeynmt.training - 	Reference:  "When I was 11 , I remember waking up one morning to the sound of joy in my house ."
2021-10-03 14:02:49,657 - INFO - joeynmt.training - 	Hypothesis: "And I the the , the the , the the the , the the the , the the the the , the the the the the the the the the the the the the the the the the the the the ."
2021-10-03 14:02:49,657 - INFO - joeynmt.training - Example #2
--- Logging error ---
Traceback (most recent call last):
  File "/sw/arch/Debian10/EB_production/2019/software/Anaconda3/2018.12/lib/python3.7/logging/__init__.py", line 1036, in emit
    stream.write(msg)
UnicodeEncodeError: 'latin-1' codec can't encode character '\u0e1e' in position 72: ordinal not in range(256)
Call stack:
  File "/sw/arch/Debian10/EB_production/2019/software/Anaconda3/2018.12/lib/python3.7/runpy.py", line 193, in _run_module_as_main
    "__main__", mod_spec)
  File "/sw/arch/Debian10/EB_production/2019/software/Anaconda3/2018.12/lib/python3.7/runpy.py", line 85, in _run_code
    exec(code, run_globals)
  File "/home/lcur0006/joeynmt/joeynmt/__main__.py", line 48, in <module>
    main()
  File "/home/lcur0006/joeynmt/joeynmt/__main__.py", line 35, in main
    train(cfg_file=args.config_path, skip_test=args.skip_test)
  File "/home/lcur0006/joeynmt/joeynmt/training.py", line 846, in train
    trainer.train_and_validate(train_data=train_data, valid_data=dev_data)
  File "/home/lcur0006/joeynmt/joeynmt/training.py", line 497, in train_and_validate
    valid_duration = self._validate(valid_data, epoch_no)
  File "/home/lcur0006/joeynmt/joeynmt/training.py", line 642, in _validate
    references=valid_references)
  File "/home/lcur0006/joeynmt/joeynmt/training.py", line 731, in _log_examples
    logger.debug("\tRaw source:     %s", sources_raw[p])
Message: '\tRaw source:     %s'
Arguments: (['\u0e1e', '\u0e48', '\u0e2d\u0e02\u0e2d\u0e07@@', '\u0e09\u0e31\u0e19@@', '\u0e01\u0e33\u0e25\u0e31\u0e07@@', '\u0e1f\u0e31\u0e07@@', '\u0e02', '\u0e48', '\u0e32\u0e27@@', '\u0e1a\u0e35@@', '\u0e1a\u0e35@@', '\u0e0b\u0e35', '\u0e08\u0e32\u0e01@@', '\u0e27\u0e34\u0e17@@', '\u0e22\u0e38@@', '\u0e2a\u0e35@@', '\u0e40\u0e17@@', '\u0e32@@', '\u0e2d\u0e31\u0e19@@', '\u0e40\u0e25', '\u0e47', '\u0e01'],)
--- Logging error ---
Traceback (most recent call last):
  File "/sw/arch/Debian10/EB_production/2019/software/Anaconda3/2018.12/lib/python3.7/logging/__init__.py", line 1036, in emit
    stream.write(msg)
UnicodeEncodeError: 'latin-1' codec can't encode character '\u0e1e' in position 65: ordinal not in range(256)
Call stack:
  File "/sw/arch/Debian10/EB_production/2019/software/Anaconda3/2018.12/lib/python3.7/runpy.py", line 193, in _run_module_as_main
    "__main__", mod_spec)
  File "/sw/arch/Debian10/EB_production/2019/software/Anaconda3/2018.12/lib/python3.7/runpy.py", line 85, in _run_code
    exec(code, run_globals)
  File "/home/lcur0006/joeynmt/joeynmt/__main__.py", line 48, in <module>
    main()
  File "/home/lcur0006/joeynmt/joeynmt/__main__.py", line 35, in main
    train(cfg_file=args.config_path, skip_test=args.skip_test)
  File "/home/lcur0006/joeynmt/joeynmt/training.py", line 846, in train
    trainer.train_and_validate(train_data=train_data, valid_data=dev_data)
  File "/home/lcur0006/joeynmt/joeynmt/training.py", line 497, in train_and_validate
    valid_duration = self._validate(valid_data, epoch_no)
  File "/home/lcur0006/joeynmt/joeynmt/training.py", line 642, in _validate
    references=valid_references)
  File "/home/lcur0006/joeynmt/joeynmt/training.py", line 737, in _log_examples
    logger.info("\tSource:     %s", sources[p])
Message: '\tSource:     %s'
Arguments: ('\u0e1e \u0e48 \u0e2d\u0e02\u0e2d\u0e07\u0e09\u0e31\u0e19\u0e01\u0e33\u0e25\u0e31\u0e07\u0e1f\u0e31\u0e07\u0e02 \u0e48 \u0e32\u0e27\u0e1a\u0e35\u0e1a\u0e35\u0e0b\u0e35 \u0e08\u0e32\u0e01\u0e27\u0e34\u0e17\u0e22\u0e38\u0e2a\u0e35\u0e40\u0e17\u0e32\u0e2d\u0e31\u0e19\u0e40\u0e25 \u0e47 \u0e01',)
2021-10-03 14:02:49,657 - INFO - joeynmt.training - 	Source:     \u0e1e \u0e48 \u0e2d\u0e02\u0e2d\u0e07\u0e09\u0e31\u0e19\u0e01\u0e33\u0e25\u0e31\u0e07\u0e1f\u0e31\u0e07\u0e02 \u0e48 \u0e32\u0e27\u0e1a\u0e35\u0e1a\u0e35\u0e0b\u0e35 \u0e08\u0e32\u0e01\u0e27\u0e34\u0e17\u0e22\u0e38\u0e2a\u0e35\u0e40\u0e17\u0e32\u0e2d\u0e31\u0e19\u0e40\u0e25 \u0e47 \u0e01
2021-10-03 14:02:49,657 - INFO - joeynmt.training - 	Reference:  "My father was listening to BBC News on his small , gray radio ."
2021-10-03 14:02:49,657 - INFO - joeynmt.training - 	Hypothesis: "And &apos;s the a , the the the the , the the the the the the the the the the the the ."
2021-10-03 14:02:49,658 - INFO - joeynmt.training - Validation result (greedy) at epoch   4, step      200: bleu:   1.23, loss: 90355.2656, ppl: 352.7296, duration: 4.9471s
2021-10-03 14:02:58,363 - INFO - joeynmt.training - Epoch   4: total training loss 6648.75
2021-10-03 14:02:58,363 - INFO - joeynmt.training - EPOCH 5
2021-10-03 14:03:09,935 - INFO - joeynmt.training - Epoch   5: total training loss 6476.82
2021-10-03 14:03:09,936 - INFO - joeynmt.training - EPOCH 6
2021-10-03 14:03:14,933 - WARNING - sacrebleu - That's 100 lines that end in a tokenized period ('.')
2021-10-03 14:03:14,933 - WARNING - sacrebleu - It looks like you forgot to detokenize your test data, which may hurt your score.
2021-10-03 14:03:14,933 - WARNING - sacrebleu - If you insist your data is detokenized, or don't care, you can suppress this message with the `force` parameter.
2021-10-03 14:03:14,940 - INFO - joeynmt.training - Example #0
2021-10-03 14:03:14,940 - INFO - joeynmt.training - 	Source:     th
2021-10-03 14:03:14,940 - INFO - joeynmt.training - 	Reference:  en
2021-10-03 14:03:14,941 - INFO - joeynmt.training - 	Hypothesis: ( Applause
2021-10-03 14:03:14,941 - INFO - joeynmt.training - Example #1
--- Logging error ---
Traceback (most recent call last):
  File "/sw/arch/Debian10/EB_production/2019/software/Anaconda3/2018.12/lib/python3.7/logging/__init__.py", line 1036, in emit
    stream.write(msg)
UnicodeEncodeError: 'latin-1' codec can't encode characters in position 72-74: ordinal not in range(256)
Call stack:
  File "/sw/arch/Debian10/EB_production/2019/software/Anaconda3/2018.12/lib/python3.7/runpy.py", line 193, in _run_module_as_main
    "__main__", mod_spec)
  File "/sw/arch/Debian10/EB_production/2019/software/Anaconda3/2018.12/lib/python3.7/runpy.py", line 85, in _run_code
    exec(code, run_globals)
  File "/home/lcur0006/joeynmt/joeynmt/__main__.py", line 48, in <module>
    main()
  File "/home/lcur0006/joeynmt/joeynmt/__main__.py", line 35, in main
    train(cfg_file=args.config_path, skip_test=args.skip_test)
  File "/home/lcur0006/joeynmt/joeynmt/training.py", line 846, in train
    trainer.train_and_validate(train_data=train_data, valid_data=dev_data)
  File "/home/lcur0006/joeynmt/joeynmt/training.py", line 497, in train_and_validate
    valid_duration = self._validate(valid_data, epoch_no)
  File "/home/lcur0006/joeynmt/joeynmt/training.py", line 642, in _validate
    references=valid_references)
  File "/home/lcur0006/joeynmt/joeynmt/training.py", line 731, in _log_examples
    logger.debug("\tRaw source:     %s", sources_raw[p])
Message: '\tRaw source:     %s'
Arguments: (['\u0e15\u0e2d\u0e19@@', '\u0e09\u0e31\u0e19@@', '\u0e2d\u0e32\u0e22\u0e38', '1@@', '1', '\u0e09\u0e31\u0e19@@', '\u0e08\u0e33@@', '\u0e44\u0e14', '\u0e49', '\u0e27', '\u0e48', '\u0e32\u0e15@@', '\u0e37', '\u0e48', '\u0e19@@', '\u0e02\u0e36', '\u0e49', '\u0e19\u0e21\u0e32@@', '\u0e40\u0e0a', '\u0e49', '\u0e32\u0e27@@', '\u0e31\u0e19@@', '\u0e2b\u0e19\u0e36', '\u0e48', '\u0e07', '\u0e41\u0e25\u0e30@@', '\u0e44\u0e14', '\u0e49', '\u0e22\u0e34\u0e19@@', '\u0e40\u0e2a\u0e35\u0e22\u0e07@@', '\u0e23', '\u0e49', '\u0e2d\u0e07@@', '\u0e14', '\u0e49', '\u0e27\u0e22\u0e04\u0e27\u0e32\u0e21@@', '\u0e22\u0e34\u0e19@@', '\u0e14\u0e35@@', '\u0e43\u0e19@@', '\u0e1a', '\u0e49', '\u0e32\u0e19'],)
--- Logging error ---
Traceback (most recent call last):
  File "/sw/arch/Debian10/EB_production/2019/software/Anaconda3/2018.12/lib/python3.7/logging/__init__.py", line 1036, in emit
    stream.write(msg)
UnicodeEncodeError: 'latin-1' codec can't encode characters in position 65-74: ordinal not in range(256)
Call stack:
  File "/sw/arch/Debian10/EB_production/2019/software/Anaconda3/2018.12/lib/python3.7/runpy.py", line 193, in _run_module_as_main
    "__main__", mod_spec)
  File "/sw/arch/Debian10/EB_production/2019/software/Anaconda3/2018.12/lib/python3.7/runpy.py", line 85, in _run_code
    exec(code, run_globals)
  File "/home/lcur0006/joeynmt/joeynmt/__main__.py", line 48, in <module>
    main()
  File "/home/lcur0006/joeynmt/joeynmt/__main__.py", line 35, in main
    train(cfg_file=args.config_path, skip_test=args.skip_test)
  File "/home/lcur0006/joeynmt/joeynmt/training.py", line 846, in train
    trainer.train_and_validate(train_data=train_data, valid_data=dev_data)
  File "/home/lcur0006/joeynmt/joeynmt/training.py", line 497, in train_and_validate
    valid_duration = self._validate(valid_data, epoch_no)
  File "/home/lcur0006/joeynmt/joeynmt/training.py", line 642, in _validate
    references=valid_references)
  File "/home/lcur0006/joeynmt/joeynmt/training.py", line 737, in _log_examples
    logger.info("\tSource:     %s", sources[p])
Message: '\tSource:     %s'
Arguments: ('\u0e15\u0e2d\u0e19\u0e09\u0e31\u0e19\u0e2d\u0e32\u0e22\u0e38 11 \u0e09\u0e31\u0e19\u0e08\u0e33\u0e44\u0e14 \u0e49 \u0e27 \u0e48 \u0e32\u0e15\u0e37 \u0e48 \u0e19\u0e02\u0e36 \u0e49 \u0e19\u0e21\u0e32\u0e40\u0e0a \u0e49 \u0e32\u0e27\u0e31\u0e19\u0e2b\u0e19\u0e36 \u0e48 \u0e07 \u0e41\u0e25\u0e30\u0e44\u0e14 \u0e49 \u0e22\u0e34\u0e19\u0e40\u0e2a\u0e35\u0e22\u0e07\u0e23 \u0e49 \u0e2d\u0e07\u0e14 \u0e49 \u0e27\u0e22\u0e04\u0e27\u0e32\u0e21\u0e22\u0e34\u0e19\u0e14\u0e35\u0e43\u0e19\u0e1a \u0e49 \u0e32\u0e19',)
2021-10-03 14:03:14,942 - INFO - joeynmt.training - 	Source:     \u0e15\u0e2d\u0e19\u0e09\u0e31\u0e19\u0e2d\u0e32\u0e22\u0e38 11 \u0e09\u0e31\u0e19\u0e08\u0e33\u0e44\u0e14 \u0e49 \u0e27 \u0e48 \u0e32\u0e15\u0e37 \u0e48 \u0e19\u0e02\u0e36 \u0e49 \u0e19\u0e21\u0e32\u0e40\u0e0a \u0e49 \u0e32\u0e27\u0e31\u0e19\u0e2b\u0e19\u0e36 \u0e48 \u0e07 \u0e41\u0e25\u0e30\u0e44\u0e14 \u0e49 \u0e22\u0e34\u0e19\u0e40\u0e2a\u0e35\u0e22\u0e07\u0e23 \u0e49 \u0e2d\u0e07\u0e14 \u0e49 \u0e27\u0e22\u0e04\u0e27\u0e32\u0e21\u0e22\u0e34\u0e19\u0e14\u0e35\u0e43\u0e19\u0e1a \u0e49 \u0e32\u0e19
2021-10-03 14:03:14,943 - INFO - joeynmt.training - 	Reference:  "When I was 11 , I remember waking up one morning to the sound of joy in my house ."
2021-10-03 14:03:14,943 - INFO - joeynmt.training - 	Hypothesis: I I I &apos;t &apos;t &apos;t I I I I I I I I I I I I I I I I I I I I I I I I I I I I I I I I I I I I I I I I I I I I I I I I I I I I I I I I I I I I I I I I I I I I I I I I I I I I I I I I I I I I I I I I I I I I I I
2021-10-03 14:03:14,943 - INFO - joeynmt.training - Example #2
--- Logging error ---
Traceback (most recent call last):
  File "/sw/arch/Debian10/EB_production/2019/software/Anaconda3/2018.12/lib/python3.7/logging/__init__.py", line 1036, in emit
    stream.write(msg)
UnicodeEncodeError: 'latin-1' codec can't encode character '\u0e1e' in position 72: ordinal not in range(256)
Call stack:
  File "/sw/arch/Debian10/EB_production/2019/software/Anaconda3/2018.12/lib/python3.7/runpy.py", line 193, in _run_module_as_main
    "__main__", mod_spec)
  File "/sw/arch/Debian10/EB_production/2019/software/Anaconda3/2018.12/lib/python3.7/runpy.py", line 85, in _run_code
    exec(code, run_globals)
  File "/home/lcur0006/joeynmt/joeynmt/__main__.py", line 48, in <module>
    main()
  File "/home/lcur0006/joeynmt/joeynmt/__main__.py", line 35, in main
    train(cfg_file=args.config_path, skip_test=args.skip_test)
  File "/home/lcur0006/joeynmt/joeynmt/training.py", line 846, in train
    trainer.train_and_validate(train_data=train_data, valid_data=dev_data)
  File "/home/lcur0006/joeynmt/joeynmt/training.py", line 497, in train_and_validate
    valid_duration = self._validate(valid_data, epoch_no)
  File "/home/lcur0006/joeynmt/joeynmt/training.py", line 642, in _validate
    references=valid_references)
  File "/home/lcur0006/joeynmt/joeynmt/training.py", line 731, in _log_examples
    logger.debug("\tRaw source:     %s", sources_raw[p])
Message: '\tRaw source:     %s'
Arguments: (['\u0e1e', '\u0e48', '\u0e2d\u0e02\u0e2d\u0e07@@', '\u0e09\u0e31\u0e19@@', '\u0e01\u0e33\u0e25\u0e31\u0e07@@', '\u0e1f\u0e31\u0e07@@', '\u0e02', '\u0e48', '\u0e32\u0e27@@', '\u0e1a\u0e35@@', '\u0e1a\u0e35@@', '\u0e0b\u0e35', '\u0e08\u0e32\u0e01@@', '\u0e27\u0e34\u0e17@@', '\u0e22\u0e38@@', '\u0e2a\u0e35@@', '\u0e40\u0e17@@', '\u0e32@@', '\u0e2d\u0e31\u0e19@@', '\u0e40\u0e25', '\u0e47', '\u0e01'],)
--- Logging error ---
Traceback (most recent call last):
  File "/sw/arch/Debian10/EB_production/2019/software/Anaconda3/2018.12/lib/python3.7/logging/__init__.py", line 1036, in emit
    stream.write(msg)
UnicodeEncodeError: 'latin-1' codec can't encode character '\u0e1e' in position 65: ordinal not in range(256)
Call stack:
  File "/sw/arch/Debian10/EB_production/2019/software/Anaconda3/2018.12/lib/python3.7/runpy.py", line 193, in _run_module_as_main
    "__main__", mod_spec)
  File "/sw/arch/Debian10/EB_production/2019/software/Anaconda3/2018.12/lib/python3.7/runpy.py", line 85, in _run_code
    exec(code, run_globals)
  File "/home/lcur0006/joeynmt/joeynmt/__main__.py", line 48, in <module>
    main()
  File "/home/lcur0006/joeynmt/joeynmt/__main__.py", line 35, in main
    train(cfg_file=args.config_path, skip_test=args.skip_test)
  File "/home/lcur0006/joeynmt/joeynmt/training.py", line 846, in train
    trainer.train_and_validate(train_data=train_data, valid_data=dev_data)
  File "/home/lcur0006/joeynmt/joeynmt/training.py", line 497, in train_and_validate
    valid_duration = self._validate(valid_data, epoch_no)
  File "/home/lcur0006/joeynmt/joeynmt/training.py", line 642, in _validate
    references=valid_references)
  File "/home/lcur0006/joeynmt/joeynmt/training.py", line 737, in _log_examples
    logger.info("\tSource:     %s", sources[p])
Message: '\tSource:     %s'
Arguments: ('\u0e1e \u0e48 \u0e2d\u0e02\u0e2d\u0e07\u0e09\u0e31\u0e19\u0e01\u0e33\u0e25\u0e31\u0e07\u0e1f\u0e31\u0e07\u0e02 \u0e48 \u0e32\u0e27\u0e1a\u0e35\u0e1a\u0e35\u0e0b\u0e35 \u0e08\u0e32\u0e01\u0e27\u0e34\u0e17\u0e22\u0e38\u0e2a\u0e35\u0e40\u0e17\u0e32\u0e2d\u0e31\u0e19\u0e40\u0e25 \u0e47 \u0e01',)
2021-10-03 14:03:14,944 - INFO - joeynmt.training - 	Source:     \u0e1e \u0e48 \u0e2d\u0e02\u0e2d\u0e07\u0e09\u0e31\u0e19\u0e01\u0e33\u0e25\u0e31\u0e07\u0e1f\u0e31\u0e07\u0e02 \u0e48 \u0e32\u0e27\u0e1a\u0e35\u0e1a\u0e35\u0e0b\u0e35 \u0e08\u0e32\u0e01\u0e27\u0e34\u0e17\u0e22\u0e38\u0e2a\u0e35\u0e40\u0e17\u0e32\u0e2d\u0e31\u0e19\u0e40\u0e25 \u0e47 \u0e01
2021-10-03 14:03:14,945 - INFO - joeynmt.training - 	Reference:  "My father was listening to BBC News on his small , gray radio ."
2021-10-03 14:03:14,945 - INFO - joeynmt.training - 	Hypothesis: "And I I I I I I I I I I I I I I I I I I I I I I I &apos;t &apos;t &apos;t &apos;t &apos;t it ."
2021-10-03 14:03:14,945 - INFO - joeynmt.training - Validation result (greedy) at epoch   6, step      300: bleu:   0.50, loss: 87273.5938, ppl: 288.7742, duration: 4.0397s
2021-10-03 14:03:28,315 - INFO - joeynmt.training - Epoch   6: total training loss 6260.19
2021-10-03 14:03:28,316 - INFO - joeynmt.training - EPOCH 7
2021-10-03 14:03:41,464 - WARNING - sacrebleu - That's 100 lines that end in a tokenized period ('.')
2021-10-03 14:03:41,465 - WARNING - sacrebleu - It looks like you forgot to detokenize your test data, which may hurt your score.
2021-10-03 14:03:41,465 - WARNING - sacrebleu - If you insist your data is detokenized, or don't care, you can suppress this message with the `force` parameter.
2021-10-03 14:03:41,471 - INFO - joeynmt.training - Example #0
2021-10-03 14:03:41,471 - INFO - joeynmt.training - 	Source:     th
2021-10-03 14:03:41,471 - INFO - joeynmt.training - 	Reference:  en
2021-10-03 14:03:41,472 - INFO - joeynmt.training - 	Hypothesis: Thank you .
2021-10-03 14:03:41,472 - INFO - joeynmt.training - Example #1
--- Logging error ---
Traceback (most recent call last):
  File "/sw/arch/Debian10/EB_production/2019/software/Anaconda3/2018.12/lib/python3.7/logging/__init__.py", line 1036, in emit
    stream.write(msg)
UnicodeEncodeError: 'latin-1' codec can't encode characters in position 72-74: ordinal not in range(256)
Call stack:
  File "/sw/arch/Debian10/EB_production/2019/software/Anaconda3/2018.12/lib/python3.7/runpy.py", line 193, in _run_module_as_main
    "__main__", mod_spec)
  File "/sw/arch/Debian10/EB_production/2019/software/Anaconda3/2018.12/lib/python3.7/runpy.py", line 85, in _run_code
    exec(code, run_globals)
  File "/home/lcur0006/joeynmt/joeynmt/__main__.py", line 48, in <module>
    main()
  File "/home/lcur0006/joeynmt/joeynmt/__main__.py", line 35, in main
    train(cfg_file=args.config_path, skip_test=args.skip_test)
  File "/home/lcur0006/joeynmt/joeynmt/training.py", line 846, in train
    trainer.train_and_validate(train_data=train_data, valid_data=dev_data)
  File "/home/lcur0006/joeynmt/joeynmt/training.py", line 497, in train_and_validate
    valid_duration = self._validate(valid_data, epoch_no)
  File "/home/lcur0006/joeynmt/joeynmt/training.py", line 642, in _validate
    references=valid_references)
  File "/home/lcur0006/joeynmt/joeynmt/training.py", line 731, in _log_examples
    logger.debug("\tRaw source:     %s", sources_raw[p])
Message: '\tRaw source:     %s'
Arguments: (['\u0e15\u0e2d\u0e19@@', '\u0e09\u0e31\u0e19@@', '\u0e2d\u0e32\u0e22\u0e38', '1@@', '1', '\u0e09\u0e31\u0e19@@', '\u0e08\u0e33@@', '\u0e44\u0e14', '\u0e49', '\u0e27', '\u0e48', '\u0e32\u0e15@@', '\u0e37', '\u0e48', '\u0e19@@', '\u0e02\u0e36', '\u0e49', '\u0e19\u0e21\u0e32@@', '\u0e40\u0e0a', '\u0e49', '\u0e32\u0e27@@', '\u0e31\u0e19@@', '\u0e2b\u0e19\u0e36', '\u0e48', '\u0e07', '\u0e41\u0e25\u0e30@@', '\u0e44\u0e14', '\u0e49', '\u0e22\u0e34\u0e19@@', '\u0e40\u0e2a\u0e35\u0e22\u0e07@@', '\u0e23', '\u0e49', '\u0e2d\u0e07@@', '\u0e14', '\u0e49', '\u0e27\u0e22\u0e04\u0e27\u0e32\u0e21@@', '\u0e22\u0e34\u0e19@@', '\u0e14\u0e35@@', '\u0e43\u0e19@@', '\u0e1a', '\u0e49', '\u0e32\u0e19'],)
--- Logging error ---
Traceback (most recent call last):
  File "/sw/arch/Debian10/EB_production/2019/software/Anaconda3/2018.12/lib/python3.7/logging/__init__.py", line 1036, in emit
    stream.write(msg)
UnicodeEncodeError: 'latin-1' codec can't encode characters in position 65-74: ordinal not in range(256)
Call stack:
  File "/sw/arch/Debian10/EB_production/2019/software/Anaconda3/2018.12/lib/python3.7/runpy.py", line 193, in _run_module_as_main
    "__main__", mod_spec)
  File "/sw/arch/Debian10/EB_production/2019/software/Anaconda3/2018.12/lib/python3.7/runpy.py", line 85, in _run_code
    exec(code, run_globals)
  File "/home/lcur0006/joeynmt/joeynmt/__main__.py", line 48, in <module>
    main()
  File "/home/lcur0006/joeynmt/joeynmt/__main__.py", line 35, in main
    train(cfg_file=args.config_path, skip_test=args.skip_test)
  File "/home/lcur0006/joeynmt/joeynmt/training.py", line 846, in train
    trainer.train_and_validate(train_data=train_data, valid_data=dev_data)
  File "/home/lcur0006/joeynmt/joeynmt/training.py", line 497, in train_and_validate
    valid_duration = self._validate(valid_data, epoch_no)
  File "/home/lcur0006/joeynmt/joeynmt/training.py", line 642, in _validate
    references=valid_references)
  File "/home/lcur0006/joeynmt/joeynmt/training.py", line 737, in _log_examples
    logger.info("\tSource:     %s", sources[p])
Message: '\tSource:     %s'
Arguments: ('\u0e15\u0e2d\u0e19\u0e09\u0e31\u0e19\u0e2d\u0e32\u0e22\u0e38 11 \u0e09\u0e31\u0e19\u0e08\u0e33\u0e44\u0e14 \u0e49 \u0e27 \u0e48 \u0e32\u0e15\u0e37 \u0e48 \u0e19\u0e02\u0e36 \u0e49 \u0e19\u0e21\u0e32\u0e40\u0e0a \u0e49 \u0e32\u0e27\u0e31\u0e19\u0e2b\u0e19\u0e36 \u0e48 \u0e07 \u0e41\u0e25\u0e30\u0e44\u0e14 \u0e49 \u0e22\u0e34\u0e19\u0e40\u0e2a\u0e35\u0e22\u0e07\u0e23 \u0e49 \u0e2d\u0e07\u0e14 \u0e49 \u0e27\u0e22\u0e04\u0e27\u0e32\u0e21\u0e22\u0e34\u0e19\u0e14\u0e35\u0e43\u0e19\u0e1a \u0e49 \u0e32\u0e19',)
2021-10-03 14:03:41,475 - INFO - joeynmt.training - 	Source:     \u0e15\u0e2d\u0e19\u0e09\u0e31\u0e19\u0e2d\u0e32\u0e22\u0e38 11 \u0e09\u0e31\u0e19\u0e08\u0e33\u0e44\u0e14 \u0e49 \u0e27 \u0e48 \u0e32\u0e15\u0e37 \u0e48 \u0e19\u0e02\u0e36 \u0e49 \u0e19\u0e21\u0e32\u0e40\u0e0a \u0e49 \u0e32\u0e27\u0e31\u0e19\u0e2b\u0e19\u0e36 \u0e48 \u0e07 \u0e41\u0e25\u0e30\u0e44\u0e14 \u0e49 \u0e22\u0e34\u0e19\u0e40\u0e2a\u0e35\u0e22\u0e07\u0e23 \u0e49 \u0e2d\u0e07\u0e14 \u0e49 \u0e27\u0e22\u0e04\u0e27\u0e32\u0e21\u0e22\u0e34\u0e19\u0e14\u0e35\u0e43\u0e19\u0e1a \u0e49 \u0e32\u0e19
2021-10-03 14:03:41,476 - INFO - joeynmt.training - 	Reference:  "When I was 11 , I remember waking up one morning to the sound of joy in my house ."
2021-10-03 14:03:41,476 - INFO - joeynmt.training - 	Hypothesis: "And I &apos;t &apos;t &apos;t &apos;t &apos;t &apos;t &apos;t &apos;t &apos;t &apos;t &apos;t &apos;t &apos;t &apos;t &apos;t &apos;t &apos;t &apos;t &apos;t &apos;t &apos;t &apos;t &apos;t &apos;t &apos;t &apos;t &apos;t &apos;t &apos;t &apos;t &apos;t &apos;t &apos;t &apos;t &apos;t &apos;t &apos;t &apos;t &apos;t &apos;t &apos;t &apos;t &apos;t &apos;t &apos;t &apos;t &apos;t &apos;t &apos;t &apos;t &apos;t &apos;t &apos;t &apos;t &apos;t &apos;t &apos;t &apos;t &apos;t &apos;t &apos;t &apos;t &apos;t &apos;t &apos;t &apos;t &apos;t &apos;t &apos;t &apos;t &apos;t &apos;t &apos;t &apos;t &apos;t &apos;t &apos;t &apos;t &apos;t &apos;t &apos;t &apos;t &apos;t &apos;t &apos;t &apos;t &apos;t &apos;t &apos;t &apos;t &apos;t &apos;t &apos;t &apos;t &apos;t &apos;t &apos;t &apos;t
2021-10-03 14:03:41,476 - INFO - joeynmt.training - Example #2
--- Logging error ---
Traceback (most recent call last):
  File "/sw/arch/Debian10/EB_production/2019/software/Anaconda3/2018.12/lib/python3.7/logging/__init__.py", line 1036, in emit
    stream.write(msg)
UnicodeEncodeError: 'latin-1' codec can't encode character '\u0e1e' in position 72: ordinal not in range(256)
Call stack:
  File "/sw/arch/Debian10/EB_production/2019/software/Anaconda3/2018.12/lib/python3.7/runpy.py", line 193, in _run_module_as_main
    "__main__", mod_spec)
  File "/sw/arch/Debian10/EB_production/2019/software/Anaconda3/2018.12/lib/python3.7/runpy.py", line 85, in _run_code
    exec(code, run_globals)
  File "/home/lcur0006/joeynmt/joeynmt/__main__.py", line 48, in <module>
    main()
  File "/home/lcur0006/joeynmt/joeynmt/__main__.py", line 35, in main
    train(cfg_file=args.config_path, skip_test=args.skip_test)
  File "/home/lcur0006/joeynmt/joeynmt/training.py", line 846, in train
    trainer.train_and_validate(train_data=train_data, valid_data=dev_data)
  File "/home/lcur0006/joeynmt/joeynmt/training.py", line 497, in train_and_validate
    valid_duration = self._validate(valid_data, epoch_no)
  File "/home/lcur0006/joeynmt/joeynmt/training.py", line 642, in _validate
    references=valid_references)
  File "/home/lcur0006/joeynmt/joeynmt/training.py", line 731, in _log_examples
    logger.debug("\tRaw source:     %s", sources_raw[p])
Message: '\tRaw source:     %s'
Arguments: (['\u0e1e', '\u0e48', '\u0e2d\u0e02\u0e2d\u0e07@@', '\u0e09\u0e31\u0e19@@', '\u0e01\u0e33\u0e25\u0e31\u0e07@@', '\u0e1f\u0e31\u0e07@@', '\u0e02', '\u0e48', '\u0e32\u0e27@@', '\u0e1a\u0e35@@', '\u0e1a\u0e35@@', '\u0e0b\u0e35', '\u0e08\u0e32\u0e01@@', '\u0e27\u0e34\u0e17@@', '\u0e22\u0e38@@', '\u0e2a\u0e35@@', '\u0e40\u0e17@@', '\u0e32@@', '\u0e2d\u0e31\u0e19@@', '\u0e40\u0e25', '\u0e47', '\u0e01'],)
--- Logging error ---
Traceback (most recent call last):
  File "/sw/arch/Debian10/EB_production/2019/software/Anaconda3/2018.12/lib/python3.7/logging/__init__.py", line 1036, in emit
    stream.write(msg)
UnicodeEncodeError: 'latin-1' codec can't encode character '\u0e1e' in position 65: ordinal not in range(256)
Call stack:
  File "/sw/arch/Debian10/EB_production/2019/software/Anaconda3/2018.12/lib/python3.7/runpy.py", line 193, in _run_module_as_main
    "__main__", mod_spec)
  File "/sw/arch/Debian10/EB_production/2019/software/Anaconda3/2018.12/lib/python3.7/runpy.py", line 85, in _run_code
    exec(code, run_globals)
  File "/home/lcur0006/joeynmt/joeynmt/__main__.py", line 48, in <module>
    main()
  File "/home/lcur0006/joeynmt/joeynmt/__main__.py", line 35, in main
    train(cfg_file=args.config_path, skip_test=args.skip_test)
  File "/home/lcur0006/joeynmt/joeynmt/training.py", line 846, in train
    trainer.train_and_validate(train_data=train_data, valid_data=dev_data)
  File "/home/lcur0006/joeynmt/joeynmt/training.py", line 497, in train_and_validate
    valid_duration = self._validate(valid_data, epoch_no)
  File "/home/lcur0006/joeynmt/joeynmt/training.py", line 642, in _validate
    references=valid_references)
  File "/home/lcur0006/joeynmt/joeynmt/training.py", line 737, in _log_examples
    logger.info("\tSource:     %s", sources[p])
Message: '\tSource:     %s'
Arguments: ('\u0e1e \u0e48 \u0e2d\u0e02\u0e2d\u0e07\u0e09\u0e31\u0e19\u0e01\u0e33\u0e25\u0e31\u0e07\u0e1f\u0e31\u0e07\u0e02 \u0e48 \u0e32\u0e27\u0e1a\u0e35\u0e1a\u0e35\u0e0b\u0e35 \u0e08\u0e32\u0e01\u0e27\u0e34\u0e17\u0e22\u0e38\u0e2a\u0e35\u0e40\u0e17\u0e32\u0e2d\u0e31\u0e19\u0e40\u0e25 \u0e47 \u0e01',)
2021-10-03 14:03:41,477 - INFO - joeynmt.training - 	Source:     \u0e1e \u0e48 \u0e2d\u0e02\u0e2d\u0e07\u0e09\u0e31\u0e19\u0e01\u0e33\u0e25\u0e31\u0e07\u0e1f\u0e31\u0e07\u0e02 \u0e48 \u0e32\u0e27\u0e1a\u0e35\u0e1a\u0e35\u0e0b\u0e35 \u0e08\u0e32\u0e01\u0e27\u0e34\u0e17\u0e22\u0e38\u0e2a\u0e35\u0e40\u0e17\u0e32\u0e2d\u0e31\u0e19\u0e40\u0e25 \u0e47 \u0e01
2021-10-03 14:03:41,478 - INFO - joeynmt.training - 	Reference:  "My father was listening to BBC News on his small , gray radio ."
2021-10-03 14:03:41,478 - INFO - joeynmt.training - 	Hypothesis: "And I &apos;t &apos;t &apos;t &apos;t &apos;t &apos;t &apos;t &apos;t &apos;t &apos;t &apos;t &apos;t &apos;t &apos;t &apos;t &apos;t &apos;t &apos;t do ."
2021-10-03 14:03:41,478 - INFO - joeynmt.training - Validation result (greedy) at epoch   7, step      400: bleu:   0.55, loss: 82511.6328, ppl: 211.9832, duration: 4.2141s
2021-10-03 14:03:47,538 - INFO - joeynmt.training - Epoch   7: total training loss 6027.56
2021-10-03 14:03:47,539 - INFO - joeynmt.training - EPOCH 8
2021-10-03 14:03:58,999 - INFO - joeynmt.training - Epoch   8: total training loss 5844.64
2021-10-03 14:03:58,999 - INFO - joeynmt.training - EPOCH 9
2021-10-03 14:04:08,500 - WARNING - sacrebleu - That's 100 lines that end in a tokenized period ('.')
2021-10-03 14:04:08,501 - WARNING - sacrebleu - It looks like you forgot to detokenize your test data, which may hurt your score.
2021-10-03 14:04:08,501 - WARNING - sacrebleu - If you insist your data is detokenized, or don't care, you can suppress this message with the `force` parameter.
2021-10-03 14:04:08,506 - INFO - joeynmt.training - Hooray! New best validation result [eval_metric]!
2021-10-03 14:04:09,436 - INFO - joeynmt.helpers - delete models/LSTM_th/200.ckpt
2021-10-03 14:04:09,507 - INFO - joeynmt.helpers - delete /home/lcur0006/joeynmt/models/LSTM_th/200.ckpt
2021-10-03 14:04:09,507 - WARNING - joeynmt.helpers - Wanted to delete old checkpoint /home/lcur0006/joeynmt/models/LSTM_th/200.ckpt but file does not exist. ([Errno 2] No such file or directory: '/home/lcur0006/joeynmt/models/LSTM_th/200.ckpt')
2021-10-03 14:04:09,509 - INFO - joeynmt.training - Example #0
2021-10-03 14:04:09,510 - INFO - joeynmt.training - 	Source:     th
2021-10-03 14:04:09,510 - INFO - joeynmt.training - 	Reference:  en
2021-10-03 14:04:09,510 - INFO - joeynmt.training - 	Hypothesis: Thank you .
2021-10-03 14:04:09,510 - INFO - joeynmt.training - Example #1
--- Logging error ---
Traceback (most recent call last):
  File "/sw/arch/Debian10/EB_production/2019/software/Anaconda3/2018.12/lib/python3.7/logging/__init__.py", line 1036, in emit
    stream.write(msg)
UnicodeEncodeError: 'latin-1' codec can't encode characters in position 72-74: ordinal not in range(256)
Call stack:
  File "/sw/arch/Debian10/EB_production/2019/software/Anaconda3/2018.12/lib/python3.7/runpy.py", line 193, in _run_module_as_main
    "__main__", mod_spec)
  File "/sw/arch/Debian10/EB_production/2019/software/Anaconda3/2018.12/lib/python3.7/runpy.py", line 85, in _run_code
    exec(code, run_globals)
  File "/home/lcur0006/joeynmt/joeynmt/__main__.py", line 48, in <module>
    main()
  File "/home/lcur0006/joeynmt/joeynmt/__main__.py", line 35, in main
    train(cfg_file=args.config_path, skip_test=args.skip_test)
  File "/home/lcur0006/joeynmt/joeynmt/training.py", line 846, in train
    trainer.train_and_validate(train_data=train_data, valid_data=dev_data)
  File "/home/lcur0006/joeynmt/joeynmt/training.py", line 497, in train_and_validate
    valid_duration = self._validate(valid_data, epoch_no)
  File "/home/lcur0006/joeynmt/joeynmt/training.py", line 642, in _validate
    references=valid_references)
  File "/home/lcur0006/joeynmt/joeynmt/training.py", line 731, in _log_examples
    logger.debug("\tRaw source:     %s", sources_raw[p])
Message: '\tRaw source:     %s'
Arguments: (['\u0e15\u0e2d\u0e19@@', '\u0e09\u0e31\u0e19@@', '\u0e2d\u0e32\u0e22\u0e38', '1@@', '1', '\u0e09\u0e31\u0e19@@', '\u0e08\u0e33@@', '\u0e44\u0e14', '\u0e49', '\u0e27', '\u0e48', '\u0e32\u0e15@@', '\u0e37', '\u0e48', '\u0e19@@', '\u0e02\u0e36', '\u0e49', '\u0e19\u0e21\u0e32@@', '\u0e40\u0e0a', '\u0e49', '\u0e32\u0e27@@', '\u0e31\u0e19@@', '\u0e2b\u0e19\u0e36', '\u0e48', '\u0e07', '\u0e41\u0e25\u0e30@@', '\u0e44\u0e14', '\u0e49', '\u0e22\u0e34\u0e19@@', '\u0e40\u0e2a\u0e35\u0e22\u0e07@@', '\u0e23', '\u0e49', '\u0e2d\u0e07@@', '\u0e14', '\u0e49', '\u0e27\u0e22\u0e04\u0e27\u0e32\u0e21@@', '\u0e22\u0e34\u0e19@@', '\u0e14\u0e35@@', '\u0e43\u0e19@@', '\u0e1a', '\u0e49', '\u0e32\u0e19'],)
--- Logging error ---
Traceback (most recent call last):
  File "/sw/arch/Debian10/EB_production/2019/software/Anaconda3/2018.12/lib/python3.7/logging/__init__.py", line 1036, in emit
    stream.write(msg)
UnicodeEncodeError: 'latin-1' codec can't encode characters in position 65-74: ordinal not in range(256)
Call stack:
  File "/sw/arch/Debian10/EB_production/2019/software/Anaconda3/2018.12/lib/python3.7/runpy.py", line 193, in _run_module_as_main
    "__main__", mod_spec)
  File "/sw/arch/Debian10/EB_production/2019/software/Anaconda3/2018.12/lib/python3.7/runpy.py", line 85, in _run_code
    exec(code, run_globals)
  File "/home/lcur0006/joeynmt/joeynmt/__main__.py", line 48, in <module>
    main()
  File "/home/lcur0006/joeynmt/joeynmt/__main__.py", line 35, in main
    train(cfg_file=args.config_path, skip_test=args.skip_test)
  File "/home/lcur0006/joeynmt/joeynmt/training.py", line 846, in train
    trainer.train_and_validate(train_data=train_data, valid_data=dev_data)
  File "/home/lcur0006/joeynmt/joeynmt/training.py", line 497, in train_and_validate
    valid_duration = self._validate(valid_data, epoch_no)
  File "/home/lcur0006/joeynmt/joeynmt/training.py", line 642, in _validate
    references=valid_references)
  File "/home/lcur0006/joeynmt/joeynmt/training.py", line 737, in _log_examples
    logger.info("\tSource:     %s", sources[p])
Message: '\tSource:     %s'
Arguments: ('\u0e15\u0e2d\u0e19\u0e09\u0e31\u0e19\u0e2d\u0e32\u0e22\u0e38 11 \u0e09\u0e31\u0e19\u0e08\u0e33\u0e44\u0e14 \u0e49 \u0e27 \u0e48 \u0e32\u0e15\u0e37 \u0e48 \u0e19\u0e02\u0e36 \u0e49 \u0e19\u0e21\u0e32\u0e40\u0e0a \u0e49 \u0e32\u0e27\u0e31\u0e19\u0e2b\u0e19\u0e36 \u0e48 \u0e07 \u0e41\u0e25\u0e30\u0e44\u0e14 \u0e49 \u0e22\u0e34\u0e19\u0e40\u0e2a\u0e35\u0e22\u0e07\u0e23 \u0e49 \u0e2d\u0e07\u0e14 \u0e49 \u0e27\u0e22\u0e04\u0e27\u0e32\u0e21\u0e22\u0e34\u0e19\u0e14\u0e35\u0e43\u0e19\u0e1a \u0e49 \u0e32\u0e19',)
2021-10-03 14:04:09,510 - INFO - joeynmt.training - 	Source:     \u0e15\u0e2d\u0e19\u0e09\u0e31\u0e19\u0e2d\u0e32\u0e22\u0e38 11 \u0e09\u0e31\u0e19\u0e08\u0e33\u0e44\u0e14 \u0e49 \u0e27 \u0e48 \u0e32\u0e15\u0e37 \u0e48 \u0e19\u0e02\u0e36 \u0e49 \u0e19\u0e21\u0e32\u0e40\u0e0a \u0e49 \u0e32\u0e27\u0e31\u0e19\u0e2b\u0e19\u0e36 \u0e48 \u0e07 \u0e41\u0e25\u0e30\u0e44\u0e14 \u0e49 \u0e22\u0e34\u0e19\u0e40\u0e2a\u0e35\u0e22\u0e07\u0e23 \u0e49 \u0e2d\u0e07\u0e14 \u0e49 \u0e27\u0e22\u0e04\u0e27\u0e32\u0e21\u0e22\u0e34\u0e19\u0e14\u0e35\u0e43\u0e19\u0e1a \u0e49 \u0e32\u0e19
2021-10-03 14:04:09,511 - INFO - joeynmt.training - 	Reference:  "When I was 11 , I remember waking up one morning to the sound of joy in my house ."
2021-10-03 14:04:09,511 - INFO - joeynmt.training - 	Hypothesis: "I I &apos;m going to be a little sst-sg-ssssssssssssor .
2021-10-03 14:04:09,511 - INFO - joeynmt.training - Example #2
--- Logging error ---
Traceback (most recent call last):
  File "/sw/arch/Debian10/EB_production/2019/software/Anaconda3/2018.12/lib/python3.7/logging/__init__.py", line 1036, in emit
    stream.write(msg)
UnicodeEncodeError: 'latin-1' codec can't encode character '\u0e1e' in position 72: ordinal not in range(256)
Call stack:
  File "/sw/arch/Debian10/EB_production/2019/software/Anaconda3/2018.12/lib/python3.7/runpy.py", line 193, in _run_module_as_main
    "__main__", mod_spec)
  File "/sw/arch/Debian10/EB_production/2019/software/Anaconda3/2018.12/lib/python3.7/runpy.py", line 85, in _run_code
    exec(code, run_globals)
  File "/home/lcur0006/joeynmt/joeynmt/__main__.py", line 48, in <module>
    main()
  File "/home/lcur0006/joeynmt/joeynmt/__main__.py", line 35, in main
    train(cfg_file=args.config_path, skip_test=args.skip_test)
  File "/home/lcur0006/joeynmt/joeynmt/training.py", line 846, in train
    trainer.train_and_validate(train_data=train_data, valid_data=dev_data)
  File "/home/lcur0006/joeynmt/joeynmt/training.py", line 497, in train_and_validate
    valid_duration = self._validate(valid_data, epoch_no)
  File "/home/lcur0006/joeynmt/joeynmt/training.py", line 642, in _validate
    references=valid_references)
  File "/home/lcur0006/joeynmt/joeynmt/training.py", line 731, in _log_examples
    logger.debug("\tRaw source:     %s", sources_raw[p])
Message: '\tRaw source:     %s'
Arguments: (['\u0e1e', '\u0e48', '\u0e2d\u0e02\u0e2d\u0e07@@', '\u0e09\u0e31\u0e19@@', '\u0e01\u0e33\u0e25\u0e31\u0e07@@', '\u0e1f\u0e31\u0e07@@', '\u0e02', '\u0e48', '\u0e32\u0e27@@', '\u0e1a\u0e35@@', '\u0e1a\u0e35@@', '\u0e0b\u0e35', '\u0e08\u0e32\u0e01@@', '\u0e27\u0e34\u0e17@@', '\u0e22\u0e38@@', '\u0e2a\u0e35@@', '\u0e40\u0e17@@', '\u0e32@@', '\u0e2d\u0e31\u0e19@@', '\u0e40\u0e25', '\u0e47', '\u0e01'],)
--- Logging error ---
Traceback (most recent call last):
  File "/sw/arch/Debian10/EB_production/2019/software/Anaconda3/2018.12/lib/python3.7/logging/__init__.py", line 1036, in emit
    stream.write(msg)
UnicodeEncodeError: 'latin-1' codec can't encode character '\u0e1e' in position 65: ordinal not in range(256)
Call stack:
  File "/sw/arch/Debian10/EB_production/2019/software/Anaconda3/2018.12/lib/python3.7/runpy.py", line 193, in _run_module_as_main
    "__main__", mod_spec)
  File "/sw/arch/Debian10/EB_production/2019/software/Anaconda3/2018.12/lib/python3.7/runpy.py", line 85, in _run_code
    exec(code, run_globals)
  File "/home/lcur0006/joeynmt/joeynmt/__main__.py", line 48, in <module>
    main()
  File "/home/lcur0006/joeynmt/joeynmt/__main__.py", line 35, in main
    train(cfg_file=args.config_path, skip_test=args.skip_test)
  File "/home/lcur0006/joeynmt/joeynmt/training.py", line 846, in train
    trainer.train_and_validate(train_data=train_data, valid_data=dev_data)
  File "/home/lcur0006/joeynmt/joeynmt/training.py", line 497, in train_and_validate
    valid_duration = self._validate(valid_data, epoch_no)
  File "/home/lcur0006/joeynmt/joeynmt/training.py", line 642, in _validate
    references=valid_references)
  File "/home/lcur0006/joeynmt/joeynmt/training.py", line 737, in _log_examples
    logger.info("\tSource:     %s", sources[p])
Message: '\tSource:     %s'
Arguments: ('\u0e1e \u0e48 \u0e2d\u0e02\u0e2d\u0e07\u0e09\u0e31\u0e19\u0e01\u0e33\u0e25\u0e31\u0e07\u0e1f\u0e31\u0e07\u0e02 \u0e48 \u0e32\u0e27\u0e1a\u0e35\u0e1a\u0e35\u0e0b\u0e35 \u0e08\u0e32\u0e01\u0e27\u0e34\u0e17\u0e22\u0e38\u0e2a\u0e35\u0e40\u0e17\u0e32\u0e2d\u0e31\u0e19\u0e40\u0e25 \u0e47 \u0e01',)
2021-10-03 14:04:09,511 - INFO - joeynmt.training - 	Source:     \u0e1e \u0e48 \u0e2d\u0e02\u0e2d\u0e07\u0e09\u0e31\u0e19\u0e01\u0e33\u0e25\u0e31\u0e07\u0e1f\u0e31\u0e07\u0e02 \u0e48 \u0e32\u0e27\u0e1a\u0e35\u0e1a\u0e35\u0e0b\u0e35 \u0e08\u0e32\u0e01\u0e27\u0e34\u0e17\u0e22\u0e38\u0e2a\u0e35\u0e40\u0e17\u0e32\u0e2d\u0e31\u0e19\u0e40\u0e25 \u0e47 \u0e01
2021-10-03 14:04:09,512 - INFO - joeynmt.training - 	Reference:  "My father was listening to BBC News on his small , gray radio ."
2021-10-03 14:04:09,512 - INFO - joeynmt.training - 	Hypothesis: I &apos;m going to be a way of the world .
2021-10-03 14:04:09,512 - INFO - joeynmt.training - Validation result (greedy) at epoch   9, step      500: bleu:   2.13, loss: 80518.2344, ppl: 186.2517, duration: 4.9819s
2021-10-03 14:04:16,978 - INFO - joeynmt.training - Epoch   9: total training loss 5697.12
2021-10-03 14:04:16,978 - INFO - joeynmt.training - EPOCH 10
2021-10-03 14:04:28,376 - INFO - joeynmt.training - Epoch  10: total training loss 5567.62
2021-10-03 14:04:28,376 - INFO - joeynmt.training - EPOCH 11
2021-10-03 14:04:34,283 - WARNING - sacrebleu - That's 100 lines that end in a tokenized period ('.')
2021-10-03 14:04:34,283 - WARNING - sacrebleu - It looks like you forgot to detokenize your test data, which may hurt your score.
2021-10-03 14:04:34,283 - WARNING - sacrebleu - If you insist your data is detokenized, or don't care, you can suppress this message with the `force` parameter.
2021-10-03 14:04:34,288 - INFO - joeynmt.training - Hooray! New best validation result [eval_metric]!
2021-10-03 14:04:35,175 - INFO - joeynmt.helpers - delete models/LSTM_th/500.ckpt
2021-10-03 14:04:35,242 - INFO - joeynmt.helpers - delete /home/lcur0006/joeynmt/models/LSTM_th/500.ckpt
2021-10-03 14:04:35,243 - WARNING - joeynmt.helpers - Wanted to delete old checkpoint /home/lcur0006/joeynmt/models/LSTM_th/500.ckpt but file does not exist. ([Errno 2] No such file or directory: '/home/lcur0006/joeynmt/models/LSTM_th/500.ckpt')
2021-10-03 14:04:35,245 - INFO - joeynmt.training - Example #0
2021-10-03 14:04:35,245 - INFO - joeynmt.training - 	Source:     th
2021-10-03 14:04:35,245 - INFO - joeynmt.training - 	Reference:  en
2021-10-03 14:04:35,245 - INFO - joeynmt.training - 	Hypothesis: Thank you .
2021-10-03 14:04:35,245 - INFO - joeynmt.training - Example #1
--- Logging error ---
Traceback (most recent call last):
  File "/sw/arch/Debian10/EB_production/2019/software/Anaconda3/2018.12/lib/python3.7/logging/__init__.py", line 1036, in emit
    stream.write(msg)
UnicodeEncodeError: 'latin-1' codec can't encode characters in position 72-74: ordinal not in range(256)
Call stack:
  File "/sw/arch/Debian10/EB_production/2019/software/Anaconda3/2018.12/lib/python3.7/runpy.py", line 193, in _run_module_as_main
    "__main__", mod_spec)
  File "/sw/arch/Debian10/EB_production/2019/software/Anaconda3/2018.12/lib/python3.7/runpy.py", line 85, in _run_code
    exec(code, run_globals)
  File "/home/lcur0006/joeynmt/joeynmt/__main__.py", line 48, in <module>
    main()
  File "/home/lcur0006/joeynmt/joeynmt/__main__.py", line 35, in main
    train(cfg_file=args.config_path, skip_test=args.skip_test)
  File "/home/lcur0006/joeynmt/joeynmt/training.py", line 846, in train
    trainer.train_and_validate(train_data=train_data, valid_data=dev_data)
  File "/home/lcur0006/joeynmt/joeynmt/training.py", line 497, in train_and_validate
    valid_duration = self._validate(valid_data, epoch_no)
  File "/home/lcur0006/joeynmt/joeynmt/training.py", line 642, in _validate
    references=valid_references)
  File "/home/lcur0006/joeynmt/joeynmt/training.py", line 731, in _log_examples
    logger.debug("\tRaw source:     %s", sources_raw[p])
Message: '\tRaw source:     %s'
Arguments: (['\u0e15\u0e2d\u0e19@@', '\u0e09\u0e31\u0e19@@', '\u0e2d\u0e32\u0e22\u0e38', '1@@', '1', '\u0e09\u0e31\u0e19@@', '\u0e08\u0e33@@', '\u0e44\u0e14', '\u0e49', '\u0e27', '\u0e48', '\u0e32\u0e15@@', '\u0e37', '\u0e48', '\u0e19@@', '\u0e02\u0e36', '\u0e49', '\u0e19\u0e21\u0e32@@', '\u0e40\u0e0a', '\u0e49', '\u0e32\u0e27@@', '\u0e31\u0e19@@', '\u0e2b\u0e19\u0e36', '\u0e48', '\u0e07', '\u0e41\u0e25\u0e30@@', '\u0e44\u0e14', '\u0e49', '\u0e22\u0e34\u0e19@@', '\u0e40\u0e2a\u0e35\u0e22\u0e07@@', '\u0e23', '\u0e49', '\u0e2d\u0e07@@', '\u0e14', '\u0e49', '\u0e27\u0e22\u0e04\u0e27\u0e32\u0e21@@', '\u0e22\u0e34\u0e19@@', '\u0e14\u0e35@@', '\u0e43\u0e19@@', '\u0e1a', '\u0e49', '\u0e32\u0e19'],)
--- Logging error ---
Traceback (most recent call last):
  File "/sw/arch/Debian10/EB_production/2019/software/Anaconda3/2018.12/lib/python3.7/logging/__init__.py", line 1036, in emit
    stream.write(msg)
UnicodeEncodeError: 'latin-1' codec can't encode characters in position 65-74: ordinal not in range(256)
Call stack:
  File "/sw/arch/Debian10/EB_production/2019/software/Anaconda3/2018.12/lib/python3.7/runpy.py", line 193, in _run_module_as_main
    "__main__", mod_spec)
  File "/sw/arch/Debian10/EB_production/2019/software/Anaconda3/2018.12/lib/python3.7/runpy.py", line 85, in _run_code
    exec(code, run_globals)
  File "/home/lcur0006/joeynmt/joeynmt/__main__.py", line 48, in <module>
    main()
  File "/home/lcur0006/joeynmt/joeynmt/__main__.py", line 35, in main
    train(cfg_file=args.config_path, skip_test=args.skip_test)
  File "/home/lcur0006/joeynmt/joeynmt/training.py", line 846, in train
    trainer.train_and_validate(train_data=train_data, valid_data=dev_data)
  File "/home/lcur0006/joeynmt/joeynmt/training.py", line 497, in train_and_validate
    valid_duration = self._validate(valid_data, epoch_no)
  File "/home/lcur0006/joeynmt/joeynmt/training.py", line 642, in _validate
    references=valid_references)
  File "/home/lcur0006/joeynmt/joeynmt/training.py", line 737, in _log_examples
    logger.info("\tSource:     %s", sources[p])
Message: '\tSource:     %s'
Arguments: ('\u0e15\u0e2d\u0e19\u0e09\u0e31\u0e19\u0e2d\u0e32\u0e22\u0e38 11 \u0e09\u0e31\u0e19\u0e08\u0e33\u0e44\u0e14 \u0e49 \u0e27 \u0e48 \u0e32\u0e15\u0e37 \u0e48 \u0e19\u0e02\u0e36 \u0e49 \u0e19\u0e21\u0e32\u0e40\u0e0a \u0e49 \u0e32\u0e27\u0e31\u0e19\u0e2b\u0e19\u0e36 \u0e48 \u0e07 \u0e41\u0e25\u0e30\u0e44\u0e14 \u0e49 \u0e22\u0e34\u0e19\u0e40\u0e2a\u0e35\u0e22\u0e07\u0e23 \u0e49 \u0e2d\u0e07\u0e14 \u0e49 \u0e27\u0e22\u0e04\u0e27\u0e32\u0e21\u0e22\u0e34\u0e19\u0e14\u0e35\u0e43\u0e19\u0e1a \u0e49 \u0e32\u0e19',)
2021-10-03 14:04:35,246 - INFO - joeynmt.training - 	Source:     \u0e15\u0e2d\u0e19\u0e09\u0e31\u0e19\u0e2d\u0e32\u0e22\u0e38 11 \u0e09\u0e31\u0e19\u0e08\u0e33\u0e44\u0e14 \u0e49 \u0e27 \u0e48 \u0e32\u0e15\u0e37 \u0e48 \u0e19\u0e02\u0e36 \u0e49 \u0e19\u0e21\u0e32\u0e40\u0e0a \u0e49 \u0e32\u0e27\u0e31\u0e19\u0e2b\u0e19\u0e36 \u0e48 \u0e07 \u0e41\u0e25\u0e30\u0e44\u0e14 \u0e49 \u0e22\u0e34\u0e19\u0e40\u0e2a\u0e35\u0e22\u0e07\u0e23 \u0e49 \u0e2d\u0e07\u0e14 \u0e49 \u0e27\u0e22\u0e04\u0e27\u0e32\u0e21\u0e22\u0e34\u0e19\u0e14\u0e35\u0e43\u0e19\u0e1a \u0e49 \u0e32\u0e19
2021-10-03 14:04:35,246 - INFO - joeynmt.training - 	Reference:  "When I was 11 , I remember waking up one morning to the sound of joy in my house ."
2021-10-03 14:04:35,246 - INFO - joeynmt.training - 	Hypothesis: "I I have a a way , I have a a world , I have a a world , I can have a lot of the world ."
2021-10-03 14:04:35,246 - INFO - joeynmt.training - Example #2
--- Logging error ---
Traceback (most recent call last):
  File "/sw/arch/Debian10/EB_production/2019/software/Anaconda3/2018.12/lib/python3.7/logging/__init__.py", line 1036, in emit
    stream.write(msg)
UnicodeEncodeError: 'latin-1' codec can't encode character '\u0e1e' in position 72: ordinal not in range(256)
Call stack:
  File "/sw/arch/Debian10/EB_production/2019/software/Anaconda3/2018.12/lib/python3.7/runpy.py", line 193, in _run_module_as_main
    "__main__", mod_spec)
  File "/sw/arch/Debian10/EB_production/2019/software/Anaconda3/2018.12/lib/python3.7/runpy.py", line 85, in _run_code
    exec(code, run_globals)
  File "/home/lcur0006/joeynmt/joeynmt/__main__.py", line 48, in <module>
    main()
  File "/home/lcur0006/joeynmt/joeynmt/__main__.py", line 35, in main
    train(cfg_file=args.config_path, skip_test=args.skip_test)
  File "/home/lcur0006/joeynmt/joeynmt/training.py", line 846, in train
    trainer.train_and_validate(train_data=train_data, valid_data=dev_data)
  File "/home/lcur0006/joeynmt/joeynmt/training.py", line 497, in train_and_validate
    valid_duration = self._validate(valid_data, epoch_no)
  File "/home/lcur0006/joeynmt/joeynmt/training.py", line 642, in _validate
    references=valid_references)
  File "/home/lcur0006/joeynmt/joeynmt/training.py", line 731, in _log_examples
    logger.debug("\tRaw source:     %s", sources_raw[p])
Message: '\tRaw source:     %s'
Arguments: (['\u0e1e', '\u0e48', '\u0e2d\u0e02\u0e2d\u0e07@@', '\u0e09\u0e31\u0e19@@', '\u0e01\u0e33\u0e25\u0e31\u0e07@@', '\u0e1f\u0e31\u0e07@@', '\u0e02', '\u0e48', '\u0e32\u0e27@@', '\u0e1a\u0e35@@', '\u0e1a\u0e35@@', '\u0e0b\u0e35', '\u0e08\u0e32\u0e01@@', '\u0e27\u0e34\u0e17@@', '\u0e22\u0e38@@', '\u0e2a\u0e35@@', '\u0e40\u0e17@@', '\u0e32@@', '\u0e2d\u0e31\u0e19@@', '\u0e40\u0e25', '\u0e47', '\u0e01'],)
--- Logging error ---
Traceback (most recent call last):
  File "/sw/arch/Debian10/EB_production/2019/software/Anaconda3/2018.12/lib/python3.7/logging/__init__.py", line 1036, in emit
    stream.write(msg)
UnicodeEncodeError: 'latin-1' codec can't encode character '\u0e1e' in position 65: ordinal not in range(256)
Call stack:
  File "/sw/arch/Debian10/EB_production/2019/software/Anaconda3/2018.12/lib/python3.7/runpy.py", line 193, in _run_module_as_main
    "__main__", mod_spec)
  File "/sw/arch/Debian10/EB_production/2019/software/Anaconda3/2018.12/lib/python3.7/runpy.py", line 85, in _run_code
    exec(code, run_globals)
  File "/home/lcur0006/joeynmt/joeynmt/__main__.py", line 48, in <module>
    main()
  File "/home/lcur0006/joeynmt/joeynmt/__main__.py", line 35, in main
    train(cfg_file=args.config_path, skip_test=args.skip_test)
  File "/home/lcur0006/joeynmt/joeynmt/training.py", line 846, in train
    trainer.train_and_validate(train_data=train_data, valid_data=dev_data)
  File "/home/lcur0006/joeynmt/joeynmt/training.py", line 497, in train_and_validate
    valid_duration = self._validate(valid_data, epoch_no)
  File "/home/lcur0006/joeynmt/joeynmt/training.py", line 642, in _validate
    references=valid_references)
  File "/home/lcur0006/joeynmt/joeynmt/training.py", line 737, in _log_examples
    logger.info("\tSource:     %s", sources[p])
Message: '\tSource:     %s'
Arguments: ('\u0e1e \u0e48 \u0e2d\u0e02\u0e2d\u0e07\u0e09\u0e31\u0e19\u0e01\u0e33\u0e25\u0e31\u0e07\u0e1f\u0e31\u0e07\u0e02 \u0e48 \u0e32\u0e27\u0e1a\u0e35\u0e1a\u0e35\u0e0b\u0e35 \u0e08\u0e32\u0e01\u0e27\u0e34\u0e17\u0e22\u0e38\u0e2a\u0e35\u0e40\u0e17\u0e32\u0e2d\u0e31\u0e19\u0e40\u0e25 \u0e47 \u0e01',)
2021-10-03 14:04:35,247 - INFO - joeynmt.training - 	Source:     \u0e1e \u0e48 \u0e2d\u0e02\u0e2d\u0e07\u0e09\u0e31\u0e19\u0e01\u0e33\u0e25\u0e31\u0e07\u0e1f\u0e31\u0e07\u0e02 \u0e48 \u0e32\u0e27\u0e1a\u0e35\u0e1a\u0e35\u0e0b\u0e35 \u0e08\u0e32\u0e01\u0e27\u0e34\u0e17\u0e22\u0e38\u0e2a\u0e35\u0e40\u0e17\u0e32\u0e2d\u0e31\u0e19\u0e40\u0e25 \u0e47 \u0e01
2021-10-03 14:04:35,247 - INFO - joeynmt.training - 	Reference:  "My father was listening to BBC News on his small , gray radio ."
2021-10-03 14:04:35,247 - INFO - joeynmt.training - 	Hypothesis: I have a way that I have a lot of the world .
2021-10-03 14:04:35,247 - INFO - joeynmt.training - Validation result (greedy) at epoch  11, step      600: bleu:   3.64, loss: 78697.5547, ppl: 165.4889, duration: 4.8947s
2021-10-03 14:04:46,141 - INFO - joeynmt.training - Epoch  11: total training loss 5447.91
2021-10-03 14:04:46,141 - INFO - joeynmt.training - EPOCH 12
2021-10-03 14:05:00,093 - WARNING - sacrebleu - That's 100 lines that end in a tokenized period ('.')
2021-10-03 14:05:00,093 - WARNING - sacrebleu - It looks like you forgot to detokenize your test data, which may hurt your score.
2021-10-03 14:05:00,093 - WARNING - sacrebleu - If you insist your data is detokenized, or don't care, you can suppress this message with the `force` parameter.
2021-10-03 14:05:00,098 - INFO - joeynmt.training - Hooray! New best validation result [eval_metric]!
2021-10-03 14:05:01,074 - INFO - joeynmt.helpers - delete models/LSTM_th/600.ckpt
2021-10-03 14:05:01,144 - INFO - joeynmt.helpers - delete /home/lcur0006/joeynmt/models/LSTM_th/600.ckpt
2021-10-03 14:05:01,145 - WARNING - joeynmt.helpers - Wanted to delete old checkpoint /home/lcur0006/joeynmt/models/LSTM_th/600.ckpt but file does not exist. ([Errno 2] No such file or directory: '/home/lcur0006/joeynmt/models/LSTM_th/600.ckpt')
2021-10-03 14:05:01,147 - INFO - joeynmt.training - Example #0
2021-10-03 14:05:01,147 - INFO - joeynmt.training - 	Source:     th
2021-10-03 14:05:01,147 - INFO - joeynmt.training - 	Reference:  en
2021-10-03 14:05:01,147 - INFO - joeynmt.training - 	Hypothesis: Thank you .
2021-10-03 14:05:01,147 - INFO - joeynmt.training - Example #1
--- Logging error ---
Traceback (most recent call last):
  File "/sw/arch/Debian10/EB_production/2019/software/Anaconda3/2018.12/lib/python3.7/logging/__init__.py", line 1036, in emit
    stream.write(msg)
UnicodeEncodeError: 'latin-1' codec can't encode characters in position 72-74: ordinal not in range(256)
Call stack:
  File "/sw/arch/Debian10/EB_production/2019/software/Anaconda3/2018.12/lib/python3.7/runpy.py", line 193, in _run_module_as_main
    "__main__", mod_spec)
  File "/sw/arch/Debian10/EB_production/2019/software/Anaconda3/2018.12/lib/python3.7/runpy.py", line 85, in _run_code
    exec(code, run_globals)
  File "/home/lcur0006/joeynmt/joeynmt/__main__.py", line 48, in <module>
    main()
  File "/home/lcur0006/joeynmt/joeynmt/__main__.py", line 35, in main
    train(cfg_file=args.config_path, skip_test=args.skip_test)
  File "/home/lcur0006/joeynmt/joeynmt/training.py", line 846, in train
    trainer.train_and_validate(train_data=train_data, valid_data=dev_data)
  File "/home/lcur0006/joeynmt/joeynmt/training.py", line 497, in train_and_validate
    valid_duration = self._validate(valid_data, epoch_no)
  File "/home/lcur0006/joeynmt/joeynmt/training.py", line 642, in _validate
    references=valid_references)
  File "/home/lcur0006/joeynmt/joeynmt/training.py", line 731, in _log_examples
    logger.debug("\tRaw source:     %s", sources_raw[p])
Message: '\tRaw source:     %s'
Arguments: (['\u0e15\u0e2d\u0e19@@', '\u0e09\u0e31\u0e19@@', '\u0e2d\u0e32\u0e22\u0e38', '1@@', '1', '\u0e09\u0e31\u0e19@@', '\u0e08\u0e33@@', '\u0e44\u0e14', '\u0e49', '\u0e27', '\u0e48', '\u0e32\u0e15@@', '\u0e37', '\u0e48', '\u0e19@@', '\u0e02\u0e36', '\u0e49', '\u0e19\u0e21\u0e32@@', '\u0e40\u0e0a', '\u0e49', '\u0e32\u0e27@@', '\u0e31\u0e19@@', '\u0e2b\u0e19\u0e36', '\u0e48', '\u0e07', '\u0e41\u0e25\u0e30@@', '\u0e44\u0e14', '\u0e49', '\u0e22\u0e34\u0e19@@', '\u0e40\u0e2a\u0e35\u0e22\u0e07@@', '\u0e23', '\u0e49', '\u0e2d\u0e07@@', '\u0e14', '\u0e49', '\u0e27\u0e22\u0e04\u0e27\u0e32\u0e21@@', '\u0e22\u0e34\u0e19@@', '\u0e14\u0e35@@', '\u0e43\u0e19@@', '\u0e1a', '\u0e49', '\u0e32\u0e19'],)
--- Logging error ---
Traceback (most recent call last):
  File "/sw/arch/Debian10/EB_production/2019/software/Anaconda3/2018.12/lib/python3.7/logging/__init__.py", line 1036, in emit
    stream.write(msg)
UnicodeEncodeError: 'latin-1' codec can't encode characters in position 65-74: ordinal not in range(256)
Call stack:
  File "/sw/arch/Debian10/EB_production/2019/software/Anaconda3/2018.12/lib/python3.7/runpy.py", line 193, in _run_module_as_main
    "__main__", mod_spec)
  File "/sw/arch/Debian10/EB_production/2019/software/Anaconda3/2018.12/lib/python3.7/runpy.py", line 85, in _run_code
    exec(code, run_globals)
  File "/home/lcur0006/joeynmt/joeynmt/__main__.py", line 48, in <module>
    main()
  File "/home/lcur0006/joeynmt/joeynmt/__main__.py", line 35, in main
    train(cfg_file=args.config_path, skip_test=args.skip_test)
  File "/home/lcur0006/joeynmt/joeynmt/training.py", line 846, in train
    trainer.train_and_validate(train_data=train_data, valid_data=dev_data)
  File "/home/lcur0006/joeynmt/joeynmt/training.py", line 497, in train_and_validate
    valid_duration = self._validate(valid_data, epoch_no)
  File "/home/lcur0006/joeynmt/joeynmt/training.py", line 642, in _validate
    references=valid_references)
  File "/home/lcur0006/joeynmt/joeynmt/training.py", line 737, in _log_examples
    logger.info("\tSource:     %s", sources[p])
Message: '\tSource:     %s'
Arguments: ('\u0e15\u0e2d\u0e19\u0e09\u0e31\u0e19\u0e2d\u0e32\u0e22\u0e38 11 \u0e09\u0e31\u0e19\u0e08\u0e33\u0e44\u0e14 \u0e49 \u0e27 \u0e48 \u0e32\u0e15\u0e37 \u0e48 \u0e19\u0e02\u0e36 \u0e49 \u0e19\u0e21\u0e32\u0e40\u0e0a \u0e49 \u0e32\u0e27\u0e31\u0e19\u0e2b\u0e19\u0e36 \u0e48 \u0e07 \u0e41\u0e25\u0e30\u0e44\u0e14 \u0e49 \u0e22\u0e34\u0e19\u0e40\u0e2a\u0e35\u0e22\u0e07\u0e23 \u0e49 \u0e2d\u0e07\u0e14 \u0e49 \u0e27\u0e22\u0e04\u0e27\u0e32\u0e21\u0e22\u0e34\u0e19\u0e14\u0e35\u0e43\u0e19\u0e1a \u0e49 \u0e32\u0e19',)
2021-10-03 14:05:01,150 - INFO - joeynmt.training - 	Source:     \u0e15\u0e2d\u0e19\u0e09\u0e31\u0e19\u0e2d\u0e32\u0e22\u0e38 11 \u0e09\u0e31\u0e19\u0e08\u0e33\u0e44\u0e14 \u0e49 \u0e27 \u0e48 \u0e32\u0e15\u0e37 \u0e48 \u0e19\u0e02\u0e36 \u0e49 \u0e19\u0e21\u0e32\u0e40\u0e0a \u0e49 \u0e32\u0e27\u0e31\u0e19\u0e2b\u0e19\u0e36 \u0e48 \u0e07 \u0e41\u0e25\u0e30\u0e44\u0e14 \u0e49 \u0e22\u0e34\u0e19\u0e40\u0e2a\u0e35\u0e22\u0e07\u0e23 \u0e49 \u0e2d\u0e07\u0e14 \u0e49 \u0e27\u0e22\u0e04\u0e27\u0e32\u0e21\u0e22\u0e34\u0e19\u0e14\u0e35\u0e43\u0e19\u0e1a \u0e49 \u0e32\u0e19
2021-10-03 14:05:01,150 - INFO - joeynmt.training - 	Reference:  "When I was 11 , I remember waking up one morning to the sound of joy in my house ."
2021-10-03 14:05:01,151 - INFO - joeynmt.training - 	Hypothesis: "I &apos;ll be a little way , I was a little way , and I was a lot of the universe ."
2021-10-03 14:05:01,151 - INFO - joeynmt.training - Example #2
--- Logging error ---
Traceback (most recent call last):
  File "/sw/arch/Debian10/EB_production/2019/software/Anaconda3/2018.12/lib/python3.7/logging/__init__.py", line 1036, in emit
    stream.write(msg)
UnicodeEncodeError: 'latin-1' codec can't encode character '\u0e1e' in position 72: ordinal not in range(256)
Call stack:
  File "/sw/arch/Debian10/EB_production/2019/software/Anaconda3/2018.12/lib/python3.7/runpy.py", line 193, in _run_module_as_main
    "__main__", mod_spec)
  File "/sw/arch/Debian10/EB_production/2019/software/Anaconda3/2018.12/lib/python3.7/runpy.py", line 85, in _run_code
    exec(code, run_globals)
  File "/home/lcur0006/joeynmt/joeynmt/__main__.py", line 48, in <module>
    main()
  File "/home/lcur0006/joeynmt/joeynmt/__main__.py", line 35, in main
    train(cfg_file=args.config_path, skip_test=args.skip_test)
  File "/home/lcur0006/joeynmt/joeynmt/training.py", line 846, in train
    trainer.train_and_validate(train_data=train_data, valid_data=dev_data)
  File "/home/lcur0006/joeynmt/joeynmt/training.py", line 497, in train_and_validate
    valid_duration = self._validate(valid_data, epoch_no)
  File "/home/lcur0006/joeynmt/joeynmt/training.py", line 642, in _validate
    references=valid_references)
  File "/home/lcur0006/joeynmt/joeynmt/training.py", line 731, in _log_examples
    logger.debug("\tRaw source:     %s", sources_raw[p])
Message: '\tRaw source:     %s'
Arguments: (['\u0e1e', '\u0e48', '\u0e2d\u0e02\u0e2d\u0e07@@', '\u0e09\u0e31\u0e19@@', '\u0e01\u0e33\u0e25\u0e31\u0e07@@', '\u0e1f\u0e31\u0e07@@', '\u0e02', '\u0e48', '\u0e32\u0e27@@', '\u0e1a\u0e35@@', '\u0e1a\u0e35@@', '\u0e0b\u0e35', '\u0e08\u0e32\u0e01@@', '\u0e27\u0e34\u0e17@@', '\u0e22\u0e38@@', '\u0e2a\u0e35@@', '\u0e40\u0e17@@', '\u0e32@@', '\u0e2d\u0e31\u0e19@@', '\u0e40\u0e25', '\u0e47', '\u0e01'],)
--- Logging error ---
Traceback (most recent call last):
  File "/sw/arch/Debian10/EB_production/2019/software/Anaconda3/2018.12/lib/python3.7/logging/__init__.py", line 1036, in emit
    stream.write(msg)
UnicodeEncodeError: 'latin-1' codec can't encode character '\u0e1e' in position 65: ordinal not in range(256)
Call stack:
  File "/sw/arch/Debian10/EB_production/2019/software/Anaconda3/2018.12/lib/python3.7/runpy.py", line 193, in _run_module_as_main
    "__main__", mod_spec)
  File "/sw/arch/Debian10/EB_production/2019/software/Anaconda3/2018.12/lib/python3.7/runpy.py", line 85, in _run_code
    exec(code, run_globals)
  File "/home/lcur0006/joeynmt/joeynmt/__main__.py", line 48, in <module>
    main()
  File "/home/lcur0006/joeynmt/joeynmt/__main__.py", line 35, in main
    train(cfg_file=args.config_path, skip_test=args.skip_test)
  File "/home/lcur0006/joeynmt/joeynmt/training.py", line 846, in train
    trainer.train_and_validate(train_data=train_data, valid_data=dev_data)
  File "/home/lcur0006/joeynmt/joeynmt/training.py", line 497, in train_and_validate
    valid_duration = self._validate(valid_data, epoch_no)
  File "/home/lcur0006/joeynmt/joeynmt/training.py", line 642, in _validate
    references=valid_references)
  File "/home/lcur0006/joeynmt/joeynmt/training.py", line 737, in _log_examples
    logger.info("\tSource:     %s", sources[p])
Message: '\tSource:     %s'
Arguments: ('\u0e1e \u0e48 \u0e2d\u0e02\u0e2d\u0e07\u0e09\u0e31\u0e19\u0e01\u0e33\u0e25\u0e31\u0e07\u0e1f\u0e31\u0e07\u0e02 \u0e48 \u0e32\u0e27\u0e1a\u0e35\u0e1a\u0e35\u0e0b\u0e35 \u0e08\u0e32\u0e01\u0e27\u0e34\u0e17\u0e22\u0e38\u0e2a\u0e35\u0e40\u0e17\u0e32\u0e2d\u0e31\u0e19\u0e40\u0e25 \u0e47 \u0e01',)
2021-10-03 14:05:01,151 - INFO - joeynmt.training - 	Source:     \u0e1e \u0e48 \u0e2d\u0e02\u0e2d\u0e07\u0e09\u0e31\u0e19\u0e01\u0e33\u0e25\u0e31\u0e07\u0e1f\u0e31\u0e07\u0e02 \u0e48 \u0e32\u0e27\u0e1a\u0e35\u0e1a\u0e35\u0e0b\u0e35 \u0e08\u0e32\u0e01\u0e27\u0e34\u0e17\u0e22\u0e38\u0e2a\u0e35\u0e40\u0e17\u0e32\u0e2d\u0e31\u0e19\u0e40\u0e25 \u0e47 \u0e01
2021-10-03 14:05:01,151 - INFO - joeynmt.training - 	Reference:  "My father was listening to BBC News on his small , gray radio ."
2021-10-03 14:05:01,151 - INFO - joeynmt.training - 	Hypothesis: I &apos;m going to be a little way of the world .
2021-10-03 14:05:01,152 - INFO - joeynmt.training - Validation result (greedy) at epoch  12, step      700: bleu:   4.31, loss: 77555.8828, ppl: 153.6671, duration: 5.0052s
2021-10-03 14:05:04,040 - INFO - joeynmt.training - Epoch  12: total training loss 5340.82
2021-10-03 14:05:04,040 - INFO - joeynmt.training - EPOCH 13
2021-10-03 14:05:15,557 - INFO - joeynmt.training - Epoch  13: total training loss 5246.53
2021-10-03 14:05:15,557 - INFO - joeynmt.training - EPOCH 14
2021-10-03 14:05:25,981 - WARNING - sacrebleu - That's 100 lines that end in a tokenized period ('.')
2021-10-03 14:05:25,982 - WARNING - sacrebleu - It looks like you forgot to detokenize your test data, which may hurt your score.
2021-10-03 14:05:25,982 - WARNING - sacrebleu - If you insist your data is detokenized, or don't care, you can suppress this message with the `force` parameter.
2021-10-03 14:05:25,988 - INFO - joeynmt.training - Example #0
2021-10-03 14:05:25,989 - INFO - joeynmt.training - 	Source:     th
2021-10-03 14:05:25,989 - INFO - joeynmt.training - 	Reference:  en
2021-10-03 14:05:25,989 - INFO - joeynmt.training - 	Hypothesis: Thank you .
2021-10-03 14:05:25,989 - INFO - joeynmt.training - Example #1
--- Logging error ---
Traceback (most recent call last):
  File "/sw/arch/Debian10/EB_production/2019/software/Anaconda3/2018.12/lib/python3.7/logging/__init__.py", line 1036, in emit
    stream.write(msg)
UnicodeEncodeError: 'latin-1' codec can't encode characters in position 72-74: ordinal not in range(256)
Call stack:
  File "/sw/arch/Debian10/EB_production/2019/software/Anaconda3/2018.12/lib/python3.7/runpy.py", line 193, in _run_module_as_main
    "__main__", mod_spec)
  File "/sw/arch/Debian10/EB_production/2019/software/Anaconda3/2018.12/lib/python3.7/runpy.py", line 85, in _run_code
    exec(code, run_globals)
  File "/home/lcur0006/joeynmt/joeynmt/__main__.py", line 48, in <module>
    main()
  File "/home/lcur0006/joeynmt/joeynmt/__main__.py", line 35, in main
    train(cfg_file=args.config_path, skip_test=args.skip_test)
  File "/home/lcur0006/joeynmt/joeynmt/training.py", line 846, in train
    trainer.train_and_validate(train_data=train_data, valid_data=dev_data)
  File "/home/lcur0006/joeynmt/joeynmt/training.py", line 497, in train_and_validate
    valid_duration = self._validate(valid_data, epoch_no)
  File "/home/lcur0006/joeynmt/joeynmt/training.py", line 642, in _validate
    references=valid_references)
  File "/home/lcur0006/joeynmt/joeynmt/training.py", line 731, in _log_examples
    logger.debug("\tRaw source:     %s", sources_raw[p])
Message: '\tRaw source:     %s'
Arguments: (['\u0e15\u0e2d\u0e19@@', '\u0e09\u0e31\u0e19@@', '\u0e2d\u0e32\u0e22\u0e38', '1@@', '1', '\u0e09\u0e31\u0e19@@', '\u0e08\u0e33@@', '\u0e44\u0e14', '\u0e49', '\u0e27', '\u0e48', '\u0e32\u0e15@@', '\u0e37', '\u0e48', '\u0e19@@', '\u0e02\u0e36', '\u0e49', '\u0e19\u0e21\u0e32@@', '\u0e40\u0e0a', '\u0e49', '\u0e32\u0e27@@', '\u0e31\u0e19@@', '\u0e2b\u0e19\u0e36', '\u0e48', '\u0e07', '\u0e41\u0e25\u0e30@@', '\u0e44\u0e14', '\u0e49', '\u0e22\u0e34\u0e19@@', '\u0e40\u0e2a\u0e35\u0e22\u0e07@@', '\u0e23', '\u0e49', '\u0e2d\u0e07@@', '\u0e14', '\u0e49', '\u0e27\u0e22\u0e04\u0e27\u0e32\u0e21@@', '\u0e22\u0e34\u0e19@@', '\u0e14\u0e35@@', '\u0e43\u0e19@@', '\u0e1a', '\u0e49', '\u0e32\u0e19'],)
--- Logging error ---
Traceback (most recent call last):
  File "/sw/arch/Debian10/EB_production/2019/software/Anaconda3/2018.12/lib/python3.7/logging/__init__.py", line 1036, in emit
    stream.write(msg)
UnicodeEncodeError: 'latin-1' codec can't encode characters in position 65-74: ordinal not in range(256)
Call stack:
  File "/sw/arch/Debian10/EB_production/2019/software/Anaconda3/2018.12/lib/python3.7/runpy.py", line 193, in _run_module_as_main
    "__main__", mod_spec)
  File "/sw/arch/Debian10/EB_production/2019/software/Anaconda3/2018.12/lib/python3.7/runpy.py", line 85, in _run_code
    exec(code, run_globals)
  File "/home/lcur0006/joeynmt/joeynmt/__main__.py", line 48, in <module>
    main()
  File "/home/lcur0006/joeynmt/joeynmt/__main__.py", line 35, in main
    train(cfg_file=args.config_path, skip_test=args.skip_test)
  File "/home/lcur0006/joeynmt/joeynmt/training.py", line 846, in train
    trainer.train_and_validate(train_data=train_data, valid_data=dev_data)
  File "/home/lcur0006/joeynmt/joeynmt/training.py", line 497, in train_and_validate
    valid_duration = self._validate(valid_data, epoch_no)
  File "/home/lcur0006/joeynmt/joeynmt/training.py", line 642, in _validate
    references=valid_references)
  File "/home/lcur0006/joeynmt/joeynmt/training.py", line 737, in _log_examples
    logger.info("\tSource:     %s", sources[p])
Message: '\tSource:     %s'
Arguments: ('\u0e15\u0e2d\u0e19\u0e09\u0e31\u0e19\u0e2d\u0e32\u0e22\u0e38 11 \u0e09\u0e31\u0e19\u0e08\u0e33\u0e44\u0e14 \u0e49 \u0e27 \u0e48 \u0e32\u0e15\u0e37 \u0e48 \u0e19\u0e02\u0e36 \u0e49 \u0e19\u0e21\u0e32\u0e40\u0e0a \u0e49 \u0e32\u0e27\u0e31\u0e19\u0e2b\u0e19\u0e36 \u0e48 \u0e07 \u0e41\u0e25\u0e30\u0e44\u0e14 \u0e49 \u0e22\u0e34\u0e19\u0e40\u0e2a\u0e35\u0e22\u0e07\u0e23 \u0e49 \u0e2d\u0e07\u0e14 \u0e49 \u0e27\u0e22\u0e04\u0e27\u0e32\u0e21\u0e22\u0e34\u0e19\u0e14\u0e35\u0e43\u0e19\u0e1a \u0e49 \u0e32\u0e19',)
2021-10-03 14:05:25,990 - INFO - joeynmt.training - 	Source:     \u0e15\u0e2d\u0e19\u0e09\u0e31\u0e19\u0e2d\u0e32\u0e22\u0e38 11 \u0e09\u0e31\u0e19\u0e08\u0e33\u0e44\u0e14 \u0e49 \u0e27 \u0e48 \u0e32\u0e15\u0e37 \u0e48 \u0e19\u0e02\u0e36 \u0e49 \u0e19\u0e21\u0e32\u0e40\u0e0a \u0e49 \u0e32\u0e27\u0e31\u0e19\u0e2b\u0e19\u0e36 \u0e48 \u0e07 \u0e41\u0e25\u0e30\u0e44\u0e14 \u0e49 \u0e22\u0e34\u0e19\u0e40\u0e2a\u0e35\u0e22\u0e07\u0e23 \u0e49 \u0e2d\u0e07\u0e14 \u0e49 \u0e27\u0e22\u0e04\u0e27\u0e32\u0e21\u0e22\u0e34\u0e19\u0e14\u0e35\u0e43\u0e19\u0e1a \u0e49 \u0e32\u0e19
2021-10-03 14:05:25,990 - INFO - joeynmt.training - 	Reference:  "When I was 11 , I remember waking up one morning to the sound of joy in my house ."
2021-10-03 14:05:25,990 - INFO - joeynmt.training - 	Hypothesis: "I &apos;ll be a very time , I was a couple of the first , and I was a lot of the world ."
2021-10-03 14:05:25,990 - INFO - joeynmt.training - Example #2
--- Logging error ---
Traceback (most recent call last):
  File "/sw/arch/Debian10/EB_production/2019/software/Anaconda3/2018.12/lib/python3.7/logging/__init__.py", line 1036, in emit
    stream.write(msg)
UnicodeEncodeError: 'latin-1' codec can't encode character '\u0e1e' in position 72: ordinal not in range(256)
Call stack:
  File "/sw/arch/Debian10/EB_production/2019/software/Anaconda3/2018.12/lib/python3.7/runpy.py", line 193, in _run_module_as_main
    "__main__", mod_spec)
  File "/sw/arch/Debian10/EB_production/2019/software/Anaconda3/2018.12/lib/python3.7/runpy.py", line 85, in _run_code
    exec(code, run_globals)
  File "/home/lcur0006/joeynmt/joeynmt/__main__.py", line 48, in <module>
    main()
  File "/home/lcur0006/joeynmt/joeynmt/__main__.py", line 35, in main
    train(cfg_file=args.config_path, skip_test=args.skip_test)
  File "/home/lcur0006/joeynmt/joeynmt/training.py", line 846, in train
    trainer.train_and_validate(train_data=train_data, valid_data=dev_data)
  File "/home/lcur0006/joeynmt/joeynmt/training.py", line 497, in train_and_validate
    valid_duration = self._validate(valid_data, epoch_no)
  File "/home/lcur0006/joeynmt/joeynmt/training.py", line 642, in _validate
    references=valid_references)
  File "/home/lcur0006/joeynmt/joeynmt/training.py", line 731, in _log_examples
    logger.debug("\tRaw source:     %s", sources_raw[p])
Message: '\tRaw source:     %s'
Arguments: (['\u0e1e', '\u0e48', '\u0e2d\u0e02\u0e2d\u0e07@@', '\u0e09\u0e31\u0e19@@', '\u0e01\u0e33\u0e25\u0e31\u0e07@@', '\u0e1f\u0e31\u0e07@@', '\u0e02', '\u0e48', '\u0e32\u0e27@@', '\u0e1a\u0e35@@', '\u0e1a\u0e35@@', '\u0e0b\u0e35', '\u0e08\u0e32\u0e01@@', '\u0e27\u0e34\u0e17@@', '\u0e22\u0e38@@', '\u0e2a\u0e35@@', '\u0e40\u0e17@@', '\u0e32@@', '\u0e2d\u0e31\u0e19@@', '\u0e40\u0e25', '\u0e47', '\u0e01'],)
--- Logging error ---
Traceback (most recent call last):
  File "/sw/arch/Debian10/EB_production/2019/software/Anaconda3/2018.12/lib/python3.7/logging/__init__.py", line 1036, in emit
    stream.write(msg)
UnicodeEncodeError: 'latin-1' codec can't encode character '\u0e1e' in position 65: ordinal not in range(256)
Call stack:
  File "/sw/arch/Debian10/EB_production/2019/software/Anaconda3/2018.12/lib/python3.7/runpy.py", line 193, in _run_module_as_main
    "__main__", mod_spec)
  File "/sw/arch/Debian10/EB_production/2019/software/Anaconda3/2018.12/lib/python3.7/runpy.py", line 85, in _run_code
    exec(code, run_globals)
  File "/home/lcur0006/joeynmt/joeynmt/__main__.py", line 48, in <module>
    main()
  File "/home/lcur0006/joeynmt/joeynmt/__main__.py", line 35, in main
    train(cfg_file=args.config_path, skip_test=args.skip_test)
  File "/home/lcur0006/joeynmt/joeynmt/training.py", line 846, in train
    trainer.train_and_validate(train_data=train_data, valid_data=dev_data)
  File "/home/lcur0006/joeynmt/joeynmt/training.py", line 497, in train_and_validate
    valid_duration = self._validate(valid_data, epoch_no)
  File "/home/lcur0006/joeynmt/joeynmt/training.py", line 642, in _validate
    references=valid_references)
  File "/home/lcur0006/joeynmt/joeynmt/training.py", line 737, in _log_examples
    logger.info("\tSource:     %s", sources[p])
Message: '\tSource:     %s'
Arguments: ('\u0e1e \u0e48 \u0e2d\u0e02\u0e2d\u0e07\u0e09\u0e31\u0e19\u0e01\u0e33\u0e25\u0e31\u0e07\u0e1f\u0e31\u0e07\u0e02 \u0e48 \u0e32\u0e27\u0e1a\u0e35\u0e1a\u0e35\u0e0b\u0e35 \u0e08\u0e32\u0e01\u0e27\u0e34\u0e17\u0e22\u0e38\u0e2a\u0e35\u0e40\u0e17\u0e32\u0e2d\u0e31\u0e19\u0e40\u0e25 \u0e47 \u0e01',)
2021-10-03 14:05:25,991 - INFO - joeynmt.training - 	Source:     \u0e1e \u0e48 \u0e2d\u0e02\u0e2d\u0e07\u0e09\u0e31\u0e19\u0e01\u0e33\u0e25\u0e31\u0e07\u0e1f\u0e31\u0e07\u0e02 \u0e48 \u0e32\u0e27\u0e1a\u0e35\u0e1a\u0e35\u0e0b\u0e35 \u0e08\u0e32\u0e01\u0e27\u0e34\u0e17\u0e22\u0e38\u0e2a\u0e35\u0e40\u0e17\u0e32\u0e2d\u0e31\u0e19\u0e40\u0e25 \u0e47 \u0e01
2021-10-03 14:05:25,991 - INFO - joeynmt.training - 	Reference:  "My father was listening to BBC News on his small , gray radio ."
2021-10-03 14:05:25,991 - INFO - joeynmt.training - 	Hypothesis: I &apos;m going to be a couple of the first .
2021-10-03 14:05:25,991 - INFO - joeynmt.training - Validation result (greedy) at epoch  14, step      800: bleu:   3.16, loss: 77074.2422, ppl: 148.9367, duration: 3.9717s
2021-10-03 14:05:32,287 - INFO - joeynmt.training - Epoch  14: total training loss 5145.84
2021-10-03 14:05:32,287 - INFO - joeynmt.training - EPOCH 15
2021-10-03 14:05:43,864 - INFO - joeynmt.training - Epoch  15: total training loss 5058.17
2021-10-03 14:05:43,865 - INFO - joeynmt.training - EPOCH 16
2021-10-03 14:05:50,833 - WARNING - sacrebleu - That's 100 lines that end in a tokenized period ('.')
2021-10-03 14:05:50,834 - WARNING - sacrebleu - It looks like you forgot to detokenize your test data, which may hurt your score.
2021-10-03 14:05:50,834 - WARNING - sacrebleu - If you insist your data is detokenized, or don't care, you can suppress this message with the `force` parameter.
2021-10-03 14:05:50,838 - INFO - joeynmt.training - Hooray! New best validation result [eval_metric]!
2021-10-03 14:05:51,693 - INFO - joeynmt.helpers - delete models/LSTM_th/700.ckpt
2021-10-03 14:05:51,766 - INFO - joeynmt.helpers - delete /home/lcur0006/joeynmt/models/LSTM_th/700.ckpt
2021-10-03 14:05:51,766 - WARNING - joeynmt.helpers - Wanted to delete old checkpoint /home/lcur0006/joeynmt/models/LSTM_th/700.ckpt but file does not exist. ([Errno 2] No such file or directory: '/home/lcur0006/joeynmt/models/LSTM_th/700.ckpt')
2021-10-03 14:05:51,768 - INFO - joeynmt.training - Example #0
2021-10-03 14:05:51,769 - INFO - joeynmt.training - 	Source:     th
2021-10-03 14:05:51,769 - INFO - joeynmt.training - 	Reference:  en
2021-10-03 14:05:51,769 - INFO - joeynmt.training - 	Hypothesis: Thank you .
2021-10-03 14:05:51,769 - INFO - joeynmt.training - Example #1
--- Logging error ---
Traceback (most recent call last):
  File "/sw/arch/Debian10/EB_production/2019/software/Anaconda3/2018.12/lib/python3.7/logging/__init__.py", line 1036, in emit
    stream.write(msg)
UnicodeEncodeError: 'latin-1' codec can't encode characters in position 72-74: ordinal not in range(256)
Call stack:
  File "/sw/arch/Debian10/EB_production/2019/software/Anaconda3/2018.12/lib/python3.7/runpy.py", line 193, in _run_module_as_main
    "__main__", mod_spec)
  File "/sw/arch/Debian10/EB_production/2019/software/Anaconda3/2018.12/lib/python3.7/runpy.py", line 85, in _run_code
    exec(code, run_globals)
  File "/home/lcur0006/joeynmt/joeynmt/__main__.py", line 48, in <module>
    main()
  File "/home/lcur0006/joeynmt/joeynmt/__main__.py", line 35, in main
    train(cfg_file=args.config_path, skip_test=args.skip_test)
  File "/home/lcur0006/joeynmt/joeynmt/training.py", line 846, in train
    trainer.train_and_validate(train_data=train_data, valid_data=dev_data)
  File "/home/lcur0006/joeynmt/joeynmt/training.py", line 497, in train_and_validate
    valid_duration = self._validate(valid_data, epoch_no)
  File "/home/lcur0006/joeynmt/joeynmt/training.py", line 642, in _validate
    references=valid_references)
  File "/home/lcur0006/joeynmt/joeynmt/training.py", line 731, in _log_examples
    logger.debug("\tRaw source:     %s", sources_raw[p])
Message: '\tRaw source:     %s'
Arguments: (['\u0e15\u0e2d\u0e19@@', '\u0e09\u0e31\u0e19@@', '\u0e2d\u0e32\u0e22\u0e38', '1@@', '1', '\u0e09\u0e31\u0e19@@', '\u0e08\u0e33@@', '\u0e44\u0e14', '\u0e49', '\u0e27', '\u0e48', '\u0e32\u0e15@@', '\u0e37', '\u0e48', '\u0e19@@', '\u0e02\u0e36', '\u0e49', '\u0e19\u0e21\u0e32@@', '\u0e40\u0e0a', '\u0e49', '\u0e32\u0e27@@', '\u0e31\u0e19@@', '\u0e2b\u0e19\u0e36', '\u0e48', '\u0e07', '\u0e41\u0e25\u0e30@@', '\u0e44\u0e14', '\u0e49', '\u0e22\u0e34\u0e19@@', '\u0e40\u0e2a\u0e35\u0e22\u0e07@@', '\u0e23', '\u0e49', '\u0e2d\u0e07@@', '\u0e14', '\u0e49', '\u0e27\u0e22\u0e04\u0e27\u0e32\u0e21@@', '\u0e22\u0e34\u0e19@@', '\u0e14\u0e35@@', '\u0e43\u0e19@@', '\u0e1a', '\u0e49', '\u0e32\u0e19'],)
--- Logging error ---
Traceback (most recent call last):
  File "/sw/arch/Debian10/EB_production/2019/software/Anaconda3/2018.12/lib/python3.7/logging/__init__.py", line 1036, in emit
    stream.write(msg)
UnicodeEncodeError: 'latin-1' codec can't encode characters in position 65-74: ordinal not in range(256)
Call stack:
  File "/sw/arch/Debian10/EB_production/2019/software/Anaconda3/2018.12/lib/python3.7/runpy.py", line 193, in _run_module_as_main
    "__main__", mod_spec)
  File "/sw/arch/Debian10/EB_production/2019/software/Anaconda3/2018.12/lib/python3.7/runpy.py", line 85, in _run_code
    exec(code, run_globals)
  File "/home/lcur0006/joeynmt/joeynmt/__main__.py", line 48, in <module>
    main()
  File "/home/lcur0006/joeynmt/joeynmt/__main__.py", line 35, in main
    train(cfg_file=args.config_path, skip_test=args.skip_test)
  File "/home/lcur0006/joeynmt/joeynmt/training.py", line 846, in train
    trainer.train_and_validate(train_data=train_data, valid_data=dev_data)
  File "/home/lcur0006/joeynmt/joeynmt/training.py", line 497, in train_and_validate
    valid_duration = self._validate(valid_data, epoch_no)
  File "/home/lcur0006/joeynmt/joeynmt/training.py", line 642, in _validate
    references=valid_references)
  File "/home/lcur0006/joeynmt/joeynmt/training.py", line 737, in _log_examples
    logger.info("\tSource:     %s", sources[p])
Message: '\tSource:     %s'
Arguments: ('\u0e15\u0e2d\u0e19\u0e09\u0e31\u0e19\u0e2d\u0e32\u0e22\u0e38 11 \u0e09\u0e31\u0e19\u0e08\u0e33\u0e44\u0e14 \u0e49 \u0e27 \u0e48 \u0e32\u0e15\u0e37 \u0e48 \u0e19\u0e02\u0e36 \u0e49 \u0e19\u0e21\u0e32\u0e40\u0e0a \u0e49 \u0e32\u0e27\u0e31\u0e19\u0e2b\u0e19\u0e36 \u0e48 \u0e07 \u0e41\u0e25\u0e30\u0e44\u0e14 \u0e49 \u0e22\u0e34\u0e19\u0e40\u0e2a\u0e35\u0e22\u0e07\u0e23 \u0e49 \u0e2d\u0e07\u0e14 \u0e49 \u0e27\u0e22\u0e04\u0e27\u0e32\u0e21\u0e22\u0e34\u0e19\u0e14\u0e35\u0e43\u0e19\u0e1a \u0e49 \u0e32\u0e19',)
2021-10-03 14:05:51,770 - INFO - joeynmt.training - 	Source:     \u0e15\u0e2d\u0e19\u0e09\u0e31\u0e19\u0e2d\u0e32\u0e22\u0e38 11 \u0e09\u0e31\u0e19\u0e08\u0e33\u0e44\u0e14 \u0e49 \u0e27 \u0e48 \u0e32\u0e15\u0e37 \u0e48 \u0e19\u0e02\u0e36 \u0e49 \u0e19\u0e21\u0e32\u0e40\u0e0a \u0e49 \u0e32\u0e27\u0e31\u0e19\u0e2b\u0e19\u0e36 \u0e48 \u0e07 \u0e41\u0e25\u0e30\u0e44\u0e14 \u0e49 \u0e22\u0e34\u0e19\u0e40\u0e2a\u0e35\u0e22\u0e07\u0e23 \u0e49 \u0e2d\u0e07\u0e14 \u0e49 \u0e27\u0e22\u0e04\u0e27\u0e32\u0e21\u0e22\u0e34\u0e19\u0e14\u0e35\u0e43\u0e19\u0e1a \u0e49 \u0e32\u0e19
2021-10-03 14:05:51,770 - INFO - joeynmt.training - 	Reference:  "When I was 11 , I remember waking up one morning to the sound of joy in my house ."
2021-10-03 14:05:51,770 - INFO - joeynmt.training - 	Hypothesis: "I was a very question , I was a couple of the first , and I was a lot of the world ."
2021-10-03 14:05:51,770 - INFO - joeynmt.training - Example #2
--- Logging error ---
Traceback (most recent call last):
  File "/sw/arch/Debian10/EB_production/2019/software/Anaconda3/2018.12/lib/python3.7/logging/__init__.py", line 1036, in emit
    stream.write(msg)
UnicodeEncodeError: 'latin-1' codec can't encode character '\u0e1e' in position 72: ordinal not in range(256)
Call stack:
  File "/sw/arch/Debian10/EB_production/2019/software/Anaconda3/2018.12/lib/python3.7/runpy.py", line 193, in _run_module_as_main
    "__main__", mod_spec)
  File "/sw/arch/Debian10/EB_production/2019/software/Anaconda3/2018.12/lib/python3.7/runpy.py", line 85, in _run_code
    exec(code, run_globals)
  File "/home/lcur0006/joeynmt/joeynmt/__main__.py", line 48, in <module>
    main()
  File "/home/lcur0006/joeynmt/joeynmt/__main__.py", line 35, in main
    train(cfg_file=args.config_path, skip_test=args.skip_test)
  File "/home/lcur0006/joeynmt/joeynmt/training.py", line 846, in train
    trainer.train_and_validate(train_data=train_data, valid_data=dev_data)
  File "/home/lcur0006/joeynmt/joeynmt/training.py", line 497, in train_and_validate
    valid_duration = self._validate(valid_data, epoch_no)
  File "/home/lcur0006/joeynmt/joeynmt/training.py", line 642, in _validate
    references=valid_references)
  File "/home/lcur0006/joeynmt/joeynmt/training.py", line 731, in _log_examples
    logger.debug("\tRaw source:     %s", sources_raw[p])
Message: '\tRaw source:     %s'
Arguments: (['\u0e1e', '\u0e48', '\u0e2d\u0e02\u0e2d\u0e07@@', '\u0e09\u0e31\u0e19@@', '\u0e01\u0e33\u0e25\u0e31\u0e07@@', '\u0e1f\u0e31\u0e07@@', '\u0e02', '\u0e48', '\u0e32\u0e27@@', '\u0e1a\u0e35@@', '\u0e1a\u0e35@@', '\u0e0b\u0e35', '\u0e08\u0e32\u0e01@@', '\u0e27\u0e34\u0e17@@', '\u0e22\u0e38@@', '\u0e2a\u0e35@@', '\u0e40\u0e17@@', '\u0e32@@', '\u0e2d\u0e31\u0e19@@', '\u0e40\u0e25', '\u0e47', '\u0e01'],)
--- Logging error ---
Traceback (most recent call last):
  File "/sw/arch/Debian10/EB_production/2019/software/Anaconda3/2018.12/lib/python3.7/logging/__init__.py", line 1036, in emit
    stream.write(msg)
UnicodeEncodeError: 'latin-1' codec can't encode character '\u0e1e' in position 65: ordinal not in range(256)
Call stack:
  File "/sw/arch/Debian10/EB_production/2019/software/Anaconda3/2018.12/lib/python3.7/runpy.py", line 193, in _run_module_as_main
    "__main__", mod_spec)
  File "/sw/arch/Debian10/EB_production/2019/software/Anaconda3/2018.12/lib/python3.7/runpy.py", line 85, in _run_code
    exec(code, run_globals)
  File "/home/lcur0006/joeynmt/joeynmt/__main__.py", line 48, in <module>
    main()
  File "/home/lcur0006/joeynmt/joeynmt/__main__.py", line 35, in main
    train(cfg_file=args.config_path, skip_test=args.skip_test)
  File "/home/lcur0006/joeynmt/joeynmt/training.py", line 846, in train
    trainer.train_and_validate(train_data=train_data, valid_data=dev_data)
  File "/home/lcur0006/joeynmt/joeynmt/training.py", line 497, in train_and_validate
    valid_duration = self._validate(valid_data, epoch_no)
  File "/home/lcur0006/joeynmt/joeynmt/training.py", line 642, in _validate
    references=valid_references)
  File "/home/lcur0006/joeynmt/joeynmt/training.py", line 737, in _log_examples
    logger.info("\tSource:     %s", sources[p])
Message: '\tSource:     %s'
Arguments: ('\u0e1e \u0e48 \u0e2d\u0e02\u0e2d\u0e07\u0e09\u0e31\u0e19\u0e01\u0e33\u0e25\u0e31\u0e07\u0e1f\u0e31\u0e07\u0e02 \u0e48 \u0e32\u0e27\u0e1a\u0e35\u0e1a\u0e35\u0e0b\u0e35 \u0e08\u0e32\u0e01\u0e27\u0e34\u0e17\u0e22\u0e38\u0e2a\u0e35\u0e40\u0e17\u0e32\u0e2d\u0e31\u0e19\u0e40\u0e25 \u0e47 \u0e01',)
2021-10-03 14:05:51,771 - INFO - joeynmt.training - 	Source:     \u0e1e \u0e48 \u0e2d\u0e02\u0e2d\u0e07\u0e09\u0e31\u0e19\u0e01\u0e33\u0e25\u0e31\u0e07\u0e1f\u0e31\u0e07\u0e02 \u0e48 \u0e32\u0e27\u0e1a\u0e35\u0e1a\u0e35\u0e0b\u0e35 \u0e08\u0e32\u0e01\u0e27\u0e34\u0e17\u0e22\u0e38\u0e2a\u0e35\u0e40\u0e17\u0e32\u0e2d\u0e31\u0e19\u0e40\u0e25 \u0e47 \u0e01
2021-10-03 14:05:51,771 - INFO - joeynmt.training - 	Reference:  "My father was listening to BBC News on his small , gray radio ."
2021-10-03 14:05:51,771 - INFO - joeynmt.training - 	Hypothesis: I was a sssssi of the Wandi .
2021-10-03 14:05:51,771 - INFO - joeynmt.training - Validation result (greedy) at epoch  16, step      900: bleu:   5.00, loss: 76587.2578, ppl: 144.3018, duration: 4.9038s
2021-10-03 14:06:01,717 - INFO - joeynmt.training - Epoch  16: total training loss 4970.62
2021-10-03 14:06:01,717 - INFO - joeynmt.training - EPOCH 17
2021-10-03 14:06:12,662 - INFO - joeynmt.training - Epoch  17, Step:     1000, Batch Loss:    77.588173, Tokens per Sec:     8113, Lr: 0.000300
2021-10-03 14:06:16,613 - WARNING - sacrebleu - That's 100 lines that end in a tokenized period ('.')
2021-10-03 14:06:16,613 - WARNING - sacrebleu - It looks like you forgot to detokenize your test data, which may hurt your score.
2021-10-03 14:06:16,613 - WARNING - sacrebleu - If you insist your data is detokenized, or don't care, you can suppress this message with the `force` parameter.
2021-10-03 14:06:16,619 - INFO - joeynmt.training - Example #0
2021-10-03 14:06:16,620 - INFO - joeynmt.training - 	Source:     th
2021-10-03 14:06:16,620 - INFO - joeynmt.training - 	Reference:  en
2021-10-03 14:06:16,620 - INFO - joeynmt.training - 	Hypothesis: Thank you .
2021-10-03 14:06:16,620 - INFO - joeynmt.training - Example #1
--- Logging error ---
Traceback (most recent call last):
  File "/sw/arch/Debian10/EB_production/2019/software/Anaconda3/2018.12/lib/python3.7/logging/__init__.py", line 1036, in emit
    stream.write(msg)
UnicodeEncodeError: 'latin-1' codec can't encode characters in position 72-74: ordinal not in range(256)
Call stack:
  File "/sw/arch/Debian10/EB_production/2019/software/Anaconda3/2018.12/lib/python3.7/runpy.py", line 193, in _run_module_as_main
    "__main__", mod_spec)
  File "/sw/arch/Debian10/EB_production/2019/software/Anaconda3/2018.12/lib/python3.7/runpy.py", line 85, in _run_code
    exec(code, run_globals)
  File "/home/lcur0006/joeynmt/joeynmt/__main__.py", line 48, in <module>
    main()
  File "/home/lcur0006/joeynmt/joeynmt/__main__.py", line 35, in main
    train(cfg_file=args.config_path, skip_test=args.skip_test)
  File "/home/lcur0006/joeynmt/joeynmt/training.py", line 846, in train
    trainer.train_and_validate(train_data=train_data, valid_data=dev_data)
  File "/home/lcur0006/joeynmt/joeynmt/training.py", line 497, in train_and_validate
    valid_duration = self._validate(valid_data, epoch_no)
  File "/home/lcur0006/joeynmt/joeynmt/training.py", line 642, in _validate
    references=valid_references)
  File "/home/lcur0006/joeynmt/joeynmt/training.py", line 731, in _log_examples
    logger.debug("\tRaw source:     %s", sources_raw[p])
Message: '\tRaw source:     %s'
Arguments: (['\u0e15\u0e2d\u0e19@@', '\u0e09\u0e31\u0e19@@', '\u0e2d\u0e32\u0e22\u0e38', '1@@', '1', '\u0e09\u0e31\u0e19@@', '\u0e08\u0e33@@', '\u0e44\u0e14', '\u0e49', '\u0e27', '\u0e48', '\u0e32\u0e15@@', '\u0e37', '\u0e48', '\u0e19@@', '\u0e02\u0e36', '\u0e49', '\u0e19\u0e21\u0e32@@', '\u0e40\u0e0a', '\u0e49', '\u0e32\u0e27@@', '\u0e31\u0e19@@', '\u0e2b\u0e19\u0e36', '\u0e48', '\u0e07', '\u0e41\u0e25\u0e30@@', '\u0e44\u0e14', '\u0e49', '\u0e22\u0e34\u0e19@@', '\u0e40\u0e2a\u0e35\u0e22\u0e07@@', '\u0e23', '\u0e49', '\u0e2d\u0e07@@', '\u0e14', '\u0e49', '\u0e27\u0e22\u0e04\u0e27\u0e32\u0e21@@', '\u0e22\u0e34\u0e19@@', '\u0e14\u0e35@@', '\u0e43\u0e19@@', '\u0e1a', '\u0e49', '\u0e32\u0e19'],)
--- Logging error ---
Traceback (most recent call last):
  File "/sw/arch/Debian10/EB_production/2019/software/Anaconda3/2018.12/lib/python3.7/logging/__init__.py", line 1036, in emit
    stream.write(msg)
UnicodeEncodeError: 'latin-1' codec can't encode characters in position 65-74: ordinal not in range(256)
Call stack:
  File "/sw/arch/Debian10/EB_production/2019/software/Anaconda3/2018.12/lib/python3.7/runpy.py", line 193, in _run_module_as_main
    "__main__", mod_spec)
  File "/sw/arch/Debian10/EB_production/2019/software/Anaconda3/2018.12/lib/python3.7/runpy.py", line 85, in _run_code
    exec(code, run_globals)
  File "/home/lcur0006/joeynmt/joeynmt/__main__.py", line 48, in <module>
    main()
  File "/home/lcur0006/joeynmt/joeynmt/__main__.py", line 35, in main
    train(cfg_file=args.config_path, skip_test=args.skip_test)
  File "/home/lcur0006/joeynmt/joeynmt/training.py", line 846, in train
    trainer.train_and_validate(train_data=train_data, valid_data=dev_data)
  File "/home/lcur0006/joeynmt/joeynmt/training.py", line 497, in train_and_validate
    valid_duration = self._validate(valid_data, epoch_no)
  File "/home/lcur0006/joeynmt/joeynmt/training.py", line 642, in _validate
    references=valid_references)
  File "/home/lcur0006/joeynmt/joeynmt/training.py", line 737, in _log_examples
    logger.info("\tSource:     %s", sources[p])
Message: '\tSource:     %s'
Arguments: ('\u0e15\u0e2d\u0e19\u0e09\u0e31\u0e19\u0e2d\u0e32\u0e22\u0e38 11 \u0e09\u0e31\u0e19\u0e08\u0e33\u0e44\u0e14 \u0e49 \u0e27 \u0e48 \u0e32\u0e15\u0e37 \u0e48 \u0e19\u0e02\u0e36 \u0e49 \u0e19\u0e21\u0e32\u0e40\u0e0a \u0e49 \u0e32\u0e27\u0e31\u0e19\u0e2b\u0e19\u0e36 \u0e48 \u0e07 \u0e41\u0e25\u0e30\u0e44\u0e14 \u0e49 \u0e22\u0e34\u0e19\u0e40\u0e2a\u0e35\u0e22\u0e07\u0e23 \u0e49 \u0e2d\u0e07\u0e14 \u0e49 \u0e27\u0e22\u0e04\u0e27\u0e32\u0e21\u0e22\u0e34\u0e19\u0e14\u0e35\u0e43\u0e19\u0e1a \u0e49 \u0e32\u0e19',)
2021-10-03 14:06:16,622 - INFO - joeynmt.training - 	Source:     \u0e15\u0e2d\u0e19\u0e09\u0e31\u0e19\u0e2d\u0e32\u0e22\u0e38 11 \u0e09\u0e31\u0e19\u0e08\u0e33\u0e44\u0e14 \u0e49 \u0e27 \u0e48 \u0e32\u0e15\u0e37 \u0e48 \u0e19\u0e02\u0e36 \u0e49 \u0e19\u0e21\u0e32\u0e40\u0e0a \u0e49 \u0e32\u0e27\u0e31\u0e19\u0e2b\u0e19\u0e36 \u0e48 \u0e07 \u0e41\u0e25\u0e30\u0e44\u0e14 \u0e49 \u0e22\u0e34\u0e19\u0e40\u0e2a\u0e35\u0e22\u0e07\u0e23 \u0e49 \u0e2d\u0e07\u0e14 \u0e49 \u0e27\u0e22\u0e04\u0e27\u0e32\u0e21\u0e22\u0e34\u0e19\u0e14\u0e35\u0e43\u0e19\u0e1a \u0e49 \u0e32\u0e19
2021-10-03 14:06:16,623 - INFO - joeynmt.training - 	Reference:  "When I was 11 , I remember waking up one morning to the sound of joy in my house ."
2021-10-03 14:06:16,623 - INFO - joeynmt.training - 	Hypothesis: "I was a very question , and I was a lot of the first , and I was a lot of the world ."
2021-10-03 14:06:16,623 - INFO - joeynmt.training - Example #2
--- Logging error ---
Traceback (most recent call last):
  File "/sw/arch/Debian10/EB_production/2019/software/Anaconda3/2018.12/lib/python3.7/logging/__init__.py", line 1036, in emit
    stream.write(msg)
UnicodeEncodeError: 'latin-1' codec can't encode character '\u0e1e' in position 72: ordinal not in range(256)
Call stack:
  File "/sw/arch/Debian10/EB_production/2019/software/Anaconda3/2018.12/lib/python3.7/runpy.py", line 193, in _run_module_as_main
    "__main__", mod_spec)
  File "/sw/arch/Debian10/EB_production/2019/software/Anaconda3/2018.12/lib/python3.7/runpy.py", line 85, in _run_code
    exec(code, run_globals)
  File "/home/lcur0006/joeynmt/joeynmt/__main__.py", line 48, in <module>
    main()
  File "/home/lcur0006/joeynmt/joeynmt/__main__.py", line 35, in main
    train(cfg_file=args.config_path, skip_test=args.skip_test)
  File "/home/lcur0006/joeynmt/joeynmt/training.py", line 846, in train
    trainer.train_and_validate(train_data=train_data, valid_data=dev_data)
  File "/home/lcur0006/joeynmt/joeynmt/training.py", line 497, in train_and_validate
    valid_duration = self._validate(valid_data, epoch_no)
  File "/home/lcur0006/joeynmt/joeynmt/training.py", line 642, in _validate
    references=valid_references)
  File "/home/lcur0006/joeynmt/joeynmt/training.py", line 731, in _log_examples
    logger.debug("\tRaw source:     %s", sources_raw[p])
Message: '\tRaw source:     %s'
Arguments: (['\u0e1e', '\u0e48', '\u0e2d\u0e02\u0e2d\u0e07@@', '\u0e09\u0e31\u0e19@@', '\u0e01\u0e33\u0e25\u0e31\u0e07@@', '\u0e1f\u0e31\u0e07@@', '\u0e02', '\u0e48', '\u0e32\u0e27@@', '\u0e1a\u0e35@@', '\u0e1a\u0e35@@', '\u0e0b\u0e35', '\u0e08\u0e32\u0e01@@', '\u0e27\u0e34\u0e17@@', '\u0e22\u0e38@@', '\u0e2a\u0e35@@', '\u0e40\u0e17@@', '\u0e32@@', '\u0e2d\u0e31\u0e19@@', '\u0e40\u0e25', '\u0e47', '\u0e01'],)
--- Logging error ---
Traceback (most recent call last):
  File "/sw/arch/Debian10/EB_production/2019/software/Anaconda3/2018.12/lib/python3.7/logging/__init__.py", line 1036, in emit
    stream.write(msg)
UnicodeEncodeError: 'latin-1' codec can't encode character '\u0e1e' in position 65: ordinal not in range(256)
Call stack:
  File "/sw/arch/Debian10/EB_production/2019/software/Anaconda3/2018.12/lib/python3.7/runpy.py", line 193, in _run_module_as_main
    "__main__", mod_spec)
  File "/sw/arch/Debian10/EB_production/2019/software/Anaconda3/2018.12/lib/python3.7/runpy.py", line 85, in _run_code
    exec(code, run_globals)
  File "/home/lcur0006/joeynmt/joeynmt/__main__.py", line 48, in <module>
    main()
  File "/home/lcur0006/joeynmt/joeynmt/__main__.py", line 35, in main
    train(cfg_file=args.config_path, skip_test=args.skip_test)
  File "/home/lcur0006/joeynmt/joeynmt/training.py", line 846, in train
    trainer.train_and_validate(train_data=train_data, valid_data=dev_data)
  File "/home/lcur0006/joeynmt/joeynmt/training.py", line 497, in train_and_validate
    valid_duration = self._validate(valid_data, epoch_no)
  File "/home/lcur0006/joeynmt/joeynmt/training.py", line 642, in _validate
    references=valid_references)
  File "/home/lcur0006/joeynmt/joeynmt/training.py", line 737, in _log_examples
    logger.info("\tSource:     %s", sources[p])
Message: '\tSource:     %s'
Arguments: ('\u0e1e \u0e48 \u0e2d\u0e02\u0e2d\u0e07\u0e09\u0e31\u0e19\u0e01\u0e33\u0e25\u0e31\u0e07\u0e1f\u0e31\u0e07\u0e02 \u0e48 \u0e32\u0e27\u0e1a\u0e35\u0e1a\u0e35\u0e0b\u0e35 \u0e08\u0e32\u0e01\u0e27\u0e34\u0e17\u0e22\u0e38\u0e2a\u0e35\u0e40\u0e17\u0e32\u0e2d\u0e31\u0e19\u0e40\u0e25 \u0e47 \u0e01',)
2021-10-03 14:06:16,623 - INFO - joeynmt.training - 	Source:     \u0e1e \u0e48 \u0e2d\u0e02\u0e2d\u0e07\u0e09\u0e31\u0e19\u0e01\u0e33\u0e25\u0e31\u0e07\u0e1f\u0e31\u0e07\u0e02 \u0e48 \u0e32\u0e27\u0e1a\u0e35\u0e1a\u0e35\u0e0b\u0e35 \u0e08\u0e32\u0e01\u0e27\u0e34\u0e17\u0e22\u0e38\u0e2a\u0e35\u0e40\u0e17\u0e32\u0e2d\u0e31\u0e19\u0e40\u0e25 \u0e47 \u0e01
2021-10-03 14:06:16,624 - INFO - joeynmt.training - 	Reference:  "My father was listening to BBC News on his small , gray radio ."
2021-10-03 14:06:16,624 - INFO - joeynmt.training - 	Hypothesis: This is a ssssssi of the Work .
2021-10-03 14:06:16,624 - INFO - joeynmt.training - Validation result (greedy) at epoch  17, step     1000: bleu:   4.19, loss: 75947.6172, ppl: 138.4325, duration: 3.9612s
2021-10-03 14:06:18,505 - INFO - joeynmt.training - Epoch  17: total training loss 4888.74
2021-10-03 14:06:18,506 - INFO - joeynmt.training - EPOCH 18
2021-10-03 14:06:30,030 - INFO - joeynmt.training - Epoch  18: total training loss 4791.64
2021-10-03 14:06:30,030 - INFO - joeynmt.training - EPOCH 19
2021-10-03 14:06:41,512 - WARNING - sacrebleu - That's 100 lines that end in a tokenized period ('.')
2021-10-03 14:06:41,512 - WARNING - sacrebleu - It looks like you forgot to detokenize your test data, which may hurt your score.
2021-10-03 14:06:41,513 - WARNING - sacrebleu - If you insist your data is detokenized, or don't care, you can suppress this message with the `force` parameter.
2021-10-03 14:06:41,519 - INFO - joeynmt.training - Example #0
2021-10-03 14:06:41,519 - INFO - joeynmt.training - 	Source:     th
2021-10-03 14:06:41,519 - INFO - joeynmt.training - 	Reference:  en
2021-10-03 14:06:41,519 - INFO - joeynmt.training - 	Hypothesis: Thank you .
2021-10-03 14:06:41,519 - INFO - joeynmt.training - Example #1
--- Logging error ---
Traceback (most recent call last):
  File "/sw/arch/Debian10/EB_production/2019/software/Anaconda3/2018.12/lib/python3.7/logging/__init__.py", line 1036, in emit
    stream.write(msg)
UnicodeEncodeError: 'latin-1' codec can't encode characters in position 72-74: ordinal not in range(256)
Call stack:
  File "/sw/arch/Debian10/EB_production/2019/software/Anaconda3/2018.12/lib/python3.7/runpy.py", line 193, in _run_module_as_main
    "__main__", mod_spec)
  File "/sw/arch/Debian10/EB_production/2019/software/Anaconda3/2018.12/lib/python3.7/runpy.py", line 85, in _run_code
    exec(code, run_globals)
  File "/home/lcur0006/joeynmt/joeynmt/__main__.py", line 48, in <module>
    main()
  File "/home/lcur0006/joeynmt/joeynmt/__main__.py", line 35, in main
    train(cfg_file=args.config_path, skip_test=args.skip_test)
  File "/home/lcur0006/joeynmt/joeynmt/training.py", line 846, in train
    trainer.train_and_validate(train_data=train_data, valid_data=dev_data)
  File "/home/lcur0006/joeynmt/joeynmt/training.py", line 497, in train_and_validate
    valid_duration = self._validate(valid_data, epoch_no)
  File "/home/lcur0006/joeynmt/joeynmt/training.py", line 642, in _validate
    references=valid_references)
  File "/home/lcur0006/joeynmt/joeynmt/training.py", line 731, in _log_examples
    logger.debug("\tRaw source:     %s", sources_raw[p])
Message: '\tRaw source:     %s'
Arguments: (['\u0e15\u0e2d\u0e19@@', '\u0e09\u0e31\u0e19@@', '\u0e2d\u0e32\u0e22\u0e38', '1@@', '1', '\u0e09\u0e31\u0e19@@', '\u0e08\u0e33@@', '\u0e44\u0e14', '\u0e49', '\u0e27', '\u0e48', '\u0e32\u0e15@@', '\u0e37', '\u0e48', '\u0e19@@', '\u0e02\u0e36', '\u0e49', '\u0e19\u0e21\u0e32@@', '\u0e40\u0e0a', '\u0e49', '\u0e32\u0e27@@', '\u0e31\u0e19@@', '\u0e2b\u0e19\u0e36', '\u0e48', '\u0e07', '\u0e41\u0e25\u0e30@@', '\u0e44\u0e14', '\u0e49', '\u0e22\u0e34\u0e19@@', '\u0e40\u0e2a\u0e35\u0e22\u0e07@@', '\u0e23', '\u0e49', '\u0e2d\u0e07@@', '\u0e14', '\u0e49', '\u0e27\u0e22\u0e04\u0e27\u0e32\u0e21@@', '\u0e22\u0e34\u0e19@@', '\u0e14\u0e35@@', '\u0e43\u0e19@@', '\u0e1a', '\u0e49', '\u0e32\u0e19'],)
--- Logging error ---
Traceback (most recent call last):
  File "/sw/arch/Debian10/EB_production/2019/software/Anaconda3/2018.12/lib/python3.7/logging/__init__.py", line 1036, in emit
    stream.write(msg)
UnicodeEncodeError: 'latin-1' codec can't encode characters in position 65-74: ordinal not in range(256)
Call stack:
  File "/sw/arch/Debian10/EB_production/2019/software/Anaconda3/2018.12/lib/python3.7/runpy.py", line 193, in _run_module_as_main
    "__main__", mod_spec)
  File "/sw/arch/Debian10/EB_production/2019/software/Anaconda3/2018.12/lib/python3.7/runpy.py", line 85, in _run_code
    exec(code, run_globals)
  File "/home/lcur0006/joeynmt/joeynmt/__main__.py", line 48, in <module>
    main()
  File "/home/lcur0006/joeynmt/joeynmt/__main__.py", line 35, in main
    train(cfg_file=args.config_path, skip_test=args.skip_test)
  File "/home/lcur0006/joeynmt/joeynmt/training.py", line 846, in train
    trainer.train_and_validate(train_data=train_data, valid_data=dev_data)
  File "/home/lcur0006/joeynmt/joeynmt/training.py", line 497, in train_and_validate
    valid_duration = self._validate(valid_data, epoch_no)
  File "/home/lcur0006/joeynmt/joeynmt/training.py", line 642, in _validate
    references=valid_references)
  File "/home/lcur0006/joeynmt/joeynmt/training.py", line 737, in _log_examples
    logger.info("\tSource:     %s", sources[p])
Message: '\tSource:     %s'
Arguments: ('\u0e15\u0e2d\u0e19\u0e09\u0e31\u0e19\u0e2d\u0e32\u0e22\u0e38 11 \u0e09\u0e31\u0e19\u0e08\u0e33\u0e44\u0e14 \u0e49 \u0e27 \u0e48 \u0e32\u0e15\u0e37 \u0e48 \u0e19\u0e02\u0e36 \u0e49 \u0e19\u0e21\u0e32\u0e40\u0e0a \u0e49 \u0e32\u0e27\u0e31\u0e19\u0e2b\u0e19\u0e36 \u0e48 \u0e07 \u0e41\u0e25\u0e30\u0e44\u0e14 \u0e49 \u0e22\u0e34\u0e19\u0e40\u0e2a\u0e35\u0e22\u0e07\u0e23 \u0e49 \u0e2d\u0e07\u0e14 \u0e49 \u0e27\u0e22\u0e04\u0e27\u0e32\u0e21\u0e22\u0e34\u0e19\u0e14\u0e35\u0e43\u0e19\u0e1a \u0e49 \u0e32\u0e19',)
2021-10-03 14:06:41,520 - INFO - joeynmt.training - 	Source:     \u0e15\u0e2d\u0e19\u0e09\u0e31\u0e19\u0e2d\u0e32\u0e22\u0e38 11 \u0e09\u0e31\u0e19\u0e08\u0e33\u0e44\u0e14 \u0e49 \u0e27 \u0e48 \u0e32\u0e15\u0e37 \u0e48 \u0e19\u0e02\u0e36 \u0e49 \u0e19\u0e21\u0e32\u0e40\u0e0a \u0e49 \u0e32\u0e27\u0e31\u0e19\u0e2b\u0e19\u0e36 \u0e48 \u0e07 \u0e41\u0e25\u0e30\u0e44\u0e14 \u0e49 \u0e22\u0e34\u0e19\u0e40\u0e2a\u0e35\u0e22\u0e07\u0e23 \u0e49 \u0e2d\u0e07\u0e14 \u0e49 \u0e27\u0e22\u0e04\u0e27\u0e32\u0e21\u0e22\u0e34\u0e19\u0e14\u0e35\u0e43\u0e19\u0e1a \u0e49 \u0e32\u0e19
2021-10-03 14:06:41,521 - INFO - joeynmt.training - 	Reference:  "When I was 11 , I remember waking up one morning to the sound of joy in my house ."
2021-10-03 14:06:41,521 - INFO - joeynmt.training - 	Hypothesis: "I was going to be a couple of the first , and I was going to be a bit of the world , and I was going to get a own time ."
2021-10-03 14:06:41,521 - INFO - joeynmt.training - Example #2
--- Logging error ---
Traceback (most recent call last):
  File "/sw/arch/Debian10/EB_production/2019/software/Anaconda3/2018.12/lib/python3.7/logging/__init__.py", line 1036, in emit
    stream.write(msg)
UnicodeEncodeError: 'latin-1' codec can't encode character '\u0e1e' in position 72: ordinal not in range(256)
Call stack:
  File "/sw/arch/Debian10/EB_production/2019/software/Anaconda3/2018.12/lib/python3.7/runpy.py", line 193, in _run_module_as_main
    "__main__", mod_spec)
  File "/sw/arch/Debian10/EB_production/2019/software/Anaconda3/2018.12/lib/python3.7/runpy.py", line 85, in _run_code
    exec(code, run_globals)
  File "/home/lcur0006/joeynmt/joeynmt/__main__.py", line 48, in <module>
    main()
  File "/home/lcur0006/joeynmt/joeynmt/__main__.py", line 35, in main
    train(cfg_file=args.config_path, skip_test=args.skip_test)
  File "/home/lcur0006/joeynmt/joeynmt/training.py", line 846, in train
    trainer.train_and_validate(train_data=train_data, valid_data=dev_data)
  File "/home/lcur0006/joeynmt/joeynmt/training.py", line 497, in train_and_validate
    valid_duration = self._validate(valid_data, epoch_no)
  File "/home/lcur0006/joeynmt/joeynmt/training.py", line 642, in _validate
    references=valid_references)
  File "/home/lcur0006/joeynmt/joeynmt/training.py", line 731, in _log_examples
    logger.debug("\tRaw source:     %s", sources_raw[p])
Message: '\tRaw source:     %s'
Arguments: (['\u0e1e', '\u0e48', '\u0e2d\u0e02\u0e2d\u0e07@@', '\u0e09\u0e31\u0e19@@', '\u0e01\u0e33\u0e25\u0e31\u0e07@@', '\u0e1f\u0e31\u0e07@@', '\u0e02', '\u0e48', '\u0e32\u0e27@@', '\u0e1a\u0e35@@', '\u0e1a\u0e35@@', '\u0e0b\u0e35', '\u0e08\u0e32\u0e01@@', '\u0e27\u0e34\u0e17@@', '\u0e22\u0e38@@', '\u0e2a\u0e35@@', '\u0e40\u0e17@@', '\u0e32@@', '\u0e2d\u0e31\u0e19@@', '\u0e40\u0e25', '\u0e47', '\u0e01'],)
--- Logging error ---
Traceback (most recent call last):
  File "/sw/arch/Debian10/EB_production/2019/software/Anaconda3/2018.12/lib/python3.7/logging/__init__.py", line 1036, in emit
    stream.write(msg)
UnicodeEncodeError: 'latin-1' codec can't encode character '\u0e1e' in position 65: ordinal not in range(256)
Call stack:
  File "/sw/arch/Debian10/EB_production/2019/software/Anaconda3/2018.12/lib/python3.7/runpy.py", line 193, in _run_module_as_main
    "__main__", mod_spec)
  File "/sw/arch/Debian10/EB_production/2019/software/Anaconda3/2018.12/lib/python3.7/runpy.py", line 85, in _run_code
    exec(code, run_globals)
  File "/home/lcur0006/joeynmt/joeynmt/__main__.py", line 48, in <module>
    main()
  File "/home/lcur0006/joeynmt/joeynmt/__main__.py", line 35, in main
    train(cfg_file=args.config_path, skip_test=args.skip_test)
  File "/home/lcur0006/joeynmt/joeynmt/training.py", line 846, in train
    trainer.train_and_validate(train_data=train_data, valid_data=dev_data)
  File "/home/lcur0006/joeynmt/joeynmt/training.py", line 497, in train_and_validate
    valid_duration = self._validate(valid_data, epoch_no)
  File "/home/lcur0006/joeynmt/joeynmt/training.py", line 642, in _validate
    references=valid_references)
  File "/home/lcur0006/joeynmt/joeynmt/training.py", line 737, in _log_examples
    logger.info("\tSource:     %s", sources[p])
Message: '\tSource:     %s'
Arguments: ('\u0e1e \u0e48 \u0e2d\u0e02\u0e2d\u0e07\u0e09\u0e31\u0e19\u0e01\u0e33\u0e25\u0e31\u0e07\u0e1f\u0e31\u0e07\u0e02 \u0e48 \u0e32\u0e27\u0e1a\u0e35\u0e1a\u0e35\u0e0b\u0e35 \u0e08\u0e32\u0e01\u0e27\u0e34\u0e17\u0e22\u0e38\u0e2a\u0e35\u0e40\u0e17\u0e32\u0e2d\u0e31\u0e19\u0e40\u0e25 \u0e47 \u0e01',)
2021-10-03 14:06:41,521 - INFO - joeynmt.training - 	Source:     \u0e1e \u0e48 \u0e2d\u0e02\u0e2d\u0e07\u0e09\u0e31\u0e19\u0e01\u0e33\u0e25\u0e31\u0e07\u0e1f\u0e31\u0e07\u0e02 \u0e48 \u0e32\u0e27\u0e1a\u0e35\u0e1a\u0e35\u0e0b\u0e35 \u0e08\u0e32\u0e01\u0e27\u0e34\u0e17\u0e22\u0e38\u0e2a\u0e35\u0e40\u0e17\u0e32\u0e2d\u0e31\u0e19\u0e40\u0e25 \u0e47 \u0e01
2021-10-03 14:06:41,522 - INFO - joeynmt.training - 	Reference:  "My father was listening to BBC News on his small , gray radio ."
2021-10-03 14:06:41,522 - INFO - joeynmt.training - 	Hypothesis: He was a very question in the Work of the Work .
2021-10-03 14:06:41,522 - INFO - joeynmt.training - Validation result (greedy) at epoch  19, step     1100: bleu:   4.00, loss: 75940.8125, ppl: 138.3714, duration: 3.9870s
2021-10-03 14:06:47,105 - INFO - joeynmt.training - Epoch  19: total training loss 4709.38
2021-10-03 14:06:47,106 - INFO - joeynmt.training - EPOCH 20
2021-10-03 14:06:58,488 - INFO - joeynmt.training - Epoch  20: total training loss 4626.45
2021-10-03 14:06:58,489 - INFO - joeynmt.training - Training ended after  20 epochs.
2021-10-03 14:06:58,489 - INFO - joeynmt.training - Best validation result (greedy) at step      900:   5.00 eval_metric.
2021-10-03 14:06:58,515 - INFO - joeynmt.prediction - Process device: cuda, n_gpu: 1, batch_size per device: 80
2021-10-03 14:06:58,515 - INFO - joeynmt.prediction - Loading model from models/LSTM_th/900.ckpt
2021-10-03 14:06:58,706 - INFO - joeynmt.model - Building an encoder-decoder model...
2021-10-03 14:06:59,227 - INFO - joeynmt.model - Enc-dec model built.
2021-10-03 14:06:59,282 - INFO - joeynmt.prediction - Decoding on dev set (../2DL4NLP/all_data/th.en_s/val.bpe.en_s)...
2021-10-03 14:07:14,847 - WARNING - sacrebleu - That's 100 lines that end in a tokenized period ('.')
2021-10-03 14:07:14,847 - WARNING - sacrebleu - It looks like you forgot to detokenize your test data, which may hurt your score.
2021-10-03 14:07:14,847 - WARNING - sacrebleu - If you insist your data is detokenized, or don't care, you can suppress this message with the `force` parameter.
2021-10-03 14:07:14,851 - INFO - joeynmt.prediction -  dev bleu[13a]:   5.30 [Beam search decoding with beam size = 5 and alpha = 1.0]
2021-10-03 14:07:14,853 - INFO - joeynmt.prediction - Translations saved to: models/LSTM_th/00000900.hyps.dev
2021-10-03 14:07:14,854 - INFO - joeynmt.prediction - Decoding on test set (../2DL4NLP/all_data/th.en_s/test.bpe.en_s)...
2021-10-03 14:07:31,768 - WARNING - sacrebleu - That's 100 lines that end in a tokenized period ('.')
2021-10-03 14:07:31,769 - WARNING - sacrebleu - It looks like you forgot to detokenize your test data, which may hurt your score.
2021-10-03 14:07:31,769 - WARNING - sacrebleu - If you insist your data is detokenized, or don't care, you can suppress this message with the `force` parameter.
2021-10-03 14:07:31,773 - INFO - joeynmt.prediction - test bleu[13a]:   6.07 [Beam search decoding with beam size = 5 and alpha = 1.0]
2021-10-03 14:07:31,776 - INFO - joeynmt.prediction - Translations saved to: models/LSTM_th/00000900.hyps.test
