2021-10-02 15:14:49,964 - INFO - root - Hello! This is Joey-NMT (version 1.3).
2021-10-02 15:14:50,035 - INFO - joeynmt.data - Loading training data...
2021-10-02 15:14:50,141 - INFO - joeynmt.data - Building vocabulary...
2021-10-02 15:14:50,595 - INFO - joeynmt.data - Loading dev data...
2021-10-02 15:14:50,608 - INFO - joeynmt.data - Loading test data...
2021-10-02 15:14:50,619 - INFO - joeynmt.data - Data loaded.
2021-10-02 15:14:50,620 - INFO - joeynmt.model - Building an encoder-decoder model...
2021-10-02 15:14:51,226 - INFO - joeynmt.model - Enc-dec model built.
2021-10-02 15:14:51,232 - INFO - joeynmt.training - Total params: 25523712
2021-10-02 15:14:55,568 - INFO - joeynmt.helpers - cfg.name                           : tr_en_bpe_model
2021-10-02 15:14:55,568 - INFO - joeynmt.helpers - cfg.data.src                       : tr
2021-10-02 15:14:55,568 - INFO - joeynmt.helpers - cfg.data.trg                       : en
2021-10-02 15:14:55,568 - INFO - joeynmt.helpers - cfg.data.train                     : ../2DL4NLP/all_data/train.bpe
2021-10-02 15:14:55,568 - INFO - joeynmt.helpers - cfg.data.dev                       : ../2DL4NLP/all_data/val.bpe
2021-10-02 15:14:55,568 - INFO - joeynmt.helpers - cfg.data.test                      : ../2DL4NLP/all_data/test.bpe
2021-10-02 15:14:55,568 - INFO - joeynmt.helpers - cfg.data.level                     : bpe
2021-10-02 15:14:55,568 - INFO - joeynmt.helpers - cfg.data.lowercase                 : False
2021-10-02 15:14:55,568 - INFO - joeynmt.helpers - cfg.data.max_sent_length           : 50
2021-10-02 15:14:55,569 - INFO - joeynmt.helpers - cfg.data.src_voc_min_freq          : 0
2021-10-02 15:14:55,569 - INFO - joeynmt.helpers - cfg.data.src_voc_limit             : 10000
2021-10-02 15:14:55,569 - INFO - joeynmt.helpers - cfg.data.trg_voc_min_freq          : 0
2021-10-02 15:14:55,569 - INFO - joeynmt.helpers - cfg.data.trg_voc_limit             : 10000
2021-10-02 15:14:55,569 - INFO - joeynmt.helpers - cfg.data.src_vocab                 : ../2DL4NLP/all_data/tr_en_vocab.txt
2021-10-02 15:14:55,569 - INFO - joeynmt.helpers - cfg.data.trg_vocab                 : ../2DL4NLP/all_data/tr_en_vocab.txt
2021-10-02 15:14:55,569 - INFO - joeynmt.helpers - cfg.testing.beam_size              : 5
2021-10-02 15:14:55,569 - INFO - joeynmt.helpers - cfg.testing.alpha                  : 1.0
2021-10-02 15:14:55,569 - INFO - joeynmt.helpers - cfg.testing.sacrebleu.remove_whitespace : True
2021-10-02 15:14:55,569 - INFO - joeynmt.helpers - cfg.testing.sacrebleu.tokenize     : none
2021-10-02 15:14:55,569 - INFO - joeynmt.helpers - cfg.training.random_seed           : 42
2021-10-02 15:14:55,569 - INFO - joeynmt.helpers - cfg.training.optimizer             : adam
2021-10-02 15:14:55,569 - INFO - joeynmt.helpers - cfg.training.weight_decay          : 0.0
2021-10-02 15:14:55,569 - INFO - joeynmt.helpers - cfg.training.batch_size            : 80
2021-10-02 15:14:55,569 - INFO - joeynmt.helpers - cfg.training.scheduling            : plateau
2021-10-02 15:14:55,569 - INFO - joeynmt.helpers - cfg.training.patience              : 1
2021-10-02 15:14:55,570 - INFO - joeynmt.helpers - cfg.training.early_stopping_metric : eval_metric
2021-10-02 15:14:55,570 - INFO - joeynmt.helpers - cfg.training.epochs                : 100
2021-10-02 15:14:55,570 - INFO - joeynmt.helpers - cfg.training.validation_freq       : 100
2021-10-02 15:14:55,570 - INFO - joeynmt.helpers - cfg.training.logging_freq          : 1000
2021-10-02 15:14:55,570 - INFO - joeynmt.helpers - cfg.training.eval_metric           : bleu
2021-10-02 15:14:55,570 - INFO - joeynmt.helpers - cfg.training.model_dir             : models/tr_en_bpe_model
2021-10-02 15:14:55,570 - INFO - joeynmt.helpers - cfg.training.overwrite             : True
2021-10-02 15:14:55,570 - INFO - joeynmt.helpers - cfg.training.shuffle               : True
2021-10-02 15:14:55,570 - INFO - joeynmt.helpers - cfg.training.use_cuda              : True
2021-10-02 15:14:55,570 - INFO - joeynmt.helpers - cfg.training.max_output_length     : 60
2021-10-02 15:14:55,570 - INFO - joeynmt.helpers - cfg.training.print_valid_sents     : [0, 1, 2]
2021-10-02 15:14:55,570 - INFO - joeynmt.helpers - cfg.model.encoder.rnn_type         : lstm
2021-10-02 15:14:55,570 - INFO - joeynmt.helpers - cfg.model.encoder.embeddings.embedding_dim : 512
2021-10-02 15:14:55,570 - INFO - joeynmt.helpers - cfg.model.encoder.embeddings.scale : False
2021-10-02 15:14:55,570 - INFO - joeynmt.helpers - cfg.model.encoder.hidden_size      : 512
2021-10-02 15:14:55,570 - INFO - joeynmt.helpers - cfg.model.encoder.bidirectional    : False
2021-10-02 15:14:55,571 - INFO - joeynmt.helpers - cfg.model.encoder.dropout          : 0.2
2021-10-02 15:14:55,571 - INFO - joeynmt.helpers - cfg.model.encoder.num_layers       : 4
2021-10-02 15:14:55,571 - INFO - joeynmt.helpers - cfg.model.decoder.rnn_type         : lstm
2021-10-02 15:14:55,571 - INFO - joeynmt.helpers - cfg.model.decoder.embeddings.embedding_dim : 512
2021-10-02 15:14:55,571 - INFO - joeynmt.helpers - cfg.model.decoder.embeddings.scale : False
2021-10-02 15:14:55,571 - INFO - joeynmt.helpers - cfg.model.decoder.emb_scale        : False
2021-10-02 15:14:55,571 - INFO - joeynmt.helpers - cfg.model.decoder.hidden_size      : 512
2021-10-02 15:14:55,571 - INFO - joeynmt.helpers - cfg.model.decoder.dropout          : 0.2
2021-10-02 15:14:55,571 - INFO - joeynmt.helpers - cfg.model.decoder.hidden_dropout   : 0.2
2021-10-02 15:14:55,571 - INFO - joeynmt.helpers - cfg.model.decoder.num_layers       : 4
2021-10-02 15:14:55,571 - INFO - joeynmt.helpers - cfg.model.decoder.input_feeding    : True
2021-10-02 15:14:55,571 - INFO - joeynmt.helpers - cfg.model.decoder.init_hidden      : bridge
2021-10-02 15:14:55,571 - INFO - joeynmt.helpers - cfg.model.decoder.attention        : bahdanau
2021-10-02 15:14:55,571 - INFO - joeynmt.helpers - Data set sizes: 
	train 5177,
	valid 551,
	test 602
2021-10-02 15:14:55,571 - INFO - joeynmt.helpers - First training example:
	[SRC] tr
	[TRG] en
2021-10-02 15:14:55,572 - INFO - joeynmt.helpers - First 10 words (src): (0) <unk> (1) <pad> (2) <s> (3) </s> (4) , (5) . (6) ." (7) the (8) a (9) &quot;
2021-10-02 15:14:55,572 - INFO - joeynmt.helpers - First 10 words (trg): (0) <unk> (1) <pad> (2) <s> (3) </s> (4) , (5) . (6) ." (7) the (8) a (9) &quot;
2021-10-02 15:14:55,572 - INFO - joeynmt.helpers - Number of Src words (types): 4136
2021-10-02 15:14:55,572 - INFO - joeynmt.helpers - Number of Trg words (types): 4136
2021-10-02 15:14:55,572 - INFO - joeynmt.training - Model(
	encoder=RecurrentEncoder(LSTM(512, 512, num_layers=4, batch_first=True, dropout=0.2)),
	decoder=RecurrentDecoder(rnn=LSTM(1024, 512, num_layers=4, batch_first=True, dropout=0.2), attention=BahdanauAttention),
	src_embed=Embeddings(embedding_dim=512, vocab_size=4136),
	trg_embed=Embeddings(embedding_dim=512, vocab_size=4136))
2021-10-02 15:14:55,582 - INFO - joeynmt.training - Train stats:
	device: cuda
	n_gpu: 1
	16-bits training: False
	gradient accumulation: 1
	batch size per device: 80
	total batch size (w. parallel & accumulation): 80
2021-10-02 15:14:55,582 - INFO - joeynmt.training - EPOCH 1
2021-10-02 15:15:10,574 - INFO - joeynmt.training - Epoch   1: total training loss 9350.46
2021-10-02 15:15:10,575 - INFO - joeynmt.training - EPOCH 2
2021-10-02 15:15:20,146 - INFO - joeynmt.training - Hooray! New best validation result [eval_metric]!
2021-10-02 15:15:21,078 - INFO - joeynmt.training - Example #0
2021-10-02 15:15:21,079 - INFO - joeynmt.training - 	Source:     tr
2021-10-02 15:15:21,079 - INFO - joeynmt.training - 	Reference:  en
2021-10-02 15:15:21,079 - INFO - joeynmt.training - 	Hypothesis: the
2021-10-02 15:15:21,079 - INFO - joeynmt.training - Example #1
--- Logging error ---
Traceback (most recent call last):
  File "/sw/arch/Debian10/EB_production/2019/software/Anaconda3/2018.12/lib/python3.7/logging/__init__.py", line 1036, in emit
    stream.write(msg)
UnicodeEncodeError: 'latin-1' codec can't encode character '\u015f' in position 86: ordinal not in range(256)
Call stack:
  File "/sw/arch/Debian10/EB_production/2019/software/Anaconda3/2018.12/lib/python3.7/runpy.py", line 193, in _run_module_as_main
    "__main__", mod_spec)
  File "/sw/arch/Debian10/EB_production/2019/software/Anaconda3/2018.12/lib/python3.7/runpy.py", line 85, in _run_code
    exec(code, run_globals)
  File "/home/lcur0008/joeynmt/joeynmt/__main__.py", line 48, in <module>
    main()
  File "/home/lcur0008/joeynmt/joeynmt/__main__.py", line 35, in main
    train(cfg_file=args.config_path, skip_test=args.skip_test)
  File "/home/lcur0008/joeynmt/joeynmt/training.py", line 846, in train
    trainer.train_and_validate(train_data=train_data, valid_data=dev_data)
  File "/home/lcur0008/joeynmt/joeynmt/training.py", line 497, in train_and_validate
    valid_duration = self._validate(valid_data, epoch_no)
  File "/home/lcur0008/joeynmt/joeynmt/training.py", line 642, in _validate
    references=valid_references)
  File "/home/lcur0008/joeynmt/joeynmt/training.py", line 731, in _log_examples
    logger.debug("\tRaw source:     %s", sources_raw[p])
Message: '\tRaw source:     %s'
Arguments: (['1@@', '1', 'ya\u015f@@', '\u0131nday@@', 'ken', 'bir', 'sa@@', 'ba@@', 'h', 'ev@@', 'im@@', 'deki', 'sev@@', 'in@@', 'ç', 'ç@@', '\u0131\u011f@@', 'l\u0131@@', 'klar@@', '\u0131yla', 'u@@', 'yan@@', 'd\u0131\u011f@@', '\u0131m\u0131', 'hat\u0131r@@', 'l\u0131@@', 'yorum', '.'],)
--- Logging error ---
Traceback (most recent call last):
  File "/sw/arch/Debian10/EB_production/2019/software/Anaconda3/2018.12/lib/python3.7/logging/__init__.py", line 1036, in emit
    stream.write(msg)
UnicodeEncodeError: 'latin-1' codec can't encode characters in position 70-71: ordinal not in range(256)
Call stack:
  File "/sw/arch/Debian10/EB_production/2019/software/Anaconda3/2018.12/lib/python3.7/runpy.py", line 193, in _run_module_as_main
    "__main__", mod_spec)
  File "/sw/arch/Debian10/EB_production/2019/software/Anaconda3/2018.12/lib/python3.7/runpy.py", line 85, in _run_code
    exec(code, run_globals)
  File "/home/lcur0008/joeynmt/joeynmt/__main__.py", line 48, in <module>
    main()
  File "/home/lcur0008/joeynmt/joeynmt/__main__.py", line 35, in main
    train(cfg_file=args.config_path, skip_test=args.skip_test)
  File "/home/lcur0008/joeynmt/joeynmt/training.py", line 846, in train
    trainer.train_and_validate(train_data=train_data, valid_data=dev_data)
  File "/home/lcur0008/joeynmt/joeynmt/training.py", line 497, in train_and_validate
    valid_duration = self._validate(valid_data, epoch_no)
  File "/home/lcur0008/joeynmt/joeynmt/training.py", line 642, in _validate
    references=valid_references)
  File "/home/lcur0008/joeynmt/joeynmt/training.py", line 737, in _log_examples
    logger.info("\tSource:     %s", sources[p])
Message: '\tSource:     %s'
Arguments: ('11 ya\u015f\u0131ndayken bir sabah evimdeki sevinç ç\u0131\u011fl\u0131klar\u0131yla uyand\u0131\u011f\u0131m\u0131 hat\u0131rl\u0131yorum .',)
2021-10-02 15:15:21,083 - INFO - joeynmt.training - 	Source:     11 ya\u015f\u0131ndayken bir sabah evimdeki sevinç ç\u0131\u011fl\u0131klar\u0131yla uyand\u0131\u011f\u0131m\u0131 hat\u0131rl\u0131yorum .
2021-10-02 15:15:21,084 - INFO - joeynmt.training - 	Reference:  "When I was 11 , I remember waking up one morning to the sound of joy in my house ."
2021-10-02 15:15:21,084 - INFO - joeynmt.training - 	Hypothesis: "And I , , , , , , , , , , , , , , , , , , , , , , , ,
2021-10-02 15:15:21,084 - INFO - joeynmt.training - Example #2
--- Logging error ---
Traceback (most recent call last):
  File "/sw/arch/Debian10/EB_production/2019/software/Anaconda3/2018.12/lib/python3.7/logging/__init__.py", line 1036, in emit
    stream.write(msg)
UnicodeEncodeError: 'latin-1' codec can't encode character '\u0131' in position 151: ordinal not in range(256)
Call stack:
  File "/sw/arch/Debian10/EB_production/2019/software/Anaconda3/2018.12/lib/python3.7/runpy.py", line 193, in _run_module_as_main
    "__main__", mod_spec)
  File "/sw/arch/Debian10/EB_production/2019/software/Anaconda3/2018.12/lib/python3.7/runpy.py", line 85, in _run_code
    exec(code, run_globals)
  File "/home/lcur0008/joeynmt/joeynmt/__main__.py", line 48, in <module>
    main()
  File "/home/lcur0008/joeynmt/joeynmt/__main__.py", line 35, in main
    train(cfg_file=args.config_path, skip_test=args.skip_test)
  File "/home/lcur0008/joeynmt/joeynmt/training.py", line 846, in train
    trainer.train_and_validate(train_data=train_data, valid_data=dev_data)
  File "/home/lcur0008/joeynmt/joeynmt/training.py", line 497, in train_and_validate
    valid_duration = self._validate(valid_data, epoch_no)
  File "/home/lcur0008/joeynmt/joeynmt/training.py", line 642, in _validate
    references=valid_references)
  File "/home/lcur0008/joeynmt/joeynmt/training.py", line 731, in _log_examples
    logger.debug("\tRaw source:     %s", sources_raw[p])
Message: '\tRaw source:     %s'
Arguments: (['"B@@', 'ab@@', 'am', 'B@@', 'B@@', 'C', 'H@@', 'ab@@', 'er', 'kan@@', 'al@@', '\u0131n\u0131', 'din@@', 'li@@', 'yordu', ';', 'o', 'uf@@', 'ak', ',', 'gr@@', 'i', 'rad@@', 'y@@', 'os@@', 'undan', '."'],)
--- Logging error ---
Traceback (most recent call last):
  File "/sw/arch/Debian10/EB_production/2019/software/Anaconda3/2018.12/lib/python3.7/logging/__init__.py", line 1036, in emit
    stream.write(msg)
UnicodeEncodeError: 'latin-1' codec can't encode character '\u0131' in position 87: ordinal not in range(256)
Call stack:
  File "/sw/arch/Debian10/EB_production/2019/software/Anaconda3/2018.12/lib/python3.7/runpy.py", line 193, in _run_module_as_main
    "__main__", mod_spec)
  File "/sw/arch/Debian10/EB_production/2019/software/Anaconda3/2018.12/lib/python3.7/runpy.py", line 85, in _run_code
    exec(code, run_globals)
  File "/home/lcur0008/joeynmt/joeynmt/__main__.py", line 48, in <module>
    main()
  File "/home/lcur0008/joeynmt/joeynmt/__main__.py", line 35, in main
    train(cfg_file=args.config_path, skip_test=args.skip_test)
  File "/home/lcur0008/joeynmt/joeynmt/training.py", line 846, in train
    trainer.train_and_validate(train_data=train_data, valid_data=dev_data)
  File "/home/lcur0008/joeynmt/joeynmt/training.py", line 497, in train_and_validate
    valid_duration = self._validate(valid_data, epoch_no)
  File "/home/lcur0008/joeynmt/joeynmt/training.py", line 642, in _validate
    references=valid_references)
  File "/home/lcur0008/joeynmt/joeynmt/training.py", line 737, in _log_examples
    logger.info("\tSource:     %s", sources[p])
Message: '\tSource:     %s'
Arguments: ('"Babam BBC Haber kanal\u0131n\u0131 dinliyordu ; o ufak , gri radyosundan ."',)
2021-10-02 15:15:21,084 - INFO - joeynmt.training - 	Source:     "Babam BBC Haber kanal\u0131n\u0131 dinliyordu ; o ufak , gri radyosundan ."
2021-10-02 15:15:21,085 - INFO - joeynmt.training - 	Reference:  "My father was listening to BBC News on his small , gray radio ."
2021-10-02 15:15:21,085 - INFO - joeynmt.training - 	Hypothesis: "And I , , , , , , , , , , , , , , , , , , , , , ,
2021-10-02 15:15:21,085 - INFO - joeynmt.training - Validation result (greedy) at epoch   2, step      100: bleu:   0.05, loss: 94890.3125, ppl: 517.6822, duration: 2.4967s
2021-10-02 15:15:29,439 - INFO - joeynmt.training - Epoch   2: total training loss 8666.36
2021-10-02 15:15:29,439 - INFO - joeynmt.training - EPOCH 3
2021-10-02 15:15:44,293 - INFO - joeynmt.training - Epoch   3: total training loss 8545.80
2021-10-02 15:15:44,294 - INFO - joeynmt.training - EPOCH 4
2021-10-02 15:15:47,248 - WARNING - sacrebleu - That's 100 lines that end in a tokenized period ('.')
2021-10-02 15:15:47,248 - WARNING - sacrebleu - It looks like you forgot to detokenize your test data, which may hurt your score.
2021-10-02 15:15:47,248 - WARNING - sacrebleu - If you insist your data is detokenized, or don't care, you can suppress this message with the `force` parameter.
2021-10-02 15:15:47,253 - INFO - joeynmt.training - Hooray! New best validation result [eval_metric]!
2021-10-02 15:15:48,156 - INFO - joeynmt.training - Example #0
2021-10-02 15:15:48,157 - INFO - joeynmt.training - 	Source:     tr
2021-10-02 15:15:48,157 - INFO - joeynmt.training - 	Reference:  en
2021-10-02 15:15:48,157 - INFO - joeynmt.training - 	Hypothesis: I .
2021-10-02 15:15:48,157 - INFO - joeynmt.training - Example #1
--- Logging error ---
Traceback (most recent call last):
  File "/sw/arch/Debian10/EB_production/2019/software/Anaconda3/2018.12/lib/python3.7/logging/__init__.py", line 1036, in emit
    stream.write(msg)
UnicodeEncodeError: 'latin-1' codec can't encode character '\u015f' in position 86: ordinal not in range(256)
Call stack:
  File "/sw/arch/Debian10/EB_production/2019/software/Anaconda3/2018.12/lib/python3.7/runpy.py", line 193, in _run_module_as_main
    "__main__", mod_spec)
  File "/sw/arch/Debian10/EB_production/2019/software/Anaconda3/2018.12/lib/python3.7/runpy.py", line 85, in _run_code
    exec(code, run_globals)
  File "/home/lcur0008/joeynmt/joeynmt/__main__.py", line 48, in <module>
    main()
  File "/home/lcur0008/joeynmt/joeynmt/__main__.py", line 35, in main
    train(cfg_file=args.config_path, skip_test=args.skip_test)
  File "/home/lcur0008/joeynmt/joeynmt/training.py", line 846, in train
    trainer.train_and_validate(train_data=train_data, valid_data=dev_data)
  File "/home/lcur0008/joeynmt/joeynmt/training.py", line 497, in train_and_validate
    valid_duration = self._validate(valid_data, epoch_no)
  File "/home/lcur0008/joeynmt/joeynmt/training.py", line 642, in _validate
    references=valid_references)
  File "/home/lcur0008/joeynmt/joeynmt/training.py", line 731, in _log_examples
    logger.debug("\tRaw source:     %s", sources_raw[p])
Message: '\tRaw source:     %s'
Arguments: (['1@@', '1', 'ya\u015f@@', '\u0131nday@@', 'ken', 'bir', 'sa@@', 'ba@@', 'h', 'ev@@', 'im@@', 'deki', 'sev@@', 'in@@', 'ç', 'ç@@', '\u0131\u011f@@', 'l\u0131@@', 'klar@@', '\u0131yla', 'u@@', 'yan@@', 'd\u0131\u011f@@', '\u0131m\u0131', 'hat\u0131r@@', 'l\u0131@@', 'yorum', '.'],)
--- Logging error ---
Traceback (most recent call last):
  File "/sw/arch/Debian10/EB_production/2019/software/Anaconda3/2018.12/lib/python3.7/logging/__init__.py", line 1036, in emit
    stream.write(msg)
UnicodeEncodeError: 'latin-1' codec can't encode characters in position 70-71: ordinal not in range(256)
Call stack:
  File "/sw/arch/Debian10/EB_production/2019/software/Anaconda3/2018.12/lib/python3.7/runpy.py", line 193, in _run_module_as_main
    "__main__", mod_spec)
  File "/sw/arch/Debian10/EB_production/2019/software/Anaconda3/2018.12/lib/python3.7/runpy.py", line 85, in _run_code
    exec(code, run_globals)
  File "/home/lcur0008/joeynmt/joeynmt/__main__.py", line 48, in <module>
    main()
  File "/home/lcur0008/joeynmt/joeynmt/__main__.py", line 35, in main
    train(cfg_file=args.config_path, skip_test=args.skip_test)
  File "/home/lcur0008/joeynmt/joeynmt/training.py", line 846, in train
    trainer.train_and_validate(train_data=train_data, valid_data=dev_data)
  File "/home/lcur0008/joeynmt/joeynmt/training.py", line 497, in train_and_validate
    valid_duration = self._validate(valid_data, epoch_no)
  File "/home/lcur0008/joeynmt/joeynmt/training.py", line 642, in _validate
    references=valid_references)
  File "/home/lcur0008/joeynmt/joeynmt/training.py", line 737, in _log_examples
    logger.info("\tSource:     %s", sources[p])
Message: '\tSource:     %s'
Arguments: ('11 ya\u015f\u0131ndayken bir sabah evimdeki sevinç ç\u0131\u011fl\u0131klar\u0131yla uyand\u0131\u011f\u0131m\u0131 hat\u0131rl\u0131yorum .',)
2021-10-02 15:15:48,160 - INFO - joeynmt.training - 	Source:     11 ya\u015f\u0131ndayken bir sabah evimdeki sevinç ç\u0131\u011fl\u0131klar\u0131yla uyand\u0131\u011f\u0131m\u0131 hat\u0131rl\u0131yorum .
2021-10-02 15:15:48,161 - INFO - joeynmt.training - 	Reference:  "When I was 11 , I remember waking up one morning to the sound of joy in my house ."
2021-10-02 15:15:48,161 - INFO - joeynmt.training - 	Hypothesis: "And I the , , , , , , , , , , , , , , , , , , , ,
2021-10-02 15:15:48,161 - INFO - joeynmt.training - Example #2
--- Logging error ---
Traceback (most recent call last):
  File "/sw/arch/Debian10/EB_production/2019/software/Anaconda3/2018.12/lib/python3.7/logging/__init__.py", line 1036, in emit
    stream.write(msg)
UnicodeEncodeError: 'latin-1' codec can't encode character '\u0131' in position 151: ordinal not in range(256)
Call stack:
  File "/sw/arch/Debian10/EB_production/2019/software/Anaconda3/2018.12/lib/python3.7/runpy.py", line 193, in _run_module_as_main
    "__main__", mod_spec)
  File "/sw/arch/Debian10/EB_production/2019/software/Anaconda3/2018.12/lib/python3.7/runpy.py", line 85, in _run_code
    exec(code, run_globals)
  File "/home/lcur0008/joeynmt/joeynmt/__main__.py", line 48, in <module>
    main()
  File "/home/lcur0008/joeynmt/joeynmt/__main__.py", line 35, in main
    train(cfg_file=args.config_path, skip_test=args.skip_test)
  File "/home/lcur0008/joeynmt/joeynmt/training.py", line 846, in train
    trainer.train_and_validate(train_data=train_data, valid_data=dev_data)
  File "/home/lcur0008/joeynmt/joeynmt/training.py", line 497, in train_and_validate
    valid_duration = self._validate(valid_data, epoch_no)
  File "/home/lcur0008/joeynmt/joeynmt/training.py", line 642, in _validate
    references=valid_references)
  File "/home/lcur0008/joeynmt/joeynmt/training.py", line 731, in _log_examples
    logger.debug("\tRaw source:     %s", sources_raw[p])
Message: '\tRaw source:     %s'
Arguments: (['"B@@', 'ab@@', 'am', 'B@@', 'B@@', 'C', 'H@@', 'ab@@', 'er', 'kan@@', 'al@@', '\u0131n\u0131', 'din@@', 'li@@', 'yordu', ';', 'o', 'uf@@', 'ak', ',', 'gr@@', 'i', 'rad@@', 'y@@', 'os@@', 'undan', '."'],)
--- Logging error ---
Traceback (most recent call last):
  File "/sw/arch/Debian10/EB_production/2019/software/Anaconda3/2018.12/lib/python3.7/logging/__init__.py", line 1036, in emit
    stream.write(msg)
UnicodeEncodeError: 'latin-1' codec can't encode character '\u0131' in position 87: ordinal not in range(256)
Call stack:
  File "/sw/arch/Debian10/EB_production/2019/software/Anaconda3/2018.12/lib/python3.7/runpy.py", line 193, in _run_module_as_main
    "__main__", mod_spec)
  File "/sw/arch/Debian10/EB_production/2019/software/Anaconda3/2018.12/lib/python3.7/runpy.py", line 85, in _run_code
    exec(code, run_globals)
  File "/home/lcur0008/joeynmt/joeynmt/__main__.py", line 48, in <module>
    main()
  File "/home/lcur0008/joeynmt/joeynmt/__main__.py", line 35, in main
    train(cfg_file=args.config_path, skip_test=args.skip_test)
  File "/home/lcur0008/joeynmt/joeynmt/training.py", line 846, in train
    trainer.train_and_validate(train_data=train_data, valid_data=dev_data)
  File "/home/lcur0008/joeynmt/joeynmt/training.py", line 497, in train_and_validate
    valid_duration = self._validate(valid_data, epoch_no)
  File "/home/lcur0008/joeynmt/joeynmt/training.py", line 642, in _validate
    references=valid_references)
  File "/home/lcur0008/joeynmt/joeynmt/training.py", line 737, in _log_examples
    logger.info("\tSource:     %s", sources[p])
Message: '\tSource:     %s'
Arguments: ('"Babam BBC Haber kanal\u0131n\u0131 dinliyordu ; o ufak , gri radyosundan ."',)
2021-10-02 15:15:48,162 - INFO - joeynmt.training - 	Source:     "Babam BBC Haber kanal\u0131n\u0131 dinliyordu ; o ufak , gri radyosundan ."
2021-10-02 15:15:48,162 - INFO - joeynmt.training - 	Reference:  "My father was listening to BBC News on his small , gray radio ."
2021-10-02 15:15:48,163 - INFO - joeynmt.training - 	Hypothesis: "And I the , , , , , , , , , , , , , , the
2021-10-02 15:15:48,163 - INFO - joeynmt.training - Validation result (greedy) at epoch   4, step      200: bleu:   0.06, loss: 94066.1562, ppl: 490.3324, duration: 2.6546s
2021-10-02 15:16:02,888 - INFO - joeynmt.training - Epoch   4: total training loss 8483.79
2021-10-02 15:16:02,889 - INFO - joeynmt.training - EPOCH 5
2021-10-02 15:16:13,579 - WARNING - sacrebleu - That's 100 lines that end in a tokenized period ('.')
2021-10-02 15:16:13,579 - WARNING - sacrebleu - It looks like you forgot to detokenize your test data, which may hurt your score.
2021-10-02 15:16:13,579 - WARNING - sacrebleu - If you insist your data is detokenized, or don't care, you can suppress this message with the `force` parameter.
2021-10-02 15:16:14,803 - INFO - joeynmt.training - Example #0
2021-10-02 15:16:14,803 - INFO - joeynmt.training - 	Source:     tr
2021-10-02 15:16:14,804 - INFO - joeynmt.training - 	Reference:  en
2021-10-02 15:16:14,804 - INFO - joeynmt.training - 	Hypothesis: ( .
2021-10-02 15:16:14,804 - INFO - joeynmt.training - Example #1
--- Logging error ---
Traceback (most recent call last):
  File "/sw/arch/Debian10/EB_production/2019/software/Anaconda3/2018.12/lib/python3.7/logging/__init__.py", line 1036, in emit
    stream.write(msg)
UnicodeEncodeError: 'latin-1' codec can't encode character '\u015f' in position 86: ordinal not in range(256)
Call stack:
  File "/sw/arch/Debian10/EB_production/2019/software/Anaconda3/2018.12/lib/python3.7/runpy.py", line 193, in _run_module_as_main
    "__main__", mod_spec)
  File "/sw/arch/Debian10/EB_production/2019/software/Anaconda3/2018.12/lib/python3.7/runpy.py", line 85, in _run_code
    exec(code, run_globals)
  File "/home/lcur0008/joeynmt/joeynmt/__main__.py", line 48, in <module>
    main()
  File "/home/lcur0008/joeynmt/joeynmt/__main__.py", line 35, in main
    train(cfg_file=args.config_path, skip_test=args.skip_test)
  File "/home/lcur0008/joeynmt/joeynmt/training.py", line 846, in train
    trainer.train_and_validate(train_data=train_data, valid_data=dev_data)
  File "/home/lcur0008/joeynmt/joeynmt/training.py", line 497, in train_and_validate
    valid_duration = self._validate(valid_data, epoch_no)
  File "/home/lcur0008/joeynmt/joeynmt/training.py", line 642, in _validate
    references=valid_references)
  File "/home/lcur0008/joeynmt/joeynmt/training.py", line 731, in _log_examples
    logger.debug("\tRaw source:     %s", sources_raw[p])
Message: '\tRaw source:     %s'
Arguments: (['1@@', '1', 'ya\u015f@@', '\u0131nday@@', 'ken', 'bir', 'sa@@', 'ba@@', 'h', 'ev@@', 'im@@', 'deki', 'sev@@', 'in@@', 'ç', 'ç@@', '\u0131\u011f@@', 'l\u0131@@', 'klar@@', '\u0131yla', 'u@@', 'yan@@', 'd\u0131\u011f@@', '\u0131m\u0131', 'hat\u0131r@@', 'l\u0131@@', 'yorum', '.'],)
--- Logging error ---
Traceback (most recent call last):
  File "/sw/arch/Debian10/EB_production/2019/software/Anaconda3/2018.12/lib/python3.7/logging/__init__.py", line 1036, in emit
    stream.write(msg)
UnicodeEncodeError: 'latin-1' codec can't encode characters in position 70-71: ordinal not in range(256)
Call stack:
  File "/sw/arch/Debian10/EB_production/2019/software/Anaconda3/2018.12/lib/python3.7/runpy.py", line 193, in _run_module_as_main
    "__main__", mod_spec)
  File "/sw/arch/Debian10/EB_production/2019/software/Anaconda3/2018.12/lib/python3.7/runpy.py", line 85, in _run_code
    exec(code, run_globals)
  File "/home/lcur0008/joeynmt/joeynmt/__main__.py", line 48, in <module>
    main()
  File "/home/lcur0008/joeynmt/joeynmt/__main__.py", line 35, in main
    train(cfg_file=args.config_path, skip_test=args.skip_test)
  File "/home/lcur0008/joeynmt/joeynmt/training.py", line 846, in train
    trainer.train_and_validate(train_data=train_data, valid_data=dev_data)
  File "/home/lcur0008/joeynmt/joeynmt/training.py", line 497, in train_and_validate
    valid_duration = self._validate(valid_data, epoch_no)
  File "/home/lcur0008/joeynmt/joeynmt/training.py", line 642, in _validate
    references=valid_references)
  File "/home/lcur0008/joeynmt/joeynmt/training.py", line 737, in _log_examples
    logger.info("\tSource:     %s", sources[p])
Message: '\tSource:     %s'
Arguments: ('11 ya\u015f\u0131ndayken bir sabah evimdeki sevinç ç\u0131\u011fl\u0131klar\u0131yla uyand\u0131\u011f\u0131m\u0131 hat\u0131rl\u0131yorum .',)
2021-10-02 15:16:14,805 - INFO - joeynmt.training - 	Source:     11 ya\u015f\u0131ndayken bir sabah evimdeki sevinç ç\u0131\u011fl\u0131klar\u0131yla uyand\u0131\u011f\u0131m\u0131 hat\u0131rl\u0131yorum .
2021-10-02 15:16:14,806 - INFO - joeynmt.training - 	Reference:  "When I was 11 , I remember waking up one morning to the sound of joy in my house ."
2021-10-02 15:16:14,806 - INFO - joeynmt.training - 	Hypothesis: "And &apos;s , , , , , , , , , , , , , , , , , , , , , , , , ,
2021-10-02 15:16:14,806 - INFO - joeynmt.training - Example #2
--- Logging error ---
Traceback (most recent call last):
  File "/sw/arch/Debian10/EB_production/2019/software/Anaconda3/2018.12/lib/python3.7/logging/__init__.py", line 1036, in emit
    stream.write(msg)
UnicodeEncodeError: 'latin-1' codec can't encode character '\u0131' in position 151: ordinal not in range(256)
Call stack:
  File "/sw/arch/Debian10/EB_production/2019/software/Anaconda3/2018.12/lib/python3.7/runpy.py", line 193, in _run_module_as_main
    "__main__", mod_spec)
  File "/sw/arch/Debian10/EB_production/2019/software/Anaconda3/2018.12/lib/python3.7/runpy.py", line 85, in _run_code
    exec(code, run_globals)
  File "/home/lcur0008/joeynmt/joeynmt/__main__.py", line 48, in <module>
    main()
  File "/home/lcur0008/joeynmt/joeynmt/__main__.py", line 35, in main
    train(cfg_file=args.config_path, skip_test=args.skip_test)
  File "/home/lcur0008/joeynmt/joeynmt/training.py", line 846, in train
    trainer.train_and_validate(train_data=train_data, valid_data=dev_data)
  File "/home/lcur0008/joeynmt/joeynmt/training.py", line 497, in train_and_validate
    valid_duration = self._validate(valid_data, epoch_no)
  File "/home/lcur0008/joeynmt/joeynmt/training.py", line 642, in _validate
    references=valid_references)
  File "/home/lcur0008/joeynmt/joeynmt/training.py", line 731, in _log_examples
    logger.debug("\tRaw source:     %s", sources_raw[p])
Message: '\tRaw source:     %s'
Arguments: (['"B@@', 'ab@@', 'am', 'B@@', 'B@@', 'C', 'H@@', 'ab@@', 'er', 'kan@@', 'al@@', '\u0131n\u0131', 'din@@', 'li@@', 'yordu', ';', 'o', 'uf@@', 'ak', ',', 'gr@@', 'i', 'rad@@', 'y@@', 'os@@', 'undan', '."'],)
--- Logging error ---
Traceback (most recent call last):
  File "/sw/arch/Debian10/EB_production/2019/software/Anaconda3/2018.12/lib/python3.7/logging/__init__.py", line 1036, in emit
    stream.write(msg)
UnicodeEncodeError: 'latin-1' codec can't encode character '\u0131' in position 87: ordinal not in range(256)
Call stack:
  File "/sw/arch/Debian10/EB_production/2019/software/Anaconda3/2018.12/lib/python3.7/runpy.py", line 193, in _run_module_as_main
    "__main__", mod_spec)
  File "/sw/arch/Debian10/EB_production/2019/software/Anaconda3/2018.12/lib/python3.7/runpy.py", line 85, in _run_code
    exec(code, run_globals)
  File "/home/lcur0008/joeynmt/joeynmt/__main__.py", line 48, in <module>
    main()
  File "/home/lcur0008/joeynmt/joeynmt/__main__.py", line 35, in main
    train(cfg_file=args.config_path, skip_test=args.skip_test)
  File "/home/lcur0008/joeynmt/joeynmt/training.py", line 846, in train
    trainer.train_and_validate(train_data=train_data, valid_data=dev_data)
  File "/home/lcur0008/joeynmt/joeynmt/training.py", line 497, in train_and_validate
    valid_duration = self._validate(valid_data, epoch_no)
  File "/home/lcur0008/joeynmt/joeynmt/training.py", line 642, in _validate
    references=valid_references)
  File "/home/lcur0008/joeynmt/joeynmt/training.py", line 737, in _log_examples
    logger.info("\tSource:     %s", sources[p])
Message: '\tSource:     %s'
Arguments: ('"Babam BBC Haber kanal\u0131n\u0131 dinliyordu ; o ufak , gri radyosundan ."',)
2021-10-02 15:16:14,807 - INFO - joeynmt.training - 	Source:     "Babam BBC Haber kanal\u0131n\u0131 dinliyordu ; o ufak , gri radyosundan ."
2021-10-02 15:16:14,808 - INFO - joeynmt.training - 	Reference:  "My father was listening to BBC News on his small , gray radio ."
2021-10-02 15:16:14,808 - INFO - joeynmt.training - 	Hypothesis: And &apos;s the the , , , , , , , , , , the the
2021-10-02 15:16:14,808 - INFO - joeynmt.training - Validation result (greedy) at epoch   5, step      300: bleu:   0.06, loss: 93886.2500, ppl: 484.5570, duration: 2.8302s
2021-10-02 15:16:21,772 - INFO - joeynmt.training - Epoch   5: total training loss 8457.20
2021-10-02 15:16:21,772 - INFO - joeynmt.training - EPOCH 6
2021-10-02 15:16:36,372 - INFO - joeynmt.training - Epoch   6: total training loss 8424.38
2021-10-02 15:16:36,373 - INFO - joeynmt.training - EPOCH 7
2021-10-02 15:16:40,354 - WARNING - sacrebleu - That's 100 lines that end in a tokenized period ('.')
2021-10-02 15:16:40,354 - WARNING - sacrebleu - It looks like you forgot to detokenize your test data, which may hurt your score.
2021-10-02 15:16:40,354 - WARNING - sacrebleu - If you insist your data is detokenized, or don't care, you can suppress this message with the `force` parameter.
2021-10-02 15:16:41,372 - INFO - joeynmt.training - Example #0
2021-10-02 15:16:41,373 - INFO - joeynmt.training - 	Source:     tr
2021-10-02 15:16:41,373 - INFO - joeynmt.training - 	Reference:  en
2021-10-02 15:16:41,373 - INFO - joeynmt.training - 	Hypothesis: ( )
2021-10-02 15:16:41,373 - INFO - joeynmt.training - Example #1
--- Logging error ---
Traceback (most recent call last):
  File "/sw/arch/Debian10/EB_production/2019/software/Anaconda3/2018.12/lib/python3.7/logging/__init__.py", line 1036, in emit
    stream.write(msg)
UnicodeEncodeError: 'latin-1' codec can't encode character '\u015f' in position 86: ordinal not in range(256)
Call stack:
  File "/sw/arch/Debian10/EB_production/2019/software/Anaconda3/2018.12/lib/python3.7/runpy.py", line 193, in _run_module_as_main
    "__main__", mod_spec)
  File "/sw/arch/Debian10/EB_production/2019/software/Anaconda3/2018.12/lib/python3.7/runpy.py", line 85, in _run_code
    exec(code, run_globals)
  File "/home/lcur0008/joeynmt/joeynmt/__main__.py", line 48, in <module>
    main()
  File "/home/lcur0008/joeynmt/joeynmt/__main__.py", line 35, in main
    train(cfg_file=args.config_path, skip_test=args.skip_test)
  File "/home/lcur0008/joeynmt/joeynmt/training.py", line 846, in train
    trainer.train_and_validate(train_data=train_data, valid_data=dev_data)
  File "/home/lcur0008/joeynmt/joeynmt/training.py", line 497, in train_and_validate
    valid_duration = self._validate(valid_data, epoch_no)
  File "/home/lcur0008/joeynmt/joeynmt/training.py", line 642, in _validate
    references=valid_references)
  File "/home/lcur0008/joeynmt/joeynmt/training.py", line 731, in _log_examples
    logger.debug("\tRaw source:     %s", sources_raw[p])
Message: '\tRaw source:     %s'
Arguments: (['1@@', '1', 'ya\u015f@@', '\u0131nday@@', 'ken', 'bir', 'sa@@', 'ba@@', 'h', 'ev@@', 'im@@', 'deki', 'sev@@', 'in@@', 'ç', 'ç@@', '\u0131\u011f@@', 'l\u0131@@', 'klar@@', '\u0131yla', 'u@@', 'yan@@', 'd\u0131\u011f@@', '\u0131m\u0131', 'hat\u0131r@@', 'l\u0131@@', 'yorum', '.'],)
--- Logging error ---
Traceback (most recent call last):
  File "/sw/arch/Debian10/EB_production/2019/software/Anaconda3/2018.12/lib/python3.7/logging/__init__.py", line 1036, in emit
    stream.write(msg)
UnicodeEncodeError: 'latin-1' codec can't encode characters in position 70-71: ordinal not in range(256)
Call stack:
  File "/sw/arch/Debian10/EB_production/2019/software/Anaconda3/2018.12/lib/python3.7/runpy.py", line 193, in _run_module_as_main
    "__main__", mod_spec)
  File "/sw/arch/Debian10/EB_production/2019/software/Anaconda3/2018.12/lib/python3.7/runpy.py", line 85, in _run_code
    exec(code, run_globals)
  File "/home/lcur0008/joeynmt/joeynmt/__main__.py", line 48, in <module>
    main()
  File "/home/lcur0008/joeynmt/joeynmt/__main__.py", line 35, in main
    train(cfg_file=args.config_path, skip_test=args.skip_test)
  File "/home/lcur0008/joeynmt/joeynmt/training.py", line 846, in train
    trainer.train_and_validate(train_data=train_data, valid_data=dev_data)
  File "/home/lcur0008/joeynmt/joeynmt/training.py", line 497, in train_and_validate
    valid_duration = self._validate(valid_data, epoch_no)
  File "/home/lcur0008/joeynmt/joeynmt/training.py", line 642, in _validate
    references=valid_references)
  File "/home/lcur0008/joeynmt/joeynmt/training.py", line 737, in _log_examples
    logger.info("\tSource:     %s", sources[p])
Message: '\tSource:     %s'
Arguments: ('11 ya\u015f\u0131ndayken bir sabah evimdeki sevinç ç\u0131\u011fl\u0131klar\u0131yla uyand\u0131\u011f\u0131m\u0131 hat\u0131rl\u0131yorum .',)
2021-10-02 15:16:41,375 - INFO - joeynmt.training - 	Source:     11 ya\u015f\u0131ndayken bir sabah evimdeki sevinç ç\u0131\u011fl\u0131klar\u0131yla uyand\u0131\u011f\u0131m\u0131 hat\u0131rl\u0131yorum .
2021-10-02 15:16:41,376 - INFO - joeynmt.training - 	Reference:  "When I was 11 , I remember waking up one morning to the sound of joy in my house ."
2021-10-02 15:16:41,376 - INFO - joeynmt.training - 	Hypothesis: "And I , , , , , , , , , , , , , , , , , , , , , , , , , , , , , , , , , , ."
2021-10-02 15:16:41,376 - INFO - joeynmt.training - Example #2
--- Logging error ---
Traceback (most recent call last):
  File "/sw/arch/Debian10/EB_production/2019/software/Anaconda3/2018.12/lib/python3.7/logging/__init__.py", line 1036, in emit
    stream.write(msg)
UnicodeEncodeError: 'latin-1' codec can't encode character '\u0131' in position 151: ordinal not in range(256)
Call stack:
  File "/sw/arch/Debian10/EB_production/2019/software/Anaconda3/2018.12/lib/python3.7/runpy.py", line 193, in _run_module_as_main
    "__main__", mod_spec)
  File "/sw/arch/Debian10/EB_production/2019/software/Anaconda3/2018.12/lib/python3.7/runpy.py", line 85, in _run_code
    exec(code, run_globals)
  File "/home/lcur0008/joeynmt/joeynmt/__main__.py", line 48, in <module>
    main()
  File "/home/lcur0008/joeynmt/joeynmt/__main__.py", line 35, in main
    train(cfg_file=args.config_path, skip_test=args.skip_test)
  File "/home/lcur0008/joeynmt/joeynmt/training.py", line 846, in train
    trainer.train_and_validate(train_data=train_data, valid_data=dev_data)
  File "/home/lcur0008/joeynmt/joeynmt/training.py", line 497, in train_and_validate
    valid_duration = self._validate(valid_data, epoch_no)
  File "/home/lcur0008/joeynmt/joeynmt/training.py", line 642, in _validate
    references=valid_references)
  File "/home/lcur0008/joeynmt/joeynmt/training.py", line 731, in _log_examples
    logger.debug("\tRaw source:     %s", sources_raw[p])
Message: '\tRaw source:     %s'
Arguments: (['"B@@', 'ab@@', 'am', 'B@@', 'B@@', 'C', 'H@@', 'ab@@', 'er', 'kan@@', 'al@@', '\u0131n\u0131', 'din@@', 'li@@', 'yordu', ';', 'o', 'uf@@', 'ak', ',', 'gr@@', 'i', 'rad@@', 'y@@', 'os@@', 'undan', '."'],)
--- Logging error ---
Traceback (most recent call last):
  File "/sw/arch/Debian10/EB_production/2019/software/Anaconda3/2018.12/lib/python3.7/logging/__init__.py", line 1036, in emit
    stream.write(msg)
UnicodeEncodeError: 'latin-1' codec can't encode character '\u0131' in position 87: ordinal not in range(256)
Call stack:
  File "/sw/arch/Debian10/EB_production/2019/software/Anaconda3/2018.12/lib/python3.7/runpy.py", line 193, in _run_module_as_main
    "__main__", mod_spec)
  File "/sw/arch/Debian10/EB_production/2019/software/Anaconda3/2018.12/lib/python3.7/runpy.py", line 85, in _run_code
    exec(code, run_globals)
  File "/home/lcur0008/joeynmt/joeynmt/__main__.py", line 48, in <module>
    main()
  File "/home/lcur0008/joeynmt/joeynmt/__main__.py", line 35, in main
    train(cfg_file=args.config_path, skip_test=args.skip_test)
  File "/home/lcur0008/joeynmt/joeynmt/training.py", line 846, in train
    trainer.train_and_validate(train_data=train_data, valid_data=dev_data)
  File "/home/lcur0008/joeynmt/joeynmt/training.py", line 497, in train_and_validate
    valid_duration = self._validate(valid_data, epoch_no)
  File "/home/lcur0008/joeynmt/joeynmt/training.py", line 642, in _validate
    references=valid_references)
  File "/home/lcur0008/joeynmt/joeynmt/training.py", line 737, in _log_examples
    logger.info("\tSource:     %s", sources[p])
Message: '\tSource:     %s'
Arguments: ('"Babam BBC Haber kanal\u0131n\u0131 dinliyordu ; o ufak , gri radyosundan ."',)
2021-10-02 15:16:41,377 - INFO - joeynmt.training - 	Source:     "Babam BBC Haber kanal\u0131n\u0131 dinliyordu ; o ufak , gri radyosundan ."
2021-10-02 15:16:41,378 - INFO - joeynmt.training - 	Reference:  "My father was listening to BBC News on his small , gray radio ."
2021-10-02 15:16:41,378 - INFO - joeynmt.training - 	Hypothesis: "And &apos;s the , , , , , , , , , , , , , , , , , the the ."
2021-10-02 15:16:41,378 - INFO - joeynmt.training - Validation result (greedy) at epoch   7, step      400: bleu:   0.06, loss: 93825.8594, ppl: 482.6339, duration: 2.7244s
2021-10-02 15:16:56,165 - INFO - joeynmt.training - Epoch   7: total training loss 8361.23
2021-10-02 15:16:56,165 - INFO - joeynmt.training - EPOCH 8
2021-10-02 15:17:08,852 - WARNING - sacrebleu - That's 100 lines that end in a tokenized period ('.')
2021-10-02 15:17:08,853 - WARNING - sacrebleu - It looks like you forgot to detokenize your test data, which may hurt your score.
2021-10-02 15:17:08,853 - WARNING - sacrebleu - If you insist your data is detokenized, or don't care, you can suppress this message with the `force` parameter.
2021-10-02 15:17:08,857 - INFO - joeynmt.training - Hooray! New best validation result [eval_metric]!
2021-10-02 15:17:09,805 - INFO - joeynmt.training - Example #0
2021-10-02 15:17:09,805 - INFO - joeynmt.training - 	Source:     tr
2021-10-02 15:17:09,805 - INFO - joeynmt.training - 	Reference:  en
2021-10-02 15:17:09,805 - INFO - joeynmt.training - 	Hypothesis: ( Applause
2021-10-02 15:17:09,806 - INFO - joeynmt.training - Example #1
--- Logging error ---
Traceback (most recent call last):
  File "/sw/arch/Debian10/EB_production/2019/software/Anaconda3/2018.12/lib/python3.7/logging/__init__.py", line 1036, in emit
    stream.write(msg)
UnicodeEncodeError: 'latin-1' codec can't encode character '\u015f' in position 86: ordinal not in range(256)
Call stack:
  File "/sw/arch/Debian10/EB_production/2019/software/Anaconda3/2018.12/lib/python3.7/runpy.py", line 193, in _run_module_as_main
    "__main__", mod_spec)
  File "/sw/arch/Debian10/EB_production/2019/software/Anaconda3/2018.12/lib/python3.7/runpy.py", line 85, in _run_code
    exec(code, run_globals)
  File "/home/lcur0008/joeynmt/joeynmt/__main__.py", line 48, in <module>
    main()
  File "/home/lcur0008/joeynmt/joeynmt/__main__.py", line 35, in main
    train(cfg_file=args.config_path, skip_test=args.skip_test)
  File "/home/lcur0008/joeynmt/joeynmt/training.py", line 846, in train
    trainer.train_and_validate(train_data=train_data, valid_data=dev_data)
  File "/home/lcur0008/joeynmt/joeynmt/training.py", line 497, in train_and_validate
    valid_duration = self._validate(valid_data, epoch_no)
  File "/home/lcur0008/joeynmt/joeynmt/training.py", line 642, in _validate
    references=valid_references)
  File "/home/lcur0008/joeynmt/joeynmt/training.py", line 731, in _log_examples
    logger.debug("\tRaw source:     %s", sources_raw[p])
Message: '\tRaw source:     %s'
Arguments: (['1@@', '1', 'ya\u015f@@', '\u0131nday@@', 'ken', 'bir', 'sa@@', 'ba@@', 'h', 'ev@@', 'im@@', 'deki', 'sev@@', 'in@@', 'ç', 'ç@@', '\u0131\u011f@@', 'l\u0131@@', 'klar@@', '\u0131yla', 'u@@', 'yan@@', 'd\u0131\u011f@@', '\u0131m\u0131', 'hat\u0131r@@', 'l\u0131@@', 'yorum', '.'],)
--- Logging error ---
Traceback (most recent call last):
  File "/sw/arch/Debian10/EB_production/2019/software/Anaconda3/2018.12/lib/python3.7/logging/__init__.py", line 1036, in emit
    stream.write(msg)
UnicodeEncodeError: 'latin-1' codec can't encode characters in position 70-71: ordinal not in range(256)
Call stack:
  File "/sw/arch/Debian10/EB_production/2019/software/Anaconda3/2018.12/lib/python3.7/runpy.py", line 193, in _run_module_as_main
    "__main__", mod_spec)
  File "/sw/arch/Debian10/EB_production/2019/software/Anaconda3/2018.12/lib/python3.7/runpy.py", line 85, in _run_code
    exec(code, run_globals)
  File "/home/lcur0008/joeynmt/joeynmt/__main__.py", line 48, in <module>
    main()
  File "/home/lcur0008/joeynmt/joeynmt/__main__.py", line 35, in main
    train(cfg_file=args.config_path, skip_test=args.skip_test)
  File "/home/lcur0008/joeynmt/joeynmt/training.py", line 846, in train
    trainer.train_and_validate(train_data=train_data, valid_data=dev_data)
  File "/home/lcur0008/joeynmt/joeynmt/training.py", line 497, in train_and_validate
    valid_duration = self._validate(valid_data, epoch_no)
  File "/home/lcur0008/joeynmt/joeynmt/training.py", line 642, in _validate
    references=valid_references)
  File "/home/lcur0008/joeynmt/joeynmt/training.py", line 737, in _log_examples
    logger.info("\tSource:     %s", sources[p])
Message: '\tSource:     %s'
Arguments: ('11 ya\u015f\u0131ndayken bir sabah evimdeki sevinç ç\u0131\u011fl\u0131klar\u0131yla uyand\u0131\u011f\u0131m\u0131 hat\u0131rl\u0131yorum .',)
2021-10-02 15:17:09,809 - INFO - joeynmt.training - 	Source:     11 ya\u015f\u0131ndayken bir sabah evimdeki sevinç ç\u0131\u011fl\u0131klar\u0131yla uyand\u0131\u011f\u0131m\u0131 hat\u0131rl\u0131yorum .
2021-10-02 15:17:09,809 - INFO - joeynmt.training - 	Reference:  "When I was 11 , I remember waking up one morning to the sound of joy in my house ."
2021-10-02 15:17:09,810 - INFO - joeynmt.training - 	Hypothesis: "And I , , , , , , , , , , , , , , , , , , , , , , , , , , , the ." ." ."
2021-10-02 15:17:09,810 - INFO - joeynmt.training - Example #2
--- Logging error ---
Traceback (most recent call last):
  File "/sw/arch/Debian10/EB_production/2019/software/Anaconda3/2018.12/lib/python3.7/logging/__init__.py", line 1036, in emit
    stream.write(msg)
UnicodeEncodeError: 'latin-1' codec can't encode character '\u0131' in position 151: ordinal not in range(256)
Call stack:
  File "/sw/arch/Debian10/EB_production/2019/software/Anaconda3/2018.12/lib/python3.7/runpy.py", line 193, in _run_module_as_main
    "__main__", mod_spec)
  File "/sw/arch/Debian10/EB_production/2019/software/Anaconda3/2018.12/lib/python3.7/runpy.py", line 85, in _run_code
    exec(code, run_globals)
  File "/home/lcur0008/joeynmt/joeynmt/__main__.py", line 48, in <module>
    main()
  File "/home/lcur0008/joeynmt/joeynmt/__main__.py", line 35, in main
    train(cfg_file=args.config_path, skip_test=args.skip_test)
  File "/home/lcur0008/joeynmt/joeynmt/training.py", line 846, in train
    trainer.train_and_validate(train_data=train_data, valid_data=dev_data)
  File "/home/lcur0008/joeynmt/joeynmt/training.py", line 497, in train_and_validate
    valid_duration = self._validate(valid_data, epoch_no)
  File "/home/lcur0008/joeynmt/joeynmt/training.py", line 642, in _validate
    references=valid_references)
  File "/home/lcur0008/joeynmt/joeynmt/training.py", line 731, in _log_examples
    logger.debug("\tRaw source:     %s", sources_raw[p])
Message: '\tRaw source:     %s'
Arguments: (['"B@@', 'ab@@', 'am', 'B@@', 'B@@', 'C', 'H@@', 'ab@@', 'er', 'kan@@', 'al@@', '\u0131n\u0131', 'din@@', 'li@@', 'yordu', ';', 'o', 'uf@@', 'ak', ',', 'gr@@', 'i', 'rad@@', 'y@@', 'os@@', 'undan', '."'],)
--- Logging error ---
Traceback (most recent call last):
  File "/sw/arch/Debian10/EB_production/2019/software/Anaconda3/2018.12/lib/python3.7/logging/__init__.py", line 1036, in emit
    stream.write(msg)
UnicodeEncodeError: 'latin-1' codec can't encode character '\u0131' in position 87: ordinal not in range(256)
Call stack:
  File "/sw/arch/Debian10/EB_production/2019/software/Anaconda3/2018.12/lib/python3.7/runpy.py", line 193, in _run_module_as_main
    "__main__", mod_spec)
  File "/sw/arch/Debian10/EB_production/2019/software/Anaconda3/2018.12/lib/python3.7/runpy.py", line 85, in _run_code
    exec(code, run_globals)
  File "/home/lcur0008/joeynmt/joeynmt/__main__.py", line 48, in <module>
    main()
  File "/home/lcur0008/joeynmt/joeynmt/__main__.py", line 35, in main
    train(cfg_file=args.config_path, skip_test=args.skip_test)
  File "/home/lcur0008/joeynmt/joeynmt/training.py", line 846, in train
    trainer.train_and_validate(train_data=train_data, valid_data=dev_data)
  File "/home/lcur0008/joeynmt/joeynmt/training.py", line 497, in train_and_validate
    valid_duration = self._validate(valid_data, epoch_no)
  File "/home/lcur0008/joeynmt/joeynmt/training.py", line 642, in _validate
    references=valid_references)
  File "/home/lcur0008/joeynmt/joeynmt/training.py", line 737, in _log_examples
    logger.info("\tSource:     %s", sources[p])
Message: '\tSource:     %s'
Arguments: ('"Babam BBC Haber kanal\u0131n\u0131 dinliyordu ; o ufak , gri radyosundan ."',)
2021-10-02 15:17:09,811 - INFO - joeynmt.training - 	Source:     "Babam BBC Haber kanal\u0131n\u0131 dinliyordu ; o ufak , gri radyosundan ."
2021-10-02 15:17:09,811 - INFO - joeynmt.training - 	Reference:  "My father was listening to BBC News on his small , gray radio ."
2021-10-02 15:17:09,812 - INFO - joeynmt.training - 	Hypothesis: "And &apos;s the , , , , , , , , , , , , , , , the the ." ."
2021-10-02 15:17:09,812 - INFO - joeynmt.training - Validation result (greedy) at epoch   8, step      500: bleu:   0.07, loss: 93729.4219, ppl: 479.5782, duration: 2.8502s
2021-10-02 15:17:16,188 - INFO - joeynmt.training - Epoch   8: total training loss 8326.87
2021-10-02 15:17:16,188 - INFO - joeynmt.training - EPOCH 9
2021-10-02 15:17:31,782 - INFO - joeynmt.training - Epoch   9: total training loss 8317.26
2021-10-02 15:17:31,783 - INFO - joeynmt.training - EPOCH 10
2021-10-02 15:17:37,286 - WARNING - sacrebleu - That's 100 lines that end in a tokenized period ('.')
2021-10-02 15:17:37,286 - WARNING - sacrebleu - It looks like you forgot to detokenize your test data, which may hurt your score.
2021-10-02 15:17:37,286 - WARNING - sacrebleu - If you insist your data is detokenized, or don't care, you can suppress this message with the `force` parameter.
2021-10-02 15:17:38,273 - INFO - joeynmt.helpers - delete models/tr_en_bpe_model/100.ckpt
2021-10-02 15:17:38,359 - INFO - joeynmt.training - Example #0
2021-10-02 15:17:38,359 - INFO - joeynmt.training - 	Source:     tr
2021-10-02 15:17:38,359 - INFO - joeynmt.training - 	Reference:  en
2021-10-02 15:17:38,360 - INFO - joeynmt.training - 	Hypothesis: ( Applause
2021-10-02 15:17:38,360 - INFO - joeynmt.training - Example #1
--- Logging error ---
Traceback (most recent call last):
  File "/sw/arch/Debian10/EB_production/2019/software/Anaconda3/2018.12/lib/python3.7/logging/__init__.py", line 1036, in emit
    stream.write(msg)
UnicodeEncodeError: 'latin-1' codec can't encode character '\u015f' in position 86: ordinal not in range(256)
Call stack:
  File "/sw/arch/Debian10/EB_production/2019/software/Anaconda3/2018.12/lib/python3.7/runpy.py", line 193, in _run_module_as_main
    "__main__", mod_spec)
  File "/sw/arch/Debian10/EB_production/2019/software/Anaconda3/2018.12/lib/python3.7/runpy.py", line 85, in _run_code
    exec(code, run_globals)
  File "/home/lcur0008/joeynmt/joeynmt/__main__.py", line 48, in <module>
    main()
  File "/home/lcur0008/joeynmt/joeynmt/__main__.py", line 35, in main
    train(cfg_file=args.config_path, skip_test=args.skip_test)
  File "/home/lcur0008/joeynmt/joeynmt/training.py", line 846, in train
    trainer.train_and_validate(train_data=train_data, valid_data=dev_data)
  File "/home/lcur0008/joeynmt/joeynmt/training.py", line 497, in train_and_validate
    valid_duration = self._validate(valid_data, epoch_no)
  File "/home/lcur0008/joeynmt/joeynmt/training.py", line 642, in _validate
    references=valid_references)
  File "/home/lcur0008/joeynmt/joeynmt/training.py", line 731, in _log_examples
    logger.debug("\tRaw source:     %s", sources_raw[p])
Message: '\tRaw source:     %s'
Arguments: (['1@@', '1', 'ya\u015f@@', '\u0131nday@@', 'ken', 'bir', 'sa@@', 'ba@@', 'h', 'ev@@', 'im@@', 'deki', 'sev@@', 'in@@', 'ç', 'ç@@', '\u0131\u011f@@', 'l\u0131@@', 'klar@@', '\u0131yla', 'u@@', 'yan@@', 'd\u0131\u011f@@', '\u0131m\u0131', 'hat\u0131r@@', 'l\u0131@@', 'yorum', '.'],)
--- Logging error ---
Traceback (most recent call last):
  File "/sw/arch/Debian10/EB_production/2019/software/Anaconda3/2018.12/lib/python3.7/logging/__init__.py", line 1036, in emit
    stream.write(msg)
UnicodeEncodeError: 'latin-1' codec can't encode characters in position 70-71: ordinal not in range(256)
Call stack:
  File "/sw/arch/Debian10/EB_production/2019/software/Anaconda3/2018.12/lib/python3.7/runpy.py", line 193, in _run_module_as_main
    "__main__", mod_spec)
  File "/sw/arch/Debian10/EB_production/2019/software/Anaconda3/2018.12/lib/python3.7/runpy.py", line 85, in _run_code
    exec(code, run_globals)
  File "/home/lcur0008/joeynmt/joeynmt/__main__.py", line 48, in <module>
    main()
  File "/home/lcur0008/joeynmt/joeynmt/__main__.py", line 35, in main
    train(cfg_file=args.config_path, skip_test=args.skip_test)
  File "/home/lcur0008/joeynmt/joeynmt/training.py", line 846, in train
    trainer.train_and_validate(train_data=train_data, valid_data=dev_data)
  File "/home/lcur0008/joeynmt/joeynmt/training.py", line 497, in train_and_validate
    valid_duration = self._validate(valid_data, epoch_no)
  File "/home/lcur0008/joeynmt/joeynmt/training.py", line 642, in _validate
    references=valid_references)
  File "/home/lcur0008/joeynmt/joeynmt/training.py", line 737, in _log_examples
    logger.info("\tSource:     %s", sources[p])
Message: '\tSource:     %s'
Arguments: ('11 ya\u015f\u0131ndayken bir sabah evimdeki sevinç ç\u0131\u011fl\u0131klar\u0131yla uyand\u0131\u011f\u0131m\u0131 hat\u0131rl\u0131yorum .',)
2021-10-02 15:17:38,360 - INFO - joeynmt.training - 	Source:     11 ya\u015f\u0131ndayken bir sabah evimdeki sevinç ç\u0131\u011fl\u0131klar\u0131yla uyand\u0131\u011f\u0131m\u0131 hat\u0131rl\u0131yorum .
2021-10-02 15:17:38,361 - INFO - joeynmt.training - 	Reference:  "When I was 11 , I remember waking up one morning to the sound of joy in my house ."
2021-10-02 15:17:38,361 - INFO - joeynmt.training - 	Hypothesis: "And I , , , , , , , , , , , , , , , , , , , , , , , , , , , , ." ." ." ."
2021-10-02 15:17:38,361 - INFO - joeynmt.training - Example #2
--- Logging error ---
Traceback (most recent call last):
  File "/sw/arch/Debian10/EB_production/2019/software/Anaconda3/2018.12/lib/python3.7/logging/__init__.py", line 1036, in emit
    stream.write(msg)
UnicodeEncodeError: 'latin-1' codec can't encode character '\u0131' in position 151: ordinal not in range(256)
Call stack:
  File "/sw/arch/Debian10/EB_production/2019/software/Anaconda3/2018.12/lib/python3.7/runpy.py", line 193, in _run_module_as_main
    "__main__", mod_spec)
  File "/sw/arch/Debian10/EB_production/2019/software/Anaconda3/2018.12/lib/python3.7/runpy.py", line 85, in _run_code
    exec(code, run_globals)
  File "/home/lcur0008/joeynmt/joeynmt/__main__.py", line 48, in <module>
    main()
  File "/home/lcur0008/joeynmt/joeynmt/__main__.py", line 35, in main
    train(cfg_file=args.config_path, skip_test=args.skip_test)
  File "/home/lcur0008/joeynmt/joeynmt/training.py", line 846, in train
    trainer.train_and_validate(train_data=train_data, valid_data=dev_data)
  File "/home/lcur0008/joeynmt/joeynmt/training.py", line 497, in train_and_validate
    valid_duration = self._validate(valid_data, epoch_no)
  File "/home/lcur0008/joeynmt/joeynmt/training.py", line 642, in _validate
    references=valid_references)
  File "/home/lcur0008/joeynmt/joeynmt/training.py", line 731, in _log_examples
    logger.debug("\tRaw source:     %s", sources_raw[p])
Message: '\tRaw source:     %s'
Arguments: (['"B@@', 'ab@@', 'am', 'B@@', 'B@@', 'C', 'H@@', 'ab@@', 'er', 'kan@@', 'al@@', '\u0131n\u0131', 'din@@', 'li@@', 'yordu', ';', 'o', 'uf@@', 'ak', ',', 'gr@@', 'i', 'rad@@', 'y@@', 'os@@', 'undan', '."'],)
--- Logging error ---
Traceback (most recent call last):
  File "/sw/arch/Debian10/EB_production/2019/software/Anaconda3/2018.12/lib/python3.7/logging/__init__.py", line 1036, in emit
    stream.write(msg)
UnicodeEncodeError: 'latin-1' codec can't encode character '\u0131' in position 87: ordinal not in range(256)
Call stack:
  File "/sw/arch/Debian10/EB_production/2019/software/Anaconda3/2018.12/lib/python3.7/runpy.py", line 193, in _run_module_as_main
    "__main__", mod_spec)
  File "/sw/arch/Debian10/EB_production/2019/software/Anaconda3/2018.12/lib/python3.7/runpy.py", line 85, in _run_code
    exec(code, run_globals)
  File "/home/lcur0008/joeynmt/joeynmt/__main__.py", line 48, in <module>
    main()
  File "/home/lcur0008/joeynmt/joeynmt/__main__.py", line 35, in main
    train(cfg_file=args.config_path, skip_test=args.skip_test)
  File "/home/lcur0008/joeynmt/joeynmt/training.py", line 846, in train
    trainer.train_and_validate(train_data=train_data, valid_data=dev_data)
  File "/home/lcur0008/joeynmt/joeynmt/training.py", line 497, in train_and_validate
    valid_duration = self._validate(valid_data, epoch_no)
  File "/home/lcur0008/joeynmt/joeynmt/training.py", line 642, in _validate
    references=valid_references)
  File "/home/lcur0008/joeynmt/joeynmt/training.py", line 737, in _log_examples
    logger.info("\tSource:     %s", sources[p])
Message: '\tSource:     %s'
Arguments: ('"Babam BBC Haber kanal\u0131n\u0131 dinliyordu ; o ufak , gri radyosundan ."',)
2021-10-02 15:17:38,361 - INFO - joeynmt.training - 	Source:     "Babam BBC Haber kanal\u0131n\u0131 dinliyordu ; o ufak , gri radyosundan ."
2021-10-02 15:17:38,362 - INFO - joeynmt.training - 	Reference:  "My father was listening to BBC News on his small , gray radio ."
2021-10-02 15:17:38,362 - INFO - joeynmt.training - 	Hypothesis: "And &apos;s , , , , , , , , , , , , , , , , the the ." ."
2021-10-02 15:17:38,362 - INFO - joeynmt.training - Validation result (greedy) at epoch  10, step      600: bleu:   0.06, loss: 93959.3750, ppl: 486.8963, duration: 2.9994s
2021-10-02 15:17:51,343 - INFO - joeynmt.training - Epoch  10: total training loss 8312.80
2021-10-02 15:17:51,343 - INFO - joeynmt.training - EPOCH 11
2021-10-02 15:18:04,258 - WARNING - sacrebleu - That's 100 lines that end in a tokenized period ('.')
2021-10-02 15:18:04,258 - WARNING - sacrebleu - It looks like you forgot to detokenize your test data, which may hurt your score.
2021-10-02 15:18:04,259 - WARNING - sacrebleu - If you insist your data is detokenized, or don't care, you can suppress this message with the `force` parameter.
2021-10-02 15:18:05,237 - INFO - joeynmt.helpers - delete models/tr_en_bpe_model/400.ckpt
2021-10-02 15:18:05,316 - INFO - joeynmt.training - Example #0
2021-10-02 15:18:05,317 - INFO - joeynmt.training - 	Source:     tr
2021-10-02 15:18:05,317 - INFO - joeynmt.training - 	Reference:  en
2021-10-02 15:18:05,317 - INFO - joeynmt.training - 	Hypothesis: ( Applause
2021-10-02 15:18:05,317 - INFO - joeynmt.training - Example #1
--- Logging error ---
Traceback (most recent call last):
  File "/sw/arch/Debian10/EB_production/2019/software/Anaconda3/2018.12/lib/python3.7/logging/__init__.py", line 1036, in emit
    stream.write(msg)
UnicodeEncodeError: 'latin-1' codec can't encode character '\u015f' in position 86: ordinal not in range(256)
Call stack:
  File "/sw/arch/Debian10/EB_production/2019/software/Anaconda3/2018.12/lib/python3.7/runpy.py", line 193, in _run_module_as_main
    "__main__", mod_spec)
  File "/sw/arch/Debian10/EB_production/2019/software/Anaconda3/2018.12/lib/python3.7/runpy.py", line 85, in _run_code
    exec(code, run_globals)
  File "/home/lcur0008/joeynmt/joeynmt/__main__.py", line 48, in <module>
    main()
  File "/home/lcur0008/joeynmt/joeynmt/__main__.py", line 35, in main
    train(cfg_file=args.config_path, skip_test=args.skip_test)
  File "/home/lcur0008/joeynmt/joeynmt/training.py", line 846, in train
    trainer.train_and_validate(train_data=train_data, valid_data=dev_data)
  File "/home/lcur0008/joeynmt/joeynmt/training.py", line 497, in train_and_validate
    valid_duration = self._validate(valid_data, epoch_no)
  File "/home/lcur0008/joeynmt/joeynmt/training.py", line 642, in _validate
    references=valid_references)
  File "/home/lcur0008/joeynmt/joeynmt/training.py", line 731, in _log_examples
    logger.debug("\tRaw source:     %s", sources_raw[p])
Message: '\tRaw source:     %s'
Arguments: (['1@@', '1', 'ya\u015f@@', '\u0131nday@@', 'ken', 'bir', 'sa@@', 'ba@@', 'h', 'ev@@', 'im@@', 'deki', 'sev@@', 'in@@', 'ç', 'ç@@', '\u0131\u011f@@', 'l\u0131@@', 'klar@@', '\u0131yla', 'u@@', 'yan@@', 'd\u0131\u011f@@', '\u0131m\u0131', 'hat\u0131r@@', 'l\u0131@@', 'yorum', '.'],)
--- Logging error ---
Traceback (most recent call last):
  File "/sw/arch/Debian10/EB_production/2019/software/Anaconda3/2018.12/lib/python3.7/logging/__init__.py", line 1036, in emit
    stream.write(msg)
UnicodeEncodeError: 'latin-1' codec can't encode characters in position 70-71: ordinal not in range(256)
Call stack:
  File "/sw/arch/Debian10/EB_production/2019/software/Anaconda3/2018.12/lib/python3.7/runpy.py", line 193, in _run_module_as_main
    "__main__", mod_spec)
  File "/sw/arch/Debian10/EB_production/2019/software/Anaconda3/2018.12/lib/python3.7/runpy.py", line 85, in _run_code
    exec(code, run_globals)
  File "/home/lcur0008/joeynmt/joeynmt/__main__.py", line 48, in <module>
    main()
  File "/home/lcur0008/joeynmt/joeynmt/__main__.py", line 35, in main
    train(cfg_file=args.config_path, skip_test=args.skip_test)
  File "/home/lcur0008/joeynmt/joeynmt/training.py", line 846, in train
    trainer.train_and_validate(train_data=train_data, valid_data=dev_data)
  File "/home/lcur0008/joeynmt/joeynmt/training.py", line 497, in train_and_validate
    valid_duration = self._validate(valid_data, epoch_no)
  File "/home/lcur0008/joeynmt/joeynmt/training.py", line 642, in _validate
    references=valid_references)
  File "/home/lcur0008/joeynmt/joeynmt/training.py", line 737, in _log_examples
    logger.info("\tSource:     %s", sources[p])
Message: '\tSource:     %s'
Arguments: ('11 ya\u015f\u0131ndayken bir sabah evimdeki sevinç ç\u0131\u011fl\u0131klar\u0131yla uyand\u0131\u011f\u0131m\u0131 hat\u0131rl\u0131yorum .',)
2021-10-02 15:18:05,319 - INFO - joeynmt.training - 	Source:     11 ya\u015f\u0131ndayken bir sabah evimdeki sevinç ç\u0131\u011fl\u0131klar\u0131yla uyand\u0131\u011f\u0131m\u0131 hat\u0131rl\u0131yorum .
2021-10-02 15:18:05,319 - INFO - joeynmt.training - 	Reference:  "When I was 11 , I remember waking up one morning to the sound of joy in my house ."
2021-10-02 15:18:05,319 - INFO - joeynmt.training - 	Hypothesis: "And I , , , , , , , , , , , , , , , , , , , , , , , , , , , , , the ." ." ."
2021-10-02 15:18:05,319 - INFO - joeynmt.training - Example #2
--- Logging error ---
Traceback (most recent call last):
  File "/sw/arch/Debian10/EB_production/2019/software/Anaconda3/2018.12/lib/python3.7/logging/__init__.py", line 1036, in emit
    stream.write(msg)
UnicodeEncodeError: 'latin-1' codec can't encode character '\u0131' in position 151: ordinal not in range(256)
Call stack:
  File "/sw/arch/Debian10/EB_production/2019/software/Anaconda3/2018.12/lib/python3.7/runpy.py", line 193, in _run_module_as_main
    "__main__", mod_spec)
  File "/sw/arch/Debian10/EB_production/2019/software/Anaconda3/2018.12/lib/python3.7/runpy.py", line 85, in _run_code
    exec(code, run_globals)
  File "/home/lcur0008/joeynmt/joeynmt/__main__.py", line 48, in <module>
    main()
  File "/home/lcur0008/joeynmt/joeynmt/__main__.py", line 35, in main
    train(cfg_file=args.config_path, skip_test=args.skip_test)
  File "/home/lcur0008/joeynmt/joeynmt/training.py", line 846, in train
    trainer.train_and_validate(train_data=train_data, valid_data=dev_data)
  File "/home/lcur0008/joeynmt/joeynmt/training.py", line 497, in train_and_validate
    valid_duration = self._validate(valid_data, epoch_no)
  File "/home/lcur0008/joeynmt/joeynmt/training.py", line 642, in _validate
    references=valid_references)
  File "/home/lcur0008/joeynmt/joeynmt/training.py", line 731, in _log_examples
    logger.debug("\tRaw source:     %s", sources_raw[p])
Message: '\tRaw source:     %s'
Arguments: (['"B@@', 'ab@@', 'am', 'B@@', 'B@@', 'C', 'H@@', 'ab@@', 'er', 'kan@@', 'al@@', '\u0131n\u0131', 'din@@', 'li@@', 'yordu', ';', 'o', 'uf@@', 'ak', ',', 'gr@@', 'i', 'rad@@', 'y@@', 'os@@', 'undan', '."'],)
--- Logging error ---
Traceback (most recent call last):
  File "/sw/arch/Debian10/EB_production/2019/software/Anaconda3/2018.12/lib/python3.7/logging/__init__.py", line 1036, in emit
    stream.write(msg)
UnicodeEncodeError: 'latin-1' codec can't encode character '\u0131' in position 87: ordinal not in range(256)
Call stack:
  File "/sw/arch/Debian10/EB_production/2019/software/Anaconda3/2018.12/lib/python3.7/runpy.py", line 193, in _run_module_as_main
    "__main__", mod_spec)
  File "/sw/arch/Debian10/EB_production/2019/software/Anaconda3/2018.12/lib/python3.7/runpy.py", line 85, in _run_code
    exec(code, run_globals)
  File "/home/lcur0008/joeynmt/joeynmt/__main__.py", line 48, in <module>
    main()
  File "/home/lcur0008/joeynmt/joeynmt/__main__.py", line 35, in main
    train(cfg_file=args.config_path, skip_test=args.skip_test)
  File "/home/lcur0008/joeynmt/joeynmt/training.py", line 846, in train
    trainer.train_and_validate(train_data=train_data, valid_data=dev_data)
  File "/home/lcur0008/joeynmt/joeynmt/training.py", line 497, in train_and_validate
    valid_duration = self._validate(valid_data, epoch_no)
  File "/home/lcur0008/joeynmt/joeynmt/training.py", line 642, in _validate
    references=valid_references)
  File "/home/lcur0008/joeynmt/joeynmt/training.py", line 737, in _log_examples
    logger.info("\tSource:     %s", sources[p])
Message: '\tSource:     %s'
Arguments: ('"Babam BBC Haber kanal\u0131n\u0131 dinliyordu ; o ufak , gri radyosundan ."',)
2021-10-02 15:18:05,320 - INFO - joeynmt.training - 	Source:     "Babam BBC Haber kanal\u0131n\u0131 dinliyordu ; o ufak , gri radyosundan ."
2021-10-02 15:18:05,320 - INFO - joeynmt.training - 	Reference:  "My father was listening to BBC News on his small , gray radio ."
2021-10-02 15:18:05,320 - INFO - joeynmt.training - 	Hypothesis: "And &apos;s , , , , , , , , , , , , , , , , , the the ." ." ."
2021-10-02 15:18:05,320 - INFO - joeynmt.training - Validation result (greedy) at epoch  11, step      700: bleu:   0.06, loss: 93949.2578, ppl: 486.5721, duration: 2.8809s
2021-10-02 15:18:10,350 - INFO - joeynmt.training - Epoch  11: total training loss 8298.48
2021-10-02 15:18:10,351 - INFO - joeynmt.training - EPOCH 12
2021-10-02 15:18:25,225 - INFO - joeynmt.training - Epoch  12: total training loss 8283.05
2021-10-02 15:18:25,225 - INFO - joeynmt.training - EPOCH 13
2021-10-02 15:18:31,519 - WARNING - sacrebleu - That's 100 lines that end in a tokenized period ('.')
2021-10-02 15:18:31,519 - WARNING - sacrebleu - It looks like you forgot to detokenize your test data, which may hurt your score.
2021-10-02 15:18:31,519 - WARNING - sacrebleu - If you insist your data is detokenized, or don't care, you can suppress this message with the `force` parameter.
2021-10-02 15:18:32,467 - INFO - joeynmt.helpers - delete models/tr_en_bpe_model/700.ckpt
2021-10-02 15:18:32,547 - INFO - joeynmt.helpers - delete /home/lcur0008/joeynmt/models/tr_en_bpe_model/700.ckpt
2021-10-02 15:18:32,548 - WARNING - joeynmt.helpers - Wanted to delete old checkpoint /home/lcur0008/joeynmt/models/tr_en_bpe_model/700.ckpt but file does not exist. ([Errno 2] No such file or directory: '/home/lcur0008/joeynmt/models/tr_en_bpe_model/700.ckpt')
2021-10-02 15:18:32,550 - INFO - joeynmt.training - Example #0
2021-10-02 15:18:32,550 - INFO - joeynmt.training - 	Source:     tr
2021-10-02 15:18:32,550 - INFO - joeynmt.training - 	Reference:  en
2021-10-02 15:18:32,550 - INFO - joeynmt.training - 	Hypothesis: ( Applause
2021-10-02 15:18:32,551 - INFO - joeynmt.training - Example #1
--- Logging error ---
Traceback (most recent call last):
  File "/sw/arch/Debian10/EB_production/2019/software/Anaconda3/2018.12/lib/python3.7/logging/__init__.py", line 1036, in emit
    stream.write(msg)
UnicodeEncodeError: 'latin-1' codec can't encode character '\u015f' in position 86: ordinal not in range(256)
Call stack:
  File "/sw/arch/Debian10/EB_production/2019/software/Anaconda3/2018.12/lib/python3.7/runpy.py", line 193, in _run_module_as_main
    "__main__", mod_spec)
  File "/sw/arch/Debian10/EB_production/2019/software/Anaconda3/2018.12/lib/python3.7/runpy.py", line 85, in _run_code
    exec(code, run_globals)
  File "/home/lcur0008/joeynmt/joeynmt/__main__.py", line 48, in <module>
    main()
  File "/home/lcur0008/joeynmt/joeynmt/__main__.py", line 35, in main
    train(cfg_file=args.config_path, skip_test=args.skip_test)
  File "/home/lcur0008/joeynmt/joeynmt/training.py", line 846, in train
    trainer.train_and_validate(train_data=train_data, valid_data=dev_data)
  File "/home/lcur0008/joeynmt/joeynmt/training.py", line 497, in train_and_validate
    valid_duration = self._validate(valid_data, epoch_no)
  File "/home/lcur0008/joeynmt/joeynmt/training.py", line 642, in _validate
    references=valid_references)
  File "/home/lcur0008/joeynmt/joeynmt/training.py", line 731, in _log_examples
    logger.debug("\tRaw source:     %s", sources_raw[p])
Message: '\tRaw source:     %s'
Arguments: (['1@@', '1', 'ya\u015f@@', '\u0131nday@@', 'ken', 'bir', 'sa@@', 'ba@@', 'h', 'ev@@', 'im@@', 'deki', 'sev@@', 'in@@', 'ç', 'ç@@', '\u0131\u011f@@', 'l\u0131@@', 'klar@@', '\u0131yla', 'u@@', 'yan@@', 'd\u0131\u011f@@', '\u0131m\u0131', 'hat\u0131r@@', 'l\u0131@@', 'yorum', '.'],)
--- Logging error ---
Traceback (most recent call last):
  File "/sw/arch/Debian10/EB_production/2019/software/Anaconda3/2018.12/lib/python3.7/logging/__init__.py", line 1036, in emit
    stream.write(msg)
UnicodeEncodeError: 'latin-1' codec can't encode characters in position 70-71: ordinal not in range(256)
Call stack:
  File "/sw/arch/Debian10/EB_production/2019/software/Anaconda3/2018.12/lib/python3.7/runpy.py", line 193, in _run_module_as_main
    "__main__", mod_spec)
  File "/sw/arch/Debian10/EB_production/2019/software/Anaconda3/2018.12/lib/python3.7/runpy.py", line 85, in _run_code
    exec(code, run_globals)
  File "/home/lcur0008/joeynmt/joeynmt/__main__.py", line 48, in <module>
    main()
  File "/home/lcur0008/joeynmt/joeynmt/__main__.py", line 35, in main
    train(cfg_file=args.config_path, skip_test=args.skip_test)
  File "/home/lcur0008/joeynmt/joeynmt/training.py", line 846, in train
    trainer.train_and_validate(train_data=train_data, valid_data=dev_data)
  File "/home/lcur0008/joeynmt/joeynmt/training.py", line 497, in train_and_validate
    valid_duration = self._validate(valid_data, epoch_no)
  File "/home/lcur0008/joeynmt/joeynmt/training.py", line 642, in _validate
    references=valid_references)
  File "/home/lcur0008/joeynmt/joeynmt/training.py", line 737, in _log_examples
    logger.info("\tSource:     %s", sources[p])
Message: '\tSource:     %s'
Arguments: ('11 ya\u015f\u0131ndayken bir sabah evimdeki sevinç ç\u0131\u011fl\u0131klar\u0131yla uyand\u0131\u011f\u0131m\u0131 hat\u0131rl\u0131yorum .',)
2021-10-02 15:18:32,553 - INFO - joeynmt.training - 	Source:     11 ya\u015f\u0131ndayken bir sabah evimdeki sevinç ç\u0131\u011fl\u0131klar\u0131yla uyand\u0131\u011f\u0131m\u0131 hat\u0131rl\u0131yorum .
2021-10-02 15:18:32,553 - INFO - joeynmt.training - 	Reference:  "When I was 11 , I remember waking up one morning to the sound of joy in my house ."
2021-10-02 15:18:32,554 - INFO - joeynmt.training - 	Hypothesis: "And I , , , , , , , , , , , , , , , , , , , , , , , , , , , , , the ." ." ."
2021-10-02 15:18:32,554 - INFO - joeynmt.training - Example #2
--- Logging error ---
Traceback (most recent call last):
  File "/sw/arch/Debian10/EB_production/2019/software/Anaconda3/2018.12/lib/python3.7/logging/__init__.py", line 1036, in emit
    stream.write(msg)
UnicodeEncodeError: 'latin-1' codec can't encode character '\u0131' in position 151: ordinal not in range(256)
Call stack:
  File "/sw/arch/Debian10/EB_production/2019/software/Anaconda3/2018.12/lib/python3.7/runpy.py", line 193, in _run_module_as_main
    "__main__", mod_spec)
  File "/sw/arch/Debian10/EB_production/2019/software/Anaconda3/2018.12/lib/python3.7/runpy.py", line 85, in _run_code
    exec(code, run_globals)
  File "/home/lcur0008/joeynmt/joeynmt/__main__.py", line 48, in <module>
    main()
  File "/home/lcur0008/joeynmt/joeynmt/__main__.py", line 35, in main
    train(cfg_file=args.config_path, skip_test=args.skip_test)
  File "/home/lcur0008/joeynmt/joeynmt/training.py", line 846, in train
    trainer.train_and_validate(train_data=train_data, valid_data=dev_data)
  File "/home/lcur0008/joeynmt/joeynmt/training.py", line 497, in train_and_validate
    valid_duration = self._validate(valid_data, epoch_no)
  File "/home/lcur0008/joeynmt/joeynmt/training.py", line 642, in _validate
    references=valid_references)
  File "/home/lcur0008/joeynmt/joeynmt/training.py", line 731, in _log_examples
    logger.debug("\tRaw source:     %s", sources_raw[p])
Message: '\tRaw source:     %s'
Arguments: (['"B@@', 'ab@@', 'am', 'B@@', 'B@@', 'C', 'H@@', 'ab@@', 'er', 'kan@@', 'al@@', '\u0131n\u0131', 'din@@', 'li@@', 'yordu', ';', 'o', 'uf@@', 'ak', ',', 'gr@@', 'i', 'rad@@', 'y@@', 'os@@', 'undan', '."'],)
--- Logging error ---
Traceback (most recent call last):
  File "/sw/arch/Debian10/EB_production/2019/software/Anaconda3/2018.12/lib/python3.7/logging/__init__.py", line 1036, in emit
    stream.write(msg)
UnicodeEncodeError: 'latin-1' codec can't encode character '\u0131' in position 87: ordinal not in range(256)
Call stack:
  File "/sw/arch/Debian10/EB_production/2019/software/Anaconda3/2018.12/lib/python3.7/runpy.py", line 193, in _run_module_as_main
    "__main__", mod_spec)
  File "/sw/arch/Debian10/EB_production/2019/software/Anaconda3/2018.12/lib/python3.7/runpy.py", line 85, in _run_code
    exec(code, run_globals)
  File "/home/lcur0008/joeynmt/joeynmt/__main__.py", line 48, in <module>
    main()
  File "/home/lcur0008/joeynmt/joeynmt/__main__.py", line 35, in main
    train(cfg_file=args.config_path, skip_test=args.skip_test)
  File "/home/lcur0008/joeynmt/joeynmt/training.py", line 846, in train
    trainer.train_and_validate(train_data=train_data, valid_data=dev_data)
  File "/home/lcur0008/joeynmt/joeynmt/training.py", line 497, in train_and_validate
    valid_duration = self._validate(valid_data, epoch_no)
  File "/home/lcur0008/joeynmt/joeynmt/training.py", line 642, in _validate
    references=valid_references)
  File "/home/lcur0008/joeynmt/joeynmt/training.py", line 737, in _log_examples
    logger.info("\tSource:     %s", sources[p])
Message: '\tSource:     %s'
Arguments: ('"Babam BBC Haber kanal\u0131n\u0131 dinliyordu ; o ufak , gri radyosundan ."',)
2021-10-02 15:18:32,554 - INFO - joeynmt.training - 	Source:     "Babam BBC Haber kanal\u0131n\u0131 dinliyordu ; o ufak , gri radyosundan ."
2021-10-02 15:18:32,554 - INFO - joeynmt.training - 	Reference:  "My father was listening to BBC News on his small , gray radio ."
2021-10-02 15:18:32,554 - INFO - joeynmt.training - 	Hypothesis: "And &apos;s , , , , , , , , , , , , , , , , the the the ." ."
2021-10-02 15:18:32,555 - INFO - joeynmt.training - Validation result (greedy) at epoch  13, step      800: bleu:   0.06, loss: 93987.1719, ppl: 487.7885, duration: 2.8625s
2021-10-02 15:18:43,980 - INFO - joeynmt.training - Epoch  13: total training loss 8285.28
2021-10-02 15:18:43,980 - INFO - joeynmt.training - EPOCH 14
2021-10-02 15:18:58,850 - WARNING - sacrebleu - That's 100 lines that end in a tokenized period ('.')
2021-10-02 15:18:58,851 - WARNING - sacrebleu - It looks like you forgot to detokenize your test data, which may hurt your score.
2021-10-02 15:18:58,851 - WARNING - sacrebleu - If you insist your data is detokenized, or don't care, you can suppress this message with the `force` parameter.
2021-10-02 15:18:59,761 - INFO - joeynmt.helpers - delete models/tr_en_bpe_model/300.ckpt
2021-10-02 15:18:59,835 - INFO - joeynmt.training - Example #0
2021-10-02 15:18:59,835 - INFO - joeynmt.training - 	Source:     tr
2021-10-02 15:18:59,835 - INFO - joeynmt.training - 	Reference:  en
2021-10-02 15:18:59,835 - INFO - joeynmt.training - 	Hypothesis: ( Applause
2021-10-02 15:18:59,835 - INFO - joeynmt.training - Example #1
--- Logging error ---
Traceback (most recent call last):
  File "/sw/arch/Debian10/EB_production/2019/software/Anaconda3/2018.12/lib/python3.7/logging/__init__.py", line 1036, in emit
    stream.write(msg)
UnicodeEncodeError: 'latin-1' codec can't encode character '\u015f' in position 86: ordinal not in range(256)
Call stack:
  File "/sw/arch/Debian10/EB_production/2019/software/Anaconda3/2018.12/lib/python3.7/runpy.py", line 193, in _run_module_as_main
    "__main__", mod_spec)
  File "/sw/arch/Debian10/EB_production/2019/software/Anaconda3/2018.12/lib/python3.7/runpy.py", line 85, in _run_code
    exec(code, run_globals)
  File "/home/lcur0008/joeynmt/joeynmt/__main__.py", line 48, in <module>
    main()
  File "/home/lcur0008/joeynmt/joeynmt/__main__.py", line 35, in main
    train(cfg_file=args.config_path, skip_test=args.skip_test)
  File "/home/lcur0008/joeynmt/joeynmt/training.py", line 846, in train
    trainer.train_and_validate(train_data=train_data, valid_data=dev_data)
  File "/home/lcur0008/joeynmt/joeynmt/training.py", line 497, in train_and_validate
    valid_duration = self._validate(valid_data, epoch_no)
  File "/home/lcur0008/joeynmt/joeynmt/training.py", line 642, in _validate
    references=valid_references)
  File "/home/lcur0008/joeynmt/joeynmt/training.py", line 731, in _log_examples
    logger.debug("\tRaw source:     %s", sources_raw[p])
Message: '\tRaw source:     %s'
Arguments: (['1@@', '1', 'ya\u015f@@', '\u0131nday@@', 'ken', 'bir', 'sa@@', 'ba@@', 'h', 'ev@@', 'im@@', 'deki', 'sev@@', 'in@@', 'ç', 'ç@@', '\u0131\u011f@@', 'l\u0131@@', 'klar@@', '\u0131yla', 'u@@', 'yan@@', 'd\u0131\u011f@@', '\u0131m\u0131', 'hat\u0131r@@', 'l\u0131@@', 'yorum', '.'],)
--- Logging error ---
Traceback (most recent call last):
  File "/sw/arch/Debian10/EB_production/2019/software/Anaconda3/2018.12/lib/python3.7/logging/__init__.py", line 1036, in emit
    stream.write(msg)
UnicodeEncodeError: 'latin-1' codec can't encode characters in position 70-71: ordinal not in range(256)
Call stack:
  File "/sw/arch/Debian10/EB_production/2019/software/Anaconda3/2018.12/lib/python3.7/runpy.py", line 193, in _run_module_as_main
    "__main__", mod_spec)
  File "/sw/arch/Debian10/EB_production/2019/software/Anaconda3/2018.12/lib/python3.7/runpy.py", line 85, in _run_code
    exec(code, run_globals)
  File "/home/lcur0008/joeynmt/joeynmt/__main__.py", line 48, in <module>
    main()
  File "/home/lcur0008/joeynmt/joeynmt/__main__.py", line 35, in main
    train(cfg_file=args.config_path, skip_test=args.skip_test)
  File "/home/lcur0008/joeynmt/joeynmt/training.py", line 846, in train
    trainer.train_and_validate(train_data=train_data, valid_data=dev_data)
  File "/home/lcur0008/joeynmt/joeynmt/training.py", line 497, in train_and_validate
    valid_duration = self._validate(valid_data, epoch_no)
  File "/home/lcur0008/joeynmt/joeynmt/training.py", line 642, in _validate
    references=valid_references)
  File "/home/lcur0008/joeynmt/joeynmt/training.py", line 737, in _log_examples
    logger.info("\tSource:     %s", sources[p])
Message: '\tSource:     %s'
Arguments: ('11 ya\u015f\u0131ndayken bir sabah evimdeki sevinç ç\u0131\u011fl\u0131klar\u0131yla uyand\u0131\u011f\u0131m\u0131 hat\u0131rl\u0131yorum .',)
2021-10-02 15:18:59,836 - INFO - joeynmt.training - 	Source:     11 ya\u015f\u0131ndayken bir sabah evimdeki sevinç ç\u0131\u011fl\u0131klar\u0131yla uyand\u0131\u011f\u0131m\u0131 hat\u0131rl\u0131yorum .
2021-10-02 15:18:59,836 - INFO - joeynmt.training - 	Reference:  "When I was 11 , I remember waking up one morning to the sound of joy in my house ."
2021-10-02 15:18:59,836 - INFO - joeynmt.training - 	Hypothesis: "And I , , , , , , , , , , , , , , , , , , , , , , , , , , , , , the ." ." ."
2021-10-02 15:18:59,836 - INFO - joeynmt.training - Example #2
--- Logging error ---
Traceback (most recent call last):
  File "/sw/arch/Debian10/EB_production/2019/software/Anaconda3/2018.12/lib/python3.7/logging/__init__.py", line 1036, in emit
    stream.write(msg)
UnicodeEncodeError: 'latin-1' codec can't encode character '\u0131' in position 151: ordinal not in range(256)
Call stack:
  File "/sw/arch/Debian10/EB_production/2019/software/Anaconda3/2018.12/lib/python3.7/runpy.py", line 193, in _run_module_as_main
    "__main__", mod_spec)
  File "/sw/arch/Debian10/EB_production/2019/software/Anaconda3/2018.12/lib/python3.7/runpy.py", line 85, in _run_code
    exec(code, run_globals)
  File "/home/lcur0008/joeynmt/joeynmt/__main__.py", line 48, in <module>
    main()
  File "/home/lcur0008/joeynmt/joeynmt/__main__.py", line 35, in main
    train(cfg_file=args.config_path, skip_test=args.skip_test)
  File "/home/lcur0008/joeynmt/joeynmt/training.py", line 846, in train
    trainer.train_and_validate(train_data=train_data, valid_data=dev_data)
  File "/home/lcur0008/joeynmt/joeynmt/training.py", line 497, in train_and_validate
    valid_duration = self._validate(valid_data, epoch_no)
  File "/home/lcur0008/joeynmt/joeynmt/training.py", line 642, in _validate
    references=valid_references)
  File "/home/lcur0008/joeynmt/joeynmt/training.py", line 731, in _log_examples
    logger.debug("\tRaw source:     %s", sources_raw[p])
Message: '\tRaw source:     %s'
Arguments: (['"B@@', 'ab@@', 'am', 'B@@', 'B@@', 'C', 'H@@', 'ab@@', 'er', 'kan@@', 'al@@', '\u0131n\u0131', 'din@@', 'li@@', 'yordu', ';', 'o', 'uf@@', 'ak', ',', 'gr@@', 'i', 'rad@@', 'y@@', 'os@@', 'undan', '."'],)
--- Logging error ---
Traceback (most recent call last):
  File "/sw/arch/Debian10/EB_production/2019/software/Anaconda3/2018.12/lib/python3.7/logging/__init__.py", line 1036, in emit
    stream.write(msg)
UnicodeEncodeError: 'latin-1' codec can't encode character '\u0131' in position 87: ordinal not in range(256)
Call stack:
  File "/sw/arch/Debian10/EB_production/2019/software/Anaconda3/2018.12/lib/python3.7/runpy.py", line 193, in _run_module_as_main
    "__main__", mod_spec)
  File "/sw/arch/Debian10/EB_production/2019/software/Anaconda3/2018.12/lib/python3.7/runpy.py", line 85, in _run_code
    exec(code, run_globals)
  File "/home/lcur0008/joeynmt/joeynmt/__main__.py", line 48, in <module>
    main()
  File "/home/lcur0008/joeynmt/joeynmt/__main__.py", line 35, in main
    train(cfg_file=args.config_path, skip_test=args.skip_test)
  File "/home/lcur0008/joeynmt/joeynmt/training.py", line 846, in train
    trainer.train_and_validate(train_data=train_data, valid_data=dev_data)
  File "/home/lcur0008/joeynmt/joeynmt/training.py", line 497, in train_and_validate
    valid_duration = self._validate(valid_data, epoch_no)
  File "/home/lcur0008/joeynmt/joeynmt/training.py", line 642, in _validate
    references=valid_references)
  File "/home/lcur0008/joeynmt/joeynmt/training.py", line 737, in _log_examples
    logger.info("\tSource:     %s", sources[p])
Message: '\tSource:     %s'
Arguments: ('"Babam BBC Haber kanal\u0131n\u0131 dinliyordu ; o ufak , gri radyosundan ."',)
2021-10-02 15:18:59,837 - INFO - joeynmt.training - 	Source:     "Babam BBC Haber kanal\u0131n\u0131 dinliyordu ; o ufak , gri radyosundan ."
2021-10-02 15:18:59,837 - INFO - joeynmt.training - 	Reference:  "My father was listening to BBC News on his small , gray radio ."
2021-10-02 15:18:59,837 - INFO - joeynmt.training - 	Hypothesis: "And &apos;s , , , , , , , , , , , , , , , , , the the ." ." ."
2021-10-02 15:18:59,837 - INFO - joeynmt.training - Validation result (greedy) at epoch  14, step      900: bleu:   0.06, loss: 94003.6875, ppl: 488.3193, duration: 3.0066s
2021-10-02 15:19:03,656 - INFO - joeynmt.training - Epoch  14: total training loss 8286.69
2021-10-02 15:19:03,656 - INFO - joeynmt.training - EPOCH 15
2021-10-02 15:19:18,535 - INFO - joeynmt.training - Epoch  15: total training loss 8281.54
2021-10-02 15:19:18,536 - INFO - joeynmt.training - EPOCH 16
2021-10-02 15:19:24,140 - INFO - joeynmt.training - Epoch  16, Step:     1000, Batch Loss:   128.316299, Tokens per Sec:     7642, Lr: 0.000000
2021-10-02 15:19:25,989 - WARNING - sacrebleu - That's 100 lines that end in a tokenized period ('.')
2021-10-02 15:19:25,989 - WARNING - sacrebleu - It looks like you forgot to detokenize your test data, which may hurt your score.
2021-10-02 15:19:25,989 - WARNING - sacrebleu - If you insist your data is detokenized, or don't care, you can suppress this message with the `force` parameter.
2021-10-02 15:19:26,988 - INFO - joeynmt.helpers - delete models/tr_en_bpe_model/200.ckpt
2021-10-02 15:19:27,075 - INFO - joeynmt.training - Example #0
2021-10-02 15:19:27,075 - INFO - joeynmt.training - 	Source:     tr
2021-10-02 15:19:27,075 - INFO - joeynmt.training - 	Reference:  en
2021-10-02 15:19:27,075 - INFO - joeynmt.training - 	Hypothesis: ( Applause
2021-10-02 15:19:27,075 - INFO - joeynmt.training - Example #1
--- Logging error ---
Traceback (most recent call last):
  File "/sw/arch/Debian10/EB_production/2019/software/Anaconda3/2018.12/lib/python3.7/logging/__init__.py", line 1036, in emit
    stream.write(msg)
UnicodeEncodeError: 'latin-1' codec can't encode character '\u015f' in position 86: ordinal not in range(256)
Call stack:
  File "/sw/arch/Debian10/EB_production/2019/software/Anaconda3/2018.12/lib/python3.7/runpy.py", line 193, in _run_module_as_main
    "__main__", mod_spec)
  File "/sw/arch/Debian10/EB_production/2019/software/Anaconda3/2018.12/lib/python3.7/runpy.py", line 85, in _run_code
    exec(code, run_globals)
  File "/home/lcur0008/joeynmt/joeynmt/__main__.py", line 48, in <module>
    main()
  File "/home/lcur0008/joeynmt/joeynmt/__main__.py", line 35, in main
    train(cfg_file=args.config_path, skip_test=args.skip_test)
  File "/home/lcur0008/joeynmt/joeynmt/training.py", line 846, in train
    trainer.train_and_validate(train_data=train_data, valid_data=dev_data)
  File "/home/lcur0008/joeynmt/joeynmt/training.py", line 497, in train_and_validate
    valid_duration = self._validate(valid_data, epoch_no)
  File "/home/lcur0008/joeynmt/joeynmt/training.py", line 642, in _validate
    references=valid_references)
  File "/home/lcur0008/joeynmt/joeynmt/training.py", line 731, in _log_examples
    logger.debug("\tRaw source:     %s", sources_raw[p])
Message: '\tRaw source:     %s'
Arguments: (['1@@', '1', 'ya\u015f@@', '\u0131nday@@', 'ken', 'bir', 'sa@@', 'ba@@', 'h', 'ev@@', 'im@@', 'deki', 'sev@@', 'in@@', 'ç', 'ç@@', '\u0131\u011f@@', 'l\u0131@@', 'klar@@', '\u0131yla', 'u@@', 'yan@@', 'd\u0131\u011f@@', '\u0131m\u0131', 'hat\u0131r@@', 'l\u0131@@', 'yorum', '.'],)
--- Logging error ---
Traceback (most recent call last):
  File "/sw/arch/Debian10/EB_production/2019/software/Anaconda3/2018.12/lib/python3.7/logging/__init__.py", line 1036, in emit
    stream.write(msg)
UnicodeEncodeError: 'latin-1' codec can't encode characters in position 70-71: ordinal not in range(256)
Call stack:
  File "/sw/arch/Debian10/EB_production/2019/software/Anaconda3/2018.12/lib/python3.7/runpy.py", line 193, in _run_module_as_main
    "__main__", mod_spec)
  File "/sw/arch/Debian10/EB_production/2019/software/Anaconda3/2018.12/lib/python3.7/runpy.py", line 85, in _run_code
    exec(code, run_globals)
  File "/home/lcur0008/joeynmt/joeynmt/__main__.py", line 48, in <module>
    main()
  File "/home/lcur0008/joeynmt/joeynmt/__main__.py", line 35, in main
    train(cfg_file=args.config_path, skip_test=args.skip_test)
  File "/home/lcur0008/joeynmt/joeynmt/training.py", line 846, in train
    trainer.train_and_validate(train_data=train_data, valid_data=dev_data)
  File "/home/lcur0008/joeynmt/joeynmt/training.py", line 497, in train_and_validate
    valid_duration = self._validate(valid_data, epoch_no)
  File "/home/lcur0008/joeynmt/joeynmt/training.py", line 642, in _validate
    references=valid_references)
  File "/home/lcur0008/joeynmt/joeynmt/training.py", line 737, in _log_examples
    logger.info("\tSource:     %s", sources[p])
Message: '\tSource:     %s'
Arguments: ('11 ya\u015f\u0131ndayken bir sabah evimdeki sevinç ç\u0131\u011fl\u0131klar\u0131yla uyand\u0131\u011f\u0131m\u0131 hat\u0131rl\u0131yorum .',)
2021-10-02 15:19:27,076 - INFO - joeynmt.training - 	Source:     11 ya\u015f\u0131ndayken bir sabah evimdeki sevinç ç\u0131\u011fl\u0131klar\u0131yla uyand\u0131\u011f\u0131m\u0131 hat\u0131rl\u0131yorum .
2021-10-02 15:19:27,077 - INFO - joeynmt.training - 	Reference:  "When I was 11 , I remember waking up one morning to the sound of joy in my house ."
2021-10-02 15:19:27,077 - INFO - joeynmt.training - 	Hypothesis: "And I , , , , , , , , , , , , , , , , , , , , , , , , , , , , , the ." ." ."
2021-10-02 15:19:27,077 - INFO - joeynmt.training - Example #2
--- Logging error ---
Traceback (most recent call last):
  File "/sw/arch/Debian10/EB_production/2019/software/Anaconda3/2018.12/lib/python3.7/logging/__init__.py", line 1036, in emit
    stream.write(msg)
UnicodeEncodeError: 'latin-1' codec can't encode character '\u0131' in position 151: ordinal not in range(256)
Call stack:
  File "/sw/arch/Debian10/EB_production/2019/software/Anaconda3/2018.12/lib/python3.7/runpy.py", line 193, in _run_module_as_main
    "__main__", mod_spec)
  File "/sw/arch/Debian10/EB_production/2019/software/Anaconda3/2018.12/lib/python3.7/runpy.py", line 85, in _run_code
    exec(code, run_globals)
  File "/home/lcur0008/joeynmt/joeynmt/__main__.py", line 48, in <module>
    main()
  File "/home/lcur0008/joeynmt/joeynmt/__main__.py", line 35, in main
    train(cfg_file=args.config_path, skip_test=args.skip_test)
  File "/home/lcur0008/joeynmt/joeynmt/training.py", line 846, in train
    trainer.train_and_validate(train_data=train_data, valid_data=dev_data)
  File "/home/lcur0008/joeynmt/joeynmt/training.py", line 497, in train_and_validate
    valid_duration = self._validate(valid_data, epoch_no)
  File "/home/lcur0008/joeynmt/joeynmt/training.py", line 642, in _validate
    references=valid_references)
  File "/home/lcur0008/joeynmt/joeynmt/training.py", line 731, in _log_examples
    logger.debug("\tRaw source:     %s", sources_raw[p])
Message: '\tRaw source:     %s'
Arguments: (['"B@@', 'ab@@', 'am', 'B@@', 'B@@', 'C', 'H@@', 'ab@@', 'er', 'kan@@', 'al@@', '\u0131n\u0131', 'din@@', 'li@@', 'yordu', ';', 'o', 'uf@@', 'ak', ',', 'gr@@', 'i', 'rad@@', 'y@@', 'os@@', 'undan', '."'],)
--- Logging error ---
Traceback (most recent call last):
  File "/sw/arch/Debian10/EB_production/2019/software/Anaconda3/2018.12/lib/python3.7/logging/__init__.py", line 1036, in emit
    stream.write(msg)
UnicodeEncodeError: 'latin-1' codec can't encode character '\u0131' in position 87: ordinal not in range(256)
Call stack:
  File "/sw/arch/Debian10/EB_production/2019/software/Anaconda3/2018.12/lib/python3.7/runpy.py", line 193, in _run_module_as_main
    "__main__", mod_spec)
  File "/sw/arch/Debian10/EB_production/2019/software/Anaconda3/2018.12/lib/python3.7/runpy.py", line 85, in _run_code
    exec(code, run_globals)
  File "/home/lcur0008/joeynmt/joeynmt/__main__.py", line 48, in <module>
    main()
  File "/home/lcur0008/joeynmt/joeynmt/__main__.py", line 35, in main
    train(cfg_file=args.config_path, skip_test=args.skip_test)
  File "/home/lcur0008/joeynmt/joeynmt/training.py", line 846, in train
    trainer.train_and_validate(train_data=train_data, valid_data=dev_data)
  File "/home/lcur0008/joeynmt/joeynmt/training.py", line 497, in train_and_validate
    valid_duration = self._validate(valid_data, epoch_no)
  File "/home/lcur0008/joeynmt/joeynmt/training.py", line 642, in _validate
    references=valid_references)
  File "/home/lcur0008/joeynmt/joeynmt/training.py", line 737, in _log_examples
    logger.info("\tSource:     %s", sources[p])
Message: '\tSource:     %s'
Arguments: ('"Babam BBC Haber kanal\u0131n\u0131 dinliyordu ; o ufak , gri radyosundan ."',)
2021-10-02 15:19:27,077 - INFO - joeynmt.training - 	Source:     "Babam BBC Haber kanal\u0131n\u0131 dinliyordu ; o ufak , gri radyosundan ."
2021-10-02 15:19:27,078 - INFO - joeynmt.training - 	Reference:  "My father was listening to BBC News on his small , gray radio ."
2021-10-02 15:19:27,078 - INFO - joeynmt.training - 	Hypothesis: "And &apos;s , , , , , , , , , , , , , , , , , the the ." ." ."
2021-10-02 15:19:27,078 - INFO - joeynmt.training - Validation result (greedy) at epoch  16, step     1000: bleu:   0.06, loss: 94022.5312, ppl: 488.9258, duration: 2.9369s
2021-10-02 15:19:37,602 - INFO - joeynmt.training - Epoch  16: total training loss 8288.23
2021-10-02 15:19:37,603 - INFO - joeynmt.training - EPOCH 17
2021-10-02 15:19:53,133 - WARNING - sacrebleu - That's 100 lines that end in a tokenized period ('.')
2021-10-02 15:19:53,133 - WARNING - sacrebleu - It looks like you forgot to detokenize your test data, which may hurt your score.
2021-10-02 15:19:53,133 - WARNING - sacrebleu - If you insist your data is detokenized, or don't care, you can suppress this message with the `force` parameter.
2021-10-02 15:19:53,139 - INFO - joeynmt.training - Example #0
2021-10-02 15:19:53,140 - INFO - joeynmt.training - 	Source:     tr
2021-10-02 15:19:53,140 - INFO - joeynmt.training - 	Reference:  en
2021-10-02 15:19:53,140 - INFO - joeynmt.training - 	Hypothesis: ( Applause
2021-10-02 15:19:53,140 - INFO - joeynmt.training - Example #1
--- Logging error ---
Traceback (most recent call last):
  File "/sw/arch/Debian10/EB_production/2019/software/Anaconda3/2018.12/lib/python3.7/logging/__init__.py", line 1036, in emit
    stream.write(msg)
UnicodeEncodeError: 'latin-1' codec can't encode character '\u015f' in position 86: ordinal not in range(256)
Call stack:
  File "/sw/arch/Debian10/EB_production/2019/software/Anaconda3/2018.12/lib/python3.7/runpy.py", line 193, in _run_module_as_main
    "__main__", mod_spec)
  File "/sw/arch/Debian10/EB_production/2019/software/Anaconda3/2018.12/lib/python3.7/runpy.py", line 85, in _run_code
    exec(code, run_globals)
  File "/home/lcur0008/joeynmt/joeynmt/__main__.py", line 48, in <module>
    main()
  File "/home/lcur0008/joeynmt/joeynmt/__main__.py", line 35, in main
    train(cfg_file=args.config_path, skip_test=args.skip_test)
  File "/home/lcur0008/joeynmt/joeynmt/training.py", line 846, in train
    trainer.train_and_validate(train_data=train_data, valid_data=dev_data)
  File "/home/lcur0008/joeynmt/joeynmt/training.py", line 497, in train_and_validate
    valid_duration = self._validate(valid_data, epoch_no)
  File "/home/lcur0008/joeynmt/joeynmt/training.py", line 642, in _validate
    references=valid_references)
  File "/home/lcur0008/joeynmt/joeynmt/training.py", line 731, in _log_examples
    logger.debug("\tRaw source:     %s", sources_raw[p])
Message: '\tRaw source:     %s'
Arguments: (['1@@', '1', 'ya\u015f@@', '\u0131nday@@', 'ken', 'bir', 'sa@@', 'ba@@', 'h', 'ev@@', 'im@@', 'deki', 'sev@@', 'in@@', 'ç', 'ç@@', '\u0131\u011f@@', 'l\u0131@@', 'klar@@', '\u0131yla', 'u@@', 'yan@@', 'd\u0131\u011f@@', '\u0131m\u0131', 'hat\u0131r@@', 'l\u0131@@', 'yorum', '.'],)
--- Logging error ---
Traceback (most recent call last):
  File "/sw/arch/Debian10/EB_production/2019/software/Anaconda3/2018.12/lib/python3.7/logging/__init__.py", line 1036, in emit
    stream.write(msg)
UnicodeEncodeError: 'latin-1' codec can't encode characters in position 70-71: ordinal not in range(256)
Call stack:
  File "/sw/arch/Debian10/EB_production/2019/software/Anaconda3/2018.12/lib/python3.7/runpy.py", line 193, in _run_module_as_main
    "__main__", mod_spec)
  File "/sw/arch/Debian10/EB_production/2019/software/Anaconda3/2018.12/lib/python3.7/runpy.py", line 85, in _run_code
    exec(code, run_globals)
  File "/home/lcur0008/joeynmt/joeynmt/__main__.py", line 48, in <module>
    main()
  File "/home/lcur0008/joeynmt/joeynmt/__main__.py", line 35, in main
    train(cfg_file=args.config_path, skip_test=args.skip_test)
  File "/home/lcur0008/joeynmt/joeynmt/training.py", line 846, in train
    trainer.train_and_validate(train_data=train_data, valid_data=dev_data)
  File "/home/lcur0008/joeynmt/joeynmt/training.py", line 497, in train_and_validate
    valid_duration = self._validate(valid_data, epoch_no)
  File "/home/lcur0008/joeynmt/joeynmt/training.py", line 642, in _validate
    references=valid_references)
  File "/home/lcur0008/joeynmt/joeynmt/training.py", line 737, in _log_examples
    logger.info("\tSource:     %s", sources[p])
Message: '\tSource:     %s'
Arguments: ('11 ya\u015f\u0131ndayken bir sabah evimdeki sevinç ç\u0131\u011fl\u0131klar\u0131yla uyand\u0131\u011f\u0131m\u0131 hat\u0131rl\u0131yorum .',)
2021-10-02 15:19:53,142 - INFO - joeynmt.training - 	Source:     11 ya\u015f\u0131ndayken bir sabah evimdeki sevinç ç\u0131\u011fl\u0131klar\u0131yla uyand\u0131\u011f\u0131m\u0131 hat\u0131rl\u0131yorum .
2021-10-02 15:19:53,142 - INFO - joeynmt.training - 	Reference:  "When I was 11 , I remember waking up one morning to the sound of joy in my house ."
2021-10-02 15:19:53,142 - INFO - joeynmt.training - 	Hypothesis: "And I , , , , , , , , , , , , , , , , , , , , , , , , , , , , , the ." ." ."
2021-10-02 15:19:53,142 - INFO - joeynmt.training - Example #2
--- Logging error ---
Traceback (most recent call last):
  File "/sw/arch/Debian10/EB_production/2019/software/Anaconda3/2018.12/lib/python3.7/logging/__init__.py", line 1036, in emit
    stream.write(msg)
UnicodeEncodeError: 'latin-1' codec can't encode character '\u0131' in position 151: ordinal not in range(256)
Call stack:
  File "/sw/arch/Debian10/EB_production/2019/software/Anaconda3/2018.12/lib/python3.7/runpy.py", line 193, in _run_module_as_main
    "__main__", mod_spec)
  File "/sw/arch/Debian10/EB_production/2019/software/Anaconda3/2018.12/lib/python3.7/runpy.py", line 85, in _run_code
    exec(code, run_globals)
  File "/home/lcur0008/joeynmt/joeynmt/__main__.py", line 48, in <module>
    main()
  File "/home/lcur0008/joeynmt/joeynmt/__main__.py", line 35, in main
    train(cfg_file=args.config_path, skip_test=args.skip_test)
  File "/home/lcur0008/joeynmt/joeynmt/training.py", line 846, in train
    trainer.train_and_validate(train_data=train_data, valid_data=dev_data)
  File "/home/lcur0008/joeynmt/joeynmt/training.py", line 497, in train_and_validate
    valid_duration = self._validate(valid_data, epoch_no)
  File "/home/lcur0008/joeynmt/joeynmt/training.py", line 642, in _validate
    references=valid_references)
  File "/home/lcur0008/joeynmt/joeynmt/training.py", line 731, in _log_examples
    logger.debug("\tRaw source:     %s", sources_raw[p])
Message: '\tRaw source:     %s'
Arguments: (['"B@@', 'ab@@', 'am', 'B@@', 'B@@', 'C', 'H@@', 'ab@@', 'er', 'kan@@', 'al@@', '\u0131n\u0131', 'din@@', 'li@@', 'yordu', ';', 'o', 'uf@@', 'ak', ',', 'gr@@', 'i', 'rad@@', 'y@@', 'os@@', 'undan', '."'],)
--- Logging error ---
Traceback (most recent call last):
  File "/sw/arch/Debian10/EB_production/2019/software/Anaconda3/2018.12/lib/python3.7/logging/__init__.py", line 1036, in emit
    stream.write(msg)
UnicodeEncodeError: 'latin-1' codec can't encode character '\u0131' in position 87: ordinal not in range(256)
Call stack:
  File "/sw/arch/Debian10/EB_production/2019/software/Anaconda3/2018.12/lib/python3.7/runpy.py", line 193, in _run_module_as_main
    "__main__", mod_spec)
  File "/sw/arch/Debian10/EB_production/2019/software/Anaconda3/2018.12/lib/python3.7/runpy.py", line 85, in _run_code
    exec(code, run_globals)
  File "/home/lcur0008/joeynmt/joeynmt/__main__.py", line 48, in <module>
    main()
  File "/home/lcur0008/joeynmt/joeynmt/__main__.py", line 35, in main
    train(cfg_file=args.config_path, skip_test=args.skip_test)
  File "/home/lcur0008/joeynmt/joeynmt/training.py", line 846, in train
    trainer.train_and_validate(train_data=train_data, valid_data=dev_data)
  File "/home/lcur0008/joeynmt/joeynmt/training.py", line 497, in train_and_validate
    valid_duration = self._validate(valid_data, epoch_no)
  File "/home/lcur0008/joeynmt/joeynmt/training.py", line 642, in _validate
    references=valid_references)
  File "/home/lcur0008/joeynmt/joeynmt/training.py", line 737, in _log_examples
    logger.info("\tSource:     %s", sources[p])
Message: '\tSource:     %s'
Arguments: ('"Babam BBC Haber kanal\u0131n\u0131 dinliyordu ; o ufak , gri radyosundan ."',)
2021-10-02 15:19:53,143 - INFO - joeynmt.training - 	Source:     "Babam BBC Haber kanal\u0131n\u0131 dinliyordu ; o ufak , gri radyosundan ."
2021-10-02 15:19:53,143 - INFO - joeynmt.training - 	Reference:  "My father was listening to BBC News on his small , gray radio ."
2021-10-02 15:19:53,143 - INFO - joeynmt.training - 	Hypothesis: "And &apos;s , , , , , , , , , , , , , , , , , the the ." ." ."
2021-10-02 15:19:53,143 - INFO - joeynmt.training - Validation result (greedy) at epoch  17, step     1100: bleu:   0.06, loss: 94019.2969, ppl: 488.8216, duration: 1.8531s
2021-10-02 15:19:55,877 - INFO - joeynmt.training - Epoch  17: total training loss 8284.27
2021-10-02 15:19:55,877 - INFO - joeynmt.training - EPOCH 18
2021-10-02 15:20:10,730 - INFO - joeynmt.training - Epoch  18: total training loss 8284.66
2021-10-02 15:20:10,730 - INFO - joeynmt.training - EPOCH 19
2021-10-02 15:20:19,503 - WARNING - sacrebleu - That's 100 lines that end in a tokenized period ('.')
2021-10-02 15:20:19,503 - WARNING - sacrebleu - It looks like you forgot to detokenize your test data, which may hurt your score.
2021-10-02 15:20:19,503 - WARNING - sacrebleu - If you insist your data is detokenized, or don't care, you can suppress this message with the `force` parameter.
2021-10-02 15:20:19,511 - INFO - joeynmt.training - Example #0
2021-10-02 15:20:19,511 - INFO - joeynmt.training - 	Source:     tr
2021-10-02 15:20:19,511 - INFO - joeynmt.training - 	Reference:  en
2021-10-02 15:20:19,511 - INFO - joeynmt.training - 	Hypothesis: ( Applause
2021-10-02 15:20:19,511 - INFO - joeynmt.training - Example #1
--- Logging error ---
Traceback (most recent call last):
  File "/sw/arch/Debian10/EB_production/2019/software/Anaconda3/2018.12/lib/python3.7/logging/__init__.py", line 1036, in emit
    stream.write(msg)
UnicodeEncodeError: 'latin-1' codec can't encode character '\u015f' in position 86: ordinal not in range(256)
Call stack:
  File "/sw/arch/Debian10/EB_production/2019/software/Anaconda3/2018.12/lib/python3.7/runpy.py", line 193, in _run_module_as_main
    "__main__", mod_spec)
  File "/sw/arch/Debian10/EB_production/2019/software/Anaconda3/2018.12/lib/python3.7/runpy.py", line 85, in _run_code
    exec(code, run_globals)
  File "/home/lcur0008/joeynmt/joeynmt/__main__.py", line 48, in <module>
    main()
  File "/home/lcur0008/joeynmt/joeynmt/__main__.py", line 35, in main
    train(cfg_file=args.config_path, skip_test=args.skip_test)
  File "/home/lcur0008/joeynmt/joeynmt/training.py", line 846, in train
    trainer.train_and_validate(train_data=train_data, valid_data=dev_data)
  File "/home/lcur0008/joeynmt/joeynmt/training.py", line 497, in train_and_validate
    valid_duration = self._validate(valid_data, epoch_no)
  File "/home/lcur0008/joeynmt/joeynmt/training.py", line 642, in _validate
    references=valid_references)
  File "/home/lcur0008/joeynmt/joeynmt/training.py", line 731, in _log_examples
    logger.debug("\tRaw source:     %s", sources_raw[p])
Message: '\tRaw source:     %s'
Arguments: (['1@@', '1', 'ya\u015f@@', '\u0131nday@@', 'ken', 'bir', 'sa@@', 'ba@@', 'h', 'ev@@', 'im@@', 'deki', 'sev@@', 'in@@', 'ç', 'ç@@', '\u0131\u011f@@', 'l\u0131@@', 'klar@@', '\u0131yla', 'u@@', 'yan@@', 'd\u0131\u011f@@', '\u0131m\u0131', 'hat\u0131r@@', 'l\u0131@@', 'yorum', '.'],)
--- Logging error ---
Traceback (most recent call last):
  File "/sw/arch/Debian10/EB_production/2019/software/Anaconda3/2018.12/lib/python3.7/logging/__init__.py", line 1036, in emit
    stream.write(msg)
UnicodeEncodeError: 'latin-1' codec can't encode characters in position 70-71: ordinal not in range(256)
Call stack:
  File "/sw/arch/Debian10/EB_production/2019/software/Anaconda3/2018.12/lib/python3.7/runpy.py", line 193, in _run_module_as_main
    "__main__", mod_spec)
  File "/sw/arch/Debian10/EB_production/2019/software/Anaconda3/2018.12/lib/python3.7/runpy.py", line 85, in _run_code
    exec(code, run_globals)
  File "/home/lcur0008/joeynmt/joeynmt/__main__.py", line 48, in <module>
    main()
  File "/home/lcur0008/joeynmt/joeynmt/__main__.py", line 35, in main
    train(cfg_file=args.config_path, skip_test=args.skip_test)
  File "/home/lcur0008/joeynmt/joeynmt/training.py", line 846, in train
    trainer.train_and_validate(train_data=train_data, valid_data=dev_data)
  File "/home/lcur0008/joeynmt/joeynmt/training.py", line 497, in train_and_validate
    valid_duration = self._validate(valid_data, epoch_no)
  File "/home/lcur0008/joeynmt/joeynmt/training.py", line 642, in _validate
    references=valid_references)
  File "/home/lcur0008/joeynmt/joeynmt/training.py", line 737, in _log_examples
    logger.info("\tSource:     %s", sources[p])
Message: '\tSource:     %s'
Arguments: ('11 ya\u015f\u0131ndayken bir sabah evimdeki sevinç ç\u0131\u011fl\u0131klar\u0131yla uyand\u0131\u011f\u0131m\u0131 hat\u0131rl\u0131yorum .',)
2021-10-02 15:20:19,512 - INFO - joeynmt.training - 	Source:     11 ya\u015f\u0131ndayken bir sabah evimdeki sevinç ç\u0131\u011fl\u0131klar\u0131yla uyand\u0131\u011f\u0131m\u0131 hat\u0131rl\u0131yorum .
2021-10-02 15:20:19,513 - INFO - joeynmt.training - 	Reference:  "When I was 11 , I remember waking up one morning to the sound of joy in my house ."
2021-10-02 15:20:19,513 - INFO - joeynmt.training - 	Hypothesis: "And I , , , , , , , , , , , , , , , , , , , , , , , , , , , , , the ." ." ."
2021-10-02 15:20:19,513 - INFO - joeynmt.training - Example #2
--- Logging error ---
Traceback (most recent call last):
  File "/sw/arch/Debian10/EB_production/2019/software/Anaconda3/2018.12/lib/python3.7/logging/__init__.py", line 1036, in emit
    stream.write(msg)
UnicodeEncodeError: 'latin-1' codec can't encode character '\u0131' in position 151: ordinal not in range(256)
Call stack:
  File "/sw/arch/Debian10/EB_production/2019/software/Anaconda3/2018.12/lib/python3.7/runpy.py", line 193, in _run_module_as_main
    "__main__", mod_spec)
  File "/sw/arch/Debian10/EB_production/2019/software/Anaconda3/2018.12/lib/python3.7/runpy.py", line 85, in _run_code
    exec(code, run_globals)
  File "/home/lcur0008/joeynmt/joeynmt/__main__.py", line 48, in <module>
    main()
  File "/home/lcur0008/joeynmt/joeynmt/__main__.py", line 35, in main
    train(cfg_file=args.config_path, skip_test=args.skip_test)
  File "/home/lcur0008/joeynmt/joeynmt/training.py", line 846, in train
    trainer.train_and_validate(train_data=train_data, valid_data=dev_data)
  File "/home/lcur0008/joeynmt/joeynmt/training.py", line 497, in train_and_validate
    valid_duration = self._validate(valid_data, epoch_no)
  File "/home/lcur0008/joeynmt/joeynmt/training.py", line 642, in _validate
    references=valid_references)
  File "/home/lcur0008/joeynmt/joeynmt/training.py", line 731, in _log_examples
    logger.debug("\tRaw source:     %s", sources_raw[p])
Message: '\tRaw source:     %s'
Arguments: (['"B@@', 'ab@@', 'am', 'B@@', 'B@@', 'C', 'H@@', 'ab@@', 'er', 'kan@@', 'al@@', '\u0131n\u0131', 'din@@', 'li@@', 'yordu', ';', 'o', 'uf@@', 'ak', ',', 'gr@@', 'i', 'rad@@', 'y@@', 'os@@', 'undan', '."'],)
--- Logging error ---
Traceback (most recent call last):
  File "/sw/arch/Debian10/EB_production/2019/software/Anaconda3/2018.12/lib/python3.7/logging/__init__.py", line 1036, in emit
    stream.write(msg)
UnicodeEncodeError: 'latin-1' codec can't encode character '\u0131' in position 87: ordinal not in range(256)
Call stack:
  File "/sw/arch/Debian10/EB_production/2019/software/Anaconda3/2018.12/lib/python3.7/runpy.py", line 193, in _run_module_as_main
    "__main__", mod_spec)
  File "/sw/arch/Debian10/EB_production/2019/software/Anaconda3/2018.12/lib/python3.7/runpy.py", line 85, in _run_code
    exec(code, run_globals)
  File "/home/lcur0008/joeynmt/joeynmt/__main__.py", line 48, in <module>
    main()
  File "/home/lcur0008/joeynmt/joeynmt/__main__.py", line 35, in main
    train(cfg_file=args.config_path, skip_test=args.skip_test)
  File "/home/lcur0008/joeynmt/joeynmt/training.py", line 846, in train
    trainer.train_and_validate(train_data=train_data, valid_data=dev_data)
  File "/home/lcur0008/joeynmt/joeynmt/training.py", line 497, in train_and_validate
    valid_duration = self._validate(valid_data, epoch_no)
  File "/home/lcur0008/joeynmt/joeynmt/training.py", line 642, in _validate
    references=valid_references)
  File "/home/lcur0008/joeynmt/joeynmt/training.py", line 737, in _log_examples
    logger.info("\tSource:     %s", sources[p])
Message: '\tSource:     %s'
Arguments: ('"Babam BBC Haber kanal\u0131n\u0131 dinliyordu ; o ufak , gri radyosundan ."',)
2021-10-02 15:20:19,513 - INFO - joeynmt.training - 	Source:     "Babam BBC Haber kanal\u0131n\u0131 dinliyordu ; o ufak , gri radyosundan ."
2021-10-02 15:20:19,514 - INFO - joeynmt.training - 	Reference:  "My father was listening to BBC News on his small , gray radio ."
2021-10-02 15:20:19,514 - INFO - joeynmt.training - 	Hypothesis: "And &apos;s , , , , , , , , , , , , , , , , , the the ." ." ."
2021-10-02 15:20:19,514 - INFO - joeynmt.training - Validation result (greedy) at epoch  19, step     1200: bleu:   0.06, loss: 94019.2188, ppl: 488.8192, duration: 1.8759s
2021-10-02 15:20:28,842 - INFO - joeynmt.training - Epoch  19: total training loss 8283.17
2021-10-02 15:20:28,843 - INFO - joeynmt.training - EPOCH 20
2021-10-02 15:20:45,310 - WARNING - sacrebleu - That's 100 lines that end in a tokenized period ('.')
2021-10-02 15:20:45,310 - WARNING - sacrebleu - It looks like you forgot to detokenize your test data, which may hurt your score.
2021-10-02 15:20:45,310 - WARNING - sacrebleu - If you insist your data is detokenized, or don't care, you can suppress this message with the `force` parameter.
2021-10-02 15:20:45,316 - INFO - joeynmt.training - Example #0
2021-10-02 15:20:45,316 - INFO - joeynmt.training - 	Source:     tr
2021-10-02 15:20:45,316 - INFO - joeynmt.training - 	Reference:  en
2021-10-02 15:20:45,316 - INFO - joeynmt.training - 	Hypothesis: ( Applause
2021-10-02 15:20:45,317 - INFO - joeynmt.training - Example #1
--- Logging error ---
Traceback (most recent call last):
  File "/sw/arch/Debian10/EB_production/2019/software/Anaconda3/2018.12/lib/python3.7/logging/__init__.py", line 1036, in emit
    stream.write(msg)
UnicodeEncodeError: 'latin-1' codec can't encode character '\u015f' in position 86: ordinal not in range(256)
Call stack:
  File "/sw/arch/Debian10/EB_production/2019/software/Anaconda3/2018.12/lib/python3.7/runpy.py", line 193, in _run_module_as_main
    "__main__", mod_spec)
  File "/sw/arch/Debian10/EB_production/2019/software/Anaconda3/2018.12/lib/python3.7/runpy.py", line 85, in _run_code
    exec(code, run_globals)
  File "/home/lcur0008/joeynmt/joeynmt/__main__.py", line 48, in <module>
    main()
  File "/home/lcur0008/joeynmt/joeynmt/__main__.py", line 35, in main
    train(cfg_file=args.config_path, skip_test=args.skip_test)
  File "/home/lcur0008/joeynmt/joeynmt/training.py", line 846, in train
    trainer.train_and_validate(train_data=train_data, valid_data=dev_data)
  File "/home/lcur0008/joeynmt/joeynmt/training.py", line 497, in train_and_validate
    valid_duration = self._validate(valid_data, epoch_no)
  File "/home/lcur0008/joeynmt/joeynmt/training.py", line 642, in _validate
    references=valid_references)
  File "/home/lcur0008/joeynmt/joeynmt/training.py", line 731, in _log_examples
    logger.debug("\tRaw source:     %s", sources_raw[p])
Message: '\tRaw source:     %s'
Arguments: (['1@@', '1', 'ya\u015f@@', '\u0131nday@@', 'ken', 'bir', 'sa@@', 'ba@@', 'h', 'ev@@', 'im@@', 'deki', 'sev@@', 'in@@', 'ç', 'ç@@', '\u0131\u011f@@', 'l\u0131@@', 'klar@@', '\u0131yla', 'u@@', 'yan@@', 'd\u0131\u011f@@', '\u0131m\u0131', 'hat\u0131r@@', 'l\u0131@@', 'yorum', '.'],)
--- Logging error ---
Traceback (most recent call last):
  File "/sw/arch/Debian10/EB_production/2019/software/Anaconda3/2018.12/lib/python3.7/logging/__init__.py", line 1036, in emit
    stream.write(msg)
UnicodeEncodeError: 'latin-1' codec can't encode characters in position 70-71: ordinal not in range(256)
Call stack:
  File "/sw/arch/Debian10/EB_production/2019/software/Anaconda3/2018.12/lib/python3.7/runpy.py", line 193, in _run_module_as_main
    "__main__", mod_spec)
  File "/sw/arch/Debian10/EB_production/2019/software/Anaconda3/2018.12/lib/python3.7/runpy.py", line 85, in _run_code
    exec(code, run_globals)
  File "/home/lcur0008/joeynmt/joeynmt/__main__.py", line 48, in <module>
    main()
  File "/home/lcur0008/joeynmt/joeynmt/__main__.py", line 35, in main
    train(cfg_file=args.config_path, skip_test=args.skip_test)
  File "/home/lcur0008/joeynmt/joeynmt/training.py", line 846, in train
    trainer.train_and_validate(train_data=train_data, valid_data=dev_data)
  File "/home/lcur0008/joeynmt/joeynmt/training.py", line 497, in train_and_validate
    valid_duration = self._validate(valid_data, epoch_no)
  File "/home/lcur0008/joeynmt/joeynmt/training.py", line 642, in _validate
    references=valid_references)
  File "/home/lcur0008/joeynmt/joeynmt/training.py", line 737, in _log_examples
    logger.info("\tSource:     %s", sources[p])
Message: '\tSource:     %s'
Arguments: ('11 ya\u015f\u0131ndayken bir sabah evimdeki sevinç ç\u0131\u011fl\u0131klar\u0131yla uyand\u0131\u011f\u0131m\u0131 hat\u0131rl\u0131yorum .',)
2021-10-02 15:20:45,318 - INFO - joeynmt.training - 	Source:     11 ya\u015f\u0131ndayken bir sabah evimdeki sevinç ç\u0131\u011fl\u0131klar\u0131yla uyand\u0131\u011f\u0131m\u0131 hat\u0131rl\u0131yorum .
2021-10-02 15:20:45,318 - INFO - joeynmt.training - 	Reference:  "When I was 11 , I remember waking up one morning to the sound of joy in my house ."
2021-10-02 15:20:45,318 - INFO - joeynmt.training - 	Hypothesis: "And I , , , , , , , , , , , , , , , , , , , , , , , , , , , , , the ." ." ."
2021-10-02 15:20:45,318 - INFO - joeynmt.training - Example #2
--- Logging error ---
Traceback (most recent call last):
  File "/sw/arch/Debian10/EB_production/2019/software/Anaconda3/2018.12/lib/python3.7/logging/__init__.py", line 1036, in emit
    stream.write(msg)
UnicodeEncodeError: 'latin-1' codec can't encode character '\u0131' in position 151: ordinal not in range(256)
Call stack:
  File "/sw/arch/Debian10/EB_production/2019/software/Anaconda3/2018.12/lib/python3.7/runpy.py", line 193, in _run_module_as_main
    "__main__", mod_spec)
  File "/sw/arch/Debian10/EB_production/2019/software/Anaconda3/2018.12/lib/python3.7/runpy.py", line 85, in _run_code
    exec(code, run_globals)
  File "/home/lcur0008/joeynmt/joeynmt/__main__.py", line 48, in <module>
    main()
  File "/home/lcur0008/joeynmt/joeynmt/__main__.py", line 35, in main
    train(cfg_file=args.config_path, skip_test=args.skip_test)
  File "/home/lcur0008/joeynmt/joeynmt/training.py", line 846, in train
    trainer.train_and_validate(train_data=train_data, valid_data=dev_data)
  File "/home/lcur0008/joeynmt/joeynmt/training.py", line 497, in train_and_validate
    valid_duration = self._validate(valid_data, epoch_no)
  File "/home/lcur0008/joeynmt/joeynmt/training.py", line 642, in _validate
    references=valid_references)
  File "/home/lcur0008/joeynmt/joeynmt/training.py", line 731, in _log_examples
    logger.debug("\tRaw source:     %s", sources_raw[p])
Message: '\tRaw source:     %s'
Arguments: (['"B@@', 'ab@@', 'am', 'B@@', 'B@@', 'C', 'H@@', 'ab@@', 'er', 'kan@@', 'al@@', '\u0131n\u0131', 'din@@', 'li@@', 'yordu', ';', 'o', 'uf@@', 'ak', ',', 'gr@@', 'i', 'rad@@', 'y@@', 'os@@', 'undan', '."'],)
--- Logging error ---
Traceback (most recent call last):
  File "/sw/arch/Debian10/EB_production/2019/software/Anaconda3/2018.12/lib/python3.7/logging/__init__.py", line 1036, in emit
    stream.write(msg)
UnicodeEncodeError: 'latin-1' codec can't encode character '\u0131' in position 87: ordinal not in range(256)
Call stack:
  File "/sw/arch/Debian10/EB_production/2019/software/Anaconda3/2018.12/lib/python3.7/runpy.py", line 193, in _run_module_as_main
    "__main__", mod_spec)
  File "/sw/arch/Debian10/EB_production/2019/software/Anaconda3/2018.12/lib/python3.7/runpy.py", line 85, in _run_code
    exec(code, run_globals)
  File "/home/lcur0008/joeynmt/joeynmt/__main__.py", line 48, in <module>
    main()
  File "/home/lcur0008/joeynmt/joeynmt/__main__.py", line 35, in main
    train(cfg_file=args.config_path, skip_test=args.skip_test)
  File "/home/lcur0008/joeynmt/joeynmt/training.py", line 846, in train
    trainer.train_and_validate(train_data=train_data, valid_data=dev_data)
  File "/home/lcur0008/joeynmt/joeynmt/training.py", line 497, in train_and_validate
    valid_duration = self._validate(valid_data, epoch_no)
  File "/home/lcur0008/joeynmt/joeynmt/training.py", line 642, in _validate
    references=valid_references)
  File "/home/lcur0008/joeynmt/joeynmt/training.py", line 737, in _log_examples
    logger.info("\tSource:     %s", sources[p])
Message: '\tSource:     %s'
Arguments: ('"Babam BBC Haber kanal\u0131n\u0131 dinliyordu ; o ufak , gri radyosundan ."',)
2021-10-02 15:20:45,319 - INFO - joeynmt.training - 	Source:     "Babam BBC Haber kanal\u0131n\u0131 dinliyordu ; o ufak , gri radyosundan ."
2021-10-02 15:20:45,319 - INFO - joeynmt.training - 	Reference:  "My father was listening to BBC News on his small , gray radio ."
2021-10-02 15:20:45,319 - INFO - joeynmt.training - 	Hypothesis: "And &apos;s , , , , , , , , , , , , , , , , , the the ." ." ."
2021-10-02 15:20:45,319 - INFO - joeynmt.training - Validation result (greedy) at epoch  20, step     1300: bleu:   0.06, loss: 94020.4531, ppl: 488.8589, duration: 1.8513s
2021-10-02 15:20:46,907 - INFO - joeynmt.training - Training ended since minimum lr 1e-08 was reached.
2021-10-02 15:20:46,917 - INFO - joeynmt.training - Best validation result (greedy) at step      500:   0.07 eval_metric.
2021-10-02 15:20:46,948 - INFO - joeynmt.prediction - Process device: cuda, n_gpu: 1, batch_size per device: 80
2021-10-02 15:20:46,948 - INFO - joeynmt.prediction - Loading model from models/tr_en_bpe_model/500.ckpt
2021-10-02 15:20:47,293 - INFO - joeynmt.model - Building an encoder-decoder model...
2021-10-02 15:20:47,838 - INFO - joeynmt.model - Enc-dec model built.
2021-10-02 15:20:47,900 - INFO - joeynmt.prediction - Decoding on dev set (../2DL4NLP/all_data/val.bpe.en)...
2021-10-02 15:20:51,347 - WARNING - sacrebleu - That's 100 lines that end in a tokenized period ('.')
2021-10-02 15:20:51,347 - WARNING - sacrebleu - It looks like you forgot to detokenize your test data, which may hurt your score.
2021-10-02 15:20:51,347 - WARNING - sacrebleu - If you insist your data is detokenized, or don't care, you can suppress this message with the `force` parameter.
2021-10-02 15:20:51,350 - INFO - joeynmt.prediction -  dev bleu[none]:   0.06 [Beam search decoding with beam size = 5 and alpha = 1.0]
2021-10-02 15:20:51,352 - INFO - joeynmt.prediction - Translations saved to: models/tr_en_bpe_model/00000500.hyps.dev
2021-10-02 15:20:51,353 - INFO - joeynmt.prediction - Decoding on test set (../2DL4NLP/all_data/test.bpe.en)...
2021-10-02 15:20:55,260 - WARNING - sacrebleu - That's 100 lines that end in a tokenized period ('.')
2021-10-02 15:20:55,260 - WARNING - sacrebleu - It looks like you forgot to detokenize your test data, which may hurt your score.
2021-10-02 15:20:55,260 - WARNING - sacrebleu - If you insist your data is detokenized, or don't care, you can suppress this message with the `force` parameter.
2021-10-02 15:20:55,264 - INFO - joeynmt.prediction - test bleu[none]:   0.06 [Beam search decoding with beam size = 5 and alpha = 1.0]
2021-10-02 15:20:55,266 - INFO - joeynmt.prediction - Translations saved to: models/tr_en_bpe_model/00000500.hyps.test
