2021-10-03 13:23:31,957 - INFO - root - Hello! This is Joey-NMT (version 1.3).
2021-10-03 13:23:32,020 - INFO - joeynmt.data - Loading training data...
2021-10-03 13:23:32,136 - INFO - joeynmt.data - Building vocabulary...
2021-10-03 13:23:32,618 - INFO - joeynmt.data - Loading dev data...
2021-10-03 13:23:32,631 - INFO - joeynmt.data - Loading test data...
2021-10-03 13:23:32,643 - INFO - joeynmt.data - Data loaded.
2021-10-03 13:23:32,643 - INFO - joeynmt.model - Building an encoder-decoder model...
2021-10-03 13:23:33,187 - INFO - joeynmt.model - Enc-dec model built.
2021-10-03 13:23:33,193 - INFO - joeynmt.training - Total params: 24931328
2021-10-03 13:23:37,450 - INFO - joeynmt.helpers - cfg.name                           : LSTM_el
2021-10-03 13:23:37,450 - INFO - joeynmt.helpers - cfg.data.src                       : el
2021-10-03 13:23:37,450 - INFO - joeynmt.helpers - cfg.data.trg                       : en_s
2021-10-03 13:23:37,451 - INFO - joeynmt.helpers - cfg.data.train                     : ../2DL4NLP/all_data/el.en_s/train.bpe
2021-10-03 13:23:37,451 - INFO - joeynmt.helpers - cfg.data.dev                       : ../2DL4NLP/all_data/el.en_s/val.bpe
2021-10-03 13:23:37,451 - INFO - joeynmt.helpers - cfg.data.test                      : ../2DL4NLP/all_data/el.en_s/test.bpe
2021-10-03 13:23:37,451 - INFO - joeynmt.helpers - cfg.data.level                     : bpe
2021-10-03 13:23:37,451 - INFO - joeynmt.helpers - cfg.data.lowercase                 : False
2021-10-03 13:23:37,451 - INFO - joeynmt.helpers - cfg.data.max_sent_length           : 50
2021-10-03 13:23:37,451 - INFO - joeynmt.helpers - cfg.data.src_voc_min_freq          : 0
2021-10-03 13:23:37,451 - INFO - joeynmt.helpers - cfg.data.src_voc_limit             : 100000
2021-10-03 13:23:37,451 - INFO - joeynmt.helpers - cfg.data.trg_voc_min_freq          : 0
2021-10-03 13:23:37,451 - INFO - joeynmt.helpers - cfg.data.trg_voc_limit             : 100000
2021-10-03 13:23:37,452 - INFO - joeynmt.helpers - cfg.data.src_vocab                 : ../2DL4NLP/all_data/el.en_s/el.en_s.vocab.txt
2021-10-03 13:23:37,452 - INFO - joeynmt.helpers - cfg.data.trg_vocab                 : ../2DL4NLP/all_data/el.en_s/el.en_s.vocab.txt
2021-10-03 13:23:37,452 - INFO - joeynmt.helpers - cfg.testing.beam_size              : 5
2021-10-03 13:23:37,452 - INFO - joeynmt.helpers - cfg.testing.alpha                  : 1.0
2021-10-03 13:23:37,452 - INFO - joeynmt.helpers - cfg.training.random_seed           : 42
2021-10-03 13:23:37,452 - INFO - joeynmt.helpers - cfg.training.optimizer             : adam
2021-10-03 13:23:37,452 - INFO - joeynmt.helpers - cfg.training.learning_rate         : 0.0003
2021-10-03 13:23:37,452 - INFO - joeynmt.helpers - cfg.training.learning_rate_min     : 5e-07
2021-10-03 13:23:37,452 - INFO - joeynmt.helpers - cfg.training.weight_decay          : 0.0
2021-10-03 13:23:37,452 - INFO - joeynmt.helpers - cfg.training.clip_grad_norm        : 1.0
2021-10-03 13:23:37,452 - INFO - joeynmt.helpers - cfg.training.batch_size            : 80
2021-10-03 13:23:37,452 - INFO - joeynmt.helpers - cfg.training.scheduling            : plateau
2021-10-03 13:23:37,452 - INFO - joeynmt.helpers - cfg.training.patience              : 10
2021-10-03 13:23:37,452 - INFO - joeynmt.helpers - cfg.training.decrease_factor       : 0.5
2021-10-03 13:23:37,452 - INFO - joeynmt.helpers - cfg.training.early_stopping_metric : eval_metric
2021-10-03 13:23:37,453 - INFO - joeynmt.helpers - cfg.training.epochs                : 20
2021-10-03 13:23:37,453 - INFO - joeynmt.helpers - cfg.training.validation_freq       : 100
2021-10-03 13:23:37,453 - INFO - joeynmt.helpers - cfg.training.logging_freq          : 1000
2021-10-03 13:23:37,453 - INFO - joeynmt.helpers - cfg.training.eval_metric           : bleu
2021-10-03 13:23:37,453 - INFO - joeynmt.helpers - cfg.training.model_dir             : models/LSTM_el
2021-10-03 13:23:37,453 - INFO - joeynmt.helpers - cfg.training.overwrite             : True
2021-10-03 13:23:37,453 - INFO - joeynmt.helpers - cfg.training.shuffle               : True
2021-10-03 13:23:37,453 - INFO - joeynmt.helpers - cfg.training.use_cuda              : True
2021-10-03 13:23:37,453 - INFO - joeynmt.helpers - cfg.training.max_output_length     : 100
2021-10-03 13:23:37,453 - INFO - joeynmt.helpers - cfg.training.print_valid_sents     : [0, 1, 2]
2021-10-03 13:23:37,453 - INFO - joeynmt.helpers - cfg.training.keep_best_ckpts       : 1
2021-10-03 13:23:37,453 - INFO - joeynmt.helpers - cfg.training.save_latest_ckpt      : True
2021-10-03 13:23:37,453 - INFO - joeynmt.helpers - cfg.model.encoder.rnn_type         : lstm
2021-10-03 13:23:37,453 - INFO - joeynmt.helpers - cfg.model.encoder.embeddings.embedding_dim : 512
2021-10-03 13:23:37,453 - INFO - joeynmt.helpers - cfg.model.encoder.embeddings.scale : False
2021-10-03 13:23:37,454 - INFO - joeynmt.helpers - cfg.model.encoder.hidden_size      : 512
2021-10-03 13:23:37,454 - INFO - joeynmt.helpers - cfg.model.encoder.bidirectional    : False
2021-10-03 13:23:37,454 - INFO - joeynmt.helpers - cfg.model.encoder.dropout          : 0.2
2021-10-03 13:23:37,454 - INFO - joeynmt.helpers - cfg.model.encoder.num_layers       : 1
2021-10-03 13:23:37,454 - INFO - joeynmt.helpers - cfg.model.decoder.rnn_type         : lstm
2021-10-03 13:23:37,454 - INFO - joeynmt.helpers - cfg.model.decoder.embeddings.embedding_dim : 512
2021-10-03 13:23:37,454 - INFO - joeynmt.helpers - cfg.model.decoder.embeddings.scale : False
2021-10-03 13:23:37,454 - INFO - joeynmt.helpers - cfg.model.decoder.emb_scale        : False
2021-10-03 13:23:37,454 - INFO - joeynmt.helpers - cfg.model.decoder.hidden_size      : 1024
2021-10-03 13:23:37,454 - INFO - joeynmt.helpers - cfg.model.decoder.dropout          : 0.2
2021-10-03 13:23:37,454 - INFO - joeynmt.helpers - cfg.model.decoder.hidden_dropout   : 0.2
2021-10-03 13:23:37,454 - INFO - joeynmt.helpers - cfg.model.decoder.num_layers       : 1
2021-10-03 13:23:37,454 - INFO - joeynmt.helpers - cfg.model.decoder.input_feeding    : True
2021-10-03 13:23:37,454 - INFO - joeynmt.helpers - cfg.model.decoder.init_hidden      : bridge
2021-10-03 13:23:37,454 - INFO - joeynmt.helpers - cfg.model.decoder.attention        : bahdanau
2021-10-03 13:23:37,455 - INFO - joeynmt.helpers - Data set sizes: 
	train 5008,
	valid 551,
	test 602
2021-10-03 13:23:37,455 - INFO - joeynmt.helpers - First training example:
	[SRC] el
	[TRG] en
--- Logging error ---
Traceback (most recent call last):
  File "/sw/arch/Debian10/EB_production/2019/software/Anaconda3/2018.12/lib/python3.7/logging/__init__.py", line 1036, in emit
    stream.write(msg)
UnicodeEncodeError: 'latin-1' codec can't encode characters in position 141-142: ordinal not in range(256)
Call stack:
  File "/sw/arch/Debian10/EB_production/2019/software/Anaconda3/2018.12/lib/python3.7/runpy.py", line 193, in _run_module_as_main
    "__main__", mod_spec)
  File "/sw/arch/Debian10/EB_production/2019/software/Anaconda3/2018.12/lib/python3.7/runpy.py", line 85, in _run_code
    exec(code, run_globals)
  File "/home/lcur0009/joeynmt/joeynmt/__main__.py", line 48, in <module>
    main()
  File "/home/lcur0009/joeynmt/joeynmt/__main__.py", line 35, in main
    train(cfg_file=args.config_path, skip_test=args.skip_test)
  File "/home/lcur0009/joeynmt/joeynmt/training.py", line 835, in train
    trg_vocab=trg_vocab)
  File "/home/lcur0009/joeynmt/joeynmt/helpers.py", line 164, in log_data_info
    " ".join('(%d) %s' % (i, t) for i, t in enumerate(src_vocab.itos[:10])))
Message: 'First 10 words (src): %s'
Arguments: ('(0) <unk> (1) <pad> (2) <s> (3) </s> (4) , (5) . (6) ." (7) the (8) \u03bd\u03b1 (9) of',)
2021-10-03 13:23:37,455 - INFO - joeynmt.helpers - First 10 words (src): (0) <unk> (1) <pad> (2) <s> (3) </s> (4) , (5) . (6) ." (7) the (8) \u03bd\u03b1 (9) of
--- Logging error ---
Traceback (most recent call last):
  File "/sw/arch/Debian10/EB_production/2019/software/Anaconda3/2018.12/lib/python3.7/logging/__init__.py", line 1036, in emit
    stream.write(msg)
UnicodeEncodeError: 'latin-1' codec can't encode characters in position 141-142: ordinal not in range(256)
Call stack:
  File "/sw/arch/Debian10/EB_production/2019/software/Anaconda3/2018.12/lib/python3.7/runpy.py", line 193, in _run_module_as_main
    "__main__", mod_spec)
  File "/sw/arch/Debian10/EB_production/2019/software/Anaconda3/2018.12/lib/python3.7/runpy.py", line 85, in _run_code
    exec(code, run_globals)
  File "/home/lcur0009/joeynmt/joeynmt/__main__.py", line 48, in <module>
    main()
  File "/home/lcur0009/joeynmt/joeynmt/__main__.py", line 35, in main
    train(cfg_file=args.config_path, skip_test=args.skip_test)
  File "/home/lcur0009/joeynmt/joeynmt/training.py", line 835, in train
    trg_vocab=trg_vocab)
  File "/home/lcur0009/joeynmt/joeynmt/helpers.py", line 167, in log_data_info
    " ".join('(%d) %s' % (i, t) for i, t in enumerate(trg_vocab.itos[:10])))
Message: 'First 10 words (trg): %s'
Arguments: ('(0) <unk> (1) <pad> (2) <s> (3) </s> (4) , (5) . (6) ." (7) the (8) \u03bd\u03b1 (9) of',)
2021-10-03 13:23:37,456 - INFO - joeynmt.helpers - First 10 words (trg): (0) <unk> (1) <pad> (2) <s> (3) </s> (4) , (5) . (6) ." (7) the (8) \u03bd\u03b1 (9) of
2021-10-03 13:23:37,457 - INFO - joeynmt.helpers - Number of Src words (types): 4230
2021-10-03 13:23:37,457 - INFO - joeynmt.helpers - Number of Trg words (types): 4230
2021-10-03 13:23:37,457 - INFO - joeynmt.training - Model(
	encoder=RecurrentEncoder(LSTM(512, 512, batch_first=True)),
	decoder=RecurrentDecoder(rnn=LSTM(1536, 1024, batch_first=True), attention=BahdanauAttention),
	src_embed=Embeddings(embedding_dim=512, vocab_size=4230),
	trg_embed=Embeddings(embedding_dim=512, vocab_size=4230))
2021-10-03 13:23:37,565 - INFO - joeynmt.training - Train stats:
	device: cuda
	n_gpu: 1
	16-bits training: False
	gradient accumulation: 1
	batch size per device: 80
	total batch size (w. parallel & accumulation): 80
2021-10-03 13:23:37,565 - INFO - joeynmt.training - EPOCH 1
2021-10-03 13:23:50,561 - INFO - joeynmt.training - Epoch   1: total training loss 8629.76
2021-10-03 13:23:50,562 - INFO - joeynmt.training - EPOCH 2
2021-10-03 13:24:01,104 - WARNING - sacrebleu - That's 100 lines that end in a tokenized period ('.')
2021-10-03 13:24:01,104 - WARNING - sacrebleu - It looks like you forgot to detokenize your test data, which may hurt your score.
2021-10-03 13:24:01,105 - WARNING - sacrebleu - If you insist your data is detokenized, or don't care, you can suppress this message with the `force` parameter.
2021-10-03 13:24:01,109 - INFO - joeynmt.training - Hooray! New best validation result [eval_metric]!
2021-10-03 13:24:02,050 - INFO - joeynmt.training - Example #0
2021-10-03 13:24:02,051 - INFO - joeynmt.training - 	Source:     el
2021-10-03 13:24:02,051 - INFO - joeynmt.training - 	Reference:  en
2021-10-03 13:24:02,051 - INFO - joeynmt.training - 	Hypothesis: I the .
2021-10-03 13:24:02,051 - INFO - joeynmt.training - Example #1
--- Logging error ---
Traceback (most recent call last):
  File "/sw/arch/Debian10/EB_production/2019/software/Anaconda3/2018.12/lib/python3.7/logging/__init__.py", line 1036, in emit
    stream.write(msg)
UnicodeEncodeError: 'latin-1' codec can't encode characters in position 73-76: ordinal not in range(256)
Call stack:
  File "/sw/arch/Debian10/EB_production/2019/software/Anaconda3/2018.12/lib/python3.7/runpy.py", line 193, in _run_module_as_main
    "__main__", mod_spec)
  File "/sw/arch/Debian10/EB_production/2019/software/Anaconda3/2018.12/lib/python3.7/runpy.py", line 85, in _run_code
    exec(code, run_globals)
  File "/home/lcur0009/joeynmt/joeynmt/__main__.py", line 48, in <module>
    main()
  File "/home/lcur0009/joeynmt/joeynmt/__main__.py", line 35, in main
    train(cfg_file=args.config_path, skip_test=args.skip_test)
  File "/home/lcur0009/joeynmt/joeynmt/training.py", line 846, in train
    trainer.train_and_validate(train_data=train_data, valid_data=dev_data)
  File "/home/lcur0009/joeynmt/joeynmt/training.py", line 497, in train_and_validate
    valid_duration = self._validate(valid_data, epoch_no)
  File "/home/lcur0009/joeynmt/joeynmt/training.py", line 642, in _validate
    references=valid_references)
  File "/home/lcur0009/joeynmt/joeynmt/training.py", line 731, in _log_examples
    logger.debug("\tRaw source:     %s", sources_raw[p])
Message: '\tRaw source:     %s'
Arguments: (['"\u038c\u03c4\u03b1\u03bd', '\u03ae\u03bc\u03bf\u03c5\u03bd', '1@@', '1', ',', '\u0398@@', '\u03c5@@', '\u03bc\u03ac@@', '\u03bc\u03b1\u03b9', '\u03c0\u03c9\u03c2', '\u03be@@', '\u03cd\u03c0@@', '\u03bd\u03b7@@', '\u03c3\u03b1', '\u03ad\u03bd\u03b1', '\u03c0\u03c1\u03c9@@', '\u03af', '\u03bc\u03b5', '\u03ae@@', '\u03c7@@', '\u03bf\u03c5\u03c2', '\u03c7\u03b1\u03c1@@', '\u03ac\u03c2', '\u03c3\u03c4\u03bf', '\u03c3\u03c0\u03af\u03c4\u03b9', '."'],)
--- Logging error ---
Traceback (most recent call last):
  File "/sw/arch/Debian10/EB_production/2019/software/Anaconda3/2018.12/lib/python3.7/logging/__init__.py", line 1036, in emit
    stream.write(msg)
UnicodeEncodeError: 'latin-1' codec can't encode characters in position 66-69: ordinal not in range(256)
Call stack:
  File "/sw/arch/Debian10/EB_production/2019/software/Anaconda3/2018.12/lib/python3.7/runpy.py", line 193, in _run_module_as_main
    "__main__", mod_spec)
  File "/sw/arch/Debian10/EB_production/2019/software/Anaconda3/2018.12/lib/python3.7/runpy.py", line 85, in _run_code
    exec(code, run_globals)
  File "/home/lcur0009/joeynmt/joeynmt/__main__.py", line 48, in <module>
    main()
  File "/home/lcur0009/joeynmt/joeynmt/__main__.py", line 35, in main
    train(cfg_file=args.config_path, skip_test=args.skip_test)
  File "/home/lcur0009/joeynmt/joeynmt/training.py", line 846, in train
    trainer.train_and_validate(train_data=train_data, valid_data=dev_data)
  File "/home/lcur0009/joeynmt/joeynmt/training.py", line 497, in train_and_validate
    valid_duration = self._validate(valid_data, epoch_no)
  File "/home/lcur0009/joeynmt/joeynmt/training.py", line 642, in _validate
    references=valid_references)
  File "/home/lcur0009/joeynmt/joeynmt/training.py", line 737, in _log_examples
    logger.info("\tSource:     %s", sources[p])
Message: '\tSource:     %s'
Arguments: ('"\u038c\u03c4\u03b1\u03bd \u03ae\u03bc\u03bf\u03c5\u03bd 11 , \u0398\u03c5\u03bc\u03ac\u03bc\u03b1\u03b9 \u03c0\u03c9\u03c2 \u03be\u03cd\u03c0\u03bd\u03b7\u03c3\u03b1 \u03ad\u03bd\u03b1 \u03c0\u03c1\u03c9\u03af \u03bc\u03b5 \u03ae\u03c7\u03bf\u03c5\u03c2 \u03c7\u03b1\u03c1\u03ac\u03c2 \u03c3\u03c4\u03bf \u03c3\u03c0\u03af\u03c4\u03b9 ."',)
2021-10-03 13:24:02,054 - INFO - joeynmt.training - 	Source:     "\u038c\u03c4\u03b1\u03bd \u03ae\u03bc\u03bf\u03c5\u03bd 11 , \u0398\u03c5\u03bc\u03ac\u03bc\u03b1\u03b9 \u03c0\u03c9\u03c2 \u03be\u03cd\u03c0\u03bd\u03b7\u03c3\u03b1 \u03ad\u03bd\u03b1 \u03c0\u03c1\u03c9\u03af \u03bc\u03b5 \u03ae\u03c7\u03bf\u03c5\u03c2 \u03c7\u03b1\u03c1\u03ac\u03c2 \u03c3\u03c4\u03bf \u03c3\u03c0\u03af\u03c4\u03b9 ."
2021-10-03 13:24:02,054 - INFO - joeynmt.training - 	Reference:  "When I was 11 , I remember waking up one morning to the sound of joy in my house ."
2021-10-03 13:24:02,055 - INFO - joeynmt.training - 	Hypothesis: "And I , , , , , , , , , , , , , , , , , , , , , , ,
2021-10-03 13:24:02,055 - INFO - joeynmt.training - Example #2
--- Logging error ---
Traceback (most recent call last):
  File "/sw/arch/Debian10/EB_production/2019/software/Anaconda3/2018.12/lib/python3.7/logging/__init__.py", line 1036, in emit
    stream.write(msg)
UnicodeEncodeError: 'latin-1' codec can't encode character '\u039f' in position 72: ordinal not in range(256)
Call stack:
  File "/sw/arch/Debian10/EB_production/2019/software/Anaconda3/2018.12/lib/python3.7/runpy.py", line 193, in _run_module_as_main
    "__main__", mod_spec)
  File "/sw/arch/Debian10/EB_production/2019/software/Anaconda3/2018.12/lib/python3.7/runpy.py", line 85, in _run_code
    exec(code, run_globals)
  File "/home/lcur0009/joeynmt/joeynmt/__main__.py", line 48, in <module>
    main()
  File "/home/lcur0009/joeynmt/joeynmt/__main__.py", line 35, in main
    train(cfg_file=args.config_path, skip_test=args.skip_test)
  File "/home/lcur0009/joeynmt/joeynmt/training.py", line 846, in train
    trainer.train_and_validate(train_data=train_data, valid_data=dev_data)
  File "/home/lcur0009/joeynmt/joeynmt/training.py", line 497, in train_and_validate
    valid_duration = self._validate(valid_data, epoch_no)
  File "/home/lcur0009/joeynmt/joeynmt/training.py", line 642, in _validate
    references=valid_references)
  File "/home/lcur0009/joeynmt/joeynmt/training.py", line 731, in _log_examples
    logger.debug("\tRaw source:     %s", sources_raw[p])
Message: '\tRaw source:     %s'
Arguments: (['\u039f', '\u03c0\u03b1\u03c4@@', '\u03ad\u03c1\u03b1\u03c2', '\u03bc\u03bf\u03c5', '\u03ac@@', '\u03ba\u03bf\u03c5@@', '\u03b3@@', '\u03b5', '\u03c4\u03b1', '\u039d@@', '\u03ad\u03b1', '\u03c4\u03bf\u03c5', 'B@@', 'B@@', 'C', '\u03c3\u03c4\u03bf', '\u03bc\u03b9\u03ba\u03c1\u03cc', '\u03b3@@', '\u03ba\u03c1@@', '\u03b9', '\u03c1\u03b1@@', '\u03b4\u03b9@@', '\u03cc@@', '\u03c6\u03c9\u03bd@@', '\u03cc', '\u03c4\u03bf\u03c5', '.'],)
--- Logging error ---
Traceback (most recent call last):
  File "/sw/arch/Debian10/EB_production/2019/software/Anaconda3/2018.12/lib/python3.7/logging/__init__.py", line 1036, in emit
    stream.write(msg)
UnicodeEncodeError: 'latin-1' codec can't encode character '\u039f' in position 65: ordinal not in range(256)
Call stack:
  File "/sw/arch/Debian10/EB_production/2019/software/Anaconda3/2018.12/lib/python3.7/runpy.py", line 193, in _run_module_as_main
    "__main__", mod_spec)
  File "/sw/arch/Debian10/EB_production/2019/software/Anaconda3/2018.12/lib/python3.7/runpy.py", line 85, in _run_code
    exec(code, run_globals)
  File "/home/lcur0009/joeynmt/joeynmt/__main__.py", line 48, in <module>
    main()
  File "/home/lcur0009/joeynmt/joeynmt/__main__.py", line 35, in main
    train(cfg_file=args.config_path, skip_test=args.skip_test)
  File "/home/lcur0009/joeynmt/joeynmt/training.py", line 846, in train
    trainer.train_and_validate(train_data=train_data, valid_data=dev_data)
  File "/home/lcur0009/joeynmt/joeynmt/training.py", line 497, in train_and_validate
    valid_duration = self._validate(valid_data, epoch_no)
  File "/home/lcur0009/joeynmt/joeynmt/training.py", line 642, in _validate
    references=valid_references)
  File "/home/lcur0009/joeynmt/joeynmt/training.py", line 737, in _log_examples
    logger.info("\tSource:     %s", sources[p])
Message: '\tSource:     %s'
Arguments: ('\u039f \u03c0\u03b1\u03c4\u03ad\u03c1\u03b1\u03c2 \u03bc\u03bf\u03c5 \u03ac\u03ba\u03bf\u03c5\u03b3\u03b5 \u03c4\u03b1 \u039d\u03ad\u03b1 \u03c4\u03bf\u03c5 BBC \u03c3\u03c4\u03bf \u03bc\u03b9\u03ba\u03c1\u03cc \u03b3\u03ba\u03c1\u03b9 \u03c1\u03b1\u03b4\u03b9\u03cc\u03c6\u03c9\u03bd\u03cc \u03c4\u03bf\u03c5 .',)
2021-10-03 13:24:02,056 - INFO - joeynmt.training - 	Source:     \u039f \u03c0\u03b1\u03c4\u03ad\u03c1\u03b1\u03c2 \u03bc\u03bf\u03c5 \u03ac\u03ba\u03bf\u03c5\u03b3\u03b5 \u03c4\u03b1 \u039d\u03ad\u03b1 \u03c4\u03bf\u03c5 BBC \u03c3\u03c4\u03bf \u03bc\u03b9\u03ba\u03c1\u03cc \u03b3\u03ba\u03c1\u03b9 \u03c1\u03b1\u03b4\u03b9\u03cc\u03c6\u03c9\u03bd\u03cc \u03c4\u03bf\u03c5 .
2021-10-03 13:24:02,056 - INFO - joeynmt.training - 	Reference:  "My father was listening to BBC News on his small , gray radio ."
2021-10-03 13:24:02,057 - INFO - joeynmt.training - 	Hypothesis: "And I , , , , , , , , , , , , , , , , ,
2021-10-03 13:24:02,057 - INFO - joeynmt.training - Validation result (greedy) at epoch   2, step      100: bleu:   0.99, loss: 94656.9688, ppl: 442.9846, duration: 3.9671s
2021-10-03 13:24:09,195 - INFO - joeynmt.training - Epoch   2: total training loss 8058.46
2021-10-03 13:24:09,196 - INFO - joeynmt.training - EPOCH 3
2021-10-03 13:24:22,239 - INFO - joeynmt.training - Epoch   3: total training loss 7843.94
2021-10-03 13:24:22,240 - INFO - joeynmt.training - EPOCH 4
2021-10-03 13:24:28,255 - WARNING - sacrebleu - That's 100 lines that end in a tokenized period ('.')
2021-10-03 13:24:28,255 - WARNING - sacrebleu - It looks like you forgot to detokenize your test data, which may hurt your score.
2021-10-03 13:24:28,255 - WARNING - sacrebleu - If you insist your data is detokenized, or don't care, you can suppress this message with the `force` parameter.
2021-10-03 13:24:28,264 - INFO - joeynmt.training - Example #0
2021-10-03 13:24:28,265 - INFO - joeynmt.training - 	Source:     el
2021-10-03 13:24:28,265 - INFO - joeynmt.training - 	Reference:  en
2021-10-03 13:24:28,265 - INFO - joeynmt.training - 	Hypothesis: Thank &apos;s .
2021-10-03 13:24:28,265 - INFO - joeynmt.training - Example #1
--- Logging error ---
Traceback (most recent call last):
  File "/sw/arch/Debian10/EB_production/2019/software/Anaconda3/2018.12/lib/python3.7/logging/__init__.py", line 1036, in emit
    stream.write(msg)
UnicodeEncodeError: 'latin-1' codec can't encode characters in position 73-76: ordinal not in range(256)
Call stack:
  File "/sw/arch/Debian10/EB_production/2019/software/Anaconda3/2018.12/lib/python3.7/runpy.py", line 193, in _run_module_as_main
    "__main__", mod_spec)
  File "/sw/arch/Debian10/EB_production/2019/software/Anaconda3/2018.12/lib/python3.7/runpy.py", line 85, in _run_code
    exec(code, run_globals)
  File "/home/lcur0009/joeynmt/joeynmt/__main__.py", line 48, in <module>
    main()
  File "/home/lcur0009/joeynmt/joeynmt/__main__.py", line 35, in main
    train(cfg_file=args.config_path, skip_test=args.skip_test)
  File "/home/lcur0009/joeynmt/joeynmt/training.py", line 846, in train
    trainer.train_and_validate(train_data=train_data, valid_data=dev_data)
  File "/home/lcur0009/joeynmt/joeynmt/training.py", line 497, in train_and_validate
    valid_duration = self._validate(valid_data, epoch_no)
  File "/home/lcur0009/joeynmt/joeynmt/training.py", line 642, in _validate
    references=valid_references)
  File "/home/lcur0009/joeynmt/joeynmt/training.py", line 731, in _log_examples
    logger.debug("\tRaw source:     %s", sources_raw[p])
Message: '\tRaw source:     %s'
Arguments: (['"\u038c\u03c4\u03b1\u03bd', '\u03ae\u03bc\u03bf\u03c5\u03bd', '1@@', '1', ',', '\u0398@@', '\u03c5@@', '\u03bc\u03ac@@', '\u03bc\u03b1\u03b9', '\u03c0\u03c9\u03c2', '\u03be@@', '\u03cd\u03c0@@', '\u03bd\u03b7@@', '\u03c3\u03b1', '\u03ad\u03bd\u03b1', '\u03c0\u03c1\u03c9@@', '\u03af', '\u03bc\u03b5', '\u03ae@@', '\u03c7@@', '\u03bf\u03c5\u03c2', '\u03c7\u03b1\u03c1@@', '\u03ac\u03c2', '\u03c3\u03c4\u03bf', '\u03c3\u03c0\u03af\u03c4\u03b9', '."'],)
--- Logging error ---
Traceback (most recent call last):
  File "/sw/arch/Debian10/EB_production/2019/software/Anaconda3/2018.12/lib/python3.7/logging/__init__.py", line 1036, in emit
    stream.write(msg)
UnicodeEncodeError: 'latin-1' codec can't encode characters in position 66-69: ordinal not in range(256)
Call stack:
  File "/sw/arch/Debian10/EB_production/2019/software/Anaconda3/2018.12/lib/python3.7/runpy.py", line 193, in _run_module_as_main
    "__main__", mod_spec)
  File "/sw/arch/Debian10/EB_production/2019/software/Anaconda3/2018.12/lib/python3.7/runpy.py", line 85, in _run_code
    exec(code, run_globals)
  File "/home/lcur0009/joeynmt/joeynmt/__main__.py", line 48, in <module>
    main()
  File "/home/lcur0009/joeynmt/joeynmt/__main__.py", line 35, in main
    train(cfg_file=args.config_path, skip_test=args.skip_test)
  File "/home/lcur0009/joeynmt/joeynmt/training.py", line 846, in train
    trainer.train_and_validate(train_data=train_data, valid_data=dev_data)
  File "/home/lcur0009/joeynmt/joeynmt/training.py", line 497, in train_and_validate
    valid_duration = self._validate(valid_data, epoch_no)
  File "/home/lcur0009/joeynmt/joeynmt/training.py", line 642, in _validate
    references=valid_references)
  File "/home/lcur0009/joeynmt/joeynmt/training.py", line 737, in _log_examples
    logger.info("\tSource:     %s", sources[p])
Message: '\tSource:     %s'
Arguments: ('"\u038c\u03c4\u03b1\u03bd \u03ae\u03bc\u03bf\u03c5\u03bd 11 , \u0398\u03c5\u03bc\u03ac\u03bc\u03b1\u03b9 \u03c0\u03c9\u03c2 \u03be\u03cd\u03c0\u03bd\u03b7\u03c3\u03b1 \u03ad\u03bd\u03b1 \u03c0\u03c1\u03c9\u03af \u03bc\u03b5 \u03ae\u03c7\u03bf\u03c5\u03c2 \u03c7\u03b1\u03c1\u03ac\u03c2 \u03c3\u03c4\u03bf \u03c3\u03c0\u03af\u03c4\u03b9 ."',)
2021-10-03 13:24:28,267 - INFO - joeynmt.training - 	Source:     "\u038c\u03c4\u03b1\u03bd \u03ae\u03bc\u03bf\u03c5\u03bd 11 , \u0398\u03c5\u03bc\u03ac\u03bc\u03b1\u03b9 \u03c0\u03c9\u03c2 \u03be\u03cd\u03c0\u03bd\u03b7\u03c3\u03b1 \u03ad\u03bd\u03b1 \u03c0\u03c1\u03c9\u03af \u03bc\u03b5 \u03ae\u03c7\u03bf\u03c5\u03c2 \u03c7\u03b1\u03c1\u03ac\u03c2 \u03c3\u03c4\u03bf \u03c3\u03c0\u03af\u03c4\u03b9 ."
2021-10-03 13:24:28,268 - INFO - joeynmt.training - 	Reference:  "When I was 11 , I remember waking up one morning to the sound of joy in my house ."
2021-10-03 13:24:28,268 - INFO - joeynmt.training - 	Hypothesis: "And &apos;s the the the the the the the the the the the the the the the the the the the the the the the the the the the the the the the the the the the the the the the the the the the the the the the the the the the the the the the the the the the the ."
2021-10-03 13:24:28,269 - INFO - joeynmt.training - Example #2
--- Logging error ---
Traceback (most recent call last):
  File "/sw/arch/Debian10/EB_production/2019/software/Anaconda3/2018.12/lib/python3.7/logging/__init__.py", line 1036, in emit
    stream.write(msg)
UnicodeEncodeError: 'latin-1' codec can't encode character '\u039f' in position 72: ordinal not in range(256)
Call stack:
  File "/sw/arch/Debian10/EB_production/2019/software/Anaconda3/2018.12/lib/python3.7/runpy.py", line 193, in _run_module_as_main
    "__main__", mod_spec)
  File "/sw/arch/Debian10/EB_production/2019/software/Anaconda3/2018.12/lib/python3.7/runpy.py", line 85, in _run_code
    exec(code, run_globals)
  File "/home/lcur0009/joeynmt/joeynmt/__main__.py", line 48, in <module>
    main()
  File "/home/lcur0009/joeynmt/joeynmt/__main__.py", line 35, in main
    train(cfg_file=args.config_path, skip_test=args.skip_test)
  File "/home/lcur0009/joeynmt/joeynmt/training.py", line 846, in train
    trainer.train_and_validate(train_data=train_data, valid_data=dev_data)
  File "/home/lcur0009/joeynmt/joeynmt/training.py", line 497, in train_and_validate
    valid_duration = self._validate(valid_data, epoch_no)
  File "/home/lcur0009/joeynmt/joeynmt/training.py", line 642, in _validate
    references=valid_references)
  File "/home/lcur0009/joeynmt/joeynmt/training.py", line 731, in _log_examples
    logger.debug("\tRaw source:     %s", sources_raw[p])
Message: '\tRaw source:     %s'
Arguments: (['\u039f', '\u03c0\u03b1\u03c4@@', '\u03ad\u03c1\u03b1\u03c2', '\u03bc\u03bf\u03c5', '\u03ac@@', '\u03ba\u03bf\u03c5@@', '\u03b3@@', '\u03b5', '\u03c4\u03b1', '\u039d@@', '\u03ad\u03b1', '\u03c4\u03bf\u03c5', 'B@@', 'B@@', 'C', '\u03c3\u03c4\u03bf', '\u03bc\u03b9\u03ba\u03c1\u03cc', '\u03b3@@', '\u03ba\u03c1@@', '\u03b9', '\u03c1\u03b1@@', '\u03b4\u03b9@@', '\u03cc@@', '\u03c6\u03c9\u03bd@@', '\u03cc', '\u03c4\u03bf\u03c5', '.'],)
--- Logging error ---
Traceback (most recent call last):
  File "/sw/arch/Debian10/EB_production/2019/software/Anaconda3/2018.12/lib/python3.7/logging/__init__.py", line 1036, in emit
    stream.write(msg)
UnicodeEncodeError: 'latin-1' codec can't encode character '\u039f' in position 65: ordinal not in range(256)
Call stack:
  File "/sw/arch/Debian10/EB_production/2019/software/Anaconda3/2018.12/lib/python3.7/runpy.py", line 193, in _run_module_as_main
    "__main__", mod_spec)
  File "/sw/arch/Debian10/EB_production/2019/software/Anaconda3/2018.12/lib/python3.7/runpy.py", line 85, in _run_code
    exec(code, run_globals)
  File "/home/lcur0009/joeynmt/joeynmt/__main__.py", line 48, in <module>
    main()
  File "/home/lcur0009/joeynmt/joeynmt/__main__.py", line 35, in main
    train(cfg_file=args.config_path, skip_test=args.skip_test)
  File "/home/lcur0009/joeynmt/joeynmt/training.py", line 846, in train
    trainer.train_and_validate(train_data=train_data, valid_data=dev_data)
  File "/home/lcur0009/joeynmt/joeynmt/training.py", line 497, in train_and_validate
    valid_duration = self._validate(valid_data, epoch_no)
  File "/home/lcur0009/joeynmt/joeynmt/training.py", line 642, in _validate
    references=valid_references)
  File "/home/lcur0009/joeynmt/joeynmt/training.py", line 737, in _log_examples
    logger.info("\tSource:     %s", sources[p])
Message: '\tSource:     %s'
Arguments: ('\u039f \u03c0\u03b1\u03c4\u03ad\u03c1\u03b1\u03c2 \u03bc\u03bf\u03c5 \u03ac\u03ba\u03bf\u03c5\u03b3\u03b5 \u03c4\u03b1 \u039d\u03ad\u03b1 \u03c4\u03bf\u03c5 BBC \u03c3\u03c4\u03bf \u03bc\u03b9\u03ba\u03c1\u03cc \u03b3\u03ba\u03c1\u03b9 \u03c1\u03b1\u03b4\u03b9\u03cc\u03c6\u03c9\u03bd\u03cc \u03c4\u03bf\u03c5 .',)
2021-10-03 13:24:28,270 - INFO - joeynmt.training - 	Source:     \u039f \u03c0\u03b1\u03c4\u03ad\u03c1\u03b1\u03c2 \u03bc\u03bf\u03c5 \u03ac\u03ba\u03bf\u03c5\u03b3\u03b5 \u03c4\u03b1 \u039d\u03ad\u03b1 \u03c4\u03bf\u03c5 BBC \u03c3\u03c4\u03bf \u03bc\u03b9\u03ba\u03c1\u03cc \u03b3\u03ba\u03c1\u03b9 \u03c1\u03b1\u03b4\u03b9\u03cc\u03c6\u03c9\u03bd\u03cc \u03c4\u03bf\u03c5 .
2021-10-03 13:24:28,270 - INFO - joeynmt.training - 	Reference:  "My father was listening to BBC News on his small , gray radio ."
2021-10-03 13:24:28,271 - INFO - joeynmt.training - 	Hypothesis: And &apos;s the the the the the the the the the the the the the the the the the the the the the the the the the the the the the the the the the the the the the the .
2021-10-03 13:24:28,271 - INFO - joeynmt.training - Validation result (greedy) at epoch   4, step      200: bleu:   0.89, loss: 91498.5234, ppl: 361.4813, duration: 3.7590s
2021-10-03 13:24:41,660 - INFO - joeynmt.training - Epoch   4: total training loss 7622.73
2021-10-03 13:24:41,661 - INFO - joeynmt.training - EPOCH 5
2021-10-03 13:24:55,294 - WARNING - sacrebleu - That's 100 lines that end in a tokenized period ('.')
2021-10-03 13:24:55,294 - WARNING - sacrebleu - It looks like you forgot to detokenize your test data, which may hurt your score.
2021-10-03 13:24:55,294 - WARNING - sacrebleu - If you insist your data is detokenized, or don't care, you can suppress this message with the `force` parameter.
2021-10-03 13:24:55,300 - INFO - joeynmt.training - Hooray! New best validation result [eval_metric]!
2021-10-03 13:24:56,244 - INFO - joeynmt.helpers - delete models/LSTM_el/100.ckpt
2021-10-03 13:24:56,320 - INFO - joeynmt.helpers - delete /home/lcur0009/joeynmt/models/LSTM_el/100.ckpt
2021-10-03 13:24:56,320 - WARNING - joeynmt.helpers - Wanted to delete old checkpoint /home/lcur0009/joeynmt/models/LSTM_el/100.ckpt but file does not exist. ([Errno 2] No such file or directory: '/home/lcur0009/joeynmt/models/LSTM_el/100.ckpt')
2021-10-03 13:24:56,322 - INFO - joeynmt.training - Example #0
2021-10-03 13:24:56,323 - INFO - joeynmt.training - 	Source:     el
2021-10-03 13:24:56,323 - INFO - joeynmt.training - 	Reference:  en
2021-10-03 13:24:56,323 - INFO - joeynmt.training - 	Hypothesis: (
2021-10-03 13:24:56,323 - INFO - joeynmt.training - Example #1
--- Logging error ---
Traceback (most recent call last):
  File "/sw/arch/Debian10/EB_production/2019/software/Anaconda3/2018.12/lib/python3.7/logging/__init__.py", line 1036, in emit
    stream.write(msg)
UnicodeEncodeError: 'latin-1' codec can't encode characters in position 73-76: ordinal not in range(256)
Call stack:
  File "/sw/arch/Debian10/EB_production/2019/software/Anaconda3/2018.12/lib/python3.7/runpy.py", line 193, in _run_module_as_main
    "__main__", mod_spec)
  File "/sw/arch/Debian10/EB_production/2019/software/Anaconda3/2018.12/lib/python3.7/runpy.py", line 85, in _run_code
    exec(code, run_globals)
  File "/home/lcur0009/joeynmt/joeynmt/__main__.py", line 48, in <module>
    main()
  File "/home/lcur0009/joeynmt/joeynmt/__main__.py", line 35, in main
    train(cfg_file=args.config_path, skip_test=args.skip_test)
  File "/home/lcur0009/joeynmt/joeynmt/training.py", line 846, in train
    trainer.train_and_validate(train_data=train_data, valid_data=dev_data)
  File "/home/lcur0009/joeynmt/joeynmt/training.py", line 497, in train_and_validate
    valid_duration = self._validate(valid_data, epoch_no)
  File "/home/lcur0009/joeynmt/joeynmt/training.py", line 642, in _validate
    references=valid_references)
  File "/home/lcur0009/joeynmt/joeynmt/training.py", line 731, in _log_examples
    logger.debug("\tRaw source:     %s", sources_raw[p])
Message: '\tRaw source:     %s'
Arguments: (['"\u038c\u03c4\u03b1\u03bd', '\u03ae\u03bc\u03bf\u03c5\u03bd', '1@@', '1', ',', '\u0398@@', '\u03c5@@', '\u03bc\u03ac@@', '\u03bc\u03b1\u03b9', '\u03c0\u03c9\u03c2', '\u03be@@', '\u03cd\u03c0@@', '\u03bd\u03b7@@', '\u03c3\u03b1', '\u03ad\u03bd\u03b1', '\u03c0\u03c1\u03c9@@', '\u03af', '\u03bc\u03b5', '\u03ae@@', '\u03c7@@', '\u03bf\u03c5\u03c2', '\u03c7\u03b1\u03c1@@', '\u03ac\u03c2', '\u03c3\u03c4\u03bf', '\u03c3\u03c0\u03af\u03c4\u03b9', '."'],)
--- Logging error ---
Traceback (most recent call last):
  File "/sw/arch/Debian10/EB_production/2019/software/Anaconda3/2018.12/lib/python3.7/logging/__init__.py", line 1036, in emit
    stream.write(msg)
UnicodeEncodeError: 'latin-1' codec can't encode characters in position 66-69: ordinal not in range(256)
Call stack:
  File "/sw/arch/Debian10/EB_production/2019/software/Anaconda3/2018.12/lib/python3.7/runpy.py", line 193, in _run_module_as_main
    "__main__", mod_spec)
  File "/sw/arch/Debian10/EB_production/2019/software/Anaconda3/2018.12/lib/python3.7/runpy.py", line 85, in _run_code
    exec(code, run_globals)
  File "/home/lcur0009/joeynmt/joeynmt/__main__.py", line 48, in <module>
    main()
  File "/home/lcur0009/joeynmt/joeynmt/__main__.py", line 35, in main
    train(cfg_file=args.config_path, skip_test=args.skip_test)
  File "/home/lcur0009/joeynmt/joeynmt/training.py", line 846, in train
    trainer.train_and_validate(train_data=train_data, valid_data=dev_data)
  File "/home/lcur0009/joeynmt/joeynmt/training.py", line 497, in train_and_validate
    valid_duration = self._validate(valid_data, epoch_no)
  File "/home/lcur0009/joeynmt/joeynmt/training.py", line 642, in _validate
    references=valid_references)
  File "/home/lcur0009/joeynmt/joeynmt/training.py", line 737, in _log_examples
    logger.info("\tSource:     %s", sources[p])
Message: '\tSource:     %s'
Arguments: ('"\u038c\u03c4\u03b1\u03bd \u03ae\u03bc\u03bf\u03c5\u03bd 11 , \u0398\u03c5\u03bc\u03ac\u03bc\u03b1\u03b9 \u03c0\u03c9\u03c2 \u03be\u03cd\u03c0\u03bd\u03b7\u03c3\u03b1 \u03ad\u03bd\u03b1 \u03c0\u03c1\u03c9\u03af \u03bc\u03b5 \u03ae\u03c7\u03bf\u03c5\u03c2 \u03c7\u03b1\u03c1\u03ac\u03c2 \u03c3\u03c4\u03bf \u03c3\u03c0\u03af\u03c4\u03b9 ."',)
2021-10-03 13:24:56,325 - INFO - joeynmt.training - 	Source:     "\u038c\u03c4\u03b1\u03bd \u03ae\u03bc\u03bf\u03c5\u03bd 11 , \u0398\u03c5\u03bc\u03ac\u03bc\u03b1\u03b9 \u03c0\u03c9\u03c2 \u03be\u03cd\u03c0\u03bd\u03b7\u03c3\u03b1 \u03ad\u03bd\u03b1 \u03c0\u03c1\u03c9\u03af \u03bc\u03b5 \u03ae\u03c7\u03bf\u03c5\u03c2 \u03c7\u03b1\u03c1\u03ac\u03c2 \u03c3\u03c4\u03bf \u03c3\u03c0\u03af\u03c4\u03b9 ."
2021-10-03 13:24:56,326 - INFO - joeynmt.training - 	Reference:  "When I was 11 , I remember waking up one morning to the sound of joy in my house ."
2021-10-03 13:24:56,326 - INFO - joeynmt.training - 	Hypothesis: "And I I I I have a a a a a a a a a a a a a a a a a a a a ."
2021-10-03 13:24:56,327 - INFO - joeynmt.training - Example #2
--- Logging error ---
Traceback (most recent call last):
  File "/sw/arch/Debian10/EB_production/2019/software/Anaconda3/2018.12/lib/python3.7/logging/__init__.py", line 1036, in emit
    stream.write(msg)
UnicodeEncodeError: 'latin-1' codec can't encode character '\u039f' in position 72: ordinal not in range(256)
Call stack:
  File "/sw/arch/Debian10/EB_production/2019/software/Anaconda3/2018.12/lib/python3.7/runpy.py", line 193, in _run_module_as_main
    "__main__", mod_spec)
  File "/sw/arch/Debian10/EB_production/2019/software/Anaconda3/2018.12/lib/python3.7/runpy.py", line 85, in _run_code
    exec(code, run_globals)
  File "/home/lcur0009/joeynmt/joeynmt/__main__.py", line 48, in <module>
    main()
  File "/home/lcur0009/joeynmt/joeynmt/__main__.py", line 35, in main
    train(cfg_file=args.config_path, skip_test=args.skip_test)
  File "/home/lcur0009/joeynmt/joeynmt/training.py", line 846, in train
    trainer.train_and_validate(train_data=train_data, valid_data=dev_data)
  File "/home/lcur0009/joeynmt/joeynmt/training.py", line 497, in train_and_validate
    valid_duration = self._validate(valid_data, epoch_no)
  File "/home/lcur0009/joeynmt/joeynmt/training.py", line 642, in _validate
    references=valid_references)
  File "/home/lcur0009/joeynmt/joeynmt/training.py", line 731, in _log_examples
    logger.debug("\tRaw source:     %s", sources_raw[p])
Message: '\tRaw source:     %s'
Arguments: (['\u039f', '\u03c0\u03b1\u03c4@@', '\u03ad\u03c1\u03b1\u03c2', '\u03bc\u03bf\u03c5', '\u03ac@@', '\u03ba\u03bf\u03c5@@', '\u03b3@@', '\u03b5', '\u03c4\u03b1', '\u039d@@', '\u03ad\u03b1', '\u03c4\u03bf\u03c5', 'B@@', 'B@@', 'C', '\u03c3\u03c4\u03bf', '\u03bc\u03b9\u03ba\u03c1\u03cc', '\u03b3@@', '\u03ba\u03c1@@', '\u03b9', '\u03c1\u03b1@@', '\u03b4\u03b9@@', '\u03cc@@', '\u03c6\u03c9\u03bd@@', '\u03cc', '\u03c4\u03bf\u03c5', '.'],)
--- Logging error ---
Traceback (most recent call last):
  File "/sw/arch/Debian10/EB_production/2019/software/Anaconda3/2018.12/lib/python3.7/logging/__init__.py", line 1036, in emit
    stream.write(msg)
UnicodeEncodeError: 'latin-1' codec can't encode character '\u039f' in position 65: ordinal not in range(256)
Call stack:
  File "/sw/arch/Debian10/EB_production/2019/software/Anaconda3/2018.12/lib/python3.7/runpy.py", line 193, in _run_module_as_main
    "__main__", mod_spec)
  File "/sw/arch/Debian10/EB_production/2019/software/Anaconda3/2018.12/lib/python3.7/runpy.py", line 85, in _run_code
    exec(code, run_globals)
  File "/home/lcur0009/joeynmt/joeynmt/__main__.py", line 48, in <module>
    main()
  File "/home/lcur0009/joeynmt/joeynmt/__main__.py", line 35, in main
    train(cfg_file=args.config_path, skip_test=args.skip_test)
  File "/home/lcur0009/joeynmt/joeynmt/training.py", line 846, in train
    trainer.train_and_validate(train_data=train_data, valid_data=dev_data)
  File "/home/lcur0009/joeynmt/joeynmt/training.py", line 497, in train_and_validate
    valid_duration = self._validate(valid_data, epoch_no)
  File "/home/lcur0009/joeynmt/joeynmt/training.py", line 642, in _validate
    references=valid_references)
  File "/home/lcur0009/joeynmt/joeynmt/training.py", line 737, in _log_examples
    logger.info("\tSource:     %s", sources[p])
Message: '\tSource:     %s'
Arguments: ('\u039f \u03c0\u03b1\u03c4\u03ad\u03c1\u03b1\u03c2 \u03bc\u03bf\u03c5 \u03ac\u03ba\u03bf\u03c5\u03b3\u03b5 \u03c4\u03b1 \u039d\u03ad\u03b1 \u03c4\u03bf\u03c5 BBC \u03c3\u03c4\u03bf \u03bc\u03b9\u03ba\u03c1\u03cc \u03b3\u03ba\u03c1\u03b9 \u03c1\u03b1\u03b4\u03b9\u03cc\u03c6\u03c9\u03bd\u03cc \u03c4\u03bf\u03c5 .',)
2021-10-03 13:24:56,328 - INFO - joeynmt.training - 	Source:     \u039f \u03c0\u03b1\u03c4\u03ad\u03c1\u03b1\u03c2 \u03bc\u03bf\u03c5 \u03ac\u03ba\u03bf\u03c5\u03b3\u03b5 \u03c4\u03b1 \u039d\u03ad\u03b1 \u03c4\u03bf\u03c5 BBC \u03c3\u03c4\u03bf \u03bc\u03b9\u03ba\u03c1\u03cc \u03b3\u03ba\u03c1\u03b9 \u03c1\u03b1\u03b4\u03b9\u03cc\u03c6\u03c9\u03bd\u03cc \u03c4\u03bf\u03c5 .
2021-10-03 13:24:56,328 - INFO - joeynmt.training - 	Reference:  "My father was listening to BBC News on his small , gray radio ."
2021-10-03 13:24:56,329 - INFO - joeynmt.training - 	Hypothesis: And I &apos;m a a a a a a a a a a a a a a a a a a a .
2021-10-03 13:24:56,329 - INFO - joeynmt.training - Validation result (greedy) at epoch   5, step      300: bleu:   1.23, loss: 88426.8203, ppl: 296.6253, duration: 4.6783s
2021-10-03 13:25:00,721 - INFO - joeynmt.training - Epoch   5: total training loss 7424.88
2021-10-03 13:25:00,722 - INFO - joeynmt.training - EPOCH 6
2021-10-03 13:25:13,814 - INFO - joeynmt.training - Epoch   6: total training loss 7249.81
2021-10-03 13:25:13,815 - INFO - joeynmt.training - EPOCH 7
2021-10-03 13:25:22,009 - WARNING - sacrebleu - That's 100 lines that end in a tokenized period ('.')
2021-10-03 13:25:22,010 - WARNING - sacrebleu - It looks like you forgot to detokenize your test data, which may hurt your score.
2021-10-03 13:25:22,010 - WARNING - sacrebleu - If you insist your data is detokenized, or don't care, you can suppress this message with the `force` parameter.
2021-10-03 13:25:22,016 - INFO - joeynmt.training - Hooray! New best validation result [eval_metric]!
2021-10-03 13:25:23,291 - INFO - joeynmt.helpers - delete models/LSTM_el/300.ckpt
2021-10-03 13:25:23,369 - INFO - joeynmt.helpers - delete /home/lcur0009/joeynmt/models/LSTM_el/300.ckpt
2021-10-03 13:25:23,370 - WARNING - joeynmt.helpers - Wanted to delete old checkpoint /home/lcur0009/joeynmt/models/LSTM_el/300.ckpt but file does not exist. ([Errno 2] No such file or directory: '/home/lcur0009/joeynmt/models/LSTM_el/300.ckpt')
2021-10-03 13:25:23,372 - INFO - joeynmt.training - Example #0
2021-10-03 13:25:23,372 - INFO - joeynmt.training - 	Source:     el
2021-10-03 13:25:23,373 - INFO - joeynmt.training - 	Reference:  en
2021-10-03 13:25:23,373 - INFO - joeynmt.training - 	Hypothesis: Thank you .
2021-10-03 13:25:23,373 - INFO - joeynmt.training - Example #1
--- Logging error ---
Traceback (most recent call last):
  File "/sw/arch/Debian10/EB_production/2019/software/Anaconda3/2018.12/lib/python3.7/logging/__init__.py", line 1036, in emit
    stream.write(msg)
UnicodeEncodeError: 'latin-1' codec can't encode characters in position 73-76: ordinal not in range(256)
Call stack:
  File "/sw/arch/Debian10/EB_production/2019/software/Anaconda3/2018.12/lib/python3.7/runpy.py", line 193, in _run_module_as_main
    "__main__", mod_spec)
  File "/sw/arch/Debian10/EB_production/2019/software/Anaconda3/2018.12/lib/python3.7/runpy.py", line 85, in _run_code
    exec(code, run_globals)
  File "/home/lcur0009/joeynmt/joeynmt/__main__.py", line 48, in <module>
    main()
  File "/home/lcur0009/joeynmt/joeynmt/__main__.py", line 35, in main
    train(cfg_file=args.config_path, skip_test=args.skip_test)
  File "/home/lcur0009/joeynmt/joeynmt/training.py", line 846, in train
    trainer.train_and_validate(train_data=train_data, valid_data=dev_data)
  File "/home/lcur0009/joeynmt/joeynmt/training.py", line 497, in train_and_validate
    valid_duration = self._validate(valid_data, epoch_no)
  File "/home/lcur0009/joeynmt/joeynmt/training.py", line 642, in _validate
    references=valid_references)
  File "/home/lcur0009/joeynmt/joeynmt/training.py", line 731, in _log_examples
    logger.debug("\tRaw source:     %s", sources_raw[p])
Message: '\tRaw source:     %s'
Arguments: (['"\u038c\u03c4\u03b1\u03bd', '\u03ae\u03bc\u03bf\u03c5\u03bd', '1@@', '1', ',', '\u0398@@', '\u03c5@@', '\u03bc\u03ac@@', '\u03bc\u03b1\u03b9', '\u03c0\u03c9\u03c2', '\u03be@@', '\u03cd\u03c0@@', '\u03bd\u03b7@@', '\u03c3\u03b1', '\u03ad\u03bd\u03b1', '\u03c0\u03c1\u03c9@@', '\u03af', '\u03bc\u03b5', '\u03ae@@', '\u03c7@@', '\u03bf\u03c5\u03c2', '\u03c7\u03b1\u03c1@@', '\u03ac\u03c2', '\u03c3\u03c4\u03bf', '\u03c3\u03c0\u03af\u03c4\u03b9', '."'],)
--- Logging error ---
Traceback (most recent call last):
  File "/sw/arch/Debian10/EB_production/2019/software/Anaconda3/2018.12/lib/python3.7/logging/__init__.py", line 1036, in emit
    stream.write(msg)
UnicodeEncodeError: 'latin-1' codec can't encode characters in position 66-69: ordinal not in range(256)
Call stack:
  File "/sw/arch/Debian10/EB_production/2019/software/Anaconda3/2018.12/lib/python3.7/runpy.py", line 193, in _run_module_as_main
    "__main__", mod_spec)
  File "/sw/arch/Debian10/EB_production/2019/software/Anaconda3/2018.12/lib/python3.7/runpy.py", line 85, in _run_code
    exec(code, run_globals)
  File "/home/lcur0009/joeynmt/joeynmt/__main__.py", line 48, in <module>
    main()
  File "/home/lcur0009/joeynmt/joeynmt/__main__.py", line 35, in main
    train(cfg_file=args.config_path, skip_test=args.skip_test)
  File "/home/lcur0009/joeynmt/joeynmt/training.py", line 846, in train
    trainer.train_and_validate(train_data=train_data, valid_data=dev_data)
  File "/home/lcur0009/joeynmt/joeynmt/training.py", line 497, in train_and_validate
    valid_duration = self._validate(valid_data, epoch_no)
  File "/home/lcur0009/joeynmt/joeynmt/training.py", line 642, in _validate
    references=valid_references)
  File "/home/lcur0009/joeynmt/joeynmt/training.py", line 737, in _log_examples
    logger.info("\tSource:     %s", sources[p])
Message: '\tSource:     %s'
Arguments: ('"\u038c\u03c4\u03b1\u03bd \u03ae\u03bc\u03bf\u03c5\u03bd 11 , \u0398\u03c5\u03bc\u03ac\u03bc\u03b1\u03b9 \u03c0\u03c9\u03c2 \u03be\u03cd\u03c0\u03bd\u03b7\u03c3\u03b1 \u03ad\u03bd\u03b1 \u03c0\u03c1\u03c9\u03af \u03bc\u03b5 \u03ae\u03c7\u03bf\u03c5\u03c2 \u03c7\u03b1\u03c1\u03ac\u03c2 \u03c3\u03c4\u03bf \u03c3\u03c0\u03af\u03c4\u03b9 ."',)
2021-10-03 13:25:23,375 - INFO - joeynmt.training - 	Source:     "\u038c\u03c4\u03b1\u03bd \u03ae\u03bc\u03bf\u03c5\u03bd 11 , \u0398\u03c5\u03bc\u03ac\u03bc\u03b1\u03b9 \u03c0\u03c9\u03c2 \u03be\u03cd\u03c0\u03bd\u03b7\u03c3\u03b1 \u03ad\u03bd\u03b1 \u03c0\u03c1\u03c9\u03af \u03bc\u03b5 \u03ae\u03c7\u03bf\u03c5\u03c2 \u03c7\u03b1\u03c1\u03ac\u03c2 \u03c3\u03c4\u03bf \u03c3\u03c0\u03af\u03c4\u03b9 ."
2021-10-03 13:25:23,375 - INFO - joeynmt.training - 	Reference:  "When I was 11 , I remember waking up one morning to the sound of joy in my house ."
2021-10-03 13:25:23,376 - INFO - joeynmt.training - 	Hypothesis: "And I I have the the ssed , and we have a the universe , the universe , the it , it &apos;s the ."
2021-10-03 13:25:23,376 - INFO - joeynmt.training - Example #2
--- Logging error ---
Traceback (most recent call last):
  File "/sw/arch/Debian10/EB_production/2019/software/Anaconda3/2018.12/lib/python3.7/logging/__init__.py", line 1036, in emit
    stream.write(msg)
UnicodeEncodeError: 'latin-1' codec can't encode character '\u039f' in position 72: ordinal not in range(256)
Call stack:
  File "/sw/arch/Debian10/EB_production/2019/software/Anaconda3/2018.12/lib/python3.7/runpy.py", line 193, in _run_module_as_main
    "__main__", mod_spec)
  File "/sw/arch/Debian10/EB_production/2019/software/Anaconda3/2018.12/lib/python3.7/runpy.py", line 85, in _run_code
    exec(code, run_globals)
  File "/home/lcur0009/joeynmt/joeynmt/__main__.py", line 48, in <module>
    main()
  File "/home/lcur0009/joeynmt/joeynmt/__main__.py", line 35, in main
    train(cfg_file=args.config_path, skip_test=args.skip_test)
  File "/home/lcur0009/joeynmt/joeynmt/training.py", line 846, in train
    trainer.train_and_validate(train_data=train_data, valid_data=dev_data)
  File "/home/lcur0009/joeynmt/joeynmt/training.py", line 497, in train_and_validate
    valid_duration = self._validate(valid_data, epoch_no)
  File "/home/lcur0009/joeynmt/joeynmt/training.py", line 642, in _validate
    references=valid_references)
  File "/home/lcur0009/joeynmt/joeynmt/training.py", line 731, in _log_examples
    logger.debug("\tRaw source:     %s", sources_raw[p])
Message: '\tRaw source:     %s'
Arguments: (['\u039f', '\u03c0\u03b1\u03c4@@', '\u03ad\u03c1\u03b1\u03c2', '\u03bc\u03bf\u03c5', '\u03ac@@', '\u03ba\u03bf\u03c5@@', '\u03b3@@', '\u03b5', '\u03c4\u03b1', '\u039d@@', '\u03ad\u03b1', '\u03c4\u03bf\u03c5', 'B@@', 'B@@', 'C', '\u03c3\u03c4\u03bf', '\u03bc\u03b9\u03ba\u03c1\u03cc', '\u03b3@@', '\u03ba\u03c1@@', '\u03b9', '\u03c1\u03b1@@', '\u03b4\u03b9@@', '\u03cc@@', '\u03c6\u03c9\u03bd@@', '\u03cc', '\u03c4\u03bf\u03c5', '.'],)
--- Logging error ---
Traceback (most recent call last):
  File "/sw/arch/Debian10/EB_production/2019/software/Anaconda3/2018.12/lib/python3.7/logging/__init__.py", line 1036, in emit
    stream.write(msg)
UnicodeEncodeError: 'latin-1' codec can't encode character '\u039f' in position 65: ordinal not in range(256)
Call stack:
  File "/sw/arch/Debian10/EB_production/2019/software/Anaconda3/2018.12/lib/python3.7/runpy.py", line 193, in _run_module_as_main
    "__main__", mod_spec)
  File "/sw/arch/Debian10/EB_production/2019/software/Anaconda3/2018.12/lib/python3.7/runpy.py", line 85, in _run_code
    exec(code, run_globals)
  File "/home/lcur0009/joeynmt/joeynmt/__main__.py", line 48, in <module>
    main()
  File "/home/lcur0009/joeynmt/joeynmt/__main__.py", line 35, in main
    train(cfg_file=args.config_path, skip_test=args.skip_test)
  File "/home/lcur0009/joeynmt/joeynmt/training.py", line 846, in train
    trainer.train_and_validate(train_data=train_data, valid_data=dev_data)
  File "/home/lcur0009/joeynmt/joeynmt/training.py", line 497, in train_and_validate
    valid_duration = self._validate(valid_data, epoch_no)
  File "/home/lcur0009/joeynmt/joeynmt/training.py", line 642, in _validate
    references=valid_references)
  File "/home/lcur0009/joeynmt/joeynmt/training.py", line 737, in _log_examples
    logger.info("\tSource:     %s", sources[p])
Message: '\tSource:     %s'
Arguments: ('\u039f \u03c0\u03b1\u03c4\u03ad\u03c1\u03b1\u03c2 \u03bc\u03bf\u03c5 \u03ac\u03ba\u03bf\u03c5\u03b3\u03b5 \u03c4\u03b1 \u039d\u03ad\u03b1 \u03c4\u03bf\u03c5 BBC \u03c3\u03c4\u03bf \u03bc\u03b9\u03ba\u03c1\u03cc \u03b3\u03ba\u03c1\u03b9 \u03c1\u03b1\u03b4\u03b9\u03cc\u03c6\u03c9\u03bd\u03cc \u03c4\u03bf\u03c5 .',)
2021-10-03 13:25:23,377 - INFO - joeynmt.training - 	Source:     \u039f \u03c0\u03b1\u03c4\u03ad\u03c1\u03b1\u03c2 \u03bc\u03bf\u03c5 \u03ac\u03ba\u03bf\u03c5\u03b3\u03b5 \u03c4\u03b1 \u039d\u03ad\u03b1 \u03c4\u03bf\u03c5 BBC \u03c3\u03c4\u03bf \u03bc\u03b9\u03ba\u03c1\u03cc \u03b3\u03ba\u03c1\u03b9 \u03c1\u03b1\u03b4\u03b9\u03cc\u03c6\u03c9\u03bd\u03cc \u03c4\u03bf\u03c5 .
2021-10-03 13:25:23,378 - INFO - joeynmt.training - 	Reference:  "My father was listening to BBC News on his small , gray radio ."
2021-10-03 13:25:23,378 - INFO - joeynmt.training - 	Hypothesis: And the the the ssed of the world of the world of the world of the world .
2021-10-03 13:25:23,378 - INFO - joeynmt.training - Validation result (greedy) at epoch   7, step      400: bleu:   1.91, loss: 85482.3906, ppl: 245.4080, duration: 4.9769s
2021-10-03 13:25:33,321 - INFO - joeynmt.training - Epoch   7: total training loss 7012.96
2021-10-03 13:25:33,321 - INFO - joeynmt.training - EPOCH 8
2021-10-03 13:25:49,389 - WARNING - sacrebleu - That's 100 lines that end in a tokenized period ('.')
2021-10-03 13:25:49,389 - WARNING - sacrebleu - It looks like you forgot to detokenize your test data, which may hurt your score.
2021-10-03 13:25:49,389 - WARNING - sacrebleu - If you insist your data is detokenized, or don't care, you can suppress this message with the `force` parameter.
2021-10-03 13:25:49,396 - INFO - joeynmt.training - Example #0
2021-10-03 13:25:49,397 - INFO - joeynmt.training - 	Source:     el
2021-10-03 13:25:49,397 - INFO - joeynmt.training - 	Reference:  en
2021-10-03 13:25:49,397 - INFO - joeynmt.training - 	Hypothesis: Thank you .
2021-10-03 13:25:49,397 - INFO - joeynmt.training - Example #1
--- Logging error ---
Traceback (most recent call last):
  File "/sw/arch/Debian10/EB_production/2019/software/Anaconda3/2018.12/lib/python3.7/logging/__init__.py", line 1036, in emit
    stream.write(msg)
UnicodeEncodeError: 'latin-1' codec can't encode characters in position 73-76: ordinal not in range(256)
Call stack:
  File "/sw/arch/Debian10/EB_production/2019/software/Anaconda3/2018.12/lib/python3.7/runpy.py", line 193, in _run_module_as_main
    "__main__", mod_spec)
  File "/sw/arch/Debian10/EB_production/2019/software/Anaconda3/2018.12/lib/python3.7/runpy.py", line 85, in _run_code
    exec(code, run_globals)
  File "/home/lcur0009/joeynmt/joeynmt/__main__.py", line 48, in <module>
    main()
  File "/home/lcur0009/joeynmt/joeynmt/__main__.py", line 35, in main
    train(cfg_file=args.config_path, skip_test=args.skip_test)
  File "/home/lcur0009/joeynmt/joeynmt/training.py", line 846, in train
    trainer.train_and_validate(train_data=train_data, valid_data=dev_data)
  File "/home/lcur0009/joeynmt/joeynmt/training.py", line 497, in train_and_validate
    valid_duration = self._validate(valid_data, epoch_no)
  File "/home/lcur0009/joeynmt/joeynmt/training.py", line 642, in _validate
    references=valid_references)
  File "/home/lcur0009/joeynmt/joeynmt/training.py", line 731, in _log_examples
    logger.debug("\tRaw source:     %s", sources_raw[p])
Message: '\tRaw source:     %s'
Arguments: (['"\u038c\u03c4\u03b1\u03bd', '\u03ae\u03bc\u03bf\u03c5\u03bd', '1@@', '1', ',', '\u0398@@', '\u03c5@@', '\u03bc\u03ac@@', '\u03bc\u03b1\u03b9', '\u03c0\u03c9\u03c2', '\u03be@@', '\u03cd\u03c0@@', '\u03bd\u03b7@@', '\u03c3\u03b1', '\u03ad\u03bd\u03b1', '\u03c0\u03c1\u03c9@@', '\u03af', '\u03bc\u03b5', '\u03ae@@', '\u03c7@@', '\u03bf\u03c5\u03c2', '\u03c7\u03b1\u03c1@@', '\u03ac\u03c2', '\u03c3\u03c4\u03bf', '\u03c3\u03c0\u03af\u03c4\u03b9', '."'],)
--- Logging error ---
Traceback (most recent call last):
  File "/sw/arch/Debian10/EB_production/2019/software/Anaconda3/2018.12/lib/python3.7/logging/__init__.py", line 1036, in emit
    stream.write(msg)
UnicodeEncodeError: 'latin-1' codec can't encode characters in position 66-69: ordinal not in range(256)
Call stack:
  File "/sw/arch/Debian10/EB_production/2019/software/Anaconda3/2018.12/lib/python3.7/runpy.py", line 193, in _run_module_as_main
    "__main__", mod_spec)
  File "/sw/arch/Debian10/EB_production/2019/software/Anaconda3/2018.12/lib/python3.7/runpy.py", line 85, in _run_code
    exec(code, run_globals)
  File "/home/lcur0009/joeynmt/joeynmt/__main__.py", line 48, in <module>
    main()
  File "/home/lcur0009/joeynmt/joeynmt/__main__.py", line 35, in main
    train(cfg_file=args.config_path, skip_test=args.skip_test)
  File "/home/lcur0009/joeynmt/joeynmt/training.py", line 846, in train
    trainer.train_and_validate(train_data=train_data, valid_data=dev_data)
  File "/home/lcur0009/joeynmt/joeynmt/training.py", line 497, in train_and_validate
    valid_duration = self._validate(valid_data, epoch_no)
  File "/home/lcur0009/joeynmt/joeynmt/training.py", line 642, in _validate
    references=valid_references)
  File "/home/lcur0009/joeynmt/joeynmt/training.py", line 737, in _log_examples
    logger.info("\tSource:     %s", sources[p])
Message: '\tSource:     %s'
Arguments: ('"\u038c\u03c4\u03b1\u03bd \u03ae\u03bc\u03bf\u03c5\u03bd 11 , \u0398\u03c5\u03bc\u03ac\u03bc\u03b1\u03b9 \u03c0\u03c9\u03c2 \u03be\u03cd\u03c0\u03bd\u03b7\u03c3\u03b1 \u03ad\u03bd\u03b1 \u03c0\u03c1\u03c9\u03af \u03bc\u03b5 \u03ae\u03c7\u03bf\u03c5\u03c2 \u03c7\u03b1\u03c1\u03ac\u03c2 \u03c3\u03c4\u03bf \u03c3\u03c0\u03af\u03c4\u03b9 ."',)
2021-10-03 13:25:49,400 - INFO - joeynmt.training - 	Source:     "\u038c\u03c4\u03b1\u03bd \u03ae\u03bc\u03bf\u03c5\u03bd 11 , \u0398\u03c5\u03bc\u03ac\u03bc\u03b1\u03b9 \u03c0\u03c9\u03c2 \u03be\u03cd\u03c0\u03bd\u03b7\u03c3\u03b1 \u03ad\u03bd\u03b1 \u03c0\u03c1\u03c9\u03af \u03bc\u03b5 \u03ae\u03c7\u03bf\u03c5\u03c2 \u03c7\u03b1\u03c1\u03ac\u03c2 \u03c3\u03c4\u03bf \u03c3\u03c0\u03af\u03c4\u03b9 ."
2021-10-03 13:25:49,400 - INFO - joeynmt.training - 	Reference:  "When I was 11 , I remember waking up one morning to the sound of joy in my house ."
2021-10-03 13:25:49,401 - INFO - joeynmt.training - 	Hypothesis: "And I have a way , I can be a way , I can be a way , I can be a way ."
2021-10-03 13:25:49,401 - INFO - joeynmt.training - Example #2
--- Logging error ---
Traceback (most recent call last):
  File "/sw/arch/Debian10/EB_production/2019/software/Anaconda3/2018.12/lib/python3.7/logging/__init__.py", line 1036, in emit
    stream.write(msg)
UnicodeEncodeError: 'latin-1' codec can't encode character '\u039f' in position 72: ordinal not in range(256)
Call stack:
  File "/sw/arch/Debian10/EB_production/2019/software/Anaconda3/2018.12/lib/python3.7/runpy.py", line 193, in _run_module_as_main
    "__main__", mod_spec)
  File "/sw/arch/Debian10/EB_production/2019/software/Anaconda3/2018.12/lib/python3.7/runpy.py", line 85, in _run_code
    exec(code, run_globals)
  File "/home/lcur0009/joeynmt/joeynmt/__main__.py", line 48, in <module>
    main()
  File "/home/lcur0009/joeynmt/joeynmt/__main__.py", line 35, in main
    train(cfg_file=args.config_path, skip_test=args.skip_test)
  File "/home/lcur0009/joeynmt/joeynmt/training.py", line 846, in train
    trainer.train_and_validate(train_data=train_data, valid_data=dev_data)
  File "/home/lcur0009/joeynmt/joeynmt/training.py", line 497, in train_and_validate
    valid_duration = self._validate(valid_data, epoch_no)
  File "/home/lcur0009/joeynmt/joeynmt/training.py", line 642, in _validate
    references=valid_references)
  File "/home/lcur0009/joeynmt/joeynmt/training.py", line 731, in _log_examples
    logger.debug("\tRaw source:     %s", sources_raw[p])
Message: '\tRaw source:     %s'
Arguments: (['\u039f', '\u03c0\u03b1\u03c4@@', '\u03ad\u03c1\u03b1\u03c2', '\u03bc\u03bf\u03c5', '\u03ac@@', '\u03ba\u03bf\u03c5@@', '\u03b3@@', '\u03b5', '\u03c4\u03b1', '\u039d@@', '\u03ad\u03b1', '\u03c4\u03bf\u03c5', 'B@@', 'B@@', 'C', '\u03c3\u03c4\u03bf', '\u03bc\u03b9\u03ba\u03c1\u03cc', '\u03b3@@', '\u03ba\u03c1@@', '\u03b9', '\u03c1\u03b1@@', '\u03b4\u03b9@@', '\u03cc@@', '\u03c6\u03c9\u03bd@@', '\u03cc', '\u03c4\u03bf\u03c5', '.'],)
--- Logging error ---
Traceback (most recent call last):
  File "/sw/arch/Debian10/EB_production/2019/software/Anaconda3/2018.12/lib/python3.7/logging/__init__.py", line 1036, in emit
    stream.write(msg)
UnicodeEncodeError: 'latin-1' codec can't encode character '\u039f' in position 65: ordinal not in range(256)
Call stack:
  File "/sw/arch/Debian10/EB_production/2019/software/Anaconda3/2018.12/lib/python3.7/runpy.py", line 193, in _run_module_as_main
    "__main__", mod_spec)
  File "/sw/arch/Debian10/EB_production/2019/software/Anaconda3/2018.12/lib/python3.7/runpy.py", line 85, in _run_code
    exec(code, run_globals)
  File "/home/lcur0009/joeynmt/joeynmt/__main__.py", line 48, in <module>
    main()
  File "/home/lcur0009/joeynmt/joeynmt/__main__.py", line 35, in main
    train(cfg_file=args.config_path, skip_test=args.skip_test)
  File "/home/lcur0009/joeynmt/joeynmt/training.py", line 846, in train
    trainer.train_and_validate(train_data=train_data, valid_data=dev_data)
  File "/home/lcur0009/joeynmt/joeynmt/training.py", line 497, in train_and_validate
    valid_duration = self._validate(valid_data, epoch_no)
  File "/home/lcur0009/joeynmt/joeynmt/training.py", line 642, in _validate
    references=valid_references)
  File "/home/lcur0009/joeynmt/joeynmt/training.py", line 737, in _log_examples
    logger.info("\tSource:     %s", sources[p])
Message: '\tSource:     %s'
Arguments: ('\u039f \u03c0\u03b1\u03c4\u03ad\u03c1\u03b1\u03c2 \u03bc\u03bf\u03c5 \u03ac\u03ba\u03bf\u03c5\u03b3\u03b5 \u03c4\u03b1 \u039d\u03ad\u03b1 \u03c4\u03bf\u03c5 BBC \u03c3\u03c4\u03bf \u03bc\u03b9\u03ba\u03c1\u03cc \u03b3\u03ba\u03c1\u03b9 \u03c1\u03b1\u03b4\u03b9\u03cc\u03c6\u03c9\u03bd\u03cc \u03c4\u03bf\u03c5 .',)
2021-10-03 13:25:49,402 - INFO - joeynmt.training - 	Source:     \u039f \u03c0\u03b1\u03c4\u03ad\u03c1\u03b1\u03c2 \u03bc\u03bf\u03c5 \u03ac\u03ba\u03bf\u03c5\u03b3\u03b5 \u03c4\u03b1 \u039d\u03ad\u03b1 \u03c4\u03bf\u03c5 BBC \u03c3\u03c4\u03bf \u03bc\u03b9\u03ba\u03c1\u03cc \u03b3\u03ba\u03c1\u03b9 \u03c1\u03b1\u03b4\u03b9\u03cc\u03c6\u03c9\u03bd\u03cc \u03c4\u03bf\u03c5 .
2021-10-03 13:25:49,403 - INFO - joeynmt.training - 	Reference:  "My father was listening to BBC News on his small , gray radio ."
2021-10-03 13:25:49,403 - INFO - joeynmt.training - 	Hypothesis: The first of the first of the world of the world of the world of the world .
2021-10-03 13:25:49,403 - INFO - joeynmt.training - Validation result (greedy) at epoch   8, step      500: bleu:   1.59, loss: 80862.2500, ppl: 182.2722, duration: 3.7311s
2021-10-03 13:25:51,460 - INFO - joeynmt.training - Epoch   8: total training loss 6711.60
2021-10-03 13:25:51,461 - INFO - joeynmt.training - EPOCH 9
2021-10-03 13:26:04,488 - INFO - joeynmt.training - Epoch   9: total training loss 6498.92
2021-10-03 13:26:04,489 - INFO - joeynmt.training - EPOCH 10
2021-10-03 13:26:15,109 - WARNING - sacrebleu - That's 100 lines that end in a tokenized period ('.')
2021-10-03 13:26:15,109 - WARNING - sacrebleu - It looks like you forgot to detokenize your test data, which may hurt your score.
2021-10-03 13:26:15,109 - WARNING - sacrebleu - If you insist your data is detokenized, or don't care, you can suppress this message with the `force` parameter.
2021-10-03 13:26:15,114 - INFO - joeynmt.training - Hooray! New best validation result [eval_metric]!
2021-10-03 13:26:16,026 - INFO - joeynmt.helpers - delete models/LSTM_el/400.ckpt
2021-10-03 13:26:16,101 - INFO - joeynmt.helpers - delete /home/lcur0009/joeynmt/models/LSTM_el/400.ckpt
2021-10-03 13:26:16,102 - WARNING - joeynmt.helpers - Wanted to delete old checkpoint /home/lcur0009/joeynmt/models/LSTM_el/400.ckpt but file does not exist. ([Errno 2] No such file or directory: '/home/lcur0009/joeynmt/models/LSTM_el/400.ckpt')
2021-10-03 13:26:16,104 - INFO - joeynmt.training - Example #0
2021-10-03 13:26:16,104 - INFO - joeynmt.training - 	Source:     el
2021-10-03 13:26:16,105 - INFO - joeynmt.training - 	Reference:  en
2021-10-03 13:26:16,105 - INFO - joeynmt.training - 	Hypothesis: Thank you .
2021-10-03 13:26:16,105 - INFO - joeynmt.training - Example #1
--- Logging error ---
Traceback (most recent call last):
  File "/sw/arch/Debian10/EB_production/2019/software/Anaconda3/2018.12/lib/python3.7/logging/__init__.py", line 1036, in emit
    stream.write(msg)
UnicodeEncodeError: 'latin-1' codec can't encode characters in position 73-76: ordinal not in range(256)
Call stack:
  File "/sw/arch/Debian10/EB_production/2019/software/Anaconda3/2018.12/lib/python3.7/runpy.py", line 193, in _run_module_as_main
    "__main__", mod_spec)
  File "/sw/arch/Debian10/EB_production/2019/software/Anaconda3/2018.12/lib/python3.7/runpy.py", line 85, in _run_code
    exec(code, run_globals)
  File "/home/lcur0009/joeynmt/joeynmt/__main__.py", line 48, in <module>
    main()
  File "/home/lcur0009/joeynmt/joeynmt/__main__.py", line 35, in main
    train(cfg_file=args.config_path, skip_test=args.skip_test)
  File "/home/lcur0009/joeynmt/joeynmt/training.py", line 846, in train
    trainer.train_and_validate(train_data=train_data, valid_data=dev_data)
  File "/home/lcur0009/joeynmt/joeynmt/training.py", line 497, in train_and_validate
    valid_duration = self._validate(valid_data, epoch_no)
  File "/home/lcur0009/joeynmt/joeynmt/training.py", line 642, in _validate
    references=valid_references)
  File "/home/lcur0009/joeynmt/joeynmt/training.py", line 731, in _log_examples
    logger.debug("\tRaw source:     %s", sources_raw[p])
Message: '\tRaw source:     %s'
Arguments: (['"\u038c\u03c4\u03b1\u03bd', '\u03ae\u03bc\u03bf\u03c5\u03bd', '1@@', '1', ',', '\u0398@@', '\u03c5@@', '\u03bc\u03ac@@', '\u03bc\u03b1\u03b9', '\u03c0\u03c9\u03c2', '\u03be@@', '\u03cd\u03c0@@', '\u03bd\u03b7@@', '\u03c3\u03b1', '\u03ad\u03bd\u03b1', '\u03c0\u03c1\u03c9@@', '\u03af', '\u03bc\u03b5', '\u03ae@@', '\u03c7@@', '\u03bf\u03c5\u03c2', '\u03c7\u03b1\u03c1@@', '\u03ac\u03c2', '\u03c3\u03c4\u03bf', '\u03c3\u03c0\u03af\u03c4\u03b9', '."'],)
--- Logging error ---
Traceback (most recent call last):
  File "/sw/arch/Debian10/EB_production/2019/software/Anaconda3/2018.12/lib/python3.7/logging/__init__.py", line 1036, in emit
    stream.write(msg)
UnicodeEncodeError: 'latin-1' codec can't encode characters in position 66-69: ordinal not in range(256)
Call stack:
  File "/sw/arch/Debian10/EB_production/2019/software/Anaconda3/2018.12/lib/python3.7/runpy.py", line 193, in _run_module_as_main
    "__main__", mod_spec)
  File "/sw/arch/Debian10/EB_production/2019/software/Anaconda3/2018.12/lib/python3.7/runpy.py", line 85, in _run_code
    exec(code, run_globals)
  File "/home/lcur0009/joeynmt/joeynmt/__main__.py", line 48, in <module>
    main()
  File "/home/lcur0009/joeynmt/joeynmt/__main__.py", line 35, in main
    train(cfg_file=args.config_path, skip_test=args.skip_test)
  File "/home/lcur0009/joeynmt/joeynmt/training.py", line 846, in train
    trainer.train_and_validate(train_data=train_data, valid_data=dev_data)
  File "/home/lcur0009/joeynmt/joeynmt/training.py", line 497, in train_and_validate
    valid_duration = self._validate(valid_data, epoch_no)
  File "/home/lcur0009/joeynmt/joeynmt/training.py", line 642, in _validate
    references=valid_references)
  File "/home/lcur0009/joeynmt/joeynmt/training.py", line 737, in _log_examples
    logger.info("\tSource:     %s", sources[p])
Message: '\tSource:     %s'
Arguments: ('"\u038c\u03c4\u03b1\u03bd \u03ae\u03bc\u03bf\u03c5\u03bd 11 , \u0398\u03c5\u03bc\u03ac\u03bc\u03b1\u03b9 \u03c0\u03c9\u03c2 \u03be\u03cd\u03c0\u03bd\u03b7\u03c3\u03b1 \u03ad\u03bd\u03b1 \u03c0\u03c1\u03c9\u03af \u03bc\u03b5 \u03ae\u03c7\u03bf\u03c5\u03c2 \u03c7\u03b1\u03c1\u03ac\u03c2 \u03c3\u03c4\u03bf \u03c3\u03c0\u03af\u03c4\u03b9 ."',)
2021-10-03 13:26:16,107 - INFO - joeynmt.training - 	Source:     "\u038c\u03c4\u03b1\u03bd \u03ae\u03bc\u03bf\u03c5\u03bd 11 , \u0398\u03c5\u03bc\u03ac\u03bc\u03b1\u03b9 \u03c0\u03c9\u03c2 \u03be\u03cd\u03c0\u03bd\u03b7\u03c3\u03b1 \u03ad\u03bd\u03b1 \u03c0\u03c1\u03c9\u03af \u03bc\u03b5 \u03ae\u03c7\u03bf\u03c5\u03c2 \u03c7\u03b1\u03c1\u03ac\u03c2 \u03c3\u03c4\u03bf \u03c3\u03c0\u03af\u03c4\u03b9 ."
2021-10-03 13:26:16,107 - INFO - joeynmt.training - 	Reference:  "When I was 11 , I remember waking up one morning to the sound of joy in my house ."
2021-10-03 13:26:16,108 - INFO - joeynmt.training - 	Hypothesis: "And I have a sssssssssssssssssssssssssssssss."
2021-10-03 13:26:16,108 - INFO - joeynmt.training - Example #2
--- Logging error ---
Traceback (most recent call last):
  File "/sw/arch/Debian10/EB_production/2019/software/Anaconda3/2018.12/lib/python3.7/logging/__init__.py", line 1036, in emit
    stream.write(msg)
UnicodeEncodeError: 'latin-1' codec can't encode character '\u039f' in position 72: ordinal not in range(256)
Call stack:
  File "/sw/arch/Debian10/EB_production/2019/software/Anaconda3/2018.12/lib/python3.7/runpy.py", line 193, in _run_module_as_main
    "__main__", mod_spec)
  File "/sw/arch/Debian10/EB_production/2019/software/Anaconda3/2018.12/lib/python3.7/runpy.py", line 85, in _run_code
    exec(code, run_globals)
  File "/home/lcur0009/joeynmt/joeynmt/__main__.py", line 48, in <module>
    main()
  File "/home/lcur0009/joeynmt/joeynmt/__main__.py", line 35, in main
    train(cfg_file=args.config_path, skip_test=args.skip_test)
  File "/home/lcur0009/joeynmt/joeynmt/training.py", line 846, in train
    trainer.train_and_validate(train_data=train_data, valid_data=dev_data)
  File "/home/lcur0009/joeynmt/joeynmt/training.py", line 497, in train_and_validate
    valid_duration = self._validate(valid_data, epoch_no)
  File "/home/lcur0009/joeynmt/joeynmt/training.py", line 642, in _validate
    references=valid_references)
  File "/home/lcur0009/joeynmt/joeynmt/training.py", line 731, in _log_examples
    logger.debug("\tRaw source:     %s", sources_raw[p])
Message: '\tRaw source:     %s'
Arguments: (['\u039f', '\u03c0\u03b1\u03c4@@', '\u03ad\u03c1\u03b1\u03c2', '\u03bc\u03bf\u03c5', '\u03ac@@', '\u03ba\u03bf\u03c5@@', '\u03b3@@', '\u03b5', '\u03c4\u03b1', '\u039d@@', '\u03ad\u03b1', '\u03c4\u03bf\u03c5', 'B@@', 'B@@', 'C', '\u03c3\u03c4\u03bf', '\u03bc\u03b9\u03ba\u03c1\u03cc', '\u03b3@@', '\u03ba\u03c1@@', '\u03b9', '\u03c1\u03b1@@', '\u03b4\u03b9@@', '\u03cc@@', '\u03c6\u03c9\u03bd@@', '\u03cc', '\u03c4\u03bf\u03c5', '.'],)
--- Logging error ---
Traceback (most recent call last):
  File "/sw/arch/Debian10/EB_production/2019/software/Anaconda3/2018.12/lib/python3.7/logging/__init__.py", line 1036, in emit
    stream.write(msg)
UnicodeEncodeError: 'latin-1' codec can't encode character '\u039f' in position 65: ordinal not in range(256)
Call stack:
  File "/sw/arch/Debian10/EB_production/2019/software/Anaconda3/2018.12/lib/python3.7/runpy.py", line 193, in _run_module_as_main
    "__main__", mod_spec)
  File "/sw/arch/Debian10/EB_production/2019/software/Anaconda3/2018.12/lib/python3.7/runpy.py", line 85, in _run_code
    exec(code, run_globals)
  File "/home/lcur0009/joeynmt/joeynmt/__main__.py", line 48, in <module>
    main()
  File "/home/lcur0009/joeynmt/joeynmt/__main__.py", line 35, in main
    train(cfg_file=args.config_path, skip_test=args.skip_test)
  File "/home/lcur0009/joeynmt/joeynmt/training.py", line 846, in train
    trainer.train_and_validate(train_data=train_data, valid_data=dev_data)
  File "/home/lcur0009/joeynmt/joeynmt/training.py", line 497, in train_and_validate
    valid_duration = self._validate(valid_data, epoch_no)
  File "/home/lcur0009/joeynmt/joeynmt/training.py", line 642, in _validate
    references=valid_references)
  File "/home/lcur0009/joeynmt/joeynmt/training.py", line 737, in _log_examples
    logger.info("\tSource:     %s", sources[p])
Message: '\tSource:     %s'
Arguments: ('\u039f \u03c0\u03b1\u03c4\u03ad\u03c1\u03b1\u03c2 \u03bc\u03bf\u03c5 \u03ac\u03ba\u03bf\u03c5\u03b3\u03b5 \u03c4\u03b1 \u039d\u03ad\u03b1 \u03c4\u03bf\u03c5 BBC \u03c3\u03c4\u03bf \u03bc\u03b9\u03ba\u03c1\u03cc \u03b3\u03ba\u03c1\u03b9 \u03c1\u03b1\u03b4\u03b9\u03cc\u03c6\u03c9\u03bd\u03cc \u03c4\u03bf\u03c5 .',)
2021-10-03 13:26:16,109 - INFO - joeynmt.training - 	Source:     \u039f \u03c0\u03b1\u03c4\u03ad\u03c1\u03b1\u03c2 \u03bc\u03bf\u03c5 \u03ac\u03ba\u03bf\u03c5\u03b3\u03b5 \u03c4\u03b1 \u039d\u03ad\u03b1 \u03c4\u03bf\u03c5 BBC \u03c3\u03c4\u03bf \u03bc\u03b9\u03ba\u03c1\u03cc \u03b3\u03ba\u03c1\u03b9 \u03c1\u03b1\u03b4\u03b9\u03cc\u03c6\u03c9\u03bd\u03cc \u03c4\u03bf\u03c5 .
2021-10-03 13:26:16,110 - INFO - joeynmt.training - 	Reference:  "My father was listening to BBC News on his small , gray radio ."
2021-10-03 13:26:16,110 - INFO - joeynmt.training - 	Hypothesis: The first of the world is the world is a world of the world .
2021-10-03 13:26:16,110 - INFO - joeynmt.training - Validation result (greedy) at epoch  10, step      600: bleu:   3.81, loss: 78809.8125, ppl: 159.7126, duration: 4.6711s
2021-10-03 13:26:23,719 - INFO - joeynmt.training - Epoch  10: total training loss 6329.73
2021-10-03 13:26:23,720 - INFO - joeynmt.training - EPOCH 11
2021-10-03 13:26:36,820 - INFO - joeynmt.training - Epoch  11: total training loss 6182.15
2021-10-03 13:26:36,821 - INFO - joeynmt.training - EPOCH 12
2021-10-03 13:26:42,032 - WARNING - sacrebleu - That's 100 lines that end in a tokenized period ('.')
2021-10-03 13:26:42,033 - WARNING - sacrebleu - It looks like you forgot to detokenize your test data, which may hurt your score.
2021-10-03 13:26:42,033 - WARNING - sacrebleu - If you insist your data is detokenized, or don't care, you can suppress this message with the `force` parameter.
2021-10-03 13:26:42,039 - INFO - joeynmt.training - Hooray! New best validation result [eval_metric]!
2021-10-03 13:26:42,981 - INFO - joeynmt.helpers - delete models/LSTM_el/600.ckpt
2021-10-03 13:26:43,061 - INFO - joeynmt.helpers - delete /home/lcur0009/joeynmt/models/LSTM_el/600.ckpt
2021-10-03 13:26:43,062 - WARNING - joeynmt.helpers - Wanted to delete old checkpoint /home/lcur0009/joeynmt/models/LSTM_el/600.ckpt but file does not exist. ([Errno 2] No such file or directory: '/home/lcur0009/joeynmt/models/LSTM_el/600.ckpt')
2021-10-03 13:26:43,064 - INFO - joeynmt.training - Example #0
2021-10-03 13:26:43,064 - INFO - joeynmt.training - 	Source:     el
2021-10-03 13:26:43,064 - INFO - joeynmt.training - 	Reference:  en
2021-10-03 13:26:43,064 - INFO - joeynmt.training - 	Hypothesis: Thank you .
2021-10-03 13:26:43,064 - INFO - joeynmt.training - Example #1
--- Logging error ---
Traceback (most recent call last):
  File "/sw/arch/Debian10/EB_production/2019/software/Anaconda3/2018.12/lib/python3.7/logging/__init__.py", line 1036, in emit
    stream.write(msg)
UnicodeEncodeError: 'latin-1' codec can't encode characters in position 73-76: ordinal not in range(256)
Call stack:
  File "/sw/arch/Debian10/EB_production/2019/software/Anaconda3/2018.12/lib/python3.7/runpy.py", line 193, in _run_module_as_main
    "__main__", mod_spec)
  File "/sw/arch/Debian10/EB_production/2019/software/Anaconda3/2018.12/lib/python3.7/runpy.py", line 85, in _run_code
    exec(code, run_globals)
  File "/home/lcur0009/joeynmt/joeynmt/__main__.py", line 48, in <module>
    main()
  File "/home/lcur0009/joeynmt/joeynmt/__main__.py", line 35, in main
    train(cfg_file=args.config_path, skip_test=args.skip_test)
  File "/home/lcur0009/joeynmt/joeynmt/training.py", line 846, in train
    trainer.train_and_validate(train_data=train_data, valid_data=dev_data)
  File "/home/lcur0009/joeynmt/joeynmt/training.py", line 497, in train_and_validate
    valid_duration = self._validate(valid_data, epoch_no)
  File "/home/lcur0009/joeynmt/joeynmt/training.py", line 642, in _validate
    references=valid_references)
  File "/home/lcur0009/joeynmt/joeynmt/training.py", line 731, in _log_examples
    logger.debug("\tRaw source:     %s", sources_raw[p])
Message: '\tRaw source:     %s'
Arguments: (['"\u038c\u03c4\u03b1\u03bd', '\u03ae\u03bc\u03bf\u03c5\u03bd', '1@@', '1', ',', '\u0398@@', '\u03c5@@', '\u03bc\u03ac@@', '\u03bc\u03b1\u03b9', '\u03c0\u03c9\u03c2', '\u03be@@', '\u03cd\u03c0@@', '\u03bd\u03b7@@', '\u03c3\u03b1', '\u03ad\u03bd\u03b1', '\u03c0\u03c1\u03c9@@', '\u03af', '\u03bc\u03b5', '\u03ae@@', '\u03c7@@', '\u03bf\u03c5\u03c2', '\u03c7\u03b1\u03c1@@', '\u03ac\u03c2', '\u03c3\u03c4\u03bf', '\u03c3\u03c0\u03af\u03c4\u03b9', '."'],)
--- Logging error ---
Traceback (most recent call last):
  File "/sw/arch/Debian10/EB_production/2019/software/Anaconda3/2018.12/lib/python3.7/logging/__init__.py", line 1036, in emit
    stream.write(msg)
UnicodeEncodeError: 'latin-1' codec can't encode characters in position 66-69: ordinal not in range(256)
Call stack:
  File "/sw/arch/Debian10/EB_production/2019/software/Anaconda3/2018.12/lib/python3.7/runpy.py", line 193, in _run_module_as_main
    "__main__", mod_spec)
  File "/sw/arch/Debian10/EB_production/2019/software/Anaconda3/2018.12/lib/python3.7/runpy.py", line 85, in _run_code
    exec(code, run_globals)
  File "/home/lcur0009/joeynmt/joeynmt/__main__.py", line 48, in <module>
    main()
  File "/home/lcur0009/joeynmt/joeynmt/__main__.py", line 35, in main
    train(cfg_file=args.config_path, skip_test=args.skip_test)
  File "/home/lcur0009/joeynmt/joeynmt/training.py", line 846, in train
    trainer.train_and_validate(train_data=train_data, valid_data=dev_data)
  File "/home/lcur0009/joeynmt/joeynmt/training.py", line 497, in train_and_validate
    valid_duration = self._validate(valid_data, epoch_no)
  File "/home/lcur0009/joeynmt/joeynmt/training.py", line 642, in _validate
    references=valid_references)
  File "/home/lcur0009/joeynmt/joeynmt/training.py", line 737, in _log_examples
    logger.info("\tSource:     %s", sources[p])
Message: '\tSource:     %s'
Arguments: ('"\u038c\u03c4\u03b1\u03bd \u03ae\u03bc\u03bf\u03c5\u03bd 11 , \u0398\u03c5\u03bc\u03ac\u03bc\u03b1\u03b9 \u03c0\u03c9\u03c2 \u03be\u03cd\u03c0\u03bd\u03b7\u03c3\u03b1 \u03ad\u03bd\u03b1 \u03c0\u03c1\u03c9\u03af \u03bc\u03b5 \u03ae\u03c7\u03bf\u03c5\u03c2 \u03c7\u03b1\u03c1\u03ac\u03c2 \u03c3\u03c4\u03bf \u03c3\u03c0\u03af\u03c4\u03b9 ."',)
2021-10-03 13:26:43,065 - INFO - joeynmt.training - 	Source:     "\u038c\u03c4\u03b1\u03bd \u03ae\u03bc\u03bf\u03c5\u03bd 11 , \u0398\u03c5\u03bc\u03ac\u03bc\u03b1\u03b9 \u03c0\u03c9\u03c2 \u03be\u03cd\u03c0\u03bd\u03b7\u03c3\u03b1 \u03ad\u03bd\u03b1 \u03c0\u03c1\u03c9\u03af \u03bc\u03b5 \u03ae\u03c7\u03bf\u03c5\u03c2 \u03c7\u03b1\u03c1\u03ac\u03c2 \u03c3\u03c4\u03bf \u03c3\u03c0\u03af\u03c4\u03b9 ."
2021-10-03 13:26:43,066 - INFO - joeynmt.training - 	Reference:  "When I was 11 , I remember waking up one morning to the sound of joy in my house ."
2021-10-03 13:26:43,066 - INFO - joeynmt.training - 	Hypothesis: "If you have a sey , I was a seth , I was a very ssy ."
2021-10-03 13:26:43,066 - INFO - joeynmt.training - Example #2
--- Logging error ---
Traceback (most recent call last):
  File "/sw/arch/Debian10/EB_production/2019/software/Anaconda3/2018.12/lib/python3.7/logging/__init__.py", line 1036, in emit
    stream.write(msg)
UnicodeEncodeError: 'latin-1' codec can't encode character '\u039f' in position 72: ordinal not in range(256)
Call stack:
  File "/sw/arch/Debian10/EB_production/2019/software/Anaconda3/2018.12/lib/python3.7/runpy.py", line 193, in _run_module_as_main
    "__main__", mod_spec)
  File "/sw/arch/Debian10/EB_production/2019/software/Anaconda3/2018.12/lib/python3.7/runpy.py", line 85, in _run_code
    exec(code, run_globals)
  File "/home/lcur0009/joeynmt/joeynmt/__main__.py", line 48, in <module>
    main()
  File "/home/lcur0009/joeynmt/joeynmt/__main__.py", line 35, in main
    train(cfg_file=args.config_path, skip_test=args.skip_test)
  File "/home/lcur0009/joeynmt/joeynmt/training.py", line 846, in train
    trainer.train_and_validate(train_data=train_data, valid_data=dev_data)
  File "/home/lcur0009/joeynmt/joeynmt/training.py", line 497, in train_and_validate
    valid_duration = self._validate(valid_data, epoch_no)
  File "/home/lcur0009/joeynmt/joeynmt/training.py", line 642, in _validate
    references=valid_references)
  File "/home/lcur0009/joeynmt/joeynmt/training.py", line 731, in _log_examples
    logger.debug("\tRaw source:     %s", sources_raw[p])
Message: '\tRaw source:     %s'
Arguments: (['\u039f', '\u03c0\u03b1\u03c4@@', '\u03ad\u03c1\u03b1\u03c2', '\u03bc\u03bf\u03c5', '\u03ac@@', '\u03ba\u03bf\u03c5@@', '\u03b3@@', '\u03b5', '\u03c4\u03b1', '\u039d@@', '\u03ad\u03b1', '\u03c4\u03bf\u03c5', 'B@@', 'B@@', 'C', '\u03c3\u03c4\u03bf', '\u03bc\u03b9\u03ba\u03c1\u03cc', '\u03b3@@', '\u03ba\u03c1@@', '\u03b9', '\u03c1\u03b1@@', '\u03b4\u03b9@@', '\u03cc@@', '\u03c6\u03c9\u03bd@@', '\u03cc', '\u03c4\u03bf\u03c5', '.'],)
--- Logging error ---
Traceback (most recent call last):
  File "/sw/arch/Debian10/EB_production/2019/software/Anaconda3/2018.12/lib/python3.7/logging/__init__.py", line 1036, in emit
    stream.write(msg)
UnicodeEncodeError: 'latin-1' codec can't encode character '\u039f' in position 65: ordinal not in range(256)
Call stack:
  File "/sw/arch/Debian10/EB_production/2019/software/Anaconda3/2018.12/lib/python3.7/runpy.py", line 193, in _run_module_as_main
    "__main__", mod_spec)
  File "/sw/arch/Debian10/EB_production/2019/software/Anaconda3/2018.12/lib/python3.7/runpy.py", line 85, in _run_code
    exec(code, run_globals)
  File "/home/lcur0009/joeynmt/joeynmt/__main__.py", line 48, in <module>
    main()
  File "/home/lcur0009/joeynmt/joeynmt/__main__.py", line 35, in main
    train(cfg_file=args.config_path, skip_test=args.skip_test)
  File "/home/lcur0009/joeynmt/joeynmt/training.py", line 846, in train
    trainer.train_and_validate(train_data=train_data, valid_data=dev_data)
  File "/home/lcur0009/joeynmt/joeynmt/training.py", line 497, in train_and_validate
    valid_duration = self._validate(valid_data, epoch_no)
  File "/home/lcur0009/joeynmt/joeynmt/training.py", line 642, in _validate
    references=valid_references)
  File "/home/lcur0009/joeynmt/joeynmt/training.py", line 737, in _log_examples
    logger.info("\tSource:     %s", sources[p])
Message: '\tSource:     %s'
Arguments: ('\u039f \u03c0\u03b1\u03c4\u03ad\u03c1\u03b1\u03c2 \u03bc\u03bf\u03c5 \u03ac\u03ba\u03bf\u03c5\u03b3\u03b5 \u03c4\u03b1 \u039d\u03ad\u03b1 \u03c4\u03bf\u03c5 BBC \u03c3\u03c4\u03bf \u03bc\u03b9\u03ba\u03c1\u03cc \u03b3\u03ba\u03c1\u03b9 \u03c1\u03b1\u03b4\u03b9\u03cc\u03c6\u03c9\u03bd\u03cc \u03c4\u03bf\u03c5 .',)
2021-10-03 13:26:43,066 - INFO - joeynmt.training - 	Source:     \u039f \u03c0\u03b1\u03c4\u03ad\u03c1\u03b1\u03c2 \u03bc\u03bf\u03c5 \u03ac\u03ba\u03bf\u03c5\u03b3\u03b5 \u03c4\u03b1 \u039d\u03ad\u03b1 \u03c4\u03bf\u03c5 BBC \u03c3\u03c4\u03bf \u03bc\u03b9\u03ba\u03c1\u03cc \u03b3\u03ba\u03c1\u03b9 \u03c1\u03b1\u03b4\u03b9\u03cc\u03c6\u03c9\u03bd\u03cc \u03c4\u03bf\u03c5 .
2021-10-03 13:26:43,067 - INFO - joeynmt.training - 	Reference:  "My father was listening to BBC News on his small , gray radio ."
2021-10-03 13:26:43,067 - INFO - joeynmt.training - 	Hypothesis: It &apos;s a first who was a first and we have to be a new world .
2021-10-03 13:26:43,067 - INFO - joeynmt.training - Validation result (greedy) at epoch  12, step      700: bleu:   3.97, loss: 77594.3594, ppl: 147.6923, duration: 4.7920s
2021-10-03 13:26:55,749 - INFO - joeynmt.training - Epoch  12: total training loss 6046.18
2021-10-03 13:26:55,750 - INFO - joeynmt.training - EPOCH 13
2021-10-03 13:27:08,537 - WARNING - sacrebleu - That's 100 lines that end in a tokenized period ('.')
2021-10-03 13:27:08,538 - WARNING - sacrebleu - It looks like you forgot to detokenize your test data, which may hurt your score.
2021-10-03 13:27:08,538 - WARNING - sacrebleu - If you insist your data is detokenized, or don't care, you can suppress this message with the `force` parameter.
2021-10-03 13:27:08,544 - INFO - joeynmt.training - Hooray! New best validation result [eval_metric]!
2021-10-03 13:27:09,587 - INFO - joeynmt.helpers - delete models/LSTM_el/700.ckpt
2021-10-03 13:27:09,666 - INFO - joeynmt.helpers - delete /home/lcur0009/joeynmt/models/LSTM_el/700.ckpt
2021-10-03 13:27:09,667 - WARNING - joeynmt.helpers - Wanted to delete old checkpoint /home/lcur0009/joeynmt/models/LSTM_el/700.ckpt but file does not exist. ([Errno 2] No such file or directory: '/home/lcur0009/joeynmt/models/LSTM_el/700.ckpt')
2021-10-03 13:27:09,671 - INFO - joeynmt.training - Example #0
2021-10-03 13:27:09,671 - INFO - joeynmt.training - 	Source:     el
2021-10-03 13:27:09,671 - INFO - joeynmt.training - 	Reference:  en
2021-10-03 13:27:09,671 - INFO - joeynmt.training - 	Hypothesis: Thank you .
2021-10-03 13:27:09,671 - INFO - joeynmt.training - Example #1
--- Logging error ---
Traceback (most recent call last):
  File "/sw/arch/Debian10/EB_production/2019/software/Anaconda3/2018.12/lib/python3.7/logging/__init__.py", line 1036, in emit
    stream.write(msg)
UnicodeEncodeError: 'latin-1' codec can't encode characters in position 73-76: ordinal not in range(256)
Call stack:
  File "/sw/arch/Debian10/EB_production/2019/software/Anaconda3/2018.12/lib/python3.7/runpy.py", line 193, in _run_module_as_main
    "__main__", mod_spec)
  File "/sw/arch/Debian10/EB_production/2019/software/Anaconda3/2018.12/lib/python3.7/runpy.py", line 85, in _run_code
    exec(code, run_globals)
  File "/home/lcur0009/joeynmt/joeynmt/__main__.py", line 48, in <module>
    main()
  File "/home/lcur0009/joeynmt/joeynmt/__main__.py", line 35, in main
    train(cfg_file=args.config_path, skip_test=args.skip_test)
  File "/home/lcur0009/joeynmt/joeynmt/training.py", line 846, in train
    trainer.train_and_validate(train_data=train_data, valid_data=dev_data)
  File "/home/lcur0009/joeynmt/joeynmt/training.py", line 497, in train_and_validate
    valid_duration = self._validate(valid_data, epoch_no)
  File "/home/lcur0009/joeynmt/joeynmt/training.py", line 642, in _validate
    references=valid_references)
  File "/home/lcur0009/joeynmt/joeynmt/training.py", line 731, in _log_examples
    logger.debug("\tRaw source:     %s", sources_raw[p])
Message: '\tRaw source:     %s'
Arguments: (['"\u038c\u03c4\u03b1\u03bd', '\u03ae\u03bc\u03bf\u03c5\u03bd', '1@@', '1', ',', '\u0398@@', '\u03c5@@', '\u03bc\u03ac@@', '\u03bc\u03b1\u03b9', '\u03c0\u03c9\u03c2', '\u03be@@', '\u03cd\u03c0@@', '\u03bd\u03b7@@', '\u03c3\u03b1', '\u03ad\u03bd\u03b1', '\u03c0\u03c1\u03c9@@', '\u03af', '\u03bc\u03b5', '\u03ae@@', '\u03c7@@', '\u03bf\u03c5\u03c2', '\u03c7\u03b1\u03c1@@', '\u03ac\u03c2', '\u03c3\u03c4\u03bf', '\u03c3\u03c0\u03af\u03c4\u03b9', '."'],)
--- Logging error ---
Traceback (most recent call last):
  File "/sw/arch/Debian10/EB_production/2019/software/Anaconda3/2018.12/lib/python3.7/logging/__init__.py", line 1036, in emit
    stream.write(msg)
UnicodeEncodeError: 'latin-1' codec can't encode characters in position 66-69: ordinal not in range(256)
Call stack:
  File "/sw/arch/Debian10/EB_production/2019/software/Anaconda3/2018.12/lib/python3.7/runpy.py", line 193, in _run_module_as_main
    "__main__", mod_spec)
  File "/sw/arch/Debian10/EB_production/2019/software/Anaconda3/2018.12/lib/python3.7/runpy.py", line 85, in _run_code
    exec(code, run_globals)
  File "/home/lcur0009/joeynmt/joeynmt/__main__.py", line 48, in <module>
    main()
  File "/home/lcur0009/joeynmt/joeynmt/__main__.py", line 35, in main
    train(cfg_file=args.config_path, skip_test=args.skip_test)
  File "/home/lcur0009/joeynmt/joeynmt/training.py", line 846, in train
    trainer.train_and_validate(train_data=train_data, valid_data=dev_data)
  File "/home/lcur0009/joeynmt/joeynmt/training.py", line 497, in train_and_validate
    valid_duration = self._validate(valid_data, epoch_no)
  File "/home/lcur0009/joeynmt/joeynmt/training.py", line 642, in _validate
    references=valid_references)
  File "/home/lcur0009/joeynmt/joeynmt/training.py", line 737, in _log_examples
    logger.info("\tSource:     %s", sources[p])
Message: '\tSource:     %s'
Arguments: ('"\u038c\u03c4\u03b1\u03bd \u03ae\u03bc\u03bf\u03c5\u03bd 11 , \u0398\u03c5\u03bc\u03ac\u03bc\u03b1\u03b9 \u03c0\u03c9\u03c2 \u03be\u03cd\u03c0\u03bd\u03b7\u03c3\u03b1 \u03ad\u03bd\u03b1 \u03c0\u03c1\u03c9\u03af \u03bc\u03b5 \u03ae\u03c7\u03bf\u03c5\u03c2 \u03c7\u03b1\u03c1\u03ac\u03c2 \u03c3\u03c4\u03bf \u03c3\u03c0\u03af\u03c4\u03b9 ."',)
2021-10-03 13:27:09,674 - INFO - joeynmt.training - 	Source:     "\u038c\u03c4\u03b1\u03bd \u03ae\u03bc\u03bf\u03c5\u03bd 11 , \u0398\u03c5\u03bc\u03ac\u03bc\u03b1\u03b9 \u03c0\u03c9\u03c2 \u03be\u03cd\u03c0\u03bd\u03b7\u03c3\u03b1 \u03ad\u03bd\u03b1 \u03c0\u03c1\u03c9\u03af \u03bc\u03b5 \u03ae\u03c7\u03bf\u03c5\u03c2 \u03c7\u03b1\u03c1\u03ac\u03c2 \u03c3\u03c4\u03bf \u03c3\u03c0\u03af\u03c4\u03b9 ."
2021-10-03 13:27:09,674 - INFO - joeynmt.training - 	Reference:  "When I was 11 , I remember waking up one morning to the sound of joy in my house ."
2021-10-03 13:27:09,674 - INFO - joeynmt.training - 	Hypothesis: "And I was a first , I was a couple of my first , I was a lot of a world ."
2021-10-03 13:27:09,674 - INFO - joeynmt.training - Example #2
--- Logging error ---
Traceback (most recent call last):
  File "/sw/arch/Debian10/EB_production/2019/software/Anaconda3/2018.12/lib/python3.7/logging/__init__.py", line 1036, in emit
    stream.write(msg)
UnicodeEncodeError: 'latin-1' codec can't encode character '\u039f' in position 72: ordinal not in range(256)
Call stack:
  File "/sw/arch/Debian10/EB_production/2019/software/Anaconda3/2018.12/lib/python3.7/runpy.py", line 193, in _run_module_as_main
    "__main__", mod_spec)
  File "/sw/arch/Debian10/EB_production/2019/software/Anaconda3/2018.12/lib/python3.7/runpy.py", line 85, in _run_code
    exec(code, run_globals)
  File "/home/lcur0009/joeynmt/joeynmt/__main__.py", line 48, in <module>
    main()
  File "/home/lcur0009/joeynmt/joeynmt/__main__.py", line 35, in main
    train(cfg_file=args.config_path, skip_test=args.skip_test)
  File "/home/lcur0009/joeynmt/joeynmt/training.py", line 846, in train
    trainer.train_and_validate(train_data=train_data, valid_data=dev_data)
  File "/home/lcur0009/joeynmt/joeynmt/training.py", line 497, in train_and_validate
    valid_duration = self._validate(valid_data, epoch_no)
  File "/home/lcur0009/joeynmt/joeynmt/training.py", line 642, in _validate
    references=valid_references)
  File "/home/lcur0009/joeynmt/joeynmt/training.py", line 731, in _log_examples
    logger.debug("\tRaw source:     %s", sources_raw[p])
Message: '\tRaw source:     %s'
Arguments: (['\u039f', '\u03c0\u03b1\u03c4@@', '\u03ad\u03c1\u03b1\u03c2', '\u03bc\u03bf\u03c5', '\u03ac@@', '\u03ba\u03bf\u03c5@@', '\u03b3@@', '\u03b5', '\u03c4\u03b1', '\u039d@@', '\u03ad\u03b1', '\u03c4\u03bf\u03c5', 'B@@', 'B@@', 'C', '\u03c3\u03c4\u03bf', '\u03bc\u03b9\u03ba\u03c1\u03cc', '\u03b3@@', '\u03ba\u03c1@@', '\u03b9', '\u03c1\u03b1@@', '\u03b4\u03b9@@', '\u03cc@@', '\u03c6\u03c9\u03bd@@', '\u03cc', '\u03c4\u03bf\u03c5', '.'],)
--- Logging error ---
Traceback (most recent call last):
  File "/sw/arch/Debian10/EB_production/2019/software/Anaconda3/2018.12/lib/python3.7/logging/__init__.py", line 1036, in emit
    stream.write(msg)
UnicodeEncodeError: 'latin-1' codec can't encode character '\u039f' in position 65: ordinal not in range(256)
Call stack:
  File "/sw/arch/Debian10/EB_production/2019/software/Anaconda3/2018.12/lib/python3.7/runpy.py", line 193, in _run_module_as_main
    "__main__", mod_spec)
  File "/sw/arch/Debian10/EB_production/2019/software/Anaconda3/2018.12/lib/python3.7/runpy.py", line 85, in _run_code
    exec(code, run_globals)
  File "/home/lcur0009/joeynmt/joeynmt/__main__.py", line 48, in <module>
    main()
  File "/home/lcur0009/joeynmt/joeynmt/__main__.py", line 35, in main
    train(cfg_file=args.config_path, skip_test=args.skip_test)
  File "/home/lcur0009/joeynmt/joeynmt/training.py", line 846, in train
    trainer.train_and_validate(train_data=train_data, valid_data=dev_data)
  File "/home/lcur0009/joeynmt/joeynmt/training.py", line 497, in train_and_validate
    valid_duration = self._validate(valid_data, epoch_no)
  File "/home/lcur0009/joeynmt/joeynmt/training.py", line 642, in _validate
    references=valid_references)
  File "/home/lcur0009/joeynmt/joeynmt/training.py", line 737, in _log_examples
    logger.info("\tSource:     %s", sources[p])
Message: '\tSource:     %s'
Arguments: ('\u039f \u03c0\u03b1\u03c4\u03ad\u03c1\u03b1\u03c2 \u03bc\u03bf\u03c5 \u03ac\u03ba\u03bf\u03c5\u03b3\u03b5 \u03c4\u03b1 \u039d\u03ad\u03b1 \u03c4\u03bf\u03c5 BBC \u03c3\u03c4\u03bf \u03bc\u03b9\u03ba\u03c1\u03cc \u03b3\u03ba\u03c1\u03b9 \u03c1\u03b1\u03b4\u03b9\u03cc\u03c6\u03c9\u03bd\u03cc \u03c4\u03bf\u03c5 .',)
2021-10-03 13:27:09,675 - INFO - joeynmt.training - 	Source:     \u039f \u03c0\u03b1\u03c4\u03ad\u03c1\u03b1\u03c2 \u03bc\u03bf\u03c5 \u03ac\u03ba\u03bf\u03c5\u03b3\u03b5 \u03c4\u03b1 \u039d\u03ad\u03b1 \u03c4\u03bf\u03c5 BBC \u03c3\u03c4\u03bf \u03bc\u03b9\u03ba\u03c1\u03cc \u03b3\u03ba\u03c1\u03b9 \u03c1\u03b1\u03b4\u03b9\u03cc\u03c6\u03c9\u03bd\u03cc \u03c4\u03bf\u03c5 .
2021-10-03 13:27:09,675 - INFO - joeynmt.training - 	Reference:  "My father was listening to BBC News on his small , gray radio ."
2021-10-03 13:27:09,675 - INFO - joeynmt.training - 	Hypothesis: It was a first of the world . &quot; &quot; The first was a world .
2021-10-03 13:27:09,675 - INFO - joeynmt.training - Validation result (greedy) at epoch  13, step      800: bleu:   4.14, loss: 76734.2422, ppl: 139.7368, duration: 4.7886s
2021-10-03 13:27:14,964 - INFO - joeynmt.training - Epoch  13: total training loss 5920.11
2021-10-03 13:27:14,965 - INFO - joeynmt.training - EPOCH 14
2021-10-03 13:27:27,838 - INFO - joeynmt.training - Epoch  14: total training loss 5798.07
2021-10-03 13:27:27,838 - INFO - joeynmt.training - EPOCH 15
2021-10-03 13:27:35,107 - WARNING - sacrebleu - That's 100 lines that end in a tokenized period ('.')
2021-10-03 13:27:35,108 - WARNING - sacrebleu - It looks like you forgot to detokenize your test data, which may hurt your score.
2021-10-03 13:27:35,108 - WARNING - sacrebleu - If you insist your data is detokenized, or don't care, you can suppress this message with the `force` parameter.
2021-10-03 13:27:35,112 - INFO - joeynmt.training - Hooray! New best validation result [eval_metric]!
2021-10-03 13:27:36,105 - INFO - joeynmt.helpers - delete models/LSTM_el/800.ckpt
2021-10-03 13:27:36,181 - INFO - joeynmt.helpers - delete /home/lcur0009/joeynmt/models/LSTM_el/800.ckpt
2021-10-03 13:27:36,182 - WARNING - joeynmt.helpers - Wanted to delete old checkpoint /home/lcur0009/joeynmt/models/LSTM_el/800.ckpt but file does not exist. ([Errno 2] No such file or directory: '/home/lcur0009/joeynmt/models/LSTM_el/800.ckpt')
2021-10-03 13:27:36,184 - INFO - joeynmt.training - Example #0
2021-10-03 13:27:36,184 - INFO - joeynmt.training - 	Source:     el
2021-10-03 13:27:36,184 - INFO - joeynmt.training - 	Reference:  en
2021-10-03 13:27:36,184 - INFO - joeynmt.training - 	Hypothesis: Thank you .
2021-10-03 13:27:36,184 - INFO - joeynmt.training - Example #1
--- Logging error ---
Traceback (most recent call last):
  File "/sw/arch/Debian10/EB_production/2019/software/Anaconda3/2018.12/lib/python3.7/logging/__init__.py", line 1036, in emit
    stream.write(msg)
UnicodeEncodeError: 'latin-1' codec can't encode characters in position 73-76: ordinal not in range(256)
Call stack:
  File "/sw/arch/Debian10/EB_production/2019/software/Anaconda3/2018.12/lib/python3.7/runpy.py", line 193, in _run_module_as_main
    "__main__", mod_spec)
  File "/sw/arch/Debian10/EB_production/2019/software/Anaconda3/2018.12/lib/python3.7/runpy.py", line 85, in _run_code
    exec(code, run_globals)
  File "/home/lcur0009/joeynmt/joeynmt/__main__.py", line 48, in <module>
    main()
  File "/home/lcur0009/joeynmt/joeynmt/__main__.py", line 35, in main
    train(cfg_file=args.config_path, skip_test=args.skip_test)
  File "/home/lcur0009/joeynmt/joeynmt/training.py", line 846, in train
    trainer.train_and_validate(train_data=train_data, valid_data=dev_data)
  File "/home/lcur0009/joeynmt/joeynmt/training.py", line 497, in train_and_validate
    valid_duration = self._validate(valid_data, epoch_no)
  File "/home/lcur0009/joeynmt/joeynmt/training.py", line 642, in _validate
    references=valid_references)
  File "/home/lcur0009/joeynmt/joeynmt/training.py", line 731, in _log_examples
    logger.debug("\tRaw source:     %s", sources_raw[p])
Message: '\tRaw source:     %s'
Arguments: (['"\u038c\u03c4\u03b1\u03bd', '\u03ae\u03bc\u03bf\u03c5\u03bd', '1@@', '1', ',', '\u0398@@', '\u03c5@@', '\u03bc\u03ac@@', '\u03bc\u03b1\u03b9', '\u03c0\u03c9\u03c2', '\u03be@@', '\u03cd\u03c0@@', '\u03bd\u03b7@@', '\u03c3\u03b1', '\u03ad\u03bd\u03b1', '\u03c0\u03c1\u03c9@@', '\u03af', '\u03bc\u03b5', '\u03ae@@', '\u03c7@@', '\u03bf\u03c5\u03c2', '\u03c7\u03b1\u03c1@@', '\u03ac\u03c2', '\u03c3\u03c4\u03bf', '\u03c3\u03c0\u03af\u03c4\u03b9', '."'],)
--- Logging error ---
Traceback (most recent call last):
  File "/sw/arch/Debian10/EB_production/2019/software/Anaconda3/2018.12/lib/python3.7/logging/__init__.py", line 1036, in emit
    stream.write(msg)
UnicodeEncodeError: 'latin-1' codec can't encode characters in position 66-69: ordinal not in range(256)
Call stack:
  File "/sw/arch/Debian10/EB_production/2019/software/Anaconda3/2018.12/lib/python3.7/runpy.py", line 193, in _run_module_as_main
    "__main__", mod_spec)
  File "/sw/arch/Debian10/EB_production/2019/software/Anaconda3/2018.12/lib/python3.7/runpy.py", line 85, in _run_code
    exec(code, run_globals)
  File "/home/lcur0009/joeynmt/joeynmt/__main__.py", line 48, in <module>
    main()
  File "/home/lcur0009/joeynmt/joeynmt/__main__.py", line 35, in main
    train(cfg_file=args.config_path, skip_test=args.skip_test)
  File "/home/lcur0009/joeynmt/joeynmt/training.py", line 846, in train
    trainer.train_and_validate(train_data=train_data, valid_data=dev_data)
  File "/home/lcur0009/joeynmt/joeynmt/training.py", line 497, in train_and_validate
    valid_duration = self._validate(valid_data, epoch_no)
  File "/home/lcur0009/joeynmt/joeynmt/training.py", line 642, in _validate
    references=valid_references)
  File "/home/lcur0009/joeynmt/joeynmt/training.py", line 737, in _log_examples
    logger.info("\tSource:     %s", sources[p])
Message: '\tSource:     %s'
Arguments: ('"\u038c\u03c4\u03b1\u03bd \u03ae\u03bc\u03bf\u03c5\u03bd 11 , \u0398\u03c5\u03bc\u03ac\u03bc\u03b1\u03b9 \u03c0\u03c9\u03c2 \u03be\u03cd\u03c0\u03bd\u03b7\u03c3\u03b1 \u03ad\u03bd\u03b1 \u03c0\u03c1\u03c9\u03af \u03bc\u03b5 \u03ae\u03c7\u03bf\u03c5\u03c2 \u03c7\u03b1\u03c1\u03ac\u03c2 \u03c3\u03c4\u03bf \u03c3\u03c0\u03af\u03c4\u03b9 ."',)
2021-10-03 13:27:36,186 - INFO - joeynmt.training - 	Source:     "\u038c\u03c4\u03b1\u03bd \u03ae\u03bc\u03bf\u03c5\u03bd 11 , \u0398\u03c5\u03bc\u03ac\u03bc\u03b1\u03b9 \u03c0\u03c9\u03c2 \u03be\u03cd\u03c0\u03bd\u03b7\u03c3\u03b1 \u03ad\u03bd\u03b1 \u03c0\u03c1\u03c9\u03af \u03bc\u03b5 \u03ae\u03c7\u03bf\u03c5\u03c2 \u03c7\u03b1\u03c1\u03ac\u03c2 \u03c3\u03c4\u03bf \u03c3\u03c0\u03af\u03c4\u03b9 ."
2021-10-03 13:27:36,187 - INFO - joeynmt.training - 	Reference:  "When I was 11 , I remember waking up one morning to the sound of joy in my house ."
2021-10-03 13:27:36,187 - INFO - joeynmt.training - 	Hypothesis: "And I was a seorst , I was a little bit of the world , I was a lot of the world ."
2021-10-03 13:27:36,187 - INFO - joeynmt.training - Example #2
--- Logging error ---
Traceback (most recent call last):
  File "/sw/arch/Debian10/EB_production/2019/software/Anaconda3/2018.12/lib/python3.7/logging/__init__.py", line 1036, in emit
    stream.write(msg)
UnicodeEncodeError: 'latin-1' codec can't encode character '\u039f' in position 72: ordinal not in range(256)
Call stack:
  File "/sw/arch/Debian10/EB_production/2019/software/Anaconda3/2018.12/lib/python3.7/runpy.py", line 193, in _run_module_as_main
    "__main__", mod_spec)
  File "/sw/arch/Debian10/EB_production/2019/software/Anaconda3/2018.12/lib/python3.7/runpy.py", line 85, in _run_code
    exec(code, run_globals)
  File "/home/lcur0009/joeynmt/joeynmt/__main__.py", line 48, in <module>
    main()
  File "/home/lcur0009/joeynmt/joeynmt/__main__.py", line 35, in main
    train(cfg_file=args.config_path, skip_test=args.skip_test)
  File "/home/lcur0009/joeynmt/joeynmt/training.py", line 846, in train
    trainer.train_and_validate(train_data=train_data, valid_data=dev_data)
  File "/home/lcur0009/joeynmt/joeynmt/training.py", line 497, in train_and_validate
    valid_duration = self._validate(valid_data, epoch_no)
  File "/home/lcur0009/joeynmt/joeynmt/training.py", line 642, in _validate
    references=valid_references)
  File "/home/lcur0009/joeynmt/joeynmt/training.py", line 731, in _log_examples
    logger.debug("\tRaw source:     %s", sources_raw[p])
Message: '\tRaw source:     %s'
Arguments: (['\u039f', '\u03c0\u03b1\u03c4@@', '\u03ad\u03c1\u03b1\u03c2', '\u03bc\u03bf\u03c5', '\u03ac@@', '\u03ba\u03bf\u03c5@@', '\u03b3@@', '\u03b5', '\u03c4\u03b1', '\u039d@@', '\u03ad\u03b1', '\u03c4\u03bf\u03c5', 'B@@', 'B@@', 'C', '\u03c3\u03c4\u03bf', '\u03bc\u03b9\u03ba\u03c1\u03cc', '\u03b3@@', '\u03ba\u03c1@@', '\u03b9', '\u03c1\u03b1@@', '\u03b4\u03b9@@', '\u03cc@@', '\u03c6\u03c9\u03bd@@', '\u03cc', '\u03c4\u03bf\u03c5', '.'],)
--- Logging error ---
Traceback (most recent call last):
  File "/sw/arch/Debian10/EB_production/2019/software/Anaconda3/2018.12/lib/python3.7/logging/__init__.py", line 1036, in emit
    stream.write(msg)
UnicodeEncodeError: 'latin-1' codec can't encode character '\u039f' in position 65: ordinal not in range(256)
Call stack:
  File "/sw/arch/Debian10/EB_production/2019/software/Anaconda3/2018.12/lib/python3.7/runpy.py", line 193, in _run_module_as_main
    "__main__", mod_spec)
  File "/sw/arch/Debian10/EB_production/2019/software/Anaconda3/2018.12/lib/python3.7/runpy.py", line 85, in _run_code
    exec(code, run_globals)
  File "/home/lcur0009/joeynmt/joeynmt/__main__.py", line 48, in <module>
    main()
  File "/home/lcur0009/joeynmt/joeynmt/__main__.py", line 35, in main
    train(cfg_file=args.config_path, skip_test=args.skip_test)
  File "/home/lcur0009/joeynmt/joeynmt/training.py", line 846, in train
    trainer.train_and_validate(train_data=train_data, valid_data=dev_data)
  File "/home/lcur0009/joeynmt/joeynmt/training.py", line 497, in train_and_validate
    valid_duration = self._validate(valid_data, epoch_no)
  File "/home/lcur0009/joeynmt/joeynmt/training.py", line 642, in _validate
    references=valid_references)
  File "/home/lcur0009/joeynmt/joeynmt/training.py", line 737, in _log_examples
    logger.info("\tSource:     %s", sources[p])
Message: '\tSource:     %s'
Arguments: ('\u039f \u03c0\u03b1\u03c4\u03ad\u03c1\u03b1\u03c2 \u03bc\u03bf\u03c5 \u03ac\u03ba\u03bf\u03c5\u03b3\u03b5 \u03c4\u03b1 \u039d\u03ad\u03b1 \u03c4\u03bf\u03c5 BBC \u03c3\u03c4\u03bf \u03bc\u03b9\u03ba\u03c1\u03cc \u03b3\u03ba\u03c1\u03b9 \u03c1\u03b1\u03b4\u03b9\u03cc\u03c6\u03c9\u03bd\u03cc \u03c4\u03bf\u03c5 .',)
2021-10-03 13:27:36,187 - INFO - joeynmt.training - 	Source:     \u039f \u03c0\u03b1\u03c4\u03ad\u03c1\u03b1\u03c2 \u03bc\u03bf\u03c5 \u03ac\u03ba\u03bf\u03c5\u03b3\u03b5 \u03c4\u03b1 \u039d\u03ad\u03b1 \u03c4\u03bf\u03c5 BBC \u03c3\u03c4\u03bf \u03bc\u03b9\u03ba\u03c1\u03cc \u03b3\u03ba\u03c1\u03b9 \u03c1\u03b1\u03b4\u03b9\u03cc\u03c6\u03c9\u03bd\u03cc \u03c4\u03bf\u03c5 .
2021-10-03 13:27:36,188 - INFO - joeynmt.training - 	Reference:  "My father was listening to BBC News on his small , gray radio ."
2021-10-03 13:27:36,188 - INFO - joeynmt.training - 	Hypothesis: I was the first . &quot; &quot; Wen was a first . &quot; &quot; You &apos;re got to be .
2021-10-03 13:27:36,188 - INFO - joeynmt.training - Validation result (greedy) at epoch  15, step      900: bleu:   4.29, loss: 76050.1719, ppl: 133.7168, duration: 4.6176s
2021-10-03 13:27:46,813 - INFO - joeynmt.training - Epoch  15: total training loss 5685.58
2021-10-03 13:27:46,814 - INFO - joeynmt.training - EPOCH 16
2021-10-03 13:27:58,038 - INFO - joeynmt.training - Epoch  16, Step:     1000, Batch Loss:    92.964279, Tokens per Sec:     8335, Lr: 0.000300
2021-10-03 13:28:01,710 - WARNING - sacrebleu - That's 100 lines that end in a tokenized period ('.')
2021-10-03 13:28:01,710 - WARNING - sacrebleu - It looks like you forgot to detokenize your test data, which may hurt your score.
2021-10-03 13:28:01,710 - WARNING - sacrebleu - If you insist your data is detokenized, or don't care, you can suppress this message with the `force` parameter.
2021-10-03 13:28:01,716 - INFO - joeynmt.training - Hooray! New best validation result [eval_metric]!
2021-10-03 13:28:02,664 - INFO - joeynmt.helpers - delete models/LSTM_el/900.ckpt
2021-10-03 13:28:02,735 - INFO - joeynmt.helpers - delete /home/lcur0009/joeynmt/models/LSTM_el/900.ckpt
2021-10-03 13:28:02,736 - WARNING - joeynmt.helpers - Wanted to delete old checkpoint /home/lcur0009/joeynmt/models/LSTM_el/900.ckpt but file does not exist. ([Errno 2] No such file or directory: '/home/lcur0009/joeynmt/models/LSTM_el/900.ckpt')
2021-10-03 13:28:02,738 - INFO - joeynmt.training - Example #0
2021-10-03 13:28:02,738 - INFO - joeynmt.training - 	Source:     el
2021-10-03 13:28:02,738 - INFO - joeynmt.training - 	Reference:  en
2021-10-03 13:28:02,738 - INFO - joeynmt.training - 	Hypothesis: Thank you .
2021-10-03 13:28:02,738 - INFO - joeynmt.training - Example #1
--- Logging error ---
Traceback (most recent call last):
  File "/sw/arch/Debian10/EB_production/2019/software/Anaconda3/2018.12/lib/python3.7/logging/__init__.py", line 1036, in emit
    stream.write(msg)
UnicodeEncodeError: 'latin-1' codec can't encode characters in position 73-76: ordinal not in range(256)
Call stack:
  File "/sw/arch/Debian10/EB_production/2019/software/Anaconda3/2018.12/lib/python3.7/runpy.py", line 193, in _run_module_as_main
    "__main__", mod_spec)
  File "/sw/arch/Debian10/EB_production/2019/software/Anaconda3/2018.12/lib/python3.7/runpy.py", line 85, in _run_code
    exec(code, run_globals)
  File "/home/lcur0009/joeynmt/joeynmt/__main__.py", line 48, in <module>
    main()
  File "/home/lcur0009/joeynmt/joeynmt/__main__.py", line 35, in main
    train(cfg_file=args.config_path, skip_test=args.skip_test)
  File "/home/lcur0009/joeynmt/joeynmt/training.py", line 846, in train
    trainer.train_and_validate(train_data=train_data, valid_data=dev_data)
  File "/home/lcur0009/joeynmt/joeynmt/training.py", line 497, in train_and_validate
    valid_duration = self._validate(valid_data, epoch_no)
  File "/home/lcur0009/joeynmt/joeynmt/training.py", line 642, in _validate
    references=valid_references)
  File "/home/lcur0009/joeynmt/joeynmt/training.py", line 731, in _log_examples
    logger.debug("\tRaw source:     %s", sources_raw[p])
Message: '\tRaw source:     %s'
Arguments: (['"\u038c\u03c4\u03b1\u03bd', '\u03ae\u03bc\u03bf\u03c5\u03bd', '1@@', '1', ',', '\u0398@@', '\u03c5@@', '\u03bc\u03ac@@', '\u03bc\u03b1\u03b9', '\u03c0\u03c9\u03c2', '\u03be@@', '\u03cd\u03c0@@', '\u03bd\u03b7@@', '\u03c3\u03b1', '\u03ad\u03bd\u03b1', '\u03c0\u03c1\u03c9@@', '\u03af', '\u03bc\u03b5', '\u03ae@@', '\u03c7@@', '\u03bf\u03c5\u03c2', '\u03c7\u03b1\u03c1@@', '\u03ac\u03c2', '\u03c3\u03c4\u03bf', '\u03c3\u03c0\u03af\u03c4\u03b9', '."'],)
--- Logging error ---
Traceback (most recent call last):
  File "/sw/arch/Debian10/EB_production/2019/software/Anaconda3/2018.12/lib/python3.7/logging/__init__.py", line 1036, in emit
    stream.write(msg)
UnicodeEncodeError: 'latin-1' codec can't encode characters in position 66-69: ordinal not in range(256)
Call stack:
  File "/sw/arch/Debian10/EB_production/2019/software/Anaconda3/2018.12/lib/python3.7/runpy.py", line 193, in _run_module_as_main
    "__main__", mod_spec)
  File "/sw/arch/Debian10/EB_production/2019/software/Anaconda3/2018.12/lib/python3.7/runpy.py", line 85, in _run_code
    exec(code, run_globals)
  File "/home/lcur0009/joeynmt/joeynmt/__main__.py", line 48, in <module>
    main()
  File "/home/lcur0009/joeynmt/joeynmt/__main__.py", line 35, in main
    train(cfg_file=args.config_path, skip_test=args.skip_test)
  File "/home/lcur0009/joeynmt/joeynmt/training.py", line 846, in train
    trainer.train_and_validate(train_data=train_data, valid_data=dev_data)
  File "/home/lcur0009/joeynmt/joeynmt/training.py", line 497, in train_and_validate
    valid_duration = self._validate(valid_data, epoch_no)
  File "/home/lcur0009/joeynmt/joeynmt/training.py", line 642, in _validate
    references=valid_references)
  File "/home/lcur0009/joeynmt/joeynmt/training.py", line 737, in _log_examples
    logger.info("\tSource:     %s", sources[p])
Message: '\tSource:     %s'
Arguments: ('"\u038c\u03c4\u03b1\u03bd \u03ae\u03bc\u03bf\u03c5\u03bd 11 , \u0398\u03c5\u03bc\u03ac\u03bc\u03b1\u03b9 \u03c0\u03c9\u03c2 \u03be\u03cd\u03c0\u03bd\u03b7\u03c3\u03b1 \u03ad\u03bd\u03b1 \u03c0\u03c1\u03c9\u03af \u03bc\u03b5 \u03ae\u03c7\u03bf\u03c5\u03c2 \u03c7\u03b1\u03c1\u03ac\u03c2 \u03c3\u03c4\u03bf \u03c3\u03c0\u03af\u03c4\u03b9 ."',)
2021-10-03 13:28:02,740 - INFO - joeynmt.training - 	Source:     "\u038c\u03c4\u03b1\u03bd \u03ae\u03bc\u03bf\u03c5\u03bd 11 , \u0398\u03c5\u03bc\u03ac\u03bc\u03b1\u03b9 \u03c0\u03c9\u03c2 \u03be\u03cd\u03c0\u03bd\u03b7\u03c3\u03b1 \u03ad\u03bd\u03b1 \u03c0\u03c1\u03c9\u03af \u03bc\u03b5 \u03ae\u03c7\u03bf\u03c5\u03c2 \u03c7\u03b1\u03c1\u03ac\u03c2 \u03c3\u03c4\u03bf \u03c3\u03c0\u03af\u03c4\u03b9 ."
2021-10-03 13:28:02,740 - INFO - joeynmt.training - 	Reference:  "When I was 11 , I remember waking up one morning to the sound of joy in my house ."
2021-10-03 13:28:02,740 - INFO - joeynmt.training - 	Hypothesis: "And I was a little mother , I was a little bit of my mind , I was a little bit of my mind ."
2021-10-03 13:28:02,740 - INFO - joeynmt.training - Example #2
--- Logging error ---
Traceback (most recent call last):
  File "/sw/arch/Debian10/EB_production/2019/software/Anaconda3/2018.12/lib/python3.7/logging/__init__.py", line 1036, in emit
    stream.write(msg)
UnicodeEncodeError: 'latin-1' codec can't encode character '\u039f' in position 72: ordinal not in range(256)
Call stack:
  File "/sw/arch/Debian10/EB_production/2019/software/Anaconda3/2018.12/lib/python3.7/runpy.py", line 193, in _run_module_as_main
    "__main__", mod_spec)
  File "/sw/arch/Debian10/EB_production/2019/software/Anaconda3/2018.12/lib/python3.7/runpy.py", line 85, in _run_code
    exec(code, run_globals)
  File "/home/lcur0009/joeynmt/joeynmt/__main__.py", line 48, in <module>
    main()
  File "/home/lcur0009/joeynmt/joeynmt/__main__.py", line 35, in main
    train(cfg_file=args.config_path, skip_test=args.skip_test)
  File "/home/lcur0009/joeynmt/joeynmt/training.py", line 846, in train
    trainer.train_and_validate(train_data=train_data, valid_data=dev_data)
  File "/home/lcur0009/joeynmt/joeynmt/training.py", line 497, in train_and_validate
    valid_duration = self._validate(valid_data, epoch_no)
  File "/home/lcur0009/joeynmt/joeynmt/training.py", line 642, in _validate
    references=valid_references)
  File "/home/lcur0009/joeynmt/joeynmt/training.py", line 731, in _log_examples
    logger.debug("\tRaw source:     %s", sources_raw[p])
Message: '\tRaw source:     %s'
Arguments: (['\u039f', '\u03c0\u03b1\u03c4@@', '\u03ad\u03c1\u03b1\u03c2', '\u03bc\u03bf\u03c5', '\u03ac@@', '\u03ba\u03bf\u03c5@@', '\u03b3@@', '\u03b5', '\u03c4\u03b1', '\u039d@@', '\u03ad\u03b1', '\u03c4\u03bf\u03c5', 'B@@', 'B@@', 'C', '\u03c3\u03c4\u03bf', '\u03bc\u03b9\u03ba\u03c1\u03cc', '\u03b3@@', '\u03ba\u03c1@@', '\u03b9', '\u03c1\u03b1@@', '\u03b4\u03b9@@', '\u03cc@@', '\u03c6\u03c9\u03bd@@', '\u03cc', '\u03c4\u03bf\u03c5', '.'],)
--- Logging error ---
Traceback (most recent call last):
  File "/sw/arch/Debian10/EB_production/2019/software/Anaconda3/2018.12/lib/python3.7/logging/__init__.py", line 1036, in emit
    stream.write(msg)
UnicodeEncodeError: 'latin-1' codec can't encode character '\u039f' in position 65: ordinal not in range(256)
Call stack:
  File "/sw/arch/Debian10/EB_production/2019/software/Anaconda3/2018.12/lib/python3.7/runpy.py", line 193, in _run_module_as_main
    "__main__", mod_spec)
  File "/sw/arch/Debian10/EB_production/2019/software/Anaconda3/2018.12/lib/python3.7/runpy.py", line 85, in _run_code
    exec(code, run_globals)
  File "/home/lcur0009/joeynmt/joeynmt/__main__.py", line 48, in <module>
    main()
  File "/home/lcur0009/joeynmt/joeynmt/__main__.py", line 35, in main
    train(cfg_file=args.config_path, skip_test=args.skip_test)
  File "/home/lcur0009/joeynmt/joeynmt/training.py", line 846, in train
    trainer.train_and_validate(train_data=train_data, valid_data=dev_data)
  File "/home/lcur0009/joeynmt/joeynmt/training.py", line 497, in train_and_validate
    valid_duration = self._validate(valid_data, epoch_no)
  File "/home/lcur0009/joeynmt/joeynmt/training.py", line 642, in _validate
    references=valid_references)
  File "/home/lcur0009/joeynmt/joeynmt/training.py", line 737, in _log_examples
    logger.info("\tSource:     %s", sources[p])
Message: '\tSource:     %s'
Arguments: ('\u039f \u03c0\u03b1\u03c4\u03ad\u03c1\u03b1\u03c2 \u03bc\u03bf\u03c5 \u03ac\u03ba\u03bf\u03c5\u03b3\u03b5 \u03c4\u03b1 \u039d\u03ad\u03b1 \u03c4\u03bf\u03c5 BBC \u03c3\u03c4\u03bf \u03bc\u03b9\u03ba\u03c1\u03cc \u03b3\u03ba\u03c1\u03b9 \u03c1\u03b1\u03b4\u03b9\u03cc\u03c6\u03c9\u03bd\u03cc \u03c4\u03bf\u03c5 .',)
2021-10-03 13:28:02,741 - INFO - joeynmt.training - 	Source:     \u039f \u03c0\u03b1\u03c4\u03ad\u03c1\u03b1\u03c2 \u03bc\u03bf\u03c5 \u03ac\u03ba\u03bf\u03c5\u03b3\u03b5 \u03c4\u03b1 \u039d\u03ad\u03b1 \u03c4\u03bf\u03c5 BBC \u03c3\u03c4\u03bf \u03bc\u03b9\u03ba\u03c1\u03cc \u03b3\u03ba\u03c1\u03b9 \u03c1\u03b1\u03b4\u03b9\u03cc\u03c6\u03c9\u03bd\u03cc \u03c4\u03bf\u03c5 .
2021-10-03 13:28:02,741 - INFO - joeynmt.training - 	Reference:  "My father was listening to BBC News on his small , gray radio ."
2021-10-03 13:28:02,741 - INFO - joeynmt.training - 	Hypothesis: I was a little bit of the first . &quot; &quot; Woen .
2021-10-03 13:28:02,741 - INFO - joeynmt.training - Validation result (greedy) at epoch  16, step     1000: bleu:   5.22, loss: 75459.7422, ppl: 128.7297, duration: 4.7023s
2021-10-03 13:28:05,915 - INFO - joeynmt.training - Epoch  16: total training loss 5565.19
2021-10-03 13:28:05,916 - INFO - joeynmt.training - EPOCH 17
2021-10-03 13:28:18,847 - INFO - joeynmt.training - Epoch  17: total training loss 5464.60
2021-10-03 13:28:18,848 - INFO - joeynmt.training - EPOCH 18
2021-10-03 13:28:28,214 - WARNING - sacrebleu - That's 100 lines that end in a tokenized period ('.')
2021-10-03 13:28:28,214 - WARNING - sacrebleu - It looks like you forgot to detokenize your test data, which may hurt your score.
2021-10-03 13:28:28,214 - WARNING - sacrebleu - If you insist your data is detokenized, or don't care, you can suppress this message with the `force` parameter.
2021-10-03 13:28:28,222 - INFO - joeynmt.training - Example #0
2021-10-03 13:28:28,223 - INFO - joeynmt.training - 	Source:     el
2021-10-03 13:28:28,223 - INFO - joeynmt.training - 	Reference:  en
2021-10-03 13:28:28,223 - INFO - joeynmt.training - 	Hypothesis: Thank you .
2021-10-03 13:28:28,223 - INFO - joeynmt.training - Example #1
--- Logging error ---
Traceback (most recent call last):
  File "/sw/arch/Debian10/EB_production/2019/software/Anaconda3/2018.12/lib/python3.7/logging/__init__.py", line 1036, in emit
    stream.write(msg)
UnicodeEncodeError: 'latin-1' codec can't encode characters in position 73-76: ordinal not in range(256)
Call stack:
  File "/sw/arch/Debian10/EB_production/2019/software/Anaconda3/2018.12/lib/python3.7/runpy.py", line 193, in _run_module_as_main
    "__main__", mod_spec)
  File "/sw/arch/Debian10/EB_production/2019/software/Anaconda3/2018.12/lib/python3.7/runpy.py", line 85, in _run_code
    exec(code, run_globals)
  File "/home/lcur0009/joeynmt/joeynmt/__main__.py", line 48, in <module>
    main()
  File "/home/lcur0009/joeynmt/joeynmt/__main__.py", line 35, in main
    train(cfg_file=args.config_path, skip_test=args.skip_test)
  File "/home/lcur0009/joeynmt/joeynmt/training.py", line 846, in train
    trainer.train_and_validate(train_data=train_data, valid_data=dev_data)
  File "/home/lcur0009/joeynmt/joeynmt/training.py", line 497, in train_and_validate
    valid_duration = self._validate(valid_data, epoch_no)
  File "/home/lcur0009/joeynmt/joeynmt/training.py", line 642, in _validate
    references=valid_references)
  File "/home/lcur0009/joeynmt/joeynmt/training.py", line 731, in _log_examples
    logger.debug("\tRaw source:     %s", sources_raw[p])
Message: '\tRaw source:     %s'
Arguments: (['"\u038c\u03c4\u03b1\u03bd', '\u03ae\u03bc\u03bf\u03c5\u03bd', '1@@', '1', ',', '\u0398@@', '\u03c5@@', '\u03bc\u03ac@@', '\u03bc\u03b1\u03b9', '\u03c0\u03c9\u03c2', '\u03be@@', '\u03cd\u03c0@@', '\u03bd\u03b7@@', '\u03c3\u03b1', '\u03ad\u03bd\u03b1', '\u03c0\u03c1\u03c9@@', '\u03af', '\u03bc\u03b5', '\u03ae@@', '\u03c7@@', '\u03bf\u03c5\u03c2', '\u03c7\u03b1\u03c1@@', '\u03ac\u03c2', '\u03c3\u03c4\u03bf', '\u03c3\u03c0\u03af\u03c4\u03b9', '."'],)
--- Logging error ---
Traceback (most recent call last):
  File "/sw/arch/Debian10/EB_production/2019/software/Anaconda3/2018.12/lib/python3.7/logging/__init__.py", line 1036, in emit
    stream.write(msg)
UnicodeEncodeError: 'latin-1' codec can't encode characters in position 66-69: ordinal not in range(256)
Call stack:
  File "/sw/arch/Debian10/EB_production/2019/software/Anaconda3/2018.12/lib/python3.7/runpy.py", line 193, in _run_module_as_main
    "__main__", mod_spec)
  File "/sw/arch/Debian10/EB_production/2019/software/Anaconda3/2018.12/lib/python3.7/runpy.py", line 85, in _run_code
    exec(code, run_globals)
  File "/home/lcur0009/joeynmt/joeynmt/__main__.py", line 48, in <module>
    main()
  File "/home/lcur0009/joeynmt/joeynmt/__main__.py", line 35, in main
    train(cfg_file=args.config_path, skip_test=args.skip_test)
  File "/home/lcur0009/joeynmt/joeynmt/training.py", line 846, in train
    trainer.train_and_validate(train_data=train_data, valid_data=dev_data)
  File "/home/lcur0009/joeynmt/joeynmt/training.py", line 497, in train_and_validate
    valid_duration = self._validate(valid_data, epoch_no)
  File "/home/lcur0009/joeynmt/joeynmt/training.py", line 642, in _validate
    references=valid_references)
  File "/home/lcur0009/joeynmt/joeynmt/training.py", line 737, in _log_examples
    logger.info("\tSource:     %s", sources[p])
Message: '\tSource:     %s'
Arguments: ('"\u038c\u03c4\u03b1\u03bd \u03ae\u03bc\u03bf\u03c5\u03bd 11 , \u0398\u03c5\u03bc\u03ac\u03bc\u03b1\u03b9 \u03c0\u03c9\u03c2 \u03be\u03cd\u03c0\u03bd\u03b7\u03c3\u03b1 \u03ad\u03bd\u03b1 \u03c0\u03c1\u03c9\u03af \u03bc\u03b5 \u03ae\u03c7\u03bf\u03c5\u03c2 \u03c7\u03b1\u03c1\u03ac\u03c2 \u03c3\u03c4\u03bf \u03c3\u03c0\u03af\u03c4\u03b9 ."',)
2021-10-03 13:28:28,226 - INFO - joeynmt.training - 	Source:     "\u038c\u03c4\u03b1\u03bd \u03ae\u03bc\u03bf\u03c5\u03bd 11 , \u0398\u03c5\u03bc\u03ac\u03bc\u03b1\u03b9 \u03c0\u03c9\u03c2 \u03be\u03cd\u03c0\u03bd\u03b7\u03c3\u03b1 \u03ad\u03bd\u03b1 \u03c0\u03c1\u03c9\u03af \u03bc\u03b5 \u03ae\u03c7\u03bf\u03c5\u03c2 \u03c7\u03b1\u03c1\u03ac\u03c2 \u03c3\u03c4\u03bf \u03c3\u03c0\u03af\u03c4\u03b9 ."
2021-10-03 13:28:28,227 - INFO - joeynmt.training - 	Reference:  "When I was 11 , I remember waking up one morning to the sound of joy in my house ."
2021-10-03 13:28:28,227 - INFO - joeynmt.training - 	Hypothesis: "And I went to my first , I was a little bit of my mother , I was a lot of a village ."
2021-10-03 13:28:28,227 - INFO - joeynmt.training - Example #2
--- Logging error ---
Traceback (most recent call last):
  File "/sw/arch/Debian10/EB_production/2019/software/Anaconda3/2018.12/lib/python3.7/logging/__init__.py", line 1036, in emit
    stream.write(msg)
UnicodeEncodeError: 'latin-1' codec can't encode character '\u039f' in position 72: ordinal not in range(256)
Call stack:
  File "/sw/arch/Debian10/EB_production/2019/software/Anaconda3/2018.12/lib/python3.7/runpy.py", line 193, in _run_module_as_main
    "__main__", mod_spec)
  File "/sw/arch/Debian10/EB_production/2019/software/Anaconda3/2018.12/lib/python3.7/runpy.py", line 85, in _run_code
    exec(code, run_globals)
  File "/home/lcur0009/joeynmt/joeynmt/__main__.py", line 48, in <module>
    main()
  File "/home/lcur0009/joeynmt/joeynmt/__main__.py", line 35, in main
    train(cfg_file=args.config_path, skip_test=args.skip_test)
  File "/home/lcur0009/joeynmt/joeynmt/training.py", line 846, in train
    trainer.train_and_validate(train_data=train_data, valid_data=dev_data)
  File "/home/lcur0009/joeynmt/joeynmt/training.py", line 497, in train_and_validate
    valid_duration = self._validate(valid_data, epoch_no)
  File "/home/lcur0009/joeynmt/joeynmt/training.py", line 642, in _validate
    references=valid_references)
  File "/home/lcur0009/joeynmt/joeynmt/training.py", line 731, in _log_examples
    logger.debug("\tRaw source:     %s", sources_raw[p])
Message: '\tRaw source:     %s'
Arguments: (['\u039f', '\u03c0\u03b1\u03c4@@', '\u03ad\u03c1\u03b1\u03c2', '\u03bc\u03bf\u03c5', '\u03ac@@', '\u03ba\u03bf\u03c5@@', '\u03b3@@', '\u03b5', '\u03c4\u03b1', '\u039d@@', '\u03ad\u03b1', '\u03c4\u03bf\u03c5', 'B@@', 'B@@', 'C', '\u03c3\u03c4\u03bf', '\u03bc\u03b9\u03ba\u03c1\u03cc', '\u03b3@@', '\u03ba\u03c1@@', '\u03b9', '\u03c1\u03b1@@', '\u03b4\u03b9@@', '\u03cc@@', '\u03c6\u03c9\u03bd@@', '\u03cc', '\u03c4\u03bf\u03c5', '.'],)
--- Logging error ---
Traceback (most recent call last):
  File "/sw/arch/Debian10/EB_production/2019/software/Anaconda3/2018.12/lib/python3.7/logging/__init__.py", line 1036, in emit
    stream.write(msg)
UnicodeEncodeError: 'latin-1' codec can't encode character '\u039f' in position 65: ordinal not in range(256)
Call stack:
  File "/sw/arch/Debian10/EB_production/2019/software/Anaconda3/2018.12/lib/python3.7/runpy.py", line 193, in _run_module_as_main
    "__main__", mod_spec)
  File "/sw/arch/Debian10/EB_production/2019/software/Anaconda3/2018.12/lib/python3.7/runpy.py", line 85, in _run_code
    exec(code, run_globals)
  File "/home/lcur0009/joeynmt/joeynmt/__main__.py", line 48, in <module>
    main()
  File "/home/lcur0009/joeynmt/joeynmt/__main__.py", line 35, in main
    train(cfg_file=args.config_path, skip_test=args.skip_test)
  File "/home/lcur0009/joeynmt/joeynmt/training.py", line 846, in train
    trainer.train_and_validate(train_data=train_data, valid_data=dev_data)
  File "/home/lcur0009/joeynmt/joeynmt/training.py", line 497, in train_and_validate
    valid_duration = self._validate(valid_data, epoch_no)
  File "/home/lcur0009/joeynmt/joeynmt/training.py", line 642, in _validate
    references=valid_references)
  File "/home/lcur0009/joeynmt/joeynmt/training.py", line 737, in _log_examples
    logger.info("\tSource:     %s", sources[p])
Message: '\tSource:     %s'
Arguments: ('\u039f \u03c0\u03b1\u03c4\u03ad\u03c1\u03b1\u03c2 \u03bc\u03bf\u03c5 \u03ac\u03ba\u03bf\u03c5\u03b3\u03b5 \u03c4\u03b1 \u039d\u03ad\u03b1 \u03c4\u03bf\u03c5 BBC \u03c3\u03c4\u03bf \u03bc\u03b9\u03ba\u03c1\u03cc \u03b3\u03ba\u03c1\u03b9 \u03c1\u03b1\u03b4\u03b9\u03cc\u03c6\u03c9\u03bd\u03cc \u03c4\u03bf\u03c5 .',)
2021-10-03 13:28:28,228 - INFO - joeynmt.training - 	Source:     \u039f \u03c0\u03b1\u03c4\u03ad\u03c1\u03b1\u03c2 \u03bc\u03bf\u03c5 \u03ac\u03ba\u03bf\u03c5\u03b3\u03b5 \u03c4\u03b1 \u039d\u03ad\u03b1 \u03c4\u03bf\u03c5 BBC \u03c3\u03c4\u03bf \u03bc\u03b9\u03ba\u03c1\u03cc \u03b3\u03ba\u03c1\u03b9 \u03c1\u03b1\u03b4\u03b9\u03cc\u03c6\u03c9\u03bd\u03cc \u03c4\u03bf\u03c5 .
2021-10-03 13:28:28,229 - INFO - joeynmt.training - 	Reference:  "My father was listening to BBC News on his small , gray radio ."
2021-10-03 13:28:28,229 - INFO - joeynmt.training - 	Hypothesis: He was a group of the first . &quot; &quot; Aeds , and I was a srit .
2021-10-03 13:28:28,229 - INFO - joeynmt.training - Validation result (greedy) at epoch  18, step     1100: bleu:   4.79, loss: 75042.7969, ppl: 125.3205, duration: 3.3994s
2021-10-03 13:28:36,538 - INFO - joeynmt.training - Epoch  18: total training loss 5347.78
2021-10-03 13:28:36,539 - INFO - joeynmt.training - EPOCH 19
2021-10-03 13:28:49,365 - INFO - joeynmt.training - Epoch  19: total training loss 5253.87
2021-10-03 13:28:49,365 - INFO - joeynmt.training - EPOCH 20
2021-10-03 13:28:53,295 - WARNING - sacrebleu - That's 100 lines that end in a tokenized period ('.')
2021-10-03 13:28:53,295 - WARNING - sacrebleu - It looks like you forgot to detokenize your test data, which may hurt your score.
2021-10-03 13:28:53,295 - WARNING - sacrebleu - If you insist your data is detokenized, or don't care, you can suppress this message with the `force` parameter.
2021-10-03 13:28:53,303 - INFO - joeynmt.training - Example #0
2021-10-03 13:28:53,303 - INFO - joeynmt.training - 	Source:     el
2021-10-03 13:28:53,303 - INFO - joeynmt.training - 	Reference:  en
2021-10-03 13:28:53,303 - INFO - joeynmt.training - 	Hypothesis: Thank you .
2021-10-03 13:28:53,303 - INFO - joeynmt.training - Example #1
--- Logging error ---
Traceback (most recent call last):
  File "/sw/arch/Debian10/EB_production/2019/software/Anaconda3/2018.12/lib/python3.7/logging/__init__.py", line 1036, in emit
    stream.write(msg)
UnicodeEncodeError: 'latin-1' codec can't encode characters in position 73-76: ordinal not in range(256)
Call stack:
  File "/sw/arch/Debian10/EB_production/2019/software/Anaconda3/2018.12/lib/python3.7/runpy.py", line 193, in _run_module_as_main
    "__main__", mod_spec)
  File "/sw/arch/Debian10/EB_production/2019/software/Anaconda3/2018.12/lib/python3.7/runpy.py", line 85, in _run_code
    exec(code, run_globals)
  File "/home/lcur0009/joeynmt/joeynmt/__main__.py", line 48, in <module>
    main()
  File "/home/lcur0009/joeynmt/joeynmt/__main__.py", line 35, in main
    train(cfg_file=args.config_path, skip_test=args.skip_test)
  File "/home/lcur0009/joeynmt/joeynmt/training.py", line 846, in train
    trainer.train_and_validate(train_data=train_data, valid_data=dev_data)
  File "/home/lcur0009/joeynmt/joeynmt/training.py", line 497, in train_and_validate
    valid_duration = self._validate(valid_data, epoch_no)
  File "/home/lcur0009/joeynmt/joeynmt/training.py", line 642, in _validate
    references=valid_references)
  File "/home/lcur0009/joeynmt/joeynmt/training.py", line 731, in _log_examples
    logger.debug("\tRaw source:     %s", sources_raw[p])
Message: '\tRaw source:     %s'
Arguments: (['"\u038c\u03c4\u03b1\u03bd', '\u03ae\u03bc\u03bf\u03c5\u03bd', '1@@', '1', ',', '\u0398@@', '\u03c5@@', '\u03bc\u03ac@@', '\u03bc\u03b1\u03b9', '\u03c0\u03c9\u03c2', '\u03be@@', '\u03cd\u03c0@@', '\u03bd\u03b7@@', '\u03c3\u03b1', '\u03ad\u03bd\u03b1', '\u03c0\u03c1\u03c9@@', '\u03af', '\u03bc\u03b5', '\u03ae@@', '\u03c7@@', '\u03bf\u03c5\u03c2', '\u03c7\u03b1\u03c1@@', '\u03ac\u03c2', '\u03c3\u03c4\u03bf', '\u03c3\u03c0\u03af\u03c4\u03b9', '."'],)
--- Logging error ---
Traceback (most recent call last):
  File "/sw/arch/Debian10/EB_production/2019/software/Anaconda3/2018.12/lib/python3.7/logging/__init__.py", line 1036, in emit
    stream.write(msg)
UnicodeEncodeError: 'latin-1' codec can't encode characters in position 66-69: ordinal not in range(256)
Call stack:
  File "/sw/arch/Debian10/EB_production/2019/software/Anaconda3/2018.12/lib/python3.7/runpy.py", line 193, in _run_module_as_main
    "__main__", mod_spec)
  File "/sw/arch/Debian10/EB_production/2019/software/Anaconda3/2018.12/lib/python3.7/runpy.py", line 85, in _run_code
    exec(code, run_globals)
  File "/home/lcur0009/joeynmt/joeynmt/__main__.py", line 48, in <module>
    main()
  File "/home/lcur0009/joeynmt/joeynmt/__main__.py", line 35, in main
    train(cfg_file=args.config_path, skip_test=args.skip_test)
  File "/home/lcur0009/joeynmt/joeynmt/training.py", line 846, in train
    trainer.train_and_validate(train_data=train_data, valid_data=dev_data)
  File "/home/lcur0009/joeynmt/joeynmt/training.py", line 497, in train_and_validate
    valid_duration = self._validate(valid_data, epoch_no)
  File "/home/lcur0009/joeynmt/joeynmt/training.py", line 642, in _validate
    references=valid_references)
  File "/home/lcur0009/joeynmt/joeynmt/training.py", line 737, in _log_examples
    logger.info("\tSource:     %s", sources[p])
Message: '\tSource:     %s'
Arguments: ('"\u038c\u03c4\u03b1\u03bd \u03ae\u03bc\u03bf\u03c5\u03bd 11 , \u0398\u03c5\u03bc\u03ac\u03bc\u03b1\u03b9 \u03c0\u03c9\u03c2 \u03be\u03cd\u03c0\u03bd\u03b7\u03c3\u03b1 \u03ad\u03bd\u03b1 \u03c0\u03c1\u03c9\u03af \u03bc\u03b5 \u03ae\u03c7\u03bf\u03c5\u03c2 \u03c7\u03b1\u03c1\u03ac\u03c2 \u03c3\u03c4\u03bf \u03c3\u03c0\u03af\u03c4\u03b9 ."',)
2021-10-03 13:28:53,305 - INFO - joeynmt.training - 	Source:     "\u038c\u03c4\u03b1\u03bd \u03ae\u03bc\u03bf\u03c5\u03bd 11 , \u0398\u03c5\u03bc\u03ac\u03bc\u03b1\u03b9 \u03c0\u03c9\u03c2 \u03be\u03cd\u03c0\u03bd\u03b7\u03c3\u03b1 \u03ad\u03bd\u03b1 \u03c0\u03c1\u03c9\u03af \u03bc\u03b5 \u03ae\u03c7\u03bf\u03c5\u03c2 \u03c7\u03b1\u03c1\u03ac\u03c2 \u03c3\u03c4\u03bf \u03c3\u03c0\u03af\u03c4\u03b9 ."
2021-10-03 13:28:53,306 - INFO - joeynmt.training - 	Reference:  "When I was 11 , I remember waking up one morning to the sound of joy in my house ."
2021-10-03 13:28:53,306 - INFO - joeynmt.training - 	Hypothesis: "And I was a child , I was a little bit of my school , I was a lot of time ."
2021-10-03 13:28:53,306 - INFO - joeynmt.training - Example #2
--- Logging error ---
Traceback (most recent call last):
  File "/sw/arch/Debian10/EB_production/2019/software/Anaconda3/2018.12/lib/python3.7/logging/__init__.py", line 1036, in emit
    stream.write(msg)
UnicodeEncodeError: 'latin-1' codec can't encode character '\u039f' in position 72: ordinal not in range(256)
Call stack:
  File "/sw/arch/Debian10/EB_production/2019/software/Anaconda3/2018.12/lib/python3.7/runpy.py", line 193, in _run_module_as_main
    "__main__", mod_spec)
  File "/sw/arch/Debian10/EB_production/2019/software/Anaconda3/2018.12/lib/python3.7/runpy.py", line 85, in _run_code
    exec(code, run_globals)
  File "/home/lcur0009/joeynmt/joeynmt/__main__.py", line 48, in <module>
    main()
  File "/home/lcur0009/joeynmt/joeynmt/__main__.py", line 35, in main
    train(cfg_file=args.config_path, skip_test=args.skip_test)
  File "/home/lcur0009/joeynmt/joeynmt/training.py", line 846, in train
    trainer.train_and_validate(train_data=train_data, valid_data=dev_data)
  File "/home/lcur0009/joeynmt/joeynmt/training.py", line 497, in train_and_validate
    valid_duration = self._validate(valid_data, epoch_no)
  File "/home/lcur0009/joeynmt/joeynmt/training.py", line 642, in _validate
    references=valid_references)
  File "/home/lcur0009/joeynmt/joeynmt/training.py", line 731, in _log_examples
    logger.debug("\tRaw source:     %s", sources_raw[p])
Message: '\tRaw source:     %s'
Arguments: (['\u039f', '\u03c0\u03b1\u03c4@@', '\u03ad\u03c1\u03b1\u03c2', '\u03bc\u03bf\u03c5', '\u03ac@@', '\u03ba\u03bf\u03c5@@', '\u03b3@@', '\u03b5', '\u03c4\u03b1', '\u039d@@', '\u03ad\u03b1', '\u03c4\u03bf\u03c5', 'B@@', 'B@@', 'C', '\u03c3\u03c4\u03bf', '\u03bc\u03b9\u03ba\u03c1\u03cc', '\u03b3@@', '\u03ba\u03c1@@', '\u03b9', '\u03c1\u03b1@@', '\u03b4\u03b9@@', '\u03cc@@', '\u03c6\u03c9\u03bd@@', '\u03cc', '\u03c4\u03bf\u03c5', '.'],)
--- Logging error ---
Traceback (most recent call last):
  File "/sw/arch/Debian10/EB_production/2019/software/Anaconda3/2018.12/lib/python3.7/logging/__init__.py", line 1036, in emit
    stream.write(msg)
UnicodeEncodeError: 'latin-1' codec can't encode character '\u039f' in position 65: ordinal not in range(256)
Call stack:
  File "/sw/arch/Debian10/EB_production/2019/software/Anaconda3/2018.12/lib/python3.7/runpy.py", line 193, in _run_module_as_main
    "__main__", mod_spec)
  File "/sw/arch/Debian10/EB_production/2019/software/Anaconda3/2018.12/lib/python3.7/runpy.py", line 85, in _run_code
    exec(code, run_globals)
  File "/home/lcur0009/joeynmt/joeynmt/__main__.py", line 48, in <module>
    main()
  File "/home/lcur0009/joeynmt/joeynmt/__main__.py", line 35, in main
    train(cfg_file=args.config_path, skip_test=args.skip_test)
  File "/home/lcur0009/joeynmt/joeynmt/training.py", line 846, in train
    trainer.train_and_validate(train_data=train_data, valid_data=dev_data)
  File "/home/lcur0009/joeynmt/joeynmt/training.py", line 497, in train_and_validate
    valid_duration = self._validate(valid_data, epoch_no)
  File "/home/lcur0009/joeynmt/joeynmt/training.py", line 642, in _validate
    references=valid_references)
  File "/home/lcur0009/joeynmt/joeynmt/training.py", line 737, in _log_examples
    logger.info("\tSource:     %s", sources[p])
Message: '\tSource:     %s'
Arguments: ('\u039f \u03c0\u03b1\u03c4\u03ad\u03c1\u03b1\u03c2 \u03bc\u03bf\u03c5 \u03ac\u03ba\u03bf\u03c5\u03b3\u03b5 \u03c4\u03b1 \u039d\u03ad\u03b1 \u03c4\u03bf\u03c5 BBC \u03c3\u03c4\u03bf \u03bc\u03b9\u03ba\u03c1\u03cc \u03b3\u03ba\u03c1\u03b9 \u03c1\u03b1\u03b4\u03b9\u03cc\u03c6\u03c9\u03bd\u03cc \u03c4\u03bf\u03c5 .',)
2021-10-03 13:28:53,307 - INFO - joeynmt.training - 	Source:     \u039f \u03c0\u03b1\u03c4\u03ad\u03c1\u03b1\u03c2 \u03bc\u03bf\u03c5 \u03ac\u03ba\u03bf\u03c5\u03b3\u03b5 \u03c4\u03b1 \u039d\u03ad\u03b1 \u03c4\u03bf\u03c5 BBC \u03c3\u03c4\u03bf \u03bc\u03b9\u03ba\u03c1\u03cc \u03b3\u03ba\u03c1\u03b9 \u03c1\u03b1\u03b4\u03b9\u03cc\u03c6\u03c9\u03bd\u03cc \u03c4\u03bf\u03c5 .
2021-10-03 13:28:53,308 - INFO - joeynmt.training - 	Reference:  "My father was listening to BBC News on his small , gray radio ."
2021-10-03 13:28:53,308 - INFO - joeynmt.training - 	Hypothesis: Some : Srki was a first . &quot; &quot; Wove the first of the world .
2021-10-03 13:28:53,308 - INFO - joeynmt.training - Validation result (greedy) at epoch  20, step     1200: bleu:   4.96, loss: 75022.7266, ppl: 125.1587, duration: 3.3311s
2021-10-03 13:29:07,074 - INFO - joeynmt.training - Epoch  20: total training loss 5149.15
2021-10-03 13:29:07,075 - INFO - joeynmt.training - Training ended after  20 epochs.
2021-10-03 13:29:07,075 - INFO - joeynmt.training - Best validation result (greedy) at step     1000:   5.22 eval_metric.
2021-10-03 13:29:07,104 - INFO - joeynmt.prediction - Process device: cuda, n_gpu: 1, batch_size per device: 80
2021-10-03 13:29:07,104 - INFO - joeynmt.prediction - Loading model from models/LSTM_el/1000.ckpt
2021-10-03 13:29:07,426 - INFO - joeynmt.model - Building an encoder-decoder model...
2021-10-03 13:29:07,951 - INFO - joeynmt.model - Enc-dec model built.
2021-10-03 13:29:08,005 - INFO - joeynmt.prediction - Decoding on dev set (../2DL4NLP/all_data/el.en_s/val.bpe.en_s)...
2021-10-03 13:29:14,530 - WARNING - sacrebleu - That's 100 lines that end in a tokenized period ('.')
2021-10-03 13:29:14,531 - WARNING - sacrebleu - It looks like you forgot to detokenize your test data, which may hurt your score.
2021-10-03 13:29:14,531 - WARNING - sacrebleu - If you insist your data is detokenized, or don't care, you can suppress this message with the `force` parameter.
2021-10-03 13:29:14,534 - INFO - joeynmt.prediction -  dev bleu[13a]:   5.50 [Beam search decoding with beam size = 5 and alpha = 1.0]
2021-10-03 13:29:14,537 - INFO - joeynmt.prediction - Translations saved to: models/LSTM_el/00001000.hyps.dev
2021-10-03 13:29:14,537 - INFO - joeynmt.prediction - Decoding on test set (../2DL4NLP/all_data/el.en_s/test.bpe.en_s)...
2021-10-03 13:29:21,792 - WARNING - sacrebleu - That's 100 lines that end in a tokenized period ('.')
2021-10-03 13:29:21,793 - WARNING - sacrebleu - It looks like you forgot to detokenize your test data, which may hurt your score.
2021-10-03 13:29:21,793 - WARNING - sacrebleu - If you insist your data is detokenized, or don't care, you can suppress this message with the `force` parameter.
2021-10-03 13:29:21,797 - INFO - joeynmt.prediction - test bleu[13a]:   6.19 [Beam search decoding with beam size = 5 and alpha = 1.0]
2021-10-03 13:29:21,800 - INFO - joeynmt.prediction - Translations saved to: models/LSTM_el/00001000.hyps.test
